Workbook

Sheet ВОР 2 э. шт.
B1: Ведомость работ и используемых материалов (Штукатурка)
A2: № п.п. | B2: Наименование | C2: Ед. изм. | D2: Коэф. расхода | E2: Объем
A3: 1 | B3: Оклейка швов сопряжения бетонных и других поверхностей стен, перегородок (газобетон, ПГП, панели АКОТЕК и др.) стеклохолстом | C3: пог. м | D3: 1 | E3: =(E6+E11+E16+E21)/100 * 71 -> 2378.7414
A4: 1.2 | B4: Шпаклевка гипсовая | C4: кг | D4: 0.3 | E4: =D4*E3 -> 713.62242
A5: 1.3 | B5: Лента армирующая ( серпянка)_/150мм | C5: пог. м | D5: 1.1 | E5: =D5*E3 -> 2616.6155
A6: 2 | B6: Штукатурка стен цементным, цементно-песчаным раствором с предварительной огрунтовкой / толщ. от 21 до 40 мм / высотой от 4,01 до 8 метров - ЧСТ-1 | C6: м2 | D6: 1 | E6: ='Спец 2 э. шт.'!C45 -> 907.3512
A7: 2.1 | B7: Штукатурка цементная | C7: кг | D7: 1.3 | E7: =$E$6*D7*23.077 -> 27220.627
A8: 2.2 | B8: Сетка штукатурная_/пластиковая/10*10 | C8: м2 | D8: 1.1 | E8: =$E$6*D8 -> 998.08632
A9: 2.3 | B9: Профиль маячковый_/ПМ10 | C9: пог. м | D9: 1 | E9: =$E$6*D9 -> 907.3512
A10: 2.4 | B10: Грунтовка БЕТОН-КОНТАКТ_/ | C10: кг | D10: 0.25 | E10: =$E$6*D10 -> 226.8378
A11: 3 | B11: Штукатурка стен цементным, цементно-песчаным раствором с предварительной огрунтовкой / толщ. от 21 до 40 мм / высотой от 4,01 до 8 метров - СТ-5, СТ-5.1 | C11: м2 | D11: 1 | E11: ='Спец 2 э. шт.'!E45 -> 62.38
A12: 3.1 | B12: Грунтовка БЕТОН-КОНТАКТ_/ | C12: кг | D12: 0.25 | E12: =E11*D12 -> 15.595
A13: 3.2 | B13: Профиль маячковый_/ПМ10 | C13: пог. м | D13: 1 | E13: =E11*D13 -> 62.38
A14: 3.3 | B14: Сетка штукатурная_/пластиковая/10*10 | C14: м2 | D14: 1.1 | E14: =E11*D14 -> 68.618
A15: 3.4 | B15: Штукатурка цементная | C15: кг | D15: 1.3 | E15: =E11*D15*23.077 -> 1871.4062
A16: 4 | B16: Штукатурка стен цементным, цементно-песчаным раствором с предварительной огрунтовкой / толщ. от 21 до 40 мм / высотой от 4,01 до 8 метров - СТ-8, СТ-8.1 | C16: м2 | D16: 1 | E16: ='Спец 2 э. шт.'!F45 -> 619.28
A17: 4.1 | B17: Штукатурка цементная | C17: кг | D17: 1.3 | E17: =E16*D17*23.077 -> 18578.462
A18: 4.2 | B18: Сетка штукатурная_/пластиковая/10*10 | C18: м2 | D18: 1.1 | E18: =E16*D18 -> 681.208
A19: 4.3 | B19: Профиль маячковый_/ПМ10 | C19: пог. м | D19: 1 | E19: =E16*D19 -> 619.28
A20: 4.4 | B20: Грунтовка БЕТОН-КОНТАКТ_/ | C20: кг | D20: 0.25 | E20: =E16*D20 -> 154.82
A21: 5 | B21: Штукатурка стен цементным, цементно-песчаным раствором с предварительной огрунтовкой / толщ. от 21 до 40 мм / высотой от 4,01 до 8 метров - ЧСТ-2, ЧСТ-4 | C21: м2 | D21: 1 | E21: ='Спец 2 э. шт.'!D45 -> 1761.3288
A22: 5.1 | B22: Грунтовка универсальный ЛАСТИМИН_ / LP-51 А | C22: кг | D22: 0.15 | E22: =E21*D22 -> 264.19932
A23: 5.2 | B23: Профиль маячковый_/ПМ10 | C23: пог. м | D23: 1 | E23: =E21*D23 -> 1761.3288
A24: 5.3 | B24: Сетка штукатурная_/пластиковая/10*10 | C24: м2 | D24: 1.1 | E24: =E21*D24 -> 1937.4617
A25: 5.4 | B25: Штукатурка цементная | C25: кг | D25: 1.3 | E25: =E21*D25*23.077 -> 52840.04
A26: 6 | B26: Профиль углозащ. оцинков. 31х31 мм 0.5 мм | C26: пог. м | D26: 1 | E26: 315

Sheet 11.2КрсИнв
A2: № п.п. | B2: Наименование | H2: Описание | J2: Ед. изм. | K2: Объем
A3: 1 | B3: Лакокрасочные работы СКБ / окраска стен / в 2 слоя | H3: СТ-6.2 RAL | J3: м2 | K3: =SUM(C11:C17,G11:G20,K11:K21) -> 708.53
A4: 2 | B4: Лакокрасочные работы СКБ / окраска стен / в 2 слоя | H4: СТ-6.3 RAL | J4: м2 | K4: =C18+G21+K22 -> 143.3
A5: 3 | B5: Лакокрасочные работы СКБ / окраска стен / в 2 слоя | H5: СТ-6.4 RAL | J5: м2 | K5: =C19+C20 -> 59.8
A6: 4 | B6: Лакокрасочные работы СКБ / окраска стен / в 2 слоя | H6: СТ-6.6 RAL | J6: м2 | K6: =G22+K23 -> 19.8
A7: 5 | B7: Лакокрасочные работы СКБ / окраска стен / в 2 слоя | H7: СТ-6.8 RAL | J7: м2 | K7: =C21+G23+K24+K25 -> 104.6
A8: 6 | B8: Лакокрасочные работы СКБ / окраска стен / в 2 слоя | H8: СТ-6.9 RAL | J8: м2 | K8: =C22+C23+G24+G25+G26+K26+K27+K28 -> 184.4
A10: Пом. | B10: Тип | C10: Площадь | E10: Пом. | F10: Тип | G10: Площадь | I10: Пом. | J10: Тип | K10: Площадь
A11: 1.027 | B11: 6.2 | C11: 24.5 | E11: 2.001 | F11: 6.2 | G11: 26.8 | I11: 3.001 | J11: 6.2 | K11: 26.3
A12: 1.028 | B12: 6.2 | C12: 25.5 | E12: 2.002 | F12: 6.2 | G12: 27.7 | I12: 3.002 | J12: 6.2 | K12: 26
A13: 1.029 | B13: 6.2 | C13: 25.53 | E13: 2.003 | F13: 6.2 | G13: 26.3 | I13: 3.003 | J13: 6.2 | K13: 26.9
A14: 1.030 | B14: 6.2 | C14: 25.5 | E14: 2.007 | F14: 6.2 | G14: 30.2 | I14: 3.004 | J14: 6.2 | K14: 26.5
A15: 1.031 | B15: 6.2 | C15: 25.6 | E15: 2.008 | F15: 6.2 | G15: 27.7 | I15: 3.008 | J15: 6.2 | K15: 26.9
A16: 1.032 | B16: 6.2 | C16: 24.1 | E16: 2.009 | F16: 6.2 | G16: 27.7 | I16: 3.009 | J16: 6.2 | K16: 26.9
A17: 1.033 | B17: 6.2 | C17: 25.5 | E17: 2.010 | F17: 6.2 | G17: 25.5 | I17: 3.010 | J17: 6.2 | K17: 27
A18: 1.026 | B18: 6.3 | C18: 45.4 | E18: 2.011 | F18: 6.2 | G18: 27.7 | I18: 3.011 | J18: 6.2 | K18: 24.8
A19: 1.040 | B19: 6.4 | C19: 39.6 | E19: 2.013 | F19: 6.2 | G19: 27.7 | I19: 3.012 | J19: 6.2 | K19: 27
A20: 1.043 | B20: 6.4 | C20: 20.2 | E20: 2.166 | F20: 6.2 | G20: 9.9 | I20: 3.013 | J20: 6.2 | K20: 26.9
A21: 1.046 | B21: 6.8 | C21: 29.6 | E21: 2.004 | F21: 6.3 | G21: 56 | I21: 3.097 | J21: 6.2 | K21: 9.9
A22: 1.046 | B22: 6.9 | C22: 11.2 | E22: 2.167 | F22: 6.6 | G22: 9.9 | I22: 3.005 | J22: 6.3 | K22: 41.9
A23: 1.039 | B23: 6.9 | C23: 29.2 | E23: 2.075 | F23: 6.8 | G23: 24.8 | I23: 3.096 | J23: 6.6 | K23: 9.9
E24: 2.012 | F24: 6.9 | G24: 29.2 | I24: 3.020 | J24: 6.8 | K24: 30.7
E25: 2.080 | F25: 6.9 | G25: 27.6 | I25: 3.077.2 | J25: 6.8 | K25: 19.5
E26: 2.082 | F26: 6.9 | G26: 10.4 | I26: 3.014 | J26: 6.9 | K26: 29.2
I27: 3.019 | J27: 6.9 | K27: 36.8
I28: 3.020 | J28: 6.9 | K28: 10.8

Sheet 11.1КрсИнв
A1: Ведомость работ
A2: № п.п. | B2: Наименование | E2: Описание | F2: Ед. изм. | G2: Объем
A3: 1 | B3: Лакокрасочные работы СКБ / окраска стен / в 2 слоя | E3: СТ-6 / КМ1 / RAL 9003 / Белый / 1, 2, 3 этаж, блок 1, 4.1 | F3: м2 | G3: =C15 -> 8639.8
A4: 2 | B4: Лакокрасочные работы СКБ / окраска стен / в 2 слоя | E4: СТ-6 / КМ1 / RAL 9003 / Белый / АРОР АЙСИБИ/МФ-СТРОЙ. 2 этаж, блок 5 | F4: м2 | G4: =C20 -> 2701.3
A5: 3 | B5: Лакокрасочные работы СКБ / окраска стен / в 2 слоя | E5: СТ-7 / КМ0 / RAL 9003 / Белый / 1, 2, 3 этаж, блок 1, 4.1 | F5: м2 | G5: =D15 -> 776.5
A6: 4 | B6: Лакокрасочные работы СКБ / окраска стен / в 2 слоя | E6: СТ-7 / КМ0 / RAL 9003 / Белый / АРОР АЙСИБИ/МФ-СТРОЙ. 2 этаж, блок 5 | F6: м2 | G6: =D20 -> 924.1
A8: Этаж | B8: Блок | C8: Площадь, м2 СТ-6 / КМ1 | D8: Площадь, м2 СТ-7 / КМ0
A9: 1 | B9: 1 | C9: 1467.2 | D9: 0
A10: 1 | B10: 4.1 | C10: 1223.8 | D10: 0
A11: 2 | B11: 1 | C11: 1536.1 | D11: 50.7
A12: 2 | B12: 4.1 | C12: 2008.3 | D12: 408.6
A13: 3 | B13: 1 | C13: 1763.1 | D13: 48.9
A14: 3 | B14: 4.1 | C14: 641.3 | D14: 268.3
B15: Итог | C15: =SUM(C9:C14) -> 8639.8 | D15: =SUM(D9:D14) -> 776.5
A17: Этаж | B17: Блок | C17: Площадь, м2 СТ-6 / КМ1 | D17: Площадь, м2 СТ-7 / КМ0
A18: 2 | B18: 5 | C18: 2701.3 | D18: 513.9
A19: 3 | B19: 5 | C19: 0 | D19: 410.2
B20: Итог | C20: =SUM(C18:C19) -> 2701.3 | D20: =SUM(D18:D19) -> 924.1

Sheet 10.6-ШтрбНЗ
A1: Наименование работ | B1: Кол-во штроб, шт. | C1: Длина, м.п. | E1: Наименование работ | G1: Ширина, мм | H1: Длина, м.п. | I1: S шпакл, м2
A2: Заделка штроб 1 этаж 1 блок | B2: =F17 -> 3 | C2: =G17 -> 10 | E2: Шпаклевка штроб 1 этаж 1 блок | G2: 200 | H2: =C2 -> 10 | I2: =H2/5 -> 2
A3: Заделка штроб 2 этаж 1 блок | B3: =F24 -> 6 | C3: =G24 -> 14 | E3: Шпаклевка штроб 2 этаж 1 блок | G3: 200 | H3: =C3 -> 14 | I3: =H3/5 -> 2.8
A4: Заделка штроб 3 этаж 1 блок | B4: =F31 -> 12 | C4: =G31 -> 36 | E4: Шпаклевка штроб 3 этаж 1 блок | G4: 200 | H4: =C4 -> 36 | I4: =H4/5 -> 7.2
A5: Заделка штроб 1 этаж 4.1 блок | B5: =F43 -> 106 | C5: =G43 -> 328 | E5: Шпаклевка штроб 1 этаж 4.1 блок | G5: 200 | H5: =C5 -> 328 | I5: =H5/5 -> 65.6
A6: Заделка штроб 2 этаж 4.1 блок | B6: =F55 -> 109 | C6: =G55 -> 513 | E6: Шпаклевка штроб 2 этаж 4.1 блок | G6: 200 | H6: =C6 -> 513 | I6: =H6/5 -> 102.6
A7: Заделка штроб 3 этаж 4.1 блок | B7: =F65 -> 40 | C7: =G65 -> 116 | E7: Шпаклевка штроб 3 этаж 4.1 блок | G7: 200 | H7: =C7 -> 116 | I7: =H7/5 -> 23.2
A8: Заделка штроб 2 этаж 5 блок | B8: =F78 -> 81 | C8: =G78 -> 575 | E8: Шпаклевка штроб 2 этаж 5 блок | G8: 200 | H8: =C8 -> 575 | I8: =H8/5 -> 115
A9: Заделка штроб 3 этаж 5 блок | B9: =F86 -> 5 | C9: =G86 -> 30 | E9: Шпаклевка штроб 3 этаж 5 блок | G9: 200 | H9: =C9 -> 30 | I9: =H9/5 -> 6
A10: Итого: | B10: =SUM(B2:B9) -> 362 | C10: =SUM(C2:C9) -> 1622 | E10: Итого: | H10: =SUM(H2:H9) -> 1622 | I10: =SUM(I2:I9) -> 324.4
A12: 1 этаж 1 блок
A13: Штробы
A14: Наименование | B14: Длина, м.п. | C14: Глубина, см | E14: Ширина, см | F14: Кол-во | G14: Длина итого | H14: S шпакл, м2
A15: №1 | B15: 2 | C15: 3 | E15: 3 | F15: 1 | G15: =B15*F15 -> 2 | H15: =G15/5 -> 0.4
A16: №2 | B16: 4 | C16: 3 | E16: 3 | F16: 2 | G16: =B16*F16 -> 8 | H16: =G16/5 -> 1.6
A17: Итого 1 этаж | F17: =SUM(F15:F16) -> 3 | G17: =SUM(G15:G16) -> 10 | H17: =SUM(H15:H16) -> 2
A19: 2 этаж 1 блок
A20: Штробы
A21: Наименование | B21: Длина, м.п. | C21: Глубина, см | E21: Ширина, см | F21: Кол-во | G21: Длина итого | H21: S шпакл, м2
A22: №1 | B22: 2 | C22: 3 | E22: 3 | F22: 5 | G22: =B22*F22 -> 10 | H22: =G22/5 -> 2
A23: №2 | B23: 4 | C23: 3 | E23: 3 | F23: 1 | G23: =B23*F23 -> 4 | H23: =G23/5 -> 0.8
A24: Итого 2 этаж | F24: =SUM(F22:F23) -> 6 | G24: =SUM(G22:G23) -> 14 | H24: =SUM(H22:H23) -> 2.8
A26: 3 этаж 1 блок
A27: Штробы
A28: Наименование | B28: Длина, м.п. | C28: Глубина, см | E28: Ширина, см | F28: Кол-во | G28: Длина итого | H28: S шпакл, м2
A29: №1 | B29: 2 | C29: 3 | E29: 3 | F29: 6 | G29: =B29*F29 -> 12 | H29: =G29/5 -> 2.4
A30: №2 | B30: 4 | C30: 3 | E30: 3 | F30: 6 | G30: =B30*F30 -> 24 | H30: =G30/5 -> 4.8
A31: Итого 3 этаж | F31: =SUM(F29:F30) -> 12 | G31: =SUM(G29:G30) -> 36 | H31: =SUM(H29:H30) -> 7.2
A33: 1 этаж 4.1 блок
A34: Штробы
A35: Наименование | B35: Длина, м.п. | C35: Глубина, см | E35: Ширина, см | F35: Кол-во | G35: Длина итого | H35: S шпакл, м2
A36: №1 | B36: 1 | C36: 3 | E36: 3 | F36: 14 | G36: =B36*F36 -> 14 | H36: =G36/5 -> 2.8
A37: №2 | B37: 2 | C37: 3 | E37: 3 | F37: 40 | G37: =B37*F37 -> 80 | H37: =G37/5 -> 16
A38: №3 | B38: 3 | C38: 3 | E38: 3 | F38: 11 | G38: =B38*F38 -> 33 | H38: =G38/5 -> 6.6
A39: №4 | B39: 4 | C39: 3 | E39: 3 | F39: 26 | G39: =B39*F39 -> 104 | H39: =G39/5 -> 20.8
A40: №5 | B40: 5 | C40: 3 | E40: 3 | F40: 7 | G40: =B40*F40 -> 35 | H40: =G40/5 -> 7
A41: №7 | B41: 7 | C41: 3 | E41: 3 | F41: 2 | G41: =B41*F41 -> 14 | H41: =G41/5 -> 2.8
A42: №8 | B42: 8 | C42: 3 | E42: 3 | F42: 6 | G42: =B42*F42 -> 48 | H42: =G42/5 -> 9.6
A43: Итого 3 этаж | F43: =SUM(F36:F42) -> 106 | G43: =SUM(G36:G42) -> 328 | H43: =SUM(H36:H42) -> 65.6
A45: 2 этаж 4.1 блок
...

Sheet 10.5Плн
A1: Ведомость работ
A2: № п.п. | B2: Наименование | G2: Описание | H2: Ед. изм. | I2: Объем
A3: 1 | B3: Штукатурка откосов гипсовыми смесями с предварительной огрунтовкой СКБ / толщ. от 21 до 40 мм / высотой от 4,01 до 8 метров | G3: Откосы | H3: м2 | I3: =G14 -> 883.757
A4: 2 | B4: Подготовка поверхности СКБ / октосов / по штукатурке / 2мм | G4: откосы / шпаклевка базовая | H4: м2 | I4: =I3 -> 883.757
A5: 3 | B5: Подготовка поверхности СКБ / октосов / по штукатурке / 2мм | G5: откосы / шпаклевка финишная | H5: м2 | I5: =I4 -> 883.757
A7: Этаж | B7: Блок | C7: Площадь, м2 (h = ср 3.7 | D7: Площадь (h = ср 7.7) | G7: Итог, м2:
A8: 1 | B8: 4.1 | C8: =3.7*(61.12-16) -> 166.944 | D8: 0 | G8: =SUM(C8:F8) -> 166.944
A9: 2 | B9: 4.1 | C9: =3.7*31.76 -> 117.512 | D9: =11.8*8 -> 94.4 | G9: =SUM(C9:F9) -> 211.912
A10: 2 | B10: 5 | C10: =1.7*3.8 -> 6.46 | D10: =7.6*43.73 -> 332.348 | G10: =SUM(C10:F10) -> 338.808
A11: 3 | B11: 1 | C11: =3.7*2.09 -> 7.733 | D11: 0 | G11: =SUM(C11:F11) -> 7.733
A12: 3 | B12: 4.1 | C12: =3.7*41.2 -> 152.44 | D12: 0 | G12: =SUM(C12:F12) -> 152.44
A13: 3 | B13: 5 | C13: =3.7*1.6 -> 5.92 | D13: 0 | G13: =SUM(C13:F13) -> 5.92
B14: Итог | C14: =SUM(C8:C13) -> 457.009 | D14: =SUM(D8:D13) -> 426.748 | G14: =SUM(G8:G13) -> 883.757

Sheet 10.4Лбк
A1: Ведомость работ
A2: № п.п. | B2: Наименование | F2: Ед. изм. | G2: Объем
A3: 1 | B3: Устройство перегородок на металлическом каркасе по системе Knauf / C-111 | F3: м2 | G3: 130.3
A4: 2 | B4: Выравнивание поверхностей откосов толщ. до 5 мм с предварительной огрунтовкой поверхности / базовая шпаклевка | F4: м2 | G4: =D38 -> 187.8689
A5: 3 | B5: Выравнивание поверхностей откосов толщ. до 5 мм с предварительной огрунтовкой поверхности / финишная шпаклевка | F5: м2 | G5: =G4 -> 187.8689
A6: 4 | B6: Лакокрасочные работы СКБ / откосов в 2 слоя | F6: м2 | G6: =G4 -> 187.8689
A8: № п.п. | B8: Пом | C8: Длина п.м: | D8: Объем, м2:
A9: 1 | B9: 1.027 | C9: 15 | D9: =C9*0.5+C9*0.1+C9*0.08 -> 10.2
A10: 2 | B10: 1.028 | C10: 9.07 | D10: =C10*0.5+C10*0.1+C10*0.08 -> 6.1676
A11: 3 | B11: 1.029 | C11: 9.09 | D11: =C11*0.5+C11*0.1+C11*0.08 -> 6.1812
A12: 4 | B12: 1.030 | C12: 9.1 | D12: =C12*0.5+C12*0.1+C12*0.08 -> 6.188
A13: 5 | B13: 1.031 | C13: 9.1 | D13: =C13*0.5+C13*0.1+C13*0.08 -> 6.188
A14: 6 | B14: 1.032 | C14: 9.1 | D14: =C14*0.5+C14*0.1+C14*0.08 -> 6.188
A15: 7 | B15: 1.033 | C15: =8.9+9.3 -> 18.2 | D15: =C15*0.5+C15*0.1+C15*0.08 -> 12.376
A16: 8 | B16: 1.049 | C16: 8.9 | D16: =C16*0.5+C16*0.1+C16*0.08 -> 6.052
A17: 9 | B17: 1.050 | C17: 2.34 | D17: =C17*0.5+C17*0.1+C17*0.08 -> 1.5912
A18: 10 | B18: 1.051 | C18: 3.04 | D18: =C18*0.5+C18*0.1+C18*0.08 -> 2.0672
A19: 11 | B19: 2.001 | C19: 9.8 | D19: =C19*0.5+C19*0.1+C19*0.08 -> 6.664
A20: 12 | B20: 2.002 | C20: 9.6 | D20: =C20*0.5+C20*0.1+C20*0.08 -> 6.528
A21: 13 | B21: 2.003 | C21: 9.08 | D21: =C21*0.5+C21*0.1+C21*0.08 -> 6.1744
A22: 14 | B22: 2.007 | C22: 9.09 | D22: =C22*0.5+C22*0.1+C22*0.08 -> 6.1812
A23: 15 | B23: 2.008 | C23: 9.1 | D23: =C23*0.5+C23*0.1+C23*0.08 -> 6.188
A24: 16 | B24: 2.009 | C24: 9.1 | D24: =C24*0.5+C24*0.1+C24*0.08 -> 6.188
A25: 17 | B25: 2.010 | C25: 9.1 | D25: =C25*0.5+C25*0.1+C25*0.08 -> 6.188
A26: 18 | B26: 2.011 | C26: 9.09 | D26: =C26*0.5+C26*0.1+C26*0.08 -> 6.1812
A27: 19 | B27: 2.013 | C27: 9.07 | D27: =C27*0.5+C27*0.1+C27*0.08 -> 6.1676
... A31: 23 | B31: 3.004 | C31: 9.07 | D31: =C31*0.5+C31*0.1+C31*0.08 -> 6.1676
A32: 24 | B32: 3.008 | C32: 9.09 | D32: =C32*0.5+C32*0.1+C32*0.08-0.01 -> 6.1712
A33: 25 | B33: 3.009 | C33: 9.1 | D33: =C33*0.5+C33*0.1+C33*0.08 -> 6.188
A34: 26 | B34: 3.010 | C34: 9.1 | D34: =C34*0.5+C34*0.1+C34*0.075 -> 6.1425
A35: 27 | B35: 3.011 | C35: 9.1 | D35: =C35*0.5+C35*0.1+C35*0.075 -> 6.1425
A36: 28 | B36: 3.012 | C36: 9.1 | D36: =C36*0.5+C36*0.1+C36*0.075 -> 6.1425
A37: 29 | B37: 3.013 | C37: 9.08 | D37: =C37*0.5+C37*0.1+C37*0.075 -> 6.129
A38: Итог: | C38: =SUM(C9:C37) -> 276.56 | D38: =SUM(D9:D37) -> 187.8689

Sheet 10.2Кр8в
A1: Ведомость работ
A2: № п.п. | B2: Наименование | G2: Описание | H2: Ед. изм. | I2: Объем
A3: 1 | B3: Лакокрасочные работы СКБ / окраска стен / в 2 слоя | G3: 2 этаж, блок 5 | H3: м2 | I3: =B8 -> 1346.8005
A5: № пом. | B5: Площадь, м2.
A6: 2.114 | B6: 610.49
A7: 2.115 | B7: 736.3105
B8: =SUM(B6:B7) -> 1346.8005

Sheet 10.1Шп8в
A1: Ведомость работ
A2: № п.п. | B2: Наименование | G2: Описание | H2: Ед. изм. | I2: Объем
A3: 1 | B3: Подготовка поверхности СКБ / стен / по штукатурке / 2мм | G3: Тип стен: ЧСТ-2.1 (шпаклевка базовая) | H3: м2 | I3: =B16 -> 3167.869
A4: 2 | B4: Подготовка поверхности СКБ / стен / по штукатурке / 2мм | G4: Тип стен: ЧСТ-2.1, шпаклевка финишна | H4: м2 | I4: =I3 -> 3167.869
A6: № пом. | B6: Площадь, м2. | C6: Ц
A7: 2.111 | B7: 590.3885
A8: 2.112 | B8: 141.96
A9: 2.114 | B9: 610.49
A10: 2.115 | B10: 736.3105
A11: 2.116 | B11: 184.6
A12: 2.117 | B12: 714.72
A13: 2.118 | B13: 94.2
A14: 2.166 | B14: 42.8
A15: 2.167 | B15: 52.4
B16: =SUM(B7:B15) -> 3167.869

Sheet 9.1.1ММПЛес
A1: Ведомость работ
A2: № п.п. | B2: Наименование затрат | E2: Описание | G2: Ед. изм. | H2: Объем
A3: 1 | B3: Монтаж, демонтаж, аренда строительных лесов | E3: ММП пом. 2.079, 2.068, 3.079 | G3: м2 | H3: =C9 -> 825
A5: № п.п. | B5: Пом | C5: Объем, м2:
A6: 1 | B6: 2.068 | C6: =7.5*2*11 + 5 * 2 * 4 + 10 * 2 * 2.5 -> 255
A7: 2 | B7: 2.079 | C7: =7.5*2*11+5*2*4+2.5*2*17 -> 290
A8: 2 | B8: 3.079 | C8: =7.5*2*10+5*2*4+2.5*2*18 -> 280
A9: Итог: | C9: =SUM(C6:C8) -> 825

Sheet 9.1ММП
A1: Ведомость работ
A2: № п.п. | B2: Наименование затрат | E2: Описание | G2: Ед. изм. | H2: Объем
A3: 1 | B3: Облицовка стен по системе Knauf / С-625 / в 1 слой с утеплением/ А-19 | E3: Устройство акустических панелей в ММП пом. 2.079, 2.068, 3.079 | G3: м2 | H3: =C9 -> 1106.2
A5: № п.п. | B5: Пом | C5: Объем, м2:
A6: 1 | B6: 2.068 | C6: 357.9
A7: 2 | B7: 2.079 | C7: 391.1
A8: 3 | B8: 3.079 | C8: 357.2
A9: Итог: | C9: =SUM(C6:C8) -> 1106.2

Sheet 8.2
A1: Ведомость работ
A2: № п.п. | B2: Наименование затрат | E2: Описание | G2: Ед. изм. | H2: Объем
A3: 1 | B3: Штукатурка стен цементным, цементно-песчаным раствором с предварительной огрунтовкой | E3: 1, 2, 3, этажи, блок 1. Стены | G3: м2 | H3: =H14+C14+C25 -> 868.15
A5: № п.п. | B5: Пом | C5: Объем, м2: | F5: № п.п. | G5: Пом | H5: Объем, м2:
A6: 1 | B6: 1.038 | C6: 37.8 | F6: 1 | G6: 2.162 | H6: 37.9
A7: 2 | B7: 1.034 | C7: 171.77 | F7: 2 | G7: 2.014 | H7: 171.21
A8: 3 | B8: 1.035 | F8: 3 | G8: 2.015
A9: 4 | B9: 1.036 | C9: 52.84 | F9: 4 | G9: 2.016 | H9: 52.61
A10: 5 | B10: 1.037 | F10: 5 | G10: 2.017
A11: 6 | B11: 1.035 | C11: 6.11 | F11: 6 | G11: 2.015 | H11: 6.2
A12: 7 | B12: 1.034 | C12: 22.31 | F12: 7 | G12: 2.014 | H12: 21.96
A13: 8 | B13: 1.036 | F13: 8 | G13: 2.016
A14: Итог: | C14: =SUM(C6:C13) -> 290.83 | F14: Итог: | H14: =SUM(H6:H13) -> 289.88
A16: № п.п. | B16: Пом | C16: Объем, м2:
A17: 1 | B17: 3.092 | C17: 37.8
A18: 2 | B18: 3.015 | C18: 169.27
A19: 3 | B19: 3.016
A20: 4 | B20: 3.017 | C20: 50.21
A21: 5 | B21: 3.018
A22: 6 | B22: 3.016 | C22: 8.11
A23: 7 | B23: 3.015 | C23: 22.05
A24: 8 | B24: 3.017
A25: Итог: | C25: =SUM(C17:C24) -> 287.44

Sheet 8.1
A1: Ведомость работ (С\У)
A2: № п.п. | B2: Поз | C2: Наименование затрат | G2: Описание | I2: Ед. изм. | J2: Объем
A3: 1 | B3: 284 | C3: Облицовка поверхности стен СКБ с затиркой швов / керамической, керамогранитной плиткой до 0,2м2/шт | G3: 1, 2, 3, этажи, блок 1. Стены Тип: СТ-5 | I3: м2 | J3: =D14 -> 113.5
A4: 2 | B4: 289 | C4: Облицовка поверхности стен СКБ с затиркой швов / керамической, керамогранитной плиткой до 0,2м2/шт | G4: 1, 2, 3, этажи, блоки 1 и 4.1. Стены Тип: СТ-8 | I4: м2 | J4: =D23 -> 512.25
A5: 3 | B5: 294 | C5: Облицовка поверхности стен СКБ с затиркой швов / керамической, керамогранитной плиткой до 0,2м2/шт | G5: 1, 2, 3, этажи, блок 1. Стены Тип: СТ-8.1 | I5: м2 | J5: =D32 -> 155.66
A6: 4 | B6: 299 | C6: Облицовка поверхности стен СКБ с затиркой швов / керамической, керамогранитной плиткой до 0,2м2/шт | G6: 1, 2, 3, этажи, блок 1. Стены Тип: СТ-8.2 | I6: м2 | J6: =D38 -> 20.42
A7: 5 | B7: 304 | C7: Облицовка поверхности стен СКБ с затиркой швов / керамической, керамогранитной плиткой до 0,2м2/шт | G7: 1, 2, 3, этажи, блок 1. Стены Тип: СТ-8.3 | I7: м2 | J7: =D47 -> 66.32
A8: Итог: | I8: м2 | J8: =SUM(J3:J7) -> 868.15
A10: № Блок | B10: Пом | C10: Тип | D10: Объем, м2:
A11: 1 | B11: 1.038 | C11: СТ-5 | D11: 37.8
A12: 1 | B12: 2.162 | C12: СТ-5 | D12: 37.9
A13: 1 | B13: 3.092 | C13: СТ-5 | D13: 37.8
C14: Итог: | D14: =SUM(D11:D13) -> 113.5
A16: № Блок | B16: Пом | C16: Тип | D16: Объем, м2:
A17: 1 | B17: 1.034 | C17: СТ-8 | D17: 171.77
A18: 1 | B18: 1.035 | C18: СТ-8
A19: 1 | B19: 2.014 | C19: СТ-8 | D19: 171.21
A20: 1 | B20: 2.015 | C20: СТ-8
A21: 1 | B21: 3.015 | C21: СТ-8 | D21: 169.27
A22: 1 | B22: 3.016 | C22: СТ-8
C23: Итог: | D23: =SUM(D17:D22) -> 512.25
A25: № Блок | B25: Пом | C25: Тип | D25: Объем, м2:
A26: 1 | B26: 1.036 | C26: СТ-8.1 | D26: 52.84
A27: 1 | B27: 1.037 | C27: СТ-8.1
A28: 1 | B28: 2.016 | C28: СТ-8.1 | D28: 52.61
A29: 1 | B29: 2.017 | C29: СТ-8.1
A30: 1 | B30: 3.017 | C30: СТ-8.1 | D30: 50.21
A31: 1 | B31: 3.018 | C31: СТ-8.1
C32: Итог: | D32: =SUM(D26:D31) -> 155.66
A34: № Блок | B34: Пом | C34: Тип | D34: Объем, м2:
A35: 1 | B35: 1.035 | C35: СТ-8.2 | D35: 6.11
A36: 1 | B36: 2.015 | C36: СТ-8.2 | D36: 6.2
A37: 1 | B37: 3.016 | C37: СТ-8.2 | D37: 8.11
C38: Итог: | D38: =SUM(D35:D37) -> 20.42
A40: № Блок | B40: Пом | C40: Тип | D40: Объем, м2:
A41: 1 | B41: 1.034 | C41: СТ-8.3 | D41: 22.31
A42: 1 | B42: 1.036 | C42: СТ-8.3
A43: 1 | B43: 2.014 | C43: СТ-8.3 | D43: 21.96
A44: 1 | B44: 2.016 | C44: СТ-8.3
A45: 1 | B45: 3.015 | C45: СТ-8.3 | D45: 22.05
...

Sheet 5.1Пл6в
A1: Ведомость работ
A2: № п.п. | B2: Поз | C2: Наименование затрат | I2: Описание | K2: Ед. изм. | L2: Объем
A3: 1 | B3: 284 | C3: Облицовка поверхности стен СКБ с затиркой швов / керамической, керамогранитной плиткой до 0,2м2/шт | I3: 1, 2, 3, этажи, блок 1. Стены Тип: СТ-5 | K3: м2 | L3: =D13 -> 113.5
A4: 2 | B4: 289 | C4: Облицовка поверхности стен СКБ с затиркой швов / керамической, керамогранитной плиткой до 0,2м2/шт | I4: 1, 2, 3, этажи, блоки 1 и 4.1. Стены Тип: СТ-8 | K4: м2 | L4: =D22 -> 512.25
A5: 3 | B5: 294 | C5: Облицовка поверхности стен СКБ с затиркой швов / керамической, керамогранитной плиткой до 0,2м2/шт | I5: 1, 2, 3, этажи, блок 1. Стены Тип: СТ-8.1 | K5: м2 | L5: =D31 -> 155.66
A6: 4 | B6: 299 | C6: Облицовка поверхности стен СКБ с затиркой швов / керамической, керамогранитной плиткой до 0,2м2/шт | I6: 1, 2, 3, этажи, блок 1. Стены Тип: СТ-8.2 | K6: м2 | L6: =D37 -> 20.42
A7: 5 | B7: 304 | C7: Облицовка поверхности стен СКБ с затиркой швов / керамической, керамогранитной плиткой до 0,2м2/шт | I7: 1, 2, 3, этажи, блок 1. Стены Тип: СТ-8.3 | K7: м2 | L7: =D46 -> 66.32
A9: № Блок | B9: Пом | C9: Тип | D9: Объем, м2:
A10: 1 | B10: 1.038 | C10: СТ-5 | D10: 37.8
A11: 1 | B11: 2.162 | C11: СТ-5 | D11: 37.9
A12: 1 | B12: 3.092 | C12: СТ-5 | D12: 37.8
C13: Итог: | D13: =SUM(D10:D12) -> 113.5
A15: № Блок | B15: Пом | C15: Тип | D15: Объем, м2:
A16: 1 | B16: 1.034 | C16: СТ-8 | D16: 171.77
A17: 1 | B17: 1.035 | C17: СТ-8
A18: 1 | B18: 2.014 | C18: СТ-8 | D18: 171.21
A19: 1 | B19: 2.015 | C19: СТ-8
A20: 1 | B20: 3.015 | C20: СТ-8 | D20: 169.27
A21: 1 | B21: 3.016 | C21: СТ-8
C22: Итог: | D22: =SUM(D16:D21) -> 512.25
A24: № Блок | B24: Пом | C24: Тип | D24: Объем, м2:
A25: 1 | B25: 1.036 | C25: СТ-8.1 | D25: 52.84
A26: 1 | B26: 1.037 | C26: СТ-8.1
A27: 1 | B27: 2.016 | C27: СТ-8.1 | D27: 52.61
A28: 1 | B28: 2.017 | C28: СТ-8.1
A29: 1 | B29: 3.017 | C29: СТ-8.1 | D29: 50.21
A30: 1 | B30: 3.018 | C30: СТ-8.1
C31: Итог: | D31: =SUM(D25:D30) -> 155.66
A33: № Блок | B33: Пом | C33: Тип | D33: Объем, м2:
A34: 1 | B34: 1.035 | C34: СТ-8.2 | D34: 6.11
A35: 1 | B35: 2.015 | C35: СТ-8.2 | D35: 6.2
A36: 1 | B36: 3.016 | C36: СТ-8.2 | D36: 8.11
C37: Итог: | D37: =SUM(D34:D36) -> 20.42
A39: № Блок | B39: Пом | C39: Тип | D39: Объем, м2:
A40: 1 | B40: 1.034 | C40: СТ-8.3 | D40: 22.31
A41: 1 | B41: 1.036 | C41: СТ-8.3
A42: 1 | B42: 2.014 | C42: СТ-8.3 | D42: 21.96
A43: 1 | B43: 2.016 | C43: СТ-8.3
A44: 1 | B44: 3.015 | C44: СТ-8.3 | D44: 22.05
A45: 1 | B45: 3.017 | C45: СТ-8.3
...

Sheet 4.5ДвОтк
A1: Ведомость работ
A2: № п.п. | B2: Наименование затрат | F2: Ед. изм. | G2: Объем
A3: 1 | B3: Штукатурка стен с предварительной огрунтовкой СКБ | F3: м2 | G3: =G23+G41+G58 -> 111.6085
A4: 2 | B4: Облицовка стен по системе Knauf | F4: м2 | G4: =G3 -> 111.6085
A5: 3 | B5: Подготовка поверхности СКБ / стен / по штукатурке / 2мм / Базовая шпаклевка | F5: м2 | G5: =G3 -> 111.6085
A6: 4 | B6: Подготовка поверхности СКБ / стен / по штукатурке / 2мм / Финишная шпаклевка | F6: м2 | G6: =G3 -> 111.6085
A8: Дверной проём, 1 этаж
A9: № эт. | B9: Тип | C9: Высота, п. м. | D9: Длина, п. м. | E9: Толщина, п. м. | F9: Кол-во, шт. | G9: Площадь, м2.
A10: 1 | B10: ВВ-3 | C10: 2.9 | D10: 2.9 | E10: 0.135 | F10: 8 | G10: =(D10+C10*2)*E10*F10 -> 9.396
A11: 1 | B11: 3 | C11: 1.9 | D11: 0.7 | E11: 0.12 | F11: 9 | G11: =(D11+C11*2)*E11*F11 -> 4.86
A12: 1 | B12: ВВ-6 | C12: 2.8 | D12: 3.1 | E12: 0.13 | F12: 2 | G12: =(D12+C12*2)*E12*F12 -> 2.262
A13: 1 | B13: ВВ-8 | C13: 2.8 | D13: 2 | E13: 0.13 | F13: 1 | G13: =(D13+C13*2)*E13*F13 -> 0.988
A14: 1 | B14: ВВ-9 | C14: 2.8 | D14: 1.65 | E14: 0.13 | F14: 3 | G14: =(D14+C14*2)*E14*F14 -> 2.8275
A15: 1 | B15: ВН-11 | C15: 3.8 | D15: 3.47 | E15: 0.25 | F15: 1 | G15: =(D15+C15*2)*E15*F15 -> 2.7675
A16: 1 | B16: ВВ-12 | C16: 2.1 | D16: 3.6 | E16: 0.13 | F16: 1 | G16: =(D16+C16*2)*E16*F16 -> 1.014
A17: 1 | B17: ВВ-13 | C17: 2.1 | D17: 1.53 | E17: 0.13 | F17: 4 | G17: =(D17+C17*2)*E17*F17 -> 2.9796
A18: 1 | B18: ВВ-14 | C18: 2.1 | D18: 2 | E18: 0.26 | F18: 3 | G18: =(D18+C18*2)*E18*F18 -> 4.836
A19: 1 | B19: ВВ-25 | C19: 2.8 | D19: 1.1 | E19: 0.135 | F19: 4 | G19: =(D19+C19*2)*E19*F19 -> 3.618
A20: 1 | B20: ВВ-26 | C20: 2.1 | D20: 1.1 | E20: 0.13 | F20: 1 | G20: =(D20+C20*2)*E20*F20 -> 0.689
A21: 1 | B21: ДВСОП-2 | C21: 2.1 | D21: 1.5 | E21: 0.13 | F21: 1 | G21: =(D21+C21*2)*E21*F21 -> 0.741
A22: 1 | B22: ДВСОП-1л | C22: 2.1 | D22: 1.8 | E22: 0.13 | F22: 3 | G22: =(D22+C22*2)*E22*F22 -> 2.34
G23: =SUM(G10:G22) -> 39.3186
A25: Дверной проём, 2 этаж
A26: № эт. | B26: Тип | C26: Высота, п. м. | D26: Длина, п. м. | E26: Толщина, п. м. | F26: Кол-во, шт. | G26: Площадь, м2.
A27: 2 | B27: ВВ-3 | C27: 2.9 | D27: 2.9 | E27: 0.135 | F27: 7 | G27: =(D27+C27*2)*E27*F27 -> 8.2215
A28: 2 | B28: 3 | C28: 1.9 | D28: 0.7 | E28: 0.12 | F28: 9 | G28: =(D28+C28*2)*E28*F28 -> 4.86
A29: 1 | B29: ВВ-8 | C29: 2.8 | D29: 2 | E29: 0.13 | F29: 1 | G29: =(D29+C29*2)*E29*F29 -> 0.988
A30: 2 | B30: ВВ-14 | C30: 2.1 | D30: 2 | E30: 0.13 | F30: 1 | G30: =(D30+C30*2)*E30*F30 -> 0.806
A31: 2 | B31: ВВ-18 | C31: 2.8 | D31: 1.8 | E31: 0.13 | F31: 4 | G31: =(D31+C31*2)*E31*F31 -> 3.848
A32: 2 | B32: ВВ-19 | C32: 2.8 | D32: 1.6 | E32: 0.13 | F32: 5 | G32: =(D32+C32*2)*E32*F32 -> 4.68
A33: 2 | B33: ВВ-20 | C33: 2.1 | D33: 1.8 | E33: 0.26 | F33: 3 | G33: =(D33+C33*2)*E33*F33 -> 4.68
A34: 2 | B34: ВВ-25 | C34: 2.8 | D34: 1.1 | E34: 0.135 | F34: 1 | G34: =(D34+C34*2)*E34*F34 -> 0.9045
A35: 2 | B35: ВВ-27 | C35: 2.1 | D35: 1.4 | E35: 0.26 | F35: 1 | G35: =(D35+C35*2)*E35*F35 -> 1.456
A36: 2 | B36: ДВСОП-2 | C36: 2.1 | D36: 1.5 | E36: 0.13 | F36: 1 | G36: =(D36+C36*2)*E36*F36 -> 0.741
A37: 2 | B37: ДВСОП-5 | C37: 2.1 | D37: 1.5 | E37: 0.13 | F37: 4 | G37: =(D37+C37*2)*E37*F37 -> 2.964
A38: 2 | B38: ДВГП-5 | C38: 2.3 | D38: 2.22 | E38: 0.13 | F38: 5 | G38: =(D38+C38*2)*E38*F38 -> 4.433
A39: 2 | B39: ДВСГП-6.1 | C39: 2.1 | D39: 0.95 | E39: 0.13 | F39: 1 | G39: =(D39+C39*2)*E39*F39 -> 0.6695
A40: 2 | B40: ДВСОП-1л | C40: 2.1 | D40: 1.8 | E40: 0.13 | F40: 3 | G40: =(D40+C40*2)*E40*F40 -> 2.34
G41: =SUM(G27:G40) -> 41.5915
A43: Дверной проём, 3 этаж
...

Sheet 4.4дмСт
A1: Ведомость работ
A2: № п.п. | B2: Наименование затрат | E2: Ед. изм. | F2: Объем
A3: 1 | B3: Алмазная резка железобетонных конструкций (учтены расходные материалы)_ / 180 мм | E3: п.м. | F3: =B14 -> 1196.09
A4: 2 | B4: Демонтаж бетона с сохранением арматуры | E4: м3 | F4: =C23 -> 13.4724
A5: 3 | B5: Шлифовка бетона | E5: м2 | F5: =B32 -> 449.08
A7: Алмазная резка
A8: № пом. | B8: Площадь, п. м.
A9: 2.111 | B9: 215.94
A10: 2.114 | B10: 213.56
A11: 2.115 | B11: =267.39 -> 267.39
A12: 2.117 | B12: 425.92
A13: 2.118 | B13: =4*11+6*4.88 -> 73.28
A14: Итог: | B14: =SUM(B9:B13) -> 1196.09
A16: Демонтаж бетона
A17: № пом. | B17: Площадь, м2. | C17: Объем, м3.
A18: 2.111 | B18: 88.86 | C18: =B18*0.03 -> 2.6658
A19: 2.114 | B19: 87.32 | C19: =B19*0.03 -> 2.6196
A20: 2.115 | B20: 108.73 | C20: =B20*0.03 -> 3.2619
A21: 2.117 | B21: 144.65 | C21: =B21*0.03 -> 4.3395
A22: 2.118 | B22: 19.52 | C22: =B22*0.03 -> 0.5856
A23: Итог: | B23: =SUM(B18:B22) -> 449.08 | C23: =SUM(C18:C22) -> 13.4724
A25: Шлифовка бетона
A26: № пом. | B26: Площадь, м2.
A27: 2.111 | B27: 88.86
A28: 2.114 | B28: 87.32
A29: 2.115 | B29: 108.73
A30: 2.117 | B30: 144.65
A31: 2.118 | B31: 19.52
A32: Итог: | B32: =SUM(B27:B31) -> 449.08

Sheet 4.3.3СуШтНЗ
A1: Ведомость работ
A2: № п.п. | B2: Наименование затрат | D2: Ед. изм. | E2: Объем
A3: 1 | B3: Штукатурка стен с/у | D3: м2 | E3: =B13 -> 105.72
A5: Штукатурка стен
A6: № пом. | B6: Площадь, м2.
A7: 1.035 | B7: =(2.47+4.97)*4 -> 29.76
A8: 1.038 | B8: =1.42*4 -> 5.68
A9: 2.015 | B9: =(2.44+4.99)*4 -> 29.72
A10: 2.162 | B10: =1.42*4 -> 5.68
A11: 3.016 | B11: =(2.4+4.9)*4 -> 29.2
A12: 3.092 | B12: =1.42*4 -> 5.68
A13: Итог: | B13: =SUM(B7:B12) -> 105.72

Sheet 4.3.2НарСтНЗ
A1: Ведомость работ
A2: № п.п. | B2: Наименование затрат | H2: Ед. изм. | I2: Объем
A3: 1 | B3: Штукатурка стен гипсовыми смесями | H3: м2 | I3: =B13 -> 117.64
A4: 2 | B4: Подготовка поверхности СКБ / стен. Базовая | H4: м2 | I4: =I3 -> 117.64
A5: 3 | B5: Подготовка поверхности СКБ / стен. Финишная | H5: м2 | I5: =I3 -> 117.64
A6: 4 | B6: Лакокрасочные работы СКБ / окраска стен / в 2 слоя | H6: м2 | I6: =I3 -> 117.64
A8: Объем работ
A9: № эт. | B9: Площадь, м2.
A10: 1 | B10: =10.19*4-1.8*0.6*5 -> 35.36
A11: 2 | B11: =11.66*4-1.8*0.6*5 -> 41.24
A12: 3 | B12: =11.61*4-1.8*0.6*5 -> 41.04
A13: Итог: | B13: =SUM(B10:B12) -> 117.64

Sheet 4.3Мтж
A1: Ведомость работ
A2: № п.п. | B2: Наименование затрат | H2: Ед. изм. | I2: Объем
A3: 1 | B3: Штукатурка стен гипсовыми смесями | H3: м2 | I3: =B13 -> 353.36
A4: 2 | B4: Подготовка поверхности СКБ / стен. Базовая | H4: м2 | I4: =I3 -> 353.36
A5: 3 | B5: Подготовка поверхности СКБ / стен. Финишная | H5: м2 | I5: =I3 -> 353.36
A6: 4 | B6: Лакокрасочные работы СКБ / окраска стен / в 2 слоя | H6: м2 | I6: =I3 -> 353.36
A8: Объем работ
A9: № эт. | B9: Площадь, м2.
A10: 1 | B10: =31.62*4-1.8*0.6*8 -> 117.84
A11: 2 | B11: =30.35*4-1.8*0.6*8 -> 112.76
A12: 3 | B12: =32.85*4-1.8*0.6*8 -> 122.76
A13: Итог: | B13: =SUM(B10:B12) -> 353.36

Sheet 4.2Дм
A1: Ведомость работ
A2: № п.п. | B2: Наименование затрат | H2: Ед. изм. | I2: Объем
A3: 1 | B3: Демонтаж штукатурки | H3: м2 | I3: =B11 -> 222.729
A4: 2 | B4: Демонтаж шпаклевки | H4: м2 | I4: =E11 -> 79.56
A6: Демонтаж штукатурки | D6: Демонтаж шпаклевки
A7: № эт. | B7: Площадь, м2. | D7: № эт. | E7: Площадь, м2.
A8: 1 | B8: =19.43*3.9 -> 75.777 | D8: 1 | E8: =12.18*2 -> 24.36
A9: 2 | B9: =18.89*3.9 -> 73.671 | D9: 2 | E9: =13.18*2 -> 26.36
A10: 3 | B10: =18.79*3.9 -> 73.281 | D10: 3 | E10: =14.42*2 -> 28.84
A11: Итог: | B11: =SUM(B8:B10) -> 222.729 | D11: Итог: | E11: =SUM(E8:E10) -> 79.56

Sheet 4.1-ШтрбНЗ
A1: Наименование работ | B1: Кол-во штроб, шт. | C1: Длина, м.п. | E1: Наименование работ | G1: Ширина, мм | H1: Длина, м.п. | I1: S шпакл, м2
A2: Заделка штроб 1 этаж 1 блок | B2: =F443 -> 224 | C2: =G443 -> 538 | E2: Шпаклевка штроб 1 этаж 1 блок | G2: 200 | H2: =C2 -> 538 | I2: =H2/5 -> 107.6
A3: Заделка штроб 2 этаж 1 блок | B3: =F452 -> 238 | C3: =G452 -> 562 | E3: Шпаклевка штроб 2 этаж 1 блок | G3: 200 | H3: =C3 -> 562 | I3: =H3/5 -> 112.4
A4: Заделка штроб 3 этаж 1 блок | B4: =F460 -> 260 | C4: =G460 -> 604 | E4: Шпаклевка штроб 3 этаж 1 блок | G4: 200 | H4: =C4 -> 604 | I4: =H4/5 -> 120.8
A5: Итого: | B5: =SUM(B2:B4) -> 722 | C5: =SUM(C2:C4) -> 1704 | E5: Итого: | H5: =SUM(H2:H4) -> 1704 | I5: =SUM(I2:I4) -> 340.8
A6: 1 этаж 1 блок
A7: Штробы
A8: Наименование | B8: Длина, м.п. | C8: Глубина, см | E8: Ширина, см | F8: Кол-во | G8: Длина итого | H8: S шпакл, м2
A9: 1 | B9: 5 | C9: 3 | E9: 3 | F9: 1 | G9: =B9*F9 -> 5
A10: 2 | B10: 4
A11: 3 | B11: 2
A12: 4 | B12: 1
A13: 5 | B13: 6
A14: 6 | B14: 8
A15: 7 | B15: 4
A16: 8 | B16: 2
A17: 9 | B17: 4
A18: 10 | B18: 1
A19: 11 | B19: 1
A20: 12 | B20: 5
A21: 13 | B21: 6
... A133: 125 | B133: 30
A137: 2 этаж 1 блок
A138: Штробы
A139: Наименование | B139: Длина, м.п. | C139: Глубина, см | E139: Ширина, см | F139: Кол-во | G139: Длина итого | H139: S шпакл, м2
A140: 1 | B140: 5
A141: 2 | B141: 4
A142: 3 | B142: 2
A143: 4 | B143: 1
A144: 5 | B144: 6
A145: 6 | B145: 8
A146: 7 | B146: 4
A147: 8 | B147: 2
A148: 9 | B148: 4
A149: 10 | B149: 1
A150: 11 | B150: 1
A151: 12 | B151: 5
... A185: 46 | B185: 6
A186: 47
A187: 48 | B187: 4
...

Sheet Лист3
A1: 3 этаж 1 блок
A2: Штробы
A3: Наименование | B3: Длина, м.п. | C3: Глубина, см | E3: Ширина, см | F3: Кол-во | G3: Длина итого | H3: S шпакл, м2
A4: №1 | B4: 1 | C4: 3 | E4: 3 | F4: 13 | G4: =B4*F4 -> 13 | H4: =G4/5 -> 2.6
A5: №2 | B5: 2 | C5: 3 | E5: 3 | F5: 26 | G5: =B5*F5 -> 52 | H5: =G5/5 -> 10.4
A6: №3 | B6: 3 | C6: 3 | E6: 3 | F6: 10 | G6: =B6*F6 -> 30 | H6: =G6/5 -> 6
A7: №4 | B7: 4 | C7: 3 | E7: 3 | F7: 29 | G7: =B7*F7 -> 116 | H7: =G7/5 -> 23.2
A8: №5 | B8: 5 | C8: 3 | E8: 3 | F8: 21 | G8: =B8*F8 -> 105 | H8: =G8/5 -> 21
A9: №6 | B9: 6 | C9: 3 | E9: 3 | F9: 14 | G9: =B9*F9 -> 84 | H9: =G9/5 -> 16.8
A10: №7 | B10: 7 | C10: 3 | E10: 3 | F10: 7 | G10: =B10*F10 -> 49 | H10: =G10/5 -> 9.8
A11: №8 | B11: 8 | C11: 3 | E11: 3 | F11: 12 | G11: =B11*F11 -> 96 | H11: =G11/5 -> 19.2
A12: №9 | B12: 9 | C12: 3 | E12: 3 | F12: 2 | G12: =B12*F12 -> 18 | H12: =G12/5 -> 3.6
A13: №10 | B13: 10 | C13: 3 | E13: 3 | F13: 1 | G13: =B13*F13 -> 10 | H13: =G13/5 -> 2
A14: №11 | B14: 16 | C14: 3 | E14: 3 | F14: 1 | G14: =B14*F14 -> 16 | H14: =G14/5 -> 3.2
A15: №12 | B15: 30 | C15: 3 | E15: 3 | F15: 1 | G15: =B15*F15 -> 30 | H15: =G15/5 -> 6
A16: Итого 3 блок | F16: =SUM(F4:F15) -> 137 | G16: =SUM(G4:G15) -> 619 | H16: =SUM(H4:H15) -> 123.8
A18: 2 этаж 1 блок
A19: Штробы
A20: Наименование | B20: Длина, м.п. | C20: Глубина, см | E20: Ширина, см | F20: Кол-во | G20: Длина итого | H20: S шпакл, м2
A21: №1 | B21: 1 | C21: 3 | E21: 3 | F21: 12 | G21: =B21*F21 -> 12 | H21: =G21/5 -> 2.4
A22: №2 | B22: 2 | C22: 3 | E22: 3 | F22: 23 | G22: =B22*F22 -> 46 | H22: =G22/5 -> 9.2
A23: №3 | B23: 3 | C23: 3 | E23: 3 | F23: 8 | G23: =B23*F23 -> 24 | H23: =G23/5 -> 4.8
A24: №4 | B24: 4 | C24: 3 | E24: 3 | F24: 33 | G24: =B24*F24 -> 132 | H24: =G24/5 -> 26.4
A25: №5 | B25: 5 | C25: 3 | E25: 3 | F25: 19 | G25: =B25*F25 -> 95 | H25: =G25/5 -> 19
A26: №6 | B26: 6 | C26: 3 | E26: 3 | F26: 12 | G26: =B26*F26 -> 72 | H26: =G26/5 -> 14.4
A27: №7 | B27: 7 | C27: 3 | E27: 3 | F27: 5 | G27: =B27*F27 -> 35 | H27: =G27/5 -> 7
A28: №8 | B28: 8 | C28: 3 | E28: 3 | F28: 11 | G28: =B28*F28 -> 88 | H28: =G28/5 -> 17.6
A29: №9 | B29: 9 | C29: 3 | E29: 3 | F29: 2 | G29: =B29*F29 -> 18 | H29: =G29/5 -> 3.6
A30: №10 | B30: 10 | C30: 3 | E30: 3 | F30: 1 | G30: =B30*F30 -> 10 | H30: =G30/5 -> 2
A31: №11 | B31: 30 | C31: 3 | E31: 3 | F31: 1 | G31: =B31*F31 -> 30 | H31: =G31/5 -> 6
A32: Итого 2 блок | F32: =SUM(F21:F31) -> 127 | G32: =SUM(G21:G31) -> 562 | H32: =SUM(H21:H31) -> 112.4
A35: 1 этаж 1 блок
A36: Штробы
A37: Наименование | B37: Длина, м.п. | C37: Глубина, см | E37: Ширина, см | F37: Кол-во | G37: Длина итого | H37: S шпакл, м2
A38: №1 | B38: 1 | C38: 3 | E38: 3 | F38: 18 | G38: =B38*F38 -> 18 | H38: =G38/5 -> 3.6
A39: №2 | B39: 2 | C39: 3 | E39: 3 | F39: 19 | G39: =B39*F39 -> 38 | H39: =G39/5 -> 7.6
A40: №3 | B40: 3 | C40: 3 | E40: 3 | F40: 13 | G40: =B40*F40 -> 39 | H40: =G40/5 -> 7.8
A41: №4 | B41: 4 | C41: 3 | E41: 3 | F41: 21 | G41: =B41*F41 -> 84 | H41: =G41/5 -> 16.8
A42: №5 | B42: 5 | C42: 3 | E42: 3 | F42: 20 | G42: =B42*F42 -> 100 | H42: =G42/5 -> 20
A43: №6 | B43: 6 | C43: 3 | E43: 3 | F43: 13 | G43: =B43*F43 -> 78 | H43: =G43/5 -> 15.6
...

Sheet 3.3ШпФн6в
A1: Ведомость работ
A2: № п.п. | B2: Поз. | C2: Наименование затрат | I2: Описание | K2: Ед. изм. | L2: Объем
A3: 1 | B3: 234 | C3: Подготовка поверхности СКБ / стен / по штукатурке / 2мм | I3: Блок 1. 1, 2, 3, этажи. Шпаклевка финишная. | K3: м2 | L3: =B9+E11+J9 -> 2842.0023
A5: № пом. | B5: Площадь, м2. | D5: № пом. | E5: Площадь, м2. | I5: № пом. | J5: Площадь, м2.
A6: 1.026 | B6: =269.907 -> 269.907 | D6: 2.004 | E6: =227.3762+5 -> 232.3762 | I6: 3.005 | J6: =257.62 -> 257.62
A7: 1.039 | B7: =348.711 -> 348.711 | D7: 2.012 | E7: =293.7626+5 -> 298.7626 | I7: 3.014 | J7: =332.8605 -> 332.8605
A8: 1.024 | B8: =14.72*4-1.35*2.1-1.5*2.2 -> 52.745 | D8: 2.005 | E8: =52.595 -> 52.595 | I8: 3.006 | J8: =52.895 -> 52.895
A9: Итог: | B9: =SUM(B6:B8) -> 671.363 | D9: 2.081 | E9: =529.498+15.4 -> 544.898 | I9: Итог: | J9: =SUM(J6:J8) -> 643.3755
D10: 2.085 | E10: =388.632+10 -> 398.632
D11: Итог: | E11: =SUM(E6:E10) -> 1527.2638

Sheet 3.2ШпФин
A1: Ведомость работ
A2: № п.п. | B2: Поз. | C2: Наименование затрат | I2: Описание | K2: Ед. изм. | L2: Объем
A3: 1 | B3: 234 | C3: Подготовка поверхности СКБ / стен / по штукатурке / 2мм | I3: Блок 1. 1, 2, 3, этажи. Шпаклевка финишная. | K3: м2 | L3: =B13+E15+J16 -> 2873.96
A5: № пом. | B5: Площадь, м2. | D5: № пом. | E5: Площадь, м2. | I5: № пом. | J5: Площадь, м2.
A6: 1.027 | B6: 125.55 | D6: 2.001 | E6: 118.18 | I6: 3.004 | J6: 116.51
A7: 1.028 | B7: 118.27 | D7: 2.002 | E7: 113.74 | I7: 3.008 | J7: 102.57
A8: 1.029 | B8: 102.42 | D8: 2.003 | E8: 122.5 | I8: 3.009 | J8: 104.7
A9: 1.030 | B9: 101.91 | D9: 2.007 | E9: 106.77 | I9: 3.010 | J9: 101.61
A10: 1.031 | B10: 98.2 | D10: 2.008 | E10: 111.51 | I10: 3.011 | J10: 105.25
A11: 1.032 | B11: 94.76 | D11: 2.009 | E11: 106.77 | I11: 3.012 | J11: 105.33
A12: 1.033 | B12: 152.44 | D12: 2.010 | E12: 93.03 | I12: 3.013 | J12: 101.95
A13: Итог: | B13: =SUM(B6:B12) -> 793.55 | D13: 2.011 | E13: 106.64 | I13: 3.003 | J13: 105.79
D14: 2.013 | E14: 83.2 | I14: 3.002 | J14: 105.58
D15: Итог: | E15: =SUM(E6:E14) -> 962.34 | I15: 3.001 | J15: 168.78
I16: Итог: | J16: =SUM(J6:J15) -> 1118.07

Sheet 2.6ЧСТ3
A1: Ведомость работ
A2: № п.п. | B2: Поз | C2: Наименование затрат | I2: Описание | K2: Ед. изм. | L2: Объем
A3: 1 | B3: 214 | C3: Подготовка поверхности СКБ / стен / ГКЛ, ПГП / 2мм | I3: ЧСТ-3 | K3: м2 | L3: =B9 -> 458.76
A5: Этаж | B5: Площадь, м2.
A6: 1 | B6: =4*40.94 -> 163.76
A7: 2 | B7: =4*42 -> 168
A8: 3 | B8: =4*31.75 -> 127
B9: =SUM(B6:B8) -> 458.76

Sheet 1.7ГКЛ
A1: Ведомость работ
A2: № п.п. | B2: Наименование затрат | H2: Описание | J2: Ед. изм. | K2: Объем
A3: 1 | B3: Облицовка стен по системе Knauf / С-626 / в 2 слоя / А-6, А-9 | H3: Блок 1, блок 4.1 1 ,2, 3 этаж Обшивка стояков и коллекторов | J3: м2 | K3: =B9 -> 127.953
A5: Этаж | B5: Площадь, м2.
A6: 1 | B6: =10.47*3.9-1.72*3.9+1.72*0.8+1.99*3.9 -> 43.262
A7: 2 | B7: =10.37*3.9-1.72*3.9+1.72*0.8+1.99*3.9 -> 42.872
A8: 3 | B8: =10.1*3.9-1.72*3.9+1.72*0.8+1.99*3.9 -> 41.819
A9: Итог: | B9: =SUM(B6:B8) -> 127.953

Sheet 2.5Шт5блСпртЗл
A1: Ведомость работ
A2: № п.п. | B2: Наименование затрат | H2: Описание | J2: Ед. изм. | K2: Объем
A3: 1 | B3: Штукатурка стен гипсовыми смесями с предварительной огрунтовкой СКБ / толщ. от 21 до 40 мм / высотой от 4,01 до 8 метров | H3: АРОР АЙСИБИ/МФ-СТРОЙ. 2 этаж, блок 5, пом. 2.111, 2.112, 2.114, 2.115, 2.116, 2.117, 2.118, 2.166, 2.167. Тип стен: ЧСТ-2.1 | J3: м2 | K3: =C15 -> 3167.869
A5: № пом. | B5: Тип | C5: Площадь, м2.
A6: 2.111 | B6: ЧСТ-2.1 | C6: 590.3885
A7: 2.112 | B7: ЧСТ-2.1 | C7: 141.96
A8: 2.114 | B8: ЧСТ-2.1 | C8: 610.49
A9: 2.115 | B9: ЧСТ-2.1 | C9: 736.3105
A10: 2.116 | B10: ЧСТ-2.1 | C10: 184.6
A11: 2.117 | B11: ЧСТ-2.1 | C11: 714.72
A12: 2.118 | B12: ЧСТ-2.1 | C12: 94.2
A13: 2.166 | B13: ЧСТ-2.1 | C13: 42.8
A14: 2.167 | B14: ЧСТ-2.1 | C14: 52.4
B15: Итог: | C15: =SUM(C6:C14) -> 3167.869

Sheet Спец 2 э. шт.
A1: Спецификация выполненных работ
A2: Штукатурка стен
C3: ЧСТ-1 | D3: ЧСТ-2, ЧСТ-4 | E3: СТ-5, СТ-5.1 | F3: СТ-8, СТ-8.1 | G3: Итог | J3: ТИП | K3: длина полилинии | L3: *4000
A4: № п.п. | B4: Помещения: | C4: Объем, м² | D4: Объем, м² | E4: Объем, м² | F4: Объем, м² | G4: Объем, м² | O4: Минус окна
A5: 1 | B5: 2.001 | C5: =P5/100*34 -> 40.18035 | D5: =P5/100*66 -> 77.99715 | G5: =SUM(C5:F5) -> 118.1775 | J5: чст-1,2 | K5: 31886.422 | L5: 4000 | M5: =ROUND(K5*L5/1000000, 2) -> 127.55 | O5: 15 | P5: =(M5-O5) / 100 * 5 + (M5-O5) -> 118.1775
A6: 2 | B6: 2.002 | C6: =P6/100*34 -> 38.67024 | D6: =P6/100*66 -> 75.06576 | G6: =SUM(C6:F6) -> 113.736 | K6: 30830.74 | L6: 4000 | M6: =ROUND(K6*L6/1000000, 2) -> 123.32 | O6: 15 | P6: =(M6-O6) / 100 * 5 + (M6-O6) -> 113.736
A7: 3 | B7: 2.003 | C7: =P7/100*34 -> 41.65119 | D7: =P7/100*66 -> 80.85231 | G7: =SUM(C7:F7) -> 122.5035 | K7: 32917.397 | L7: 4000 | M7: =ROUND(K7*L7/1000000, 2) -> 131.67 | O7: 15 | P7: =(M7-O7) / 100 * 5 + (M7-O7) -> 122.5035
A8: 4 | B8: 2.004 | C8: =P8/100*34 -> 106.96434 | D8: =P8/100*66 -> 207.63666 | G8: =SUM(C8:F8) -> 314.601 | K8: 78654.636 | L8: 4000 | M8: =ROUND(K8*L8/1000000, 2) -> 314.62 | O8: 15 | P8: =(M8-O8) / 100 * 5 + (M8-O8) -> 314.601
A9: 5 | B9: 2.005 | C9: =P9/100*34 -> 10.07454 | D9: =P9/100*66 -> 19.55646 | G9: =SUM(C9:F9) -> 29.631 | K9: 12056 | L9: 4000 | M9: =ROUND(K9*L9/1000000, 2) -> 48.22 | O9: 20 | P9: =(M9-O9) / 100 * 5 + (M9-O9) -> 29.631
A10: 6 | B10: 2.007 | C10: =P10/100*34 -> 36.30333 | D10: =P10/100*66 -> 70.47117 | G10: =SUM(C10:F10) -> 106.7745 | K10: 30423 | L10: 4000 | M10: =ROUND(K10*L10/1000000, 2) -> 121.69 | O10: 20 | P10: =(M10-O10) / 100 * 5 + (M10-O10) -> 106.7745
A11: 7 | B11: 2.008 | C11: =P11/100*34 -> 37.9134 | D11: =P11/100*66 -> 73.5966 | G11: =SUM(C11:F11) -> 111.51 | K11: 31549 | L11: 4000 | M11: =ROUND(K11*L11/1000000, 2) -> 126.2 | O11: 20 | P11: =(M11-O11) / 100 * 5 + (M11-O11) -> 111.51
A12: 8 | B12: 2.009 | C12: =P12/100*34 -> 36.30333 | D12: =P12/100*66 -> 70.47117 | G12: =SUM(C12:F12) -> 106.7745 | K12: 30423 | L12: 4000 | M12: =ROUND(K12*L12/1000000, 2) -> 121.69 | O12: 20 | P12: =(M12-O12) / 100 * 5 + (M12-O12) -> 106.7745
A13: 9 | B13: 2.010 | C13: =P13/100*34 -> 31.6302 | D13: =P13/100*66 -> 61.3998 | G13: =SUM(C13:F13) -> 93.03 | K13: 27149 | L13: 4000 | M13: =ROUND(K13*L13/1000000, 2) -> 108.6 | O13: 20 | P13: =(M13-O13) / 100 * 5 + (M13-O13) -> 93.03
A14: 10 | B14: 2.011 | C14: =P14/100*34 -> 36.25692 | D14: =P14/100*66 -> 70.38108 | G14: =SUM(C14:F14) -> 106.638 | K14: 30390 | L14: 4000 | M14: =ROUND(K14*L14/1000000, 2) -> 121.56 | O14: 20 | P14: =(M14-O14) / 100 * 5 + (M14-O14) -> 106.638
A15: 11 | B15: 2.012 | C15: =P15/100*34 -> 79.80735 | D15: =P15/100*66 -> 154.92015 | G15: =SUM(C15:F15) -> 234.7275 | K15: 59638 | L15: 4000 | M15: =ROUND(K15*L15/1000000, 2) -> 238.55 | O15: 15 | P15: =(M15-O15) / 100 * 5 + (M15-O15) -> 234.7275
A16: 12 | B16: 2.013 | C16: =P16/100*34 -> 28.28868 | D16: =P16/100*66 -> 54.91332 | G16: =SUM(C16:F16) -> 83.202 | K16: 24809 | L16: 4000 | M16: =ROUND(K16*L16/1000000, 2) -> 99.24 | O16: 20 | P16: =(M16-O16) / 100 * 5 + (M16-O16) -> 83.202
A17: 13 | B17: 2.014 | F17: 69.49 | G17: =SUM(C17:F17) -> 69.49 | J17: СТ-8, СТ-8.1 | K17: 18723 | L17: 4000 | M17: =ROUND(K17*L17/1000000, 2) -> 74.89 | O17: 5.4 | P17: =(M17-O17) / 100 * 5 + (M17-O17) -> 72.9645
A18: 14 | B18: 2.015 | F18: 87.93 | G18: =SUM(C18:F18) -> 87.93 | J18: СТ-8, СТ-8.1 | K18: 23333 | L18: 4000 | M18: =ROUND(K18*L18/1000000, 2) -> 93.33 | O18: 5.4 | P18: =(M18-O18) / 100 * 5 + (M18-O18) -> 92.3265
A19: 15 | B19: 2.016 | F19: 33.98 | G19: =SUM(C19:F19) -> 33.98 | J19: СТ-8, СТ-8.1 | K19: 8495 | L19: 4000 | M19: =ROUND(K19*L19/1000000, 2) -> 33.98 | P19: =(M19-O19) / 100 * 5 + (M19-O19) -> 35.679
A20: 16 | B20: 2.017 | F20: 16.4 | G20: =SUM(C20:F20) -> 16.4 | J20: СТ-8, СТ-8.1 | K20: 4100 | L20: 4000 | M20: =ROUND(K20*L20/1000000, 2) -> 16.4 | P20: =(M20-O20) / 100 * 5 + (M20-O20) -> 17.22
A21: 17 | B21: 2.162 | E21: 36.46 | G21: =SUM(C21:F21) -> 36.46 | J21: СТ-5, СТ-5.1 | K21: 9115 | L21: 4000 | M21: =ROUND(K21*L21/1000000, 2) -> 36.46 | P21: =(M21-O21) / 100 * 5 + (M21-O21) -> 38.283
A22: 18 | B22: 2.075 | C22: =P22/100*34 -> 96.57921 | D22: =P22/100*66 -> 187.47729 | G22: =SUM(C22:F22) -> 284.0565 | K22: 68290 | L22: 4001 | M22: =ROUND(K22*L22/1000000, 2) -> 273.23 | O22: 2.7 | P22: =(M22-O22) / 100 * 5 + (M22-O22) -> 284.0565
A23: 19 | B23: 2.080 | C23: =P23/100*34 -> 152.13198 | D23: =P23/100*66 -> 295.31502 | G23: =SUM(C23:F23) -> 447.447 | K23: 107884 | L23: 4000 | M23: =ROUND(K23*L23/1000000, 2) -> 431.54 | O23: 5.4 | P23: =(M23-O23) / 100 * 5 + (M23-O23) -> 447.447
A24: 20 | B24: 2.088 | C24: =P24/100*34 -> 18.07848 | D24: =P24/100*66 -> 35.09352 | G24: =SUM(C24:F24) -> 53.172 | K24: 12659 | L24: 4000 | M24: =ROUND(K24*L24/1000000, 2) -> 50.64 | P24: =(M24-O24) / 100 * 5 + (M24-O24) -> 53.172
A25: 21 | B25: 2.089 | F25: 29.16 | G25: =SUM(C25:F25) -> 29.16 | J25: СТ-8, СТ-8.1 | K25: 7290 | L25: 4000 | M25: =ROUND(K25*L25/1000000, 2) -> 29.16 | P25: =(M25-O25) / 100 * 5 + (M25-O25) -> 30.618
A26: 22 | B26: 2.090 | F26: 35.47 | G26: =SUM(C26:F26) -> 35.47 | J26: СТ-8, СТ-8.1 | K26: 8867 | L26: 4000 | M26: =ROUND(K26*L26/1000000, 2) -> 35.47 | P26: =(M26-O26) / 100 * 5 + (M26-O26) -> 37.2435
A27: 23 | B27: 2.091 | F27: 48.34 | G27: =SUM(C27:F27) -> 48.34 | J27: СТ-8, СТ-8.1 | K27: 12084 | L27: 4000 | M27: =ROUND(K27*L27/1000000, 2) -> 48.34 | P27: =(M27-O27) / 100 * 5 + (M27-O27) -> 50.757
A28: 24 | B28: 2.094 | C28: =P28/100*34 -> 15.69372 | D28: =P28/100*66 -> 30.46428 | G28: =SUM(C28:F28) -> 46.158 | K28: =5400+3590+2000 -> 10990 | L28: 4000 | M28: =ROUND(K28*L28/1000000, 2) -> 43.96 | P28: =(M28-O28) / 100 * 5 + (M28-O28) -> 46.158
A29: 25 | B29: 2.095 | F29: 35.2 | G29: =SUM(C29:F29) -> 35.2 | J29: СТ-8, СТ-8.1 | K29: 8800 | L29: 4000 | M29: =ROUND(K29*L29/1000000, 2) -> 35.2 | P29: =(M29-O29) / 100 * 5 + (M29-O29) -> 36.96
A30: 26 | B30: 2.096 | F30: 63.16 | G30: =SUM(C30:F30) -> 63.16 | J30: СТ-8, СТ-8.1 | K30: 15790 | L30: 4000 | M30: =ROUND(K30*L30/1000000, 2) -> 63.16 | P30: =(M30-O30) / 100 * 5 + (M30-O30) -> 66.318
A31: 27 | B31: 2.097 | E31: 13.12 | G31: =SUM(C31:F31) -> 13.12 | J31: СТ-5, СТ-5.1 | K31: =3240+40 -> 3280 | L31: 4000 | M31: =ROUND(K31*L31/1000000, 2) -> 13.12 | P31: =(M31-O31) / 100 * 5 + (M31-O31) -> 13.776
A32: 28 | B32: 2.098 | E32: 12.8 | G32: =SUM(C32:F32) -> 12.8 | J32: СТ-5, СТ-5.1 | K32: 3200 | L32: 4000 | M32: =ROUND(K32*L32/1000000, 2) -> 12.8 | P32: =(M32-O32) / 100 * 5 + (M32-O32) -> 13.44
A33: 29 | B33: 2.099 | C33: =P33/100*34 -> 8.7465 | D33: =P33/100*66 -> 16.9785 | G33: =SUM(C33:F33) -> 25.725 | K33: 6124 | L33: 4000 | M33: =ROUND(K33*L33/1000000, 2) -> 24.5 | P33: =(M33-O33) / 100 * 5 + (M33-O33) -> 25.725
A34: 30 | B34: 2.100 | F34: 44.08 | G34: =SUM(C34:F34) -> 44.08 | J34: СТ-8, СТ-8.1 | K34: 11020 | L34: 4000 | M34: =ROUND(K34*L34/1000000, 2) -> 44.08 | P34: =(M34-O34) / 100 * 5 + (M34-O34) -> 46.284
A35: 31 | B35: 2.101 | F35: 33.04 | G35: =SUM(C35:F35) -> 33.04 | J35: СТ-8, СТ-8.1 | K35: 8260 | L35: 4000 | M35: =ROUND(K35*L35/1000000, 2) -> 33.04 | P35: =(M35-O35) / 100 * 5 + (M35-O35) -> 34.692
A36: 32 | B36: 2.102 | C36: =P36/100*34 -> 10.96704 | D36: =P36/100*66 -> 21.28896 | G36: =SUM(C36:F36) -> 32.256 | K36: 7681 | L36: 4000 | M36: =ROUND(K36*L36/1000000, 2) -> 30.72 | P36: =(M36-O36) / 100 * 5 + (M36-O36) -> 32.256
A37: 33 | B37: 2.103 | C37: =P37/100*34 -> 19.53504 | D37: =P37/100*66 -> 37.92096 | G37: =SUM(C37:F37) -> 57.456 | K37: 13680 | L37: 4000 | M37: =ROUND(K37*L37/1000000, 2) -> 54.72 | P37: =(M37-O37) / 100 * 5 + (M37-O37) -> 57.456
A38: 34 | B38: 2.104 | F38: 15.6 | G38: =SUM(C38:F38) -> 15.6 | J38: СТ-8, СТ-8.1 | K38: 3900 | L38: 4000 | M38: =ROUND(K38*L38/1000000, 2) -> 15.6 | P38: =(M38-O38) / 100 * 5 + (M38-O38) -> 16.38
A39: 35 | B39: 2.105 | F39: 42.99 | G39: =SUM(C39:F39) -> 42.99 | J39: СТ-8, СТ-8.1 | K39: 10748 | L39: 4000 | M39: =ROUND(K39*L39/1000000, 2) -> 42.99 | P39: =(M39-O39) / 100 * 5 + (M39-O39) -> 45.1395
A40: 36 | B40: 2.106 | C40: =P40/100*34 -> 11.3526 | D40: =P40/100*66 -> 22.0374 | G40: =SUM(C40:F40) -> 33.39 | K40: =7500+1800 -> 9300 | L40: 4000 | M40: =ROUND(K40*L40/1000000, 2) -> 37.2 | O40: 5.4 | P40: =(M40-O40) / 100 * 5 + (M40-O40) -> 33.39
...

Sheet ВОР 3 э. шт.
B1: Ведомость работ (Штукатурка)
A2: № п.п. | B2: Наименование | C2: Ед. изм. | D2: Коэф. расхода | E2: Объем
A3: 1 | B3: Оклейка швов сопряжения бетонных и других поверхностей стен, перегородок (газобетон, ПГП, панели АКОТЕК и др.) стеклохолстом | C3: пог. м | D3: 1 | E3: =(E6+E11+E16+E21)/100 * 71 -> 2134.0328
A4: 1.2 | B4: Шпаклевка гипсовая | C4: кг | D4: 0.3 | E4: =D4*E3 -> 640.20984
A5: 1.3 | B5: Лента армирующая ( серпянка)_/150мм | C5: пог. м | D5: 1.1 | E5: =D5*E3 -> 2347.4361
A6: 2 | B6: Штукатурка стен цементным, цементно-песчаным раствором с предварительной огрунтовкой / толщ. от 21 до 40 мм / высотой от 4,01 до 8 метров - ЧСТ-1 | C6: м2 | D6: 1 | E6: ='Спец 3 э. шт.'!C28 -> 840.61
A7: 2.1 | B7: Штукатурка цементная | C7: кг | D7: 1.3 | E7: =$E$6*D7*23.077 -> 25218.384
A8: 2.2 | B8: Сетка штукатурная_/пластиковая/10*10 | C8: м2 | D8: 1.1 | E8: =$E$6*D8 -> 924.671
A9: 2.3 | B9: Профиль маячковый_/ПМ10 | C9: пог. м | D9: 1 | E9: =$E$6*D9 -> 840.61
A10: 2.4 | B10: Грунтовка БЕТОН-КОНТАКТ_/ | C10: кг | D10: 0.25 | E10: =$E$6*D10 -> 210.1525
A11: 3 | B11: Штукатурка стен цементным, цементно-песчаным раствором с предварительной огрунтовкой / толщ. от 21 до 40 мм / высотой от 4,01 до 8 метров - СТ-5, СТ-5.1 | C11: м2 | D11: 1 | E11: ='Спец 3 э. шт.'!E28 -> 38.59
A12: 3.1 | B12: Грунтовка БЕТОН-КОНТАКТ_/ | C12: кг | D12: 0.25 | E12: =E11*D12 -> 9.6475
A13: 3.2 | B13: Профиль маячковый_/ПМ10 | C13: пог. м | D13: 1 | E13: =E11*D13 -> 38.59
A14: 3.3 | B14: Сетка штукатурная_/пластиковая/10*10 | C14: м2 | D14: 1.1 | E14: =E11*D14 -> 42.449
A15: 3.4 | B15: Штукатурка цементная | C15: кг | D15: 1.3 | E15: =E11*D15*23.077 -> 1157.7039
A16: 4 | B16: Штукатурка стен цементным, цементно-песчаным раствором с предварительной огрунтовкой / толщ. от 21 до 40 мм / высотой от 4,01 до 8 метров - СТ-8, СТ-8.1 | C16: м2 | D16: 1 | E16: ='Спец 3 э. шт.'!F28 -> 261.49
A17: 4.1 | B17: Штукатурка цементная | C17: кг | D17: 1.3 | E17: =E16*D17*23.077 -> 7844.7261
A18: 4.2 | B18: Сетка штукатурная_/пластиковая/10*10 | C18: м2 | D18: 1.1 | E18: =E16*D18 -> 287.639
A19: 4.3 | B19: Профиль маячковый_/ПМ10 | C19: пог. м | D19: 1 | E19: =E16*D19 -> 261.49
A20: 4.4 | B20: Грунтовка БЕТОН-КОНТАКТ_/ | C20: кг | D20: 0.25 | E20: =E16*D20 -> 65.3725
A21: 5 | B21: Штукатурка стен цементным, цементно-песчаным раствором с предварительной огрунтовкой / толщ. от 21 до 40 мм / высотой от 4,01 до 8 метров - ЧСТ-2, ЧСТ-4 | C21: м2 | D21: 1 | E21: ='Спец 3 э. шт.'!D28 -> 1864.99
A22: 5.1 | B22: Грунтовка универсальный ЛАСТИМИН_ / LP-51 А | C22: кг | D22: 0.15 | E22: =E21*D22 -> 279.7485
A23: 5.2 | B23: Профиль маячковый_/ПМ10 | C23: пог. м | D23: 1 | E23: =E21*D23 -> 1864.99
A24: 5.3 | B24: Сетка штукатурная_/пластиковая/10*10 | C24: м2 | D24: 1.1 | E24: =E21*D24 -> 2051.489
A25: 5.4 | B25: Штукатурка цементная | C25: кг | D25: 1.3 | E25: =E21*D25*23.077 -> 55949.886
A26: 6 | B26: Профиль углозащ. оцинков. 31х31 мм 0.5 мм | C26: пог. м | D26: 1 | E26: 315

Sheet Спец 3 э. шт.
A1: Спецификация выполненных работ
A2: Штукатурка стен
C3: ЧСТ-1 | D3: ЧСТ-2, ЧСТ-4 | E3: СТ-5, СТ-5.1 | F3: СТ-8, СТ-8.1 | G3: Итог | H3: ЧСТ-1 | I3: вверх блок 300 | J3: ЧСТ-2, ЧСТ-4 | K3: низ 900 ГАЗОБЛОК | L3: Между окнами 2700 | M3: ТИП | N3: БЕТОН | O3: над окнами ЖБ 0.3 | P3: ПГП | Q3: под окнами ПГП 1 | R3: ПГП между окнами | S3: ДВЕРИ В ПГП | T3: ДВЕРИ В ЖБ | U3: длина полилинии | V3: *4000
A4: № п.п. | B4: Помещения: | C4: Объем, м² | D4: Объем, м² | E4: Объем, м² | F4: Объем, м² | G4: Объем, м² | K4: =I4 -> 0 | Y4: Минус окна
A5: 1 | B5: 3.001 | C5: =ROUND(N5+O5-T5, 2) -> 53.82 | D5: =ROUND(P5+Q5+R5-S5, 2) -> 114.96 | G5: =SUM(C5:F5) -> 168.78 | H5: =ROUND(N5+O5-T5, 2) -> 53.82 | I5: =ROUND(P5+Q5+R5-S5, 2) -> 114.96 | K5: =I5 -> 114.96 | M5: чст-1,2 | N5: 50.3955 | O5: 3.42 | P5: 103.56 | Q5: 11.4 | R5: 0 | S5: 0 | T5: 0 | V5: 4000 | W5: =ROUND(U5*V5/1000000, 2) -> 0 | Y5: 15 | Z5: =(W5-Y5) / 100 * 5 + (W5-Y5) -> -15.75
A6: 2 | B6: 3.002 | C6: =ROUND(N6+O6-T6, 2) -> 14.03 | D6: =ROUND(P6+Q6+R6-S6, 2) -> 91.55 | G6: =SUM(C6:F6) -> 105.58 | I6: =6900+1200 -> 8100 | K6: =I6 -> 8100 | N6: 11.6 | O6: 2.43 | P6: 80.12 | Q6: 8.1 | R6: 3.33 | S6: 0 | T6: 0 | U6: 30830.74 | V6: 4000 | W6: =ROUND(U6*V6/1000000, 2) -> 123.32 | Y6: 15 | Z6: =(W6-Y6) / 100 * 5 + (W6-Y6) -> 113.736
A7: 3 | B7: 3.003 | C7: =ROUND(N7+O7-T7, 2) -> 19.86 | D7: =ROUND(P7+Q7+R7-S7, 2) -> 85.93 | G7: =SUM(C7:F7) -> 105.79 | H7: =(900+900+480+900+1200)*4/1000 -> 17.52 | I7: =4300+3500 -> 7800 | J7: =1010+3530+14190 -> 18730 | K7: =I7 -> 7800 | N7: 17.52 | O7: 2.34 | P7: 74.8 | Q7: 7.8 | R7: 3.33 | S7: 0 | T7: 0 | U7: 32917.397 | V7: 4000 | W7: =ROUND(U7*V7/1000000, 2) -> 131.67 | Y7: 15 | Z7: =(W7-Y7) / 100 * 5 + (W7-Y7) -> 122.5035
A8: 4 | B8: 3.004 | C8: =ROUND(N8+O8-T8, 2) -> 45.58 | D8: =ROUND(P8+Q8+R8-S8, 2) -> 70.93 | G8: =SUM(C8:F8) -> 116.51 | H8: =10460*4/1000 -> 41.84 | I8: =3450+3300 -> 6750 | J8: =15250*4/1000 -> 61 | K8: =I8 -> 6750 | N8: 43.6 | O8: 1.98 | P8: 61 | Q8: 6.6 | R8: 3.33 | S8: 0 | T8: 0 | U8: 78654.636 | V8: 4000 | W8: =ROUND(U8*V8/1000000, 2) -> 314.62 | Y8: 15 | Z8: =(W8-Y8) / 100 * 5 + (W8-Y8) -> 314.601
A9: 5 | B9: 3.005 | C9: =ROUND(N9+O9-T9, 2) -> 159.75 | D9: =ROUND(P9+Q9+R9-S9, 2) -> 242.78 | G9: =SUM(C9:F9) -> 402.53 | K9: =I9 -> 0 | N9: 161.94 | O9: 5.23 | P9: 230.3 | Q9: 17.42 | R9: 0 | S9: 4.9351 | T9: 7.4239 | U9: 12056 | V9: 4000 | W9: =ROUND(U9*V9/1000000, 2) -> 48.22 | Y9: 20 | Z9: =(W9-Y9) / 100 * 5 + (W9-Y9) -> 29.631
A10: 6 | B10: 3.006 | C10: =ROUND(N10+O10-T10, 2) -> 33.93 | D10: =ROUND(P10+Q10+R10-S10, 2) -> 14.8 | G10: =SUM(C10:F10) -> 48.73 | K10: =I10 -> 0 | N10: 41.35 | O10: 0 | P10: 14.8 | Q10: 0 | R10: 0 | S10: 0 | T10: 7.42 | U10: 30423 | V10: 4000 | W10: =ROUND(U10*V10/1000000, 2) -> 121.69 | Y10: 20 | Z10: =(W10-Y10) / 100 * 5 + (W10-Y10) -> 106.7745
A11: 7 | B11: 3.008 | C11: =ROUND(N11+O11-T11, 2) -> 34.19 | D11: =ROUND(P11+Q11+R11-S11, 2) -> 68.38 | G11: =SUM(C11:F11) -> 102.57 | K11: =I11 -> 0 | N11: 32.05 | O11: 2.14 | P11: 57.92 | Q11: 7.13 | R11: 3.33 | S11: 0 | T11: 0 | U11: 30423 | V11: 4000 | W11: =ROUND(U11*V11/1000000, 2) -> 121.69 | Y11: 20 | Z11: =(W11-Y11) / 100 * 5 + (W11-Y11) -> 106.7745
A12: 8 | B12: 3.009 | C12: =ROUND(N12+O12-T12, 2) -> 36.79 | D12: =ROUND(P12+Q12+R12-S12, 2) -> 67.91 | G12: =SUM(C12:F12) -> 104.7 | K12: =I12 -> 0 | N12: 34.48 | O12: 2.31 | P12: 56.88 | Q12: 7.7 | R12: 3.33 | S12: 0 | T12: 0 | U12: 27149 | V12: 4000 | W12: =ROUND(U12*V12/1000000, 2) -> 108.6 | Y12: 20 | Z12: =(W12-Y12) / 100 * 5 + (W12-Y12) -> 93.03
A13: 9 | B13: 3.010 | C13: =ROUND(N13+O13-T13, 2) -> 13.36 | D13: =ROUND(P13+Q13+R13-S13, 2) -> 88.25 | G13: =SUM(C13:F13) -> 101.61 | K13: =I13 -> 0 | N13: 11.2 | O13: 2.16 | P13: 77.72 | Q13: 7.2 | R13: 3.33 | S13: 0 | T13: 0 | U13: 30390 | V13: 4000 | W13: =ROUND(U13*V13/1000000, 2) -> 121.56 | Y13: 20 | Z13: =(W13-Y13) / 100 * 5 + (W13-Y13) -> 106.638
A14: 10 | B14: 3.011 | C14: =ROUND(N14+O14-T14, 2) -> 34.97 | D14: =ROUND(P14+Q14+R14-S14, 2) -> 70.28 | G14: =SUM(C14:F14) -> 105.25 | K14: =I14 -> 0 | N14: 32.76 | O14: 2.21 | P14: 59.6 | Q14: 7.35 | R14: 3.33 | S14: 0 | T14: 0 | U14: 59638 | V14: 4000 | W14: =ROUND(U14*V14/1000000, 2) -> 238.55 | Y14: 15 | Z14: =(W14-Y14) / 100 * 5 + (W14-Y14) -> 234.7275
A15: 11 | B15: 3.012 | C15: =ROUND(N15+O15-T15, 2) -> 15.36 | D15: =ROUND(P15+Q15+R15-S15, 2) -> 89.97 | G15: =SUM(C15:F15) -> 105.33 | K15: =I15 -> 0 | N15: 13.2 | O15: 2.16 | P15: 79.44 | Q15: 7.2 | R15: 3.33 | S15: 0 | T15: 0 | U15: 24809 | V15: 4000 | W15: =ROUND(U15*V15/1000000, 2) -> 99.24 | Y15: 20 | Z15: =(W15-Y15) / 100 * 5 + (W15-Y15) -> 83.202
A16: 12 | B16: 3.013 | C16: =ROUND(N16+O16-T16, 2) -> 42.14 | D16: =ROUND(P16+Q16+R16-S16, 2) -> 59.81 | G16: =SUM(C16:F16) -> 101.95 | K16: =I16 -> 0 | N16: 40.1 | O16: 2.04 | P16: 49.68 | Q16: 6.8 | R16: 3.33 | S16: 0 | T16: 0 | U16: 18723 | V16: 4000 | W16: =ROUND(U16*V16/1000000, 2) -> 74.89 | Y16: 5.4 | Z16: =(W16-Y16) / 100 * 5 + (W16-Y16) -> 72.9645
A17: 13 | B17: 3.014 | C17: =ROUND(N17+O17-T17, 2) -> 63.53 | D17: =ROUND(P17+Q17+R17-S17, 2) -> 157.89 | G17: =SUM(C17:F17) -> 221.42 | K17: =I17 -> 0 | N17: 62.07 | O17: 1.46 | P17: 164.12 | Q17: 4.88 | R17: 0 | S17: 11.11 | T17: 0 | U17: 23333 | V17: 4000 | W17: =ROUND(U17*V17/1000000, 2) -> 93.33 | Y17: 5.4 | Z17: =(W17-Y17) / 100 * 5 + (W17-Y17) -> 92.3265
A18: 14 | B18: 3.015 | F18: =SUM(N18:R18)-SUM(S18:T18) -> 86.31 | G18: =SUM(C18:F18) -> 86.31 | K18: =I18 -> 0 | M18: СТ-8, СТ-8.1 | N18: 33.02 | O18: 0 | P18: 55.58 | Q18: 0 | R18: 0 | S18: 2.29 | T18: 0 | U18: 8495 | V18: 4000 | W18: =ROUND(U18*V18/1000000, 2) -> 33.98 | Z18: =(W18-Y18) / 100 * 5 + (W18-Y18) -> 35.679
A19: 15 | B19: 3.016 | F19: =SUM(N19:R19)-SUM(S19:T19) -> 113.91 | G19: =SUM(C19:F19) -> 113.91 | K19: =I19 -> 0 | M19: СТ-8, СТ-8.1 | N19: 8.08 | O19: 0 | P19: 108.12 | Q19: 0 | R19: 0 | S19: 2.29 | T19: 0 | U19: 4100 | V19: 4000 | W19: =ROUND(U19*V19/1000000, 2) -> 16.4 | Z19: =(W19-Y19) / 100 * 5 + (W19-Y19) -> 17.22
A20: 16 | B20: 3.017 | F20: =SUM(N20:R20)-SUM(S20:T20) -> 36.11 | G20: =SUM(C20:F20) -> 36.11 | K20: =I20 -> 0 | M20: СТ-8, СТ-8.1 | N20: 3.12 | O20: 0 | P20: 35.28 | Q20: 0 | R20: 0 | S20: 2.29 | T20: 0 | U20: 9115 | V20: 4000 | W20: =ROUND(U20*V20/1000000, 2) -> 36.46 | Z20: =(W20-Y20) / 100 * 5 + (W20-Y20) -> 38.283
A21: 17 | B21: 3.018 | F21: =SUM(N21:R21)-SUM(S21:T21) -> 25.16 | G21: =SUM(C21:F21) -> 25.16 | K21: =I21 -> 0 | M21: СТ-8, СТ-8.1 | N21: 4 | O21: 0 | P21: 25.06 | Q21: 0 | R21: 0 | S21: 1.95 | T21: 1.95 | U21: 68290 | V21: 4001 | W21: =ROUND(U21*V21/1000000, 2) -> 273.23 | Y21: 2.7 | Z21: =(W21-Y21) / 100 * 5 + (W21-Y21) -> 284.0565
A22: 18 | B22: 3.019 | C22: =ROUND(N22+O22-T22, 2) -> 78.07 | D22: =ROUND(P22+Q22+R22-S22, 2) -> 205.31 | G22: =SUM(C22:F22) -> 283.38 | K22: =I22 -> 0 | N22: 76.3 | O22: 1.77 | P22: 195.71 | Q22: 5.9 | R22: 3.7 | S22: 0 | T22: 0 | U22: 107884 | V22: 4000 | W22: =ROUND(U22*V22/1000000, 2) -> 431.54 | Y22: 5.4 | Z22: =(W22-Y22) / 100 * 5 + (W22-Y22) -> 447.447
A23: 19 | B23: 3.020 | C23: =ROUND(N23+O23-T23, 2) -> 74.56 | D23: =ROUND(P23+Q23+R23-S23, 2) -> 243.42 | G23: =SUM(C23:F23) -> 317.98 | K23: =I23 -> 0 | N23: 79.26 | O23: 0.52 | P23: 249.17 | Q23: 1.73 | R23: 1.96 | S23: 9.44 | T23: 5.22 | U23: 12659 | V23: 4000 | W23: =ROUND(U23*V23/1000000, 2) -> 50.64 | Z23: =(W23-Y23) / 100 * 5 + (W23-Y23) -> 53.172
A24: 20 | B24: 3.021 | C24: =ROUND(N24+O24-T24, 2) -> 37.6 | D24: =ROUND(P24+Q24+R24-S24, 2) -> 48.09 | G24: =SUM(C24:F24) -> 85.69 | K24: =I24 -> 0 | N24: 37.6 | O24: 0 | P24: 50.4 | Q24: 0 | R24: 0 | S24: 2.31 | T24: 0 | U24: 7290 | V24: 4000 | W24: =ROUND(U24*V24/1000000, 2) -> 29.16 | Z24: =(W24-Y24) / 100 * 5 + (W24-Y24) -> 30.618
A25: 21 | B25: 3.077.2 | C25: =ROUND(N25+O25-T25, 2) -> 69.51 | D25: =ROUND(P25+Q25+R25-S25, 2) -> 95.88 | G25: =SUM(C25:F25) -> 165.39 | K25: =I25 -> 0 | N25: 66.96 | O25: 2.55 | P25: 89.69 | Q25: 8.5 | R25: 0 | S25: 2.31 | T25: 0 | U25: 8867 | V25: 4000 | W25: =ROUND(U25*V25/1000000, 2) -> 35.47 | Z25: =(W25-Y25) / 100 * 5 + (W25-Y25) -> 37.2435
A26: 22 | B26: 3.092 | E26: =SUM(N26:R26)-SUM(S26:T26) -> 38.59 | G26: =SUM(C26:F26) -> 38.59 | K26: =I26 -> 0 | M26: СТ-5, СТ-5.1 | N26: 0 | O26: 0 | P26: 40.88 | Q26: 0 | R26: 0 | S26: 2.29 | T26: 0 | U26: 12084 | V26: 4000 | W26: =ROUND(U26*V26/1000000, 2) -> 48.34 | Z26: =(W26-Y26) / 100 * 5 + (W26-Y26) -> 50.757
A27: 23 | B27: 3.094 | C27: =ROUND(N27+O27-T27, 2) -> 13.56 | D27: =ROUND(P27+Q27+R27-S27, 2) -> 48.85 | G27: =SUM(C27:F27) -> 62.41 | K27: =I27 -> 0 | M27: СТ-5, СТ-5.1 | N27: 13.56 | O27: 0 | P27: 52 | Q27: 0 | R27: 0 | S27: 3.15 | T27: 0 | U27: =5400+3590+2000 -> 10990 | V27: 4000 | W27: =ROUND(U27*V27/1000000, 2) -> 43.96 | Z27: =(W27-Y27) / 100 * 5 + (W27-Y27) -> 46.158
B28: сумма: | C28: =SUM(C5:C27) -> 840.61 | D28: =SUM(D5:D27) -> 1864.99 | E28: =SUM(E5:E27) -> 38.59 | F28: =SUM(F5:F27) -> 261.49 | G28: =SUM(G5:G27) -> 3005.68

Sheet ВОР 1.2.3 э. шт.
B1: Ведомость работ и используемых материалов (Штукатурка)
A2: № п.п. | B2: Наименование | C2: Ед. изм. | D2: Коэф. расхода | E2: Объем
A3: 1 | B3: Оклейка швов сопряжения бетонных и других поверхностей стен, перегородок (газобетон, ПГП, панели АКОТЕК и др.) стеклохолстом | C3: пог. м | D3: 1 | E3: 3167.23
A4: 1.2 | B4: Шпаклевка гипсовая | C4: кг | D4: 0.3 | E4: =D4*E3 -> 950.169
A5: 1.3 | B5: Лента армирующая ( серпянка)_/150мм | C5: пог. м | D5: 1.1 | E5: =D5*E3 -> 3483.953
A6: 2 | B6: Штукатурка стен цементным, цементно-песчаным раствором с предварительной огрунтовкой / толщ. от 21 до 40 мм / высотой от 4,01 до 8 метров - ЧСТ-1 | C6: м2 | D6: 1 | E6: =сп1.2.3эт!C22 -> 235.59
A7: 2.1 | B7: Штукатурка цементная | C7: кг | D7: 1.3 | E7: =$E$6*D7*23.077 -> 7067.7236
A8: 2.2 | B8: Сетка штукатурная_/пластиковая/10*10 | C8: м2 | D8: 1.1 | E8: =$E$6*D8 -> 259.149
