Workbook

Sheet 6.3инжКом (2)
A1: Ведомость работ
A2: № п.п. | B2: Наименование | D2: Описание | E2: Ед. изм. | F2: Объем, м2
A3: 1 | B3: Лакокрасочные работы СКБ / окраска потолков / | D3: ПТ-2.16, Окраска потолка/ окраска инженерных коммуникации | E3: м2 | F3: =B14 -> 5365.56
A4: 2 | B4: Лакокрасочные работы СКБ / окраска потолков / | D4: ПТ-2.1, Окраска потолка/ окраска инженерных коммуникации | E4: м2 | F4: =B20 -> 118.8
A5: 3 | B5: Лакокрасочные работы СКБ / окраска потолков / | D5: ПТ-2.3, Окраска потолка/ окраска инженерных коммуникации | E5: м2 | F5: =B27 -> 2405.28
A6: 4 | B6: Лакокрасочные работы СКБ / окраска потолков / | D6: ПТ-1.2, Окраска потолка/ окраска инженерных коммуникации | E6: м2 | F6: =F12 -> 32.52
A7: 5 | B7: Лакокрасочные работы СКБ / окраска потолков / | D7: ПТ-1.1, Окраска потолка/ окраска инженерных коммуникации | E7: м2 | F7: =F17 -> 240.72
A9: ПТ-2.16 | E9: ПТ-1.2
A10: № этажа | B10: объем, м2 | E10: № этажа | F10: объем, м2
A11: 1 | B11: =1752.6*1.2 -> 2103.12 | E11: 1 | F11: =27.1*1.2 -> 32.52
A12: 2 | B12: =1381.8*1.2 -> 1658.16 | E12: Итог: | F12: =SUM(F11:F11) -> 32.52
A13: 3 | B13: =1336.9*1.2 -> 1604.28
A14: Итог: | B14: =SUM(B11:B13) -> 5365.56 | E14: ПТ-1.1
E15: № этажа | F15: объем, м2
A16: ПТ-2.1 | E16: 3 | F16: =200.6*1.2 -> 240.72
A17: № этажа | B17: объем, м2 | E17: Итог: | F17: =SUM(F16:F16) -> 240.72
A18: 1 | B18: =60.1*1.2 -> 72.12
A19: 3 | B19: =38.9*1.2 -> 46.68
A20: Итог: | B20: =SUM(B18:B19) -> 118.8
A22: ПТ-2.3
A23: № этажа | B23: объем, м2
A24: 1 | B24: =892.5*1.2 -> 1071
A25: 2 | B25: =375.1*1.2 -> 450.12
A26: 3 | B26: =736.8*1.2 -> 884.16
A27: Итог: | B27: =SUM(B24:B26) -> 2405.28

Sheet 6.4ГКЛ
A1: Ведомость работ и используемых материалов
A2: № п.п. | B2: Наименование | C2: Описание | D2: Ед. изм. | E2: Объем, м2
A3: 1 | B3: Устройство перегородок на металлическом каркасе по системе Knauf из Файерборда в 1 слой | C3: пом. 1.077, 1.047 | D3: м2 | E3: =3.91+7.12 -> 11.03
A4: 2 | B4: Подготовка поверхности СКБ / стен / ГКЛ, ПГП / 2мм (базовый слой) | D4: м2 | E4: =E3 -> 11.03
A5: 3 | B5: Подготовка поверхности СКБ / стен / ГКЛ, ПГП / 2мм (финишный слой) | D5: м2 | E5: =E4 -> 11.03
A6: 4 | B6: Лакокрасочные работы СКБ / окраска потолков / в 2 слоя / ПТ-5.1 | D6: м2 | E6: 3.91
A7: 5 | B7: Лакокрасочные работы СКБ / окраска потолков / в 2 слоя / ПТ-2.3 | D7: м2 | E7: 7.12
A8: 6 | B8: Монтаж, демонтаж, аренда строительных лесов | D8: м2 | E8: =C11 -> 24
A10: Расчет (Строительные леса)
A11: 2.006 | B11: 3 м(высота) * 2м(длина) * 4 шт = | C11: =3*4*2 -> 24 | D11: м2

Sheet 6.3инжКом
A1: Ведомость работ
A2: № п.п. | B2: Наименование | D2: Описание | E2: Ед. изм. | F2: Объем, м2
A3: 1 | B3: Лакокрасочные работы СКБ / окраска потолков / | D3: ПТ-2.16, Окраска потолка/ окраска инженерных коммуникации | E3: м2 | F3: =B14 -> 6131.73
A4: 2 | B4: Лакокрасочные работы СКБ / окраска потолков / | D4: ПТ-2.1, Окраска потолка/ окраска инженерных коммуникации | E4: м2 | F4: =B20 -> 87
A5: 3 | B5: Лакокрасочные работы СКБ / окраска потолков / | D5: ПТ-2.3, Окраска потолка/ окраска инженерных коммуникации | E5: м2 | F5: =B27 -> 2236.205
A6: 4 | B6: Лакокрасочные работы СКБ / окраска потолков / | D6: ПТ-1.2, Окраска потолка/ окраска инженерных коммуникации | E6: м2 | F6: =F12 -> 146.6
A7: 5 | B7: Лакокрасочные работы СКБ / окраска потолков / | D7: ПТ-1.1, Окраска потолка/ окраска инженерных коммуникации | E7: м2 | F7: =F17 -> 231.97645
A9: ПТ-2.16 | E9: ПТ-1.2
A10: № этажа | B10: объем, м2 | E10: № этажа | F10: объем, м2
A11: 1 | B11: =1750.1+21*(0.3*2+0.4*2)+4.4*(0.45*2+0.5*2)+3.5*(0.95*2+0.5*2)+2.5*(2*0.75+0.3*2)*4+32*(0.8*2+0.35*2)+9.7*(2*0.4+2*0.5)+26*2*(1*2+0.5*2)+86*0.4*4 + 34.4*0.25*4+13.7*2*0.6+11.4*0.9*2+20*2*0.75 -> 2305.03 | E11: 1 | F11: 146.6
A12: 2 | B12: =1381.8+554 -> 1935.8 | E12: Итог: | F12: =SUM(F11:F11) -> 146.6
A13: 3 | B13: =1336.9+554 -> 1890.9
A14: Итог: | B14: =SUM(B11:B13) -> 6131.73 | E14: ПТ-1.1
E15: № этажа | F15: объем, м2
A16: ПТ-2.1 | E16: 3 | F16: =200.6+7.4*0.2*3.14+5.7*0.25*3.14+22.5*3.14*0.315 -> 231.97645
A17: № этажа | B17: объем, м2 | E17: Итог: | F17: =SUM(F16:F16) -> 231.97645
A18: 1 | B18: 48.1
A19: 3 | B19: =38.9 -> 38.9
A20: Итог: | B20: =SUM(B18:B19) -> 87
A22: ПТ-2.3
A23: № этажа | B23: объем, м2
A24: 1 | B24: =892.54+3.14*0.4*(10+6)*5 -> 993.02
A25: 2 | B25: =375.1*1.35 -> 506.385
A26: 3 | B26: =736.8 -> 736.8
A27: Итог: | B27: =SUM(B24:B26) -> 2236.205

Sheet 6.2ГКЛ
A1: Ведомость работ и используемых материалов
A2: № п.п. | B2: Наименование | C2: Описание | D2: Ед. изм. | E2: Объем, м2
A3: 1 | B3: Устройство перегородок на металлическом каркасе по системе Knauf из Файерборда в 1 слой с двух сторон | C3: пом. 1.008, 1.042, 1.094, 1.095, 2.009, 2.045, 2.055, 3.007, 3.033, 3.046 | D3: м2 | E3: 25.7
A4: 2 | B4: Подготовка поверхности СКБ / стен / ГКЛ, ПГП / 2мм (базовый слой) | D4: м2 | E4: 45.04
A5: 3 | B5: Подготовка поверхности СКБ / стен / ГКЛ, ПГП / 2мм (финишный слой) | D5: м2 | E5: =E4 -> 45.04
A6: 4 | B6: Лакокрасочные работы СКБ / окраска потолков / в 2 слоя | D6: м2 | E6: =E4 -> 45.04
A7: 5 | B7: Монтаж, демонтаж, аренда строительных лесов | D7: м2 | E7: =C22 -> 65
A9: Расчет (Облицовка вент. коробов - монтаж)
A10: 1 | B10: 1м(выс) * 2м(дл) * 6 шт (лиф. шах) = | C10: 12 | D10: м2
A11: 2 | B11: (0.4 * 2 + 0,85) L * 1 h * 2 шт = | C11: 3.3 | D11: м2
A12: 3 | B12: (0,6*2 + 1,3*2)L * 0,42 h * 1шт = | C12: 1.6 | D12: м2
A13: 4 | B13: (0,7 + 0,25*2)L * 0,3 h * 2 шт = | C13: 0.72 | D13: м2
A14: Итог: | C14: =SUM(C10:C13) -> 17.62 | D14: м2
A16: Расчет (Облицовка)
A17: 1 | B17: 4,04 * 2 шт = | C17: 8.08 | D17: м2
A18: Расчет (Нижняя плоскость)
A19: 1 | B19: (2 L * 6 шт + (0.4 * 2 + 0,85) L * 2 шт + + (0,6*2 + 1,3*2)L + (0,7 + 0,25*2) L ) * 0,08 ширина. | C19: =( 2*6 + (0.4*2 + 0.85) * 2 + (0.6*2+1.3*2) + (0.7 + 0.25 * 2) * 2) * 0.08 -> 1.72 | D19: м2
A21: Расчет (Строительные леса)
A22: 2.006 | B22: 2.5м(высота) * 2м(длина) * 13 шт = | C22: 65 | D22: м2

Sheet 6.1ГКЛ
A1: Ведомость работ
A2: № п.п. | B2: Наименование | E2: Описание | F2: Ед. изм. | G2: Объем, м2
A3: 1 | B3: Монтаж подвесного потолка / с применением профиля ПП | E3: Зашивка потолков 1 слой. Файерборд, 1, 2, 3 эт. | F3: м2 | G3: =C19 -> 90.8
A4: 2 | B4: Подготовка поверхности СКБ / потолка | E4: базовый слой | F4: м2 | G4: =G3 -> 90.8
A5: 3 | B5: Подготовка поверхности СКБ / потолка | E5: финишная слой | F5: м2 | G5: =G3 -> 90.8
A6: 4 | B6: Лакокрасочные работы СКБ / окраска потолков / в 2 слоя | E6: опуск на стены 0.4 м | F6: м2 | G6: =G3+14.2*0.4*6+12.9*0.4*3 -> 140.36
A7: 5 | B7: Строительные леса | E7: 1 эт, (3 * 4 шт. *2 L *2.5 h) 2 эт, (3 * 3 шт. *2 L *2.5 h) 3 эт, (3 * 3 шт. *2 L *2.5 h) | F7: м2 | G7: =4 * 3 * 2 * 2.5 + 2*3*3*2*2.5 -> 150
A9: № п.п | B9: пом. | C9: объем, м2.
A10: 1 | B10: 1.012 | C10: 11.22
A11: 2 | B11: 1.056 | C11: 11.23
A12: 3 | B12: 1.067 | C12: 11.25
A13: 4 | B13: 2.009 | C13: 10.13
A14: 5 | B14: 2.043 | C14: 10.13
A15: 6 | B15: 2.055 | C15: 10.14
A16: 7 | B16: 3.007 | C16: 8.9
A17: 8 | B17: 3.033 | C17: 8.9
A18: 9 | B18: 3.046 | C18: 8.9
A19: Итог: | C19: =SUM(C10:C18) -> 90.8

Sheet Лист2
A1: Ведомость работ и используемых материалов
A2: Тип | B2: Наименование | C2: Ед. изм. | D2: Коэф. расхода | E2: Объем
A3: Подготовка поверхности СКБ / потолка / ЖБ / 5 мм | B3: 2 этаж. Шпаклевка потолков базовая | C3: м2 | D3: 1 | E3: =Лист1!B31 -> 2126.2
A4: Грунтовка БЕТОН-КОНТАКТ_/ | C4: кг | D4: 0.15 | E4: =E3*D4 -> 318.93
A5: Шпатлевка гипсовая_ / белая / Унифицированная по ПИК-СТАНДАРТ, 30кг | C5: кг | D5: 4.5 | E5: =E3*D5 -> 9567.9
A6: Подготовка поверхности СКБ / потолка / по штукатурке / 2мм | B6: 2 этаж. Шпаклевка потолков финишная под покраску | C6: м2 | D6: 1 | E6: =E3 -> 2126.2
A7: Шпатлевка гипсовая_ / белая / Унифицированная по ПИК-СТАНДАРТ, 30кг (BIM) | C7: кг | D7: 1.8 | E7: =E6*D7 -> 3827.16
A8: Грунтовка универсальный ЛАСТИМИН_ / УНКОНТ ЛЮКС LP51 А | C8: кг | D8: 0.15 | E8: =E6*D8 -> 318.93

Sheet Лист1
A1: Номер помещения | B1: Площадь, м²
A2: 2003 | B2: 217.9
A3: 2009 | B3: 8.9
A4: 2010 | B4: 21.6
A5: 2017 | B5: 236.7
A6: 2018 | B6: 18.9
A7: 2020 | B7: 9.6
A8: 2022 | B8: 471.2
A9: 2026 | B9: 15.6
A10: 2027 | B10: 7.6
A11: 2028 | B11: 19
A12: 2029 | B12: 7.3
A13: 2032 | B13: 19.5
... A30: 2071 | B30: 128.1
A31: Итог: | B31: =SUM(B2:B30) -> 2126.2

Sheet 5.1ГКЛ
A1: Ведомость работ и используемых материалов
A2: № п.п. | B2: Наименование | C2: Ед. изм. | D2: Ед./шт. | E2: Кол-во | F2: Объем, м2
A3: 1 | B3: Зашивка приборов Knauf Файерборд 12,5мм / 1 слой | C3: м2 | D3: =5.2*0.38+0.69 -> 2.666 | E3: 5 | F3: =D3*E3 -> 13.33
A4: 2 | B4: Подготовка поверхности СКБ / потолка / базовая | C4: м2 | D4: =5.2*0.38+0.69 -> 2.666 | E4: 5 | F4: =D4*E4 -> 13.33
A5: 3 | B5: Подготовка поверхности СКБ / потолка / финишная | C5: м2 | D5: =5.2*0.38+0.69 -> 2.666 | E5: 5 | F5: =D5*E5 -> 13.33
A6: 4 | B6: Лакокрасочные работы СКБ / окраска потолков / в 2 слоя | C6: м2 | D6: =5.2*0.38+0.69 -> 2.666 | E6: 5 | F6: =D6*E6 -> 13.33
A7: 5 | B7: Строительные леса | C7: м2 | D7: - | E7: 20 | F7: =C14 -> 280
A9: Расчет (Строительные леса)
A10: 2.006 | B10: 10м(высота) * 2м(длина) * 4 шт = | C10: =10*2*4 -> 80 | D10: м2
A11: 2.006 | B11: 7,5м(высота) * 2м(длина) * 4 шт = | C11: =7.5*2*4 -> 60 | D11: м2
A12: 2.058 | B12: 7,5м(высота) * 2м(длина) * 8 шт = | C12: =7.5*2*8 -> 120 | D12: м2
A13: 3.019 | B13: 2,5м(высота) * 2м(длина) * 4 шт = | C13: =2.5*2*4 -> 20 | D13: м2
A14: Итог: | C14: =SUM(C10:C13) -> 280 | D14: м2

Sheet Table 1
A1: Номер помещени я | B1: Наименование помещения | C1: Вид отделки | D1: Площадь оригина | E1: Площадь, м² | F1: Примечание | G1: Столбец1 | H1: Столбец2
A2: 2001 | B2: Универсальное помещение с возможностью проведения занятий во внеурочное время, в том числе для групп продленного дня | C2: - обеспыливание; - грунтовка глубокого проникновения; - подвесной потолок (см. раздел АИ) | D2: 80.7 | E2: 80.7 | F2: Работы по черновой отделке выполнять при необходимости выравнивания стен | G2: пт-6
A3: 2002 | B3: Универсальное помещение с возможностью проведения занятий во внеурочное время, в том числе для групп продленного дня | C3: - обеспыливание; - грунтовка глубокого проникновения; - подвесной потолок (см. раздел АИ) | D3: 64.8 | E3: 64.8 | F3: Работы по черновой отделке выполнять при необходимости выравнивания стен | G3: пт-6
A4: 2003 | B4: Рекреация начальных классов (с коридором) | C4: - затирка; - грунтовка "Бетоноконтакт"; - шпатлёвка; - грунтовка глубокого проникновения δ = 5 мм | D4: 218.2 | E4: 218.2 | F4: Работы по черновой отделке выполнять при необходимости выравнивания стен
A5: 2004 | B5: Кабинет с рабочим пространством для учителей | C5: - обеспыливание; - грунтовка глубокого проникновения; - подвесной потолок (см. раздел АИ) | D5: 45.5 | E5: 45.5 | F5: Работы по черновой отделке выполнять при необходимости выравнивания стен | G5: пт-6
A6: 2005 | B6: Административный кабинет | C6: - обеспыливание; - грунтовка глубокого проникновения; - подвесной потолок (см. раздел АИ) | D6: 23.7 | E6: 23.7 | F6: Работы по черновой отделке выполнять при необходимости выравнивания стен | G6: пт-6
A7: 2006 | B7: Верхние ряды актового зала | C7: - затирка; - грунтовка "Бетоноконтакт"; - шпатлёвка; - грунтовка глубокого проникновения δ = 5 мм | D7: 0 | E7: 0 | F7: Работы по черновой отделке выполнять при необходимости выравнивания стен
A8: 2007 | B8: Технический центр | C8: - обеспыливание; - грунтовка глубокого проникновения; - подвесной потолок (см. раздел АИ) | D8: 23.7 | E8: 23.7 | F8: Работы по черновой отделке выполнять при необходимости выравнивания стен | G8: пт-5.1
A9: 2008 | B9: Лестничная клетка | C9: - затирка; - грунтовка "Бетоноконтакт"; - шпатлёвка; - грунтовка глубокого проникновения δ = 5 мм | D9: 65.6 | E9: 65.6 | F9: Работы по черновой отделке выполнять при необходимости выравнивания стен
A10: 2009 | B10: Лифтовый холл. Зона безопасности МГН | C10: - затирка; - грунтовка "Бетоноконтакт"; - шпатлёвка; - грунтовка глубокого проникновения δ = 5 мм | D10: 10.3 | E10: 10.3 | F10: Работы по черновой отделке выполнять при необходимости выравнивания стен
A11: 2010 | B11: Санузел для девочек | C11: - затирка; - грунтовка "Бетоноконтакт"; - шпатлёвка; - грунтовка глубокого проникновения δ = 5 мм | D11: 23.5 | E11: 23.5 | F11: Работы по черновой отделке выполнять при
A12: 2011 | B12: Помещение уборочного инвентаря | C12: - обеспыливание; - грунтовка глубокого проникновения; - подвесной потолок (см. раздел АИ) | D12: 4.7 | E12: 4.7 | F12: Работы по черновой отделке выполнять при необходимости выравнивания стен | G12: пт-7
A13: 2012 | B13: Учебный кабинет (2-4 классы) | C13: - обеспыливание; - грунтовка глубокого проникновения; - подвесной потолок (см. раздел АИ) | D13: 63.2 | E13: 63.2 | F13: Работы по черновой отделке выполнять при необходимости выравнивания стен
A14: 2013 | B14: Учебный кабинет (2-4 классы) | C14: - обеспыливание; - грунтовка глубокого проникновения; - подвесной потолок (см. раздел АИ) | D14: 64.2 | E14: 64.2 | F14: Работы по черновой отделке выполнять при необходимости выравнивания стен
A15: 2014 | B15: Учебный кабинет (2-4 классы) | C15: - обеспыливание; - грунтовка глубокого проникновения; - подвесной потолок (см. раздел АИ) | D15: 64.8 | E15: 64.8 | F15: Работы по черновой отделке выполнять при необходимости выравнивания стен
A16: 2015 | B16: Учебный кабинет (2-4 классы) | C16: - обеспыливание; - грунтовка глубокого проникновения; - подвесной потолок (см. раздел АИ) | D16: 63.4 | E16: 63.4 | F16: Работы по черновой отделке выполнять при необходимости выравнивания стен
A17: 2016 | B17: Учебный кабинет (2-4 классы) | C17: - обеспыливание; - грунтовка глубокого проникновения; - подвесной потолок (см. раздел АИ) | D17: 63.9 | E17: 63.9 | F17: Работы по черновой отделке выполнять при необходимости выравнивания стен
A18: 2017 | B18: Рекреация начальных классов (с коридором) | C18: - затирка; - грунтовка "Бетоноконтакт"; - шпатлёвка; - грунтовка глубокого проникновения δ = 5 мм | D18: =478.8 -> 478.8 | E18: =478.8/2 -> 239.4 | F18: Работы по черновой отделке выполнять при необходимости выравнивания стен
A19: 2018 | B19: Санузел для мальчиков | C19: - затирка; - грунтовка "Бетоноконтакт"; - шпатлёвка; - грунтовка глубокого проникновения δ = 5 мм | D19: 19.6 | E19: 19.6 | F19: Работы по черновой отделке выполнять при необходимости выравнивания стен
A20: 2019 | B20: Лестничная клетка | C20: - затирка; - грунтовка "Бетоноконтакт"; - шпатлёвка; - грунтовка глубокого проникновения δ = 5 мм | D20: 78.5 | E20: 78.5 | F20: Работы по черновой отделке выполнять при необходимости выравнивания стен
A21: 2020 | B21: Туалет для МГН ( для детей) | C21: - затирка; - грунтовка "Бетоноконтакт"; - шпатлёвка; - грунтовка глубокого проникновения δ = 5 мм | D21: 10.3 | E21: 10.3 | F21: Работы по черновой отделке выполнять при необходимости выравнивания стен
A22: 2021 | B22: Санузел персонала, комната личной гигиены | C22: - обеспыливание; - грунтовка глубокого проникновения; - подвесной потолок (см. раздел АИ) | D22: 5.5 | E22: 5.5 | F22: Работы по черновой отделке выполнять при необходимости выравнивания стен
A23: 2022 | B23: Многофункциональный информационный библиотечный центр с зонами для индивидуальных и групповых занятий, медиатеки, хранения ( закрытый фонд и выдачи книг | C23: - затирка; - грунтовка "Бетоноконтакт"; - шпатлёвка; - грунтовка глубокого проникновения δ = 5 мм | D23: 478.7 | E23: 478.7 | F23: Работы по черновой отделке выполнять при необходимости выравнивания стен
A24: 2023 | B24: Лестничная клетка | C24: - затирка; - грунтовка "Бетоноконтакт"; - шпатлёвка; - грунтовка глубокого проникновения δ = 5 мм | D24: 60.4 | E24: 60.4 | F24: Работы по черновой отделке выполнять при необходимости выравнивания стен
A25: 2024 | B25: Лестничная клетка | C25: - затирка; - грунтовка "Бетоноконтакт"; - шпатлёвка; - грунтовка глубокого проникновения δ = 5 мм | D25: 60.3 | E25: 60.3 | F25: Работы по черновой отделке выполнять при необходимости выравнивания стен
A26: 2025 | B26: Раздевальная | C26: - обеспыливание; - грунтовка глубокого проникновения; - подвесной потолок (см. раздел АИ) | D26: 28.1 | E26: 28.1 | F26: Работы по черновой отделке выполнять при необходимости выравнивания стен
A27: 2026 | B27: Душевая | C27: - затирка; - грунтовка "Бетоноконтакт"; - шпатлёвка; - грунтовка глубокого проникновения δ = 5 мм | D27: 16.6 | E27: 16.6 | F27: Работы по черновой отделке выполнять при необходимости выравнивания стен
A28: 2027 | B28: Туалет | C28: - затирка; - грунтовка "Бетоноконтакт"; - шпатлёвка; - грунтовка глубокого проникновения δ = 5 мм | D28: 8.1 | E28: 8.1 | F28: Работы по черновой отделке выполнять при необходимости выравнивания стен
A29: 2028 | B29: Душевая | C29: - затирка; - грунтовка "Бетоноконтакт"; - шпатлёвка; - грунтовка глубокого проникновения δ = 5 мм | D29: 19.8 | E29: 19.8 | F29: Работы по черновой отделке выполнять при необходимости выравнивания стен
A30: 2029 | B30: Туалет | C30: - затирка; - грунтовка "Бетоноконтакт"; - шпатлёвка; - грунтовка глубокого проникновения δ = 5 мм | D30: 8.2 | E30: 8.2 | F30: Работы по черновой отделке выполнять при необходимости выравнивания стен
... A37: 2036 | B37: Кабинет иностранного языка с возможностью деления трансформируемой перегородкой на два помещения | C37: - обеспыливание; - грунтовка глубокого проникновения; - подвесной потолок (см. раздел АИ) | D37: 88.5 | E37: 88.5 | F37: Работы по черновой отделке выполнять при необходимости выравнивания стен
A38: 2037 | B38: Универсальный трансформируемый спортивный зал 18x30 м с разделительным занавесом на электрическом приводе | C38: - окраска RAL 9003 (марку и огнестойкость краски см. раздел КР) | D38: 554.3 | E38: 554.3 | F38: Работы по черновой отделке выполнять при необходимости выравнивания стен | G38: отдельно
A39: 2038 | B39: Кабинет музыки и пения | C39: - обеспыливание; - грунтовка глубокого проникновения; - подвесной потолок (см. раздел АИ) | D39: 65.5 | E39: 65.5 | F39: Работы по черновой отделке выполнять при необходимости выравнивания стен
A40: 2039 | B40: Учебный кабинет универсального назначения ( 5-9 классы) | C40: - обеспыливание; - грунтовка глубокого проникновения; - подвесной потолок (см. раздел АИ) | D40: 62.3 | E40: 62.3 | F40: Работы по черновой отделке выполнять при необходимости выравнивания стен
A41: 2040 | B41: Учебный кабинет универсального назначения ( 5-9 классы) | C41: - обеспыливание; - грунтовка глубокого проникновения; - подвесной потолок (см. раздел АИ) | D41: 64.4 | E41: 64.4 | F41: Работы по черновой отделке выполнять при необходимости выравнивания стен
A42: 2041 | B42: Учебный кабинет универсального назначения ( 5-9 классы) | C42: - обеспыливание; - грунтовка глубокого проникновения; - подвесной потолок (см. раздел АИ) | D42: 64.1 | E42: 64.1 | F42: Работы по черновой отделке выполнять при необходимости выравнивания стен
A43: 2042 | B43: Рекреация с коридором | C43: - затирка; - грунтовка "Бетоноконтакт"; - шпатлёвка; - грунтовка глубокого проникновения δ = 5 мм | D43: 103.6 | E43: 103.6 | F43: Работы по черновой отделке выполнять при необходимости выравнивания стен
A44: 2043 | B44: Лифтовый холл. Зона безопасности МГН | C44: - затирка; - грунтовка "Бетоноконтакт"; - шпатлёвка; - грунтовка глубокого проникновения δ = 5 мм | D44: 10.4 | E44: 10.4 | F44: Работы по черновой отделке выполнять при необходимости выравнивания стен
A45: 2044 | B45: Лестничная клетка | C45: - затирка; - грунтовка "Бетоноконтакт"; - шпатлёвка; - грунтовка глубокого проникновения δ = 5 мм | D45: 71.8 | E45: 71.8 | F45: Работы по черновой отделке выполнять при необходимости выравнивания стен
A46: 2045 | B46: Специализированный учебный кабинет естествознания (тип В: экология+география+ОБЖ) с зонами | C46: - обеспыливание; - грунтовка глубокого проникновения; - подвесной потолок (см. раздел АИ) | D46: 432.2 | E46: 432.2 | F46: Работы по черновой отделке выполнять при необходимости выравнивания стен
...

Sheet 2расчет
A1: Номер помещения | B1: Площадь,по исп схемам | C1: По в-ти потолка | E1: Площадь по полу | F1: разница между полом и потолком
A2: 2003 | B2: =Лист1!B2 -> 217.9 | C2: 218.2 | E2: 218.2 | F2: =C2-E2 -> 0
A3: 2009 | B3: =Лист1!B3 -> 8.9 | C3: 10.3 | E3: 10.3 | F3: =C3-E3 -> 0
A4: 2010 | B4: =Лист1!B4 -> 21.6 | C4: 23.5 | E4: 23.5 | F4: =C4-E4 -> 0
A5: 2017 | B5: =Лист1!B5 -> 236.7 | C5: =478.8 -> 478.8 | E5: 237.9 | F5: =C5-E5 -> 240.9
A6: 2018 | B6: =Лист1!B6 -> 18.9 | C6: 19.6 | E6: 19.6 | F6: =C6-E6 -> 0
A7: 2020 | B7: =Лист1!B7 -> 9.6 | C7: 10.3 | E7: 10.3 | F7: =C7-E7 -> 0
A8: 2022 | B8: =Лист1!B8 -> 471.2 | C8: =478.7 -> 478.7 | E8: 476.6 | F8: =C8-E8 -> 2.1
A9: 2026 | B9: =Лист1!B9 -> 15.6 | C9: 16.6 | E9: 16.6 | F9: =C9-E9 -> 0
A10: 2027 | B10: =Лист1!B10 -> 7.6 | C10: 8.1 | E10: 8.1 | F10: =C10-E10 -> 0
A11: 2028 | B11: =Лист1!B11 -> 19 | C11: 19.8 | E11: 19.8 | F11: =C11-E11 -> 0
A12: 2029 | B12: =Лист1!B12 -> 7.3 | C12: 8.2 | E12: 8.2 | F12: =C12-E12 -> 0
A13: 2032 | B13: =Лист1!B13 -> 19.5 | C13: 20.1 | E13: 20.1 | F13: =C13-E13 -> 0
A14: 2042 | B14: =Лист1!B14 -> 101.8 | C14: 103.6 | E14: 103.6 | F14: =C14-E14 -> 0
A15: 2043 | B15: =Лист1!B15 -> 10.3 | C15: 10.4 | E15: 10.4 | F15: =C15-E15 -> 0
A16: 2046 | B16: =Лист1!B16 -> 162.1 | C16: =326 -> 326 | E16: 163.3 | F16: =C16-E16 -> 162.7
A17: 2049 | B17: =Лист1!B17 -> 127 | C17: 256.2 | E17: 128.3 | F17: =C17-E17 -> 127.9
A18: 2051 | B18: =Лист1!B18 -> 21.4 | C18: 22.2 | E18: 22.2 | F18: =C18-E18 -> 0
A19: 2052 | B19: =Лист1!B19 -> 4 | C19: 4.4 | E19: 4.4 | F19: =C19-E19 -> 0
A20: 2053 | B20: =Лист1!B20 -> 5.3 | C20: 5.6 | E20: 5.6 | F20: =C20-E20 -> 0
A21: 2054 | B21: =Лист1!B21 -> 20.6 | C21: 22.1 | E21: 22.1 | F21: =C21-E21 -> 0
A22: 2055 | B22: =Лист1!B22 -> 8.6 | C22: 10.3 | E22: 10.3 | F22: =C22-E22 -> 0
A23: 2057 | B23: =Лист1!B23 -> 18 | C23: 19.9 | E23: 19.9 | F23: =C23-E23 -> 0
A24: 2058 | B24: =Лист1!B24 -> 34.3 | C24: 35.8 | E24: 35.8 | F24: =C24-E24 -> 0
A25: 2062 | B25: =Лист1!B25 -> 212.7 | C25: =426.5 -> 426.5 | E25: 213.5 | F25: =C25-E25 -> 213
A26: 2067 | B26: =Лист1!B26 -> 89.6 | C26: 90.8 | E26: 90.8 | F26: =C26-E26 -> 0
A27: 2068 | B27: =Лист1!B27 -> 111.8 | C27: 112.7 | E27: 112.7 | F27: =C27-E27 -> 0
A28: 2069 | B28: =Лист1!B28 -> 3.1 | C28: 3.2 | E28: 3.2 | F28: =C28-E28 -> 0
A29: 2070 | B29: =Лист1!B29 -> 13.7 | C29: 15.3 | E29: 15.3 | F29: =C29-E29 -> 0
A30: 2071 | B30: =Лист1!B30 -> 128.1 | C30: 257.1 | E30: 128.9 | F30: =C30-E30 -> 128.2
A31: Итог: | B31: =SUM(B2:B30) -> 2126.2 | C31: =SUM(C2:C30) -> 3034.3 | D31: =SUM(D2:D30) -> 0 | E31: =SUM(E2:E30) -> 2159.5
A33: 2008 | B33: 57.1 | C33: 40.3 | E33: 31.5
A34: 2019 | B34: 55.6 | C34: =40.6+15 -> 55.6 | E34: 38
A35: 2023 | B35: 23.4 | C35: 23.4 | E35: 28.9
A36: 2024 | B36: 67.6 | C36: =52.6+15 -> 67.6 | E36: 28.9
A37: 2044 | B37: 63.6 | C37: =43.6+20 -> 63.6 | E37: 34.7
A38: 2056 | B38: 50.4 | C38: =30.4+20 -> 50.4 | E38: 33.9
A39: 2063 | B39: 66.1 | C39: =23.4+22.7+20 -> 66.1 | E39: 29.6
F40: лист 1 | G40: =B23+B24+B25 -> 265
F41: лист 2 | G41: =SUM(B16:B22)+B28 -> 352.1
...

Sheet 3вор
A1: Ведомость работ и используемых материалов
A2: Тип | B2: Наименование | C2: Ед. изм. | D2: Коэф. расхода | E2: Объем
A3: Подготовка поверхности СКБ / потолка / ЖБ / 5 мм | B3: 3 этаж. Шпаклевка потолков базовая | C3: м2 | D3: 1 | E3: ='3пом'!B30 -> 2056.8
A4: Грунтовка БЕТОН-КОНТАКТ_/ | C4: кг | D4: 0.15 | E4: =D4*E3 -> 308.52
A5: Шпатлевка гипсовая_ / белая / Унифицированная по ПИК-СТАНДАРТ, 30кг | C5: кг | D5: 4.5 | E5: =D5*E3 -> 9255.6
A6: Подготовка поверхности СКБ / потолка / по штукатурке / 2мм | B6: 3 этаж. Шпаклевка потолков финишная под покраску | C6: м2 | D6: 1 | E6: =E3 -> 2056.8
A7: Шпатлевка гипсовая_ / белая / Унифицированная по ПИК-СТАНДАРТ, 30кг (BIM) | C7: кг | D7: 1.8 | E7: =D7*E6 -> 3702.24
A8: Грунтовка универсальный ЛАСТИМИН_ / УНКОНТ ЛЮКС LP51 А | C8: кг | D8: 0.15 | E8: =D8*E6 -> 308.52

Sheet общая
A1: Номер п/п | B1: Код узла ИСР | C1: Наименование затрат | D1: Комментарий по ИСР | E1: Комментарий подрядчика | F1: Ед. изм. | G1: Коэф.расхода | H1: Кол-во БО | I1: Общее кол-во | J1: Осталось закрыть
A2: 1.1.1.1.1.3.1 | B2: 6.3.1.5.3.1 | C2: Черновые работы по поверхности потолков | K2: 1.1-Пт | L2: 2.1-Пт | M2: 3.1-Пт | N2: 4.1-Пт
A3: 1.1.1.1.1.3.1.2 | B3: 6.3.1.5.3.1.6.1 | C3: Подготовка поверхности СКБ / потолка / ЖБ / 5 мм | E3: 3 этаж. Шпаклевка потолков базовая (тип ПТ-1.4, ПТ-1.8, ПТ-1.1, ПТ-2.3, ПТ-2.4, ПТ-2.6, ПТ-2.8, ПТ-1.2, ПТ-2.1, ПТ-2.5, ПТ-2.7, ПТ-2.8, ПТ-2.10, ПТ-2.16, ПТ-4.1, ПТ-4.3, ПТ-5.1, ПТ-5.2, ПТ-8.1, ПТ-8.2) | F3: м2 | G3: 1 | I3: 2789.37 | J3: =I3-SUM(K3:T3) -> 364.37 | L3: ='3вор'!E3 -> 2056.8 | M3: 368.2
A4: 1.1.1.1.1.3.1.2.1 | C4: Шпатлевка гипсовая_ / белая / Унифицированная по ПИК-СТАНДАРТ, 30кг | F4: кг | G4: 4.5 | I4: 12552.165 | J4: =I4-SUM(K4:T4) -> 12552.165
A5: 1.1.1.1.1.3.1.2.2 | C5: Грунтовка БЕТОН-КОНТАКТ_/ | F5: кг | G5: 0.15 | I5: 418.406 | J5: =I5-SUM(K5:T5) -> 418.406
A6: 1.1.1.1.1.3.1.3 | B6: 6.3.1.5.3.1.6.1 | C6: Подготовка поверхности СКБ / потолка / ЖБ / 5 мм | E6: 2 этаж. Шпаклевка потолков базовая (тип ПТ-1.4, ПТ-1.8, ПТ-1.1, ПТ-2.3, ПТ-2.4, ПТ-2.6, ПТ-2.8, ПТ-1.2, ПТ-2.1, ПТ-2.5, ПТ-2.7, ПТ-2.8, ПТ-2.10, ПТ-2.16, ПТ-4.1, ПТ-4.3, ПТ-5.1, ПТ-5.2, ПТ-8.1, ПТ-8.2) | F6: м2 | G6: 1 | I6: 3418.18 | J6: =I6-SUM(K6:T6) -> 823.28 | K6: =Лист2!E3 -> 2126.2 | N6: 468.7
A7: 1.1.1.1.1.3.1.3.1 | C7: Грунтовка БЕТОН-КОНТАКТ_/ | F7: кг | G7: 0.15 | I7: 512.727 | J7: =I7-SUM(K7:T7) -> 512.727
A8: 1.1.1.1.1.3.1.3.2 | C8: Шпатлевка гипсовая_ / белая / Унифицированная по ПИК-СТАНДАРТ, 30кг | F8: кг | G8: 4.5 | I8: 15381.81 | J8: =I8-SUM(K8:T8) -> 15381.81
A9: 1.1.1.1.1.3.1.4 | B9: 6.3.1.5.3.1.6.6 | C9: Подготовка поверхности СКБ / потолка / по штукатурке / 2мм | E9: 2 этаж. Шпаклевка потолков финишная под покраску (тип ПТ-1.4, ПТ-1.8, ПТ-1.1, ПТ-2.3, ПТ-2.4, ПТ-2.6, ПТ-2.8, ПТ-1.2, ПТ-2.1, ПТ-2.5, ПТ-2.7, ПТ-2.8, ПТ-2.10, ПТ-2.16, ПТ-4.1, ПТ-4.3, ПТ-5.1, ПТ-5.2, ПТ-8.1, ПТ-8.2) | F9: м2 | G9: 1 | I9: 3418.18 | J9: =I9-SUM(K9:T9) -> 823.28 | K9: =Лист2!E6 -> 2126.2 | N9: =N6 -> 468.7
A10: 1.1.1.1.1.3.1.4.1 | C10: Шпатлевка гипсовая_ / белая / Унифицированная по ПИК-СТАНДАРТ, 30кг (BIM) | F10: кг | G10: 1.8 | I10: 6152.724 | J10: =I10-SUM(K10:T10) -> 6152.724
A11: 1.1.1.1.1.3.1.4.2 | C11: Грунтовка универсальный ЛАСТИМИН_ / УНКОНТ ЛЮКС LP51 А | F11: кг | G11: 0.15 | I11: 512.727 | J11: =I11-SUM(K11:T11) -> 512.727
A12: 1.1.1.1.1.3.1.5 | B12: 6.3.1.5.3.1.6.6 | C12: Подготовка поверхности СКБ / потолка / по штукатурке / 2мм | E12: 3 этаж. Шпаклевка потолков финишная под покраску (тип ПТ-1.4, ПТ-1.8, ПТ-1.1, ПТ-2.3, ПТ-2.4, ПТ-2.6, ПТ-2.8, ПТ-1.2, ПТ-2.1, ПТ-2.5, ПТ-2.7, ПТ-2.8, ПТ-2.10, ПТ-2.16, ПТ-4.1, ПТ-4.3, ПТ-5.1, ПТ-5.2, ПТ-8.1, ПТ-8.2) | F12: м2 | G12: 1 | I12: 2789.37 | J12: =I12-SUM(K12:T12) -> 364.37 | L12: ='3вор'!E6 -> 2056.8 | M12: =M3 -> 368.2
A13: 1.1.1.1.1.3.1.5.1 | C13: Грунтовка универсальный ЛАСТИМИН_ / УНКОНТ ЛЮКС LP51 А | F13: кг | G13: 0.15 | I13: 418.406
A14: 1.1.1.1.1.3.1.5.2 | C14: Шпатлевка гипсовая_ / белая / Унифицированная по ПИК-СТАНДАРТ, 30кг (BIM) | F14: кг | G14: 1.8 | I14: 5020.866
A15: 1.1.1.1.1.3.2 | B15: 6.3.1.5.3.2 | C15: Чистовые работы по поверхности потолков
A16: 1.1.1.1.1.3.2.1 | B16: 6.3.1.5.3.2.1.1 | C16: Окраска поверхностей потолков с предварительной огрунтовкой поверхностей / в 2 слоя | E16: 2 этаж | F16: м2 | G16: 1 | I16: 0
A17: 1.1.1.1.1.3.2.1.1 | C17: Краска водно-дисперсионная интерьерная Акриловая, моющаяся Матовая, Г1(КМ1), RAL 7035 | E17: Окраска матовой водно-дисперсионной краской для высококачественной отделки Antega Строитель (моющаяся) цвет серый шелк RAL 7044, КМ1 | F17: кг | G17: 0.3 | I17: 0
A18: 1.1.1.1.1.3.2.1.2 | C18: Грунтовка универсальный ЛАСТИМИН_ / LP-51 А | F18: кг | G18: 0.15 | I18: 0
A19: 1.1.1.1.1.3.2.2 | B19: 6.3.1.5.3.2.1.1 | C19: Окраска поверхностей потолков с предварительной огрунтовкой поверхностей / в 2 слоя | E19: 2 этаж | F19: м2 | G19: 1 | I19: 0
A20: 1.1.1.1.1.3.2.2.1 | C20: Грунтовка универсальный ЛАСТИМИН_ / LP-51 А | F20: кг | G20: 0.15 | I20: 0
A21: 1.1.1.1.1.3.2.2.2 | C21: Краска негорючая моющаяся Protect Decor_ / RAL 9003 | E21: Краска огнестойкая Antega Строитель НГ, цвет - белый RAL 9003, КМ0 | F21: кг | G21: 0.3 | I21: 0
A22: 1.1.1.1.1.3.2.3 | B22: 6.3.1.5.3.2.1.1 | C22: Окраска поверхностей потолков с предварительной огрунтовкой поверхностей / в 2 слоя | E22: 2 этаж | F22: м2 | G22: 1 | I22: 0
A23: 1.1.1.1.1.3.2.3.1 | C23: Краска негорючая моющаяся Protect Decor_ / RAL 9003 | E23: Краска огнестойкая Antega Строитель НГ, цвет - темно-серый RAL 7016, КМ0 | F23: кг | G23: 0.3 | I23: 0
A24: 1.1.1.1.1.3.2.3.2 | C24: Грунтовка универсальный ЛАСТИМИН_ / LP-51 А | F24: кг | G24: 0.15 | I24: 0
A25: 1.1.1.1.1.3.2.4 | B25: 6.3.1.5.3.2.1.1 | C25: Окраска поверхностей потолков с предварительной огрунтовкой поверхностей / в 2 слоя | E25: 2 этаж | F25: м2 | G25: 1 | I25: 0
A26: 1.1.1.1.1.3.2.4.1 | C26: Грунтовка универсальный ЛАСТИМИН_ / LP-51 А | F26: кг | G26: 0.15 | I26: 0
A27: 1.1.1.1.1.3.2.4.2 | C27: Краска негорючая моющаяся Protect Decor_ / RAL 9003 | E27: Краска огнестойкая Antega Строитель НГ, цвет серый шелк RAL 7044, КМ0 | F27: кг | G27: 0.3 | I27: 0
A28: 1.1.1.1.1.3.2.5 | B28: 6.3.1.5.3.2.1.1 | C28: Окраска поверхностей потолков с предварительной огрунтовкой поверхностей / в 2 слоя | E28: 2 этаж | F28: м2 | G28: 1 | I28: 0
A29: 1.1.1.1.1.3.2.5.1 | C29: Краска негорючая моющаяся Protect Decor_ / RAL 9003 | E29: Краска огнестойкая Antega Строитель НГ, цвет голубой NCS S 2030-R80B, КМ0 | F29: кг | G29: 0.3 | I29: 0
A30: 1.1.1.1.1.3.2.5.2 | C30: Грунтовка универсальный ЛАСТИМИН_ / LP-51 А | F30: кг | G30: 0.15 | I30: 0
A31: 1.1.1.1.1.3.2.6 | B31: 6.3.1.5.3.2.1.1 | C31: Окраска поверхностей потолков с предварительной огрунтовкой поверхностей / в 2 слоя | E31: 2 этаж | F31: м2 | G31: 1 | I31: 0
A32: 1.1.1.1.1.3.2.6.1 | C32: Грунтовка универсальный ЛАСТИМИН_ / LP-51 А | F32: кг | G32: 0.15 | I32: 0
A33: 1.1.1.1.1.3.2.6.2 | C33: Краска негорючая моющаяся Protect Decor_ / RAL 9003 | E33: Краска огнестойкая Antega Строитель НГ, цвет зеленый RAL NCS S 2060-G40Y, КМ0 | F33: кг | G33: 0.3 | I33: 0
A34: 1.1.1.1.1.3.2.7 | B34: 6.3.1.5.3.2.1.1 | C34: Окраска поверхностей потолков с предварительной огрунтовкой поверхностей / в 2 слоя | E34: 2 этаж | F34: м2 | G34: 1 | I34: 0
A35: 1.1.1.1.1.3.2.7.1 | C35: Краска негорючая моющаяся Protect Decor_ / RAL 9003 | E35: Краска огнестойкая Antega Строитель НГ, цвет желтый NCS S 1070-Y20R, КМ0 | F35: кг | G35: 0.3 | I35: 0
A36: 1.1.1.1.1.3.2.7.2 | C36: Грунтовка универсальный ЛАСТИМИН_ / LP-51 А | F36: кг | G36: 0.15 | I36: 0
A37: 1.1.1.1.1.3.2.8 | B37: 6.3.1.5.3.2.1.1 | C37: Окраска поверхностей потолков с предварительной огрунтовкой поверхностей / в 2 слоя | E37: 2 этаж | F37: м2 | G37: 1 | I37: 0
A38: 1.1.1.1.1.3.2.8.1 | C38: Грунтовка универсальный ЛАСТИМИН_ / LP-51 А | F38: кг | G38: 0.15 | I38: 0
A39: 1.1.1.1.1.3.2.8.2 | C39: Краска негорючая моющаяся Protect Decor_ / RAL 9003 | E39: Краска огнестойкая Antega Строитель НГ, цвет оранжевый NCS S 2060-Y30R, КМ0 | F39: кг | G39: 0.3 | I39: 0
A40: 1.1.1.1.1.3.2.9 | B40: 6.3.1.5.3.2.3.2 | C40: Лакокрасочные работы СКБ / окраска потолков / в 2 слоя | E40: 2 этаж. ПТ-1.4 | F40: м2 | G40: 1 | I40: 0.85
...

Sheet 3пом
A1: Номер помещения | B1: Площадь, м²
A2: 3004 | B2: 241.1
A3: 3007 | B3: 8.1
A4: 3009 | B4: 22.8
A5: 3012 | B5: 233.5
A6: 3015 | B6: 19.1
A7: 3017 | B7: 9.4
A8: 3019 | B8: 315.5
A9: 3023 | B9: 185.9
A10: 3033 | B10: 8.9
A11: 3037 | B11: 111.6
A12: 3041 | B12: 159.8
A13: 3042 | B13: 21.4
... A29: 3067 | B29: 14.3
A30: итог: | B30: =SUM(B2:B29) -> 2056.8

Sheet 3расчет
A1: Номер помещения | B1: по исп схема | C1: По вед-ти(РД) потолка | D1: По РД по полу | E1: Разница между полом и потолком
A2: 3004 | B2: ='3пом'!B2 -> 241.1 | C2: 244.1 | D2: 244.9 | E2: =B2-D2 -> -3.8
A3: 3007 | B3: ='3пом'!B3 -> 8.1 | C3: 9.1 | D3: 9.1 | E3: =B3-D3 -> -1
A4: 3009 | B4: ='3пом'!B4 -> 22.8 | C4: 23.5 | D4: 23.5 | E4: =B4-D4 -> -0.7
A5: 3012 | B5: ='3пом'!B5 -> 233.5 | C5: 470.2 | D5: 235.7 | E5: =B5-D5 -> -2.2
A6: 3015 | B6: ='3пом'!B6 -> 19.1 | C6: 19.6 | D6: 19.6 | E6: =B6-D6 -> -0.5
A7: 3017 | B7: ='3пом'!B7 -> 9.4 | C7: 10.3 | D7: 10.3 | E7: =B7-D7 -> -0.9
A8: 3019 | B8: ='3пом'!B8 -> 315.5 | C8: 321.8 | D8: 320.4 | E8: =B8-D8 -> -4.9
A9: 3023 | B9: ='3пом'!B9 -> 185.9 | C9: 364.3 | D9: 188.6 | E9: =B9-D9 -> -2.7
A10: 3033 | B10: ='3пом'!B10 -> 8.9 | C10: 9.2 | D10: 9.2 | E10: =B10-D10 -> -0.3
A11: 3037 | B11: ='3пом'!B11 -> 111.6 | C11: 232.5 | D11: 116.4 | E11: =B11-D11 -> -4.8
A12: 3041 | B12: ='3пом'!B12 -> 159.8 | C12: 331.2 | D12: 165.8 | E12: =B12-D12 -> -6
A13: 3042 | B13: ='3пом'!B13 -> 21.4 | C13: 22.2 | D13: 22.2 | E13: =B13-D13 -> -0.8
... A23: 3061 | B23: ='3пом'!B23 -> 12 | C23: 12.8 | D23: 12.8 | E23: =B23-D23 -> -0.8
A24: 3062 | B24: ='3пом'!B24 -> 11.5 | C24: 11.8 | D24: =B24 -> 11.5 | E24: =B24-D24 -> 0
A25: 3063 | B25: ='3пом'!B25 -> 72 | C25: 72.8 | D25: =B25 -> 72 | E25: =B25-D25 -> 0
A26: 3064 | B26: ='3пом'!B26 -> 14.6 | C26: 15.6 | D26: =B26 -> 14.6 | E26: =B26-D26 -> 0
A27: 3065 | B27: ='3пом'!B27 -> 2.3 | C27: 3.2 | D27: =B27 -> 2.3 | E27: =B27-D27 -> 0
A28: 3066 | B28: ='3пом'!B28 -> 97.6 | C28: 102.2 | D28: 101.7 | E28: =B28-D28 -> -4.1
A29: 3067 | B29: ='3пом'!B29 -> 14.3 | C29: 15.3 | D29: 15.2 | E29: =B29-D29 -> -0.9
B30: =SUM(B2:B29) -> 2056.8 | C30: =SUM(C2:C29) -> 2962.9 | D30: =SUM(D2:D29) -> 2101.3 | E30: =SUM(E2:E29) -> -44.5
A33: 3006
A34: 3016
A35: 3020
A36: 3024
A37: 3034
A38: 3047
A39: 3052
G40: лист 1 | H40: =B17+B18+B21+B22+B23+B24 -> 461.7
G41: лист 2 | H41: =SUM(B11:B16)+B27 -> 330.5
G42: лист 3 | H42: =B10+B28+B19+B20+B26 -> 142.9
G43: лист 4 | H43: =B8+B9+B25 -> 573.4
G44: лист 5 | H44: =SUM(B5:B7)+B29 -> 276.3
G45: лист 6 | H45: =SUM(B2:B4) -> 272
H46: =B30 -> 2056.8
H47: =SUM(H40:H45)-H46 -> 0

Sheet 3.1-Пт
A1: № п.п. | B1: Наименование затрат | C1: Описание | D1: Ед. изм. | E1: Кол-во
A2: 1 | B2: Подготовка поверхности СКБ / потолка / ЖБ / 5 мм | C2: 3 этаж. Шпаклевка потолков базовая | D2: м2 | E2: ='3.1'!B9 -> 365.1
A3: 2 | B3: Подготовка поверхности СКБ / потолка / по штукатурке / 2мм | C3: 3 этаж. Шпаклевка потолков финишная под покраску | D3: м2 | E3: =E2 -> 365.1

Sheet 3.1
A1: Номер помещения | B1: Площадь, м²
A2: 3006 | B2: 51.7
A3: 3016 | B3: 58.2
A4: 3020 | B4: 48.4
A5: 3024 | B5: 48.6
A6: 3034 | B6: 54.7
A7: 3047 | B7: 54.1
A8: 3052 | B8: 49.4
A9: итог: | B9: =SUM(B2:B8) -> 365.1

Sheet 4.1-Пт
A1: № п.п. | B1: Наименование затрат | C1: Описание | D1: Ед. изм. | E1: Кол-во
A2: 1 | B2: Подготовка поверхности СКБ / потолка / ЖБ / 5 мм | C2: 2 этаж. Шпаклевка потолков базовая | D2: м2 | E2: ='4.1'!B9 -> 468.7
A3: 2 | B3: Подготовка поверхности СКБ / потолка / по штукатурке / 2мм | C3: 2 этаж. Шпаклевка потолков финишная под покраску | D3: м2 | E3: =E2 -> 468.7

Sheet 4.1
A1: Номер помещения | B1: Площадь, м²
A2: 2008 | B2: 65.6
A3: 2019 | B3: 78.5
A4: 2023 | B4: 60.4
A5: 2024 | B5: 60.3
A6: 2044 | B6: 71.8
A7: 2056 | B7: 70.4
A8: 2063 | B8: 61.7
A9: итог: | B9: =SUM(B2:B8) -> 468.7

Sheet ПТ3эт
A1: Столбец1 | B1: Столбец2 | C1: Столбец3
A2: ПТ-1.1 | B2: 3.001 | C2: 3.3
A3: ПТ-6 | B3: 3.001 | C3: 77
A4: ПТ-1.1 | B4: 3.002 | C4: 8.1
A5: ПТ-4.1 | B5: 3.002 | C5: 0.2
A6: ПТ-6 | B6: 3.002 | C6: 61.3
A7: ПТ-6 | B7: 3.003 | C7: 82.1
A8: ПТ-2.16 | B8: 3.004 | C8: 92.2
A9: ПТ-2.1 | B9: 3.005 | C9: 1.1
A10: ПТ-3 | B10: 3.005 | C10: 17.8
A11: ПТ-2.5 | B11: 3.006 | C11: 28.3
A12: ПТ-2.16 | B12: 3.007 | C12: 9.1
A13: ПТ-7 | B13: 3.008 | C13: 4.7
... A80: ПТ-6 | B80: 3.040 | C80: 115.5
A81: ДШ-2.2 | B81: 3.041 | C81: 2,,9
A82: ПТ-1.1 | B82: 3.042 | C82: 1.1
A83: ПТ-2.16 | B83: 3.042 | C83: 20.6
A84: ПТ-4.3 | B84: 3.042 | C84: 7.1
A85: ПТ-8.2 | B85: 3.042 | C85: 20.6
A86: ПТ-1.1 | B86: 3.043 | C86: 1.3
A87: ПТ-2.16 | B87: 3.043 | C87: 23.5
A88: ПТ-4.1 | B88: 3.043 | C88: 4.5
A89: ПТ-4.3 | B89: 3.043 | C89: 3.8
A90: ПТ-8.1 | B90: 3.043 | C90: 23.5
A91: ПТ-7 | B91: 3.044 | C91: 4.4
A92: ПТ-2.16 | B92: 3.045 | C92: 5.6
A93: ПТ-8.1 | B93: 3.045 | C93: 5.6
... A136: ПТ-2.16 | B136: 3.066 | C136: 24.3

Sheet ПТ2эт
A1: Столбец1 | B1: Столбец2 | C1: Столбец3
A2: ПТ-1.1 | B2: 2.001 | C2: 1.8
A3: ПТ-4.1 | B3: 2.001 | C3: 10.7
A4: ПТ-6 | B4: 2.001 | C4: 78.7
A5: ПТ-1.1 | B5: 2.002 | C5: 1.8
A6: ПТ-4.1 | B6: 2.002 | C6: 1.8
A7: ПТ-6 | B7: 2.002 | C7: 60.9
A8: ПТ-2.1 | B8: 2.003 | C8: 10.2
A9: ПТ-2.16 | B9: 2.003 | C9: 215.2
A10: ПТ-1.1 | B10: 2.004 | C10: 1.2
A11: ПТ-4.1 | B11: 2.004 | C11: 7.7
A12: ПТ-6 | B12: 2.004 | C12: 42.9
A13: ПТ-1.1 | B13: 2.005 | C13: 1
... A168: ПТ-2.16 | B168: 2.071 | C168: 130.9
