Workbook

Sheet 7.6Плнтс
A1: Ведомость работ
A2: № п.п. | B2: Наименование затрат | E2: Ед. изм. | F2: Объем
A3: 1 | B3: Установка напольного плинтуса | E3: пог. м. | F3: =B9 -> 347.7
A5: Этаж | B5: Объем
A6: 1 | B6: 74.96
A7: 2 | B7: 124.78
A8: 3 | B8: 147.96
A9: Итог: | B9: =SUM(B6:B8) -> 347.7

Sheet 7.5Линол
A1: Ведомость работ
A2: № п.п. | B2: Наименование затрат | E2: Описание | F2: Ед. изм. | G2: Объем
A3: 1 | B3: Устройство покрытия пола из линолеума | E3: Линолеум для коридоров БНК и ДОО - Линолеум TARKETT TEMPO PLUS 1004 | F3: м2 | G3: =B22 -> 1014.5
A4: 2 | B4: Устройство покрытия пола из линолеума | E4: Линолеум для спортзалов - Спортивные покрытия OMNISPORTS ACTION 40 GREY 200212004 | F4: м2 | G4: =G9 -> 419.8
A6: Пом. | B6: Объем | F6: Пом. | G6: Объем
A7: 1.05 | B7: 20.5 | F7: 2.19 | G7: 349.3
A8: 1.61 | B8: 15.1 | F8: 2.47 | G8: 70.5
A9: 2.58 | B9: 74.9 | F9: Итог: | G9: =SUM(G7:G8) -> 419.8
A10: 2.27 | B10: 18.6
A11: 2.28 | B11: 186.6
A12: 2.30 | B12: 105.8
A13: 2.08 | B13: 78.9
A14: 2.51 | B14: 37.5
A15: 2.56 | B15: 60.1
A16: 3.45 | B16: 86.2
A17: 3.44 | B17: 21.4
A18: 3.18 | B18: 106.1
A19: 3.19 | B19: 106.8
A20: 3.41 | B20: 36.4
A21: 3.42 | B21: 59.6
A22: Итог: | B22: =SUM(B7:B21) -> 1014.5

Sheet 7.4ПлЛш
A1: Ведомость работ
A2: № п.п. | B2: Наименование затрат | E2: Описание | F2: Ед. изм. | G2: Объем
A3: 1 | B3: Устройство покрытия пола СКБ из керамогранитной плитки | E3: размер 600x600 | F3: м2 | G3: =B9 -> 15.25
A4: 2 | B4: Устройство плинтуса из керамогранитной плитки СКБ | E4: размер 600x95 | F4: пог.м. | G4: 21.94
A5: Пом. | B5: Объем
A6: 1.36 | B6: 5.63
A7: 2.23 | B7: 4.92
A8: 3.18 | B8: 4.7
A9: Итог: | B9: =SUM(B6:B8) -> 15.25

Sheet 7.3Плт
A1: Ведомость работ
A2: № п.п. | B2: Наименование затрат | E2: Описание | F2: Ед. изм. | G2: Объем
A3: 1 | B3: Устройство покрытия пола СКБ из керамогранитной плитки / Керамогранит Грани Таганая моноколор, арт. GT100, цвет бежевый, толщина 10мм, матовый | E3: размер 600x600 | F3: м2 | G3: =B8 -> 102.6
A4: 2 | B4: Устройство плинтуса из керамогранитной плитки СКБ / Керамогранит Грани Таганая моноколор, арт. GT100, цвет бежевый, толщина 10мм, матовый | E4: размер 600x95 | F4: м2 | G4: =C8 -> 51.9
A5: Пом. | B5: Объем | C5: Пог.м.
A6: 1,77 | B6: 41.8 | C6: 21.12
A7: 1.78 | B7: 60.8 | C7: 30.78
A8: Итог: | B8: =SUM(B6:B7) -> 102.6 | C8: =SUM(C6:C7) -> 51.9

Sheet 7.1Стж
A1: Ведомость работ
A2: № п.п. | B2: Наименование затрат | E2: Описание | F2: Ед. изм. | G2: Объем
A3: 1 | B3: Устройство стяжки СКБ / армированная сеткой от 41 мм до 60 мм | E3: Толщина 50 мм. | F3: м2 | G3: =B11 -> 258
A4: Пом. | B4: Объем
A5: 1.64 | B5: 24
A6: 1.67 | B6: 51.3
A7: 1.68 | B7: 56.6
A8: 1.69 | B8: 18.5
A9: 1.73 | B9: 51.3
A10: 1.74 | B10: 56.3
A11: Итог: | B11: =SUM(B5:B10) -> 258

Sheet 6.4Гр
A1: Ведомость работ
A2: № п.п. | B2: Наименование затрат | E2: Описание | F2: Ед. изм. | G2: Объем
A3: 1 | B3: Укладка систем грязезащиты на пол | E3: Тип: Гр-1 | F3: пог.м | G3: =B9 -> 37.09
A4: Пом. | B4: Объем
A5: 1.01 | B5: 8.39
A6: 1.59 | B6: 8.2
A7: 1.63 | B7: 8.4
A8: 3.21 | B8: 12.1
A9: Итог: | B9: =SUM(B5:B8) -> 37.09

Sheet 6.3ПлинКер
A1: Ведомость работ
A2: № п.п. | B2: Наименование затрат | E2: Описание | F2: Ед. изм. | G2: Объем
A3: 1 | B3: Устройство плинтуса из керамогранитной плитки СКБ | E3: Плинтус H=100мм из керамогранита Kerama Marazzi Коллиано | F3: пог.м | G3: =B7 -> 20.42
A4: Пом. | B4: Объем
A5: 2.35 | B5: 10.25
A6: 3.21 | B6: 10.17
A7: Итог: | B7: =SUM(B5:B6) -> 20.42

Sheet 6.2Плинт
A1: Ведомость работ
A2: № п.п. | B2: Наименование затрат | D2: Описание | E2: Ед. изм. | F2: Объем
A3: 1 | B3: Установка напольного плинтуса / полимерного на клею | D3: Тип - ПЛ-4 | E3: пог.м | F3: =B9 -> 1553.13
A5: Эт | B5: Объем
A6: 1 | B6: 371.2
A7: 2 | B7: 590.25
A8: 3 | B8: 591.68
A9: Итог: | B9: =SUM(B6:B8) -> 1553.13

Sheet 6.1НалПл
A1: Ведомость работ
A2: № п.п. | B2: Наименование затрат | G2: Описание | I2: Ед. изм. | J2: Объем
A3: 1 | B3: Устройство наливных полов с огрунтовкой поверхности и проклейкой демпферной лентой / толщ. от 11 мм до 15 мм | G3: Тип П-13 Самовыравнивающаяся смесь с последующей шлифовкой − 13мм. | I3: м2 | J3: =B11+E8 -> 264.8
A5: Пом. | B5: Объем | D5: Пом. | E5: Объем
A6: 2.37 | B6: 23.5 | D6: 3.23 | E6: 23.4
A7: 2.42 | B7: 23.1 | D7: 3.28 | E7: 23.2
A8: 2.49 | B8: 72.5 | D8: Итог: | E8: =SUM(E6:E7) -> 46.6
A9: 2.51 | B9: 41.9
A10: 2.56 | B10: 57.2
A11: Итог: | B11: =SUM(B6:B10) -> 218.2

Sheet Общ
A1: Помещение | B1: Тип | C1: Площадь
A2: 1.01 | B2: П-7 | C2: 13.2
A3: 1.01 | B3: П-8 | C3: 13.2
A4: 1.02 | B4: П-8 | C4: 16.7
A5: 1.03 | B5: П-11 | C5: 5.3
A6: 1.04 | B6: П-3.1 | C6: 380.4
A7: 1.04 | B7: П-8 | C7: 380.4
A8: 1.04 | B8: П-12 | C8: 380.4
A9: 1.05 | B9: П-9.1 | C9: 22
A10: 1.06 | B10: П-11 | C10: 6.1
A11: 1.07 | B11: П-8 | C11: 10
A12: 1.08 | B12: П-8 | C12: 105.4
A13: 1.09 | B13: П-9.1 | C13: 63
... A126: 2.36 | B126: П-12 | C126: 8.4
A127: 2.37 | B127: П-13 | C127: 24 | E127: 23.4
A128: 2.38 | B128: П-15 | C128: 6.7
A129: 2.39 | B129: П-15 | C129: 29.7
A130: 2.40 | B130: П-13.1 | C130: 51.3 | E130: 50.9
A131: 2.41 | B131: П-13.1 | C131: 56.6 | E131: 55.8
A132: 2.42 | B132: П-13 | C132: 23.8 | E132: 23.01
A133: 2.43 | B133: П-15 | C133: 6.7
A134: 2.44 | B134: П-13.1 | C134: 51.3 | E134: 50.45
A135: 2.45 | B135: П-13.1 | C135: 56.3 | E135: 54.22
A136: 2.46 | B136: П-15 | C136: 29.7
A137: 2.47 | B137: П-14 | C137: 75.6
A138: 2.48 | B138: П-13 | C138: 7
A139: 2.49 | B139: П-13 | C139: 75.2 | E139: 73
A140: 2.50 | B140: П-13 | C140: 6.2 | E140: 6
A141: 2.51 | B141: П-13 | C141: 37.1 | E141: 42.4
A142: 2.52 | B142: П-15 | C142: 5.8
A143: 2.53 | B143: П-12 | C143: 6.2
A144: 2.54 | B144: П-12 | C144: 32.1
A145: 2.55 | B145: П-12 | C145: 6.5
A146: 2.56 | B146: П-13 | C146: 60.9 | E146: 59.6
A147: 2.57 | B147: П-12 | C147: 28.1
A148: 2.58 | B148: П-13.2 | C148: 76.2
A149: 3.01 | B149: П-13.3 | C149: 62.8
A150: 3.02 | B150: П-13.3 | C150: 89.1
A151: 3.03 | B151: П-13.3 | C151: 29.7
A152: 3.04 | B152: П-13.3 | C152: 64.8
...

Sheet 469
A1: Ведомость работ
A2: № п.п. | B2: Наименование затрат | C2: Описание | D2: Ед. изм. | E2: Объем
A3: 1 | B3: Устройство покрытия пола СКБ с затиркой и укрытием ДВП / из керамогранитной плитки до 0,2м2/шт | C3: Тип: КР-10 | D3: м2 | E3: 207.1
A4: 2 | B4: Устройство покрытия пола СКБ с затиркой и укрытием ДВП / из керамогранитной плитки до 0,2м2/шт | C4: Тип: КР-1.1 | D4: м2 | E4: 207.5

Sheet 459
A1: Ведомость работ
A2: № п.п. | B2: Наименование затрат | C2: Описание | D2: Ед. изм. | E2: Объем
A3: 1 | B3: Устройство покрытия пола СКБ с затиркой и укрытием ДВП / из керамогранитной плитки до 0,2м2/шт | C3: Тип: КР-3 | D3: м2 | E3: 15.88

Sheet 454
A1: Ведомость работ
A2: № п.п. | B2: Наименование затрат | C2: Описание | D2: Ед. изм. | E2: Объем
A3: 1 | B3: Устройство покрытия пола СКБ с затиркой и укрытием ДВП / из керамогранитной плитки до 0,2м2/шт | C3: Тип: КР-2 | D3: м2 | E3: 31.2

Sheet 449
A1: Ведомость работ
A2: № п.п. | B2: Наименование затрат | C2: Описание | D2: Ед. изм. | E2: Объем
A3: 1 | B3: Устройство покрытия пола СКБ с затиркой и укрытием ДВП / из керамогранитной плитки до 0,2м2/шт | C3: Тип: КР-1 | D3: м2 | E3: -109.68

Sheet 414
A1: Ведомость работ
A2: № п.п. | B2: Наименование затрат | C2: Описание | D2: Ед. изм. | E2: Объем
A3: 1 | B3: Устройство покрытия пола СКБ с затиркой и укрытием ДВП / из керамогранитной плитки до 0,2м2/шт | C3: Подвал. Керамогранит Kerama Marazzi | D3: м2 | E3: 90.33

Sheet 409
A1: Ведомость работ
A2: № п.п. | B2: Наименование затрат | C2: Описание | D2: Ед. изм. | E2: Объем
A3: 1 | B3: Устройство покрытия пола СКБ с затиркой и укрытием ДВП / из керамогранитной плитки до 0,2м2/шт | C3: Тип: КР-6 | D3: м2 | E3: 20.54

Sheet 389
A1: Ведомость работ
A2: № п.п. | B2: Наименование затрат | C2: Описание | D2: Ед. изм. | E2: Объем
A3: 1 | B3: Устройство плинтуса из керамогранитной плитки СКБ | C3: Стены. П-1 | D3: пог. м | E3: 210
A4: 2 | B4: Устройство плинтуса из керамогранитной плитки СКБ | C4: Подвал. Плинтус H=100мм | D4: пог. м | E4: 7

Sheet 370
A1: Ведомость работ
A2: № п.п. | B2: Наименование затрат | C2: Описание | D2: Ед. изм. | E2: Объем
A3: 1 | B3: Устройство плинтуса из керамогранитной плитки СКБ | C3: Тип: ПК-1 | D3: пог. м | E3: 91.86
A4: 2 | B4: Устройство плинтуса из керамогранитной плитки СКБ | C4: Тип: ПК-4 | D4: пог. м | E4: 394.02
A5: 3 | B5: Устройство плинтуса из керамогранитной плитки СКБ | C5: Тип: ПК-3 | D5: пог. м | E5: 381.88
A6: 4 | B6: Устройство плинтуса из керамогранитной плитки СКБ | C6: Тип: ПК-5 Плинтус H=100мм из керамогранита Kerama Marazzi Коллиано, арт.SG912900N | D6: пог. м | E6: 38.27

Sheet 346
A1: Ведомость работ
A2: № п.п. | B2: Наименование затрат | F2: Описание | J2: Ед. изм. | K2: Объем
A3: 1 | B3: Облицовка ступеней СКБ керамогранитной плиткой с затиркой швов | F3: Тип: КР-9, Амфитеатр ступени. | J3: м2 | K3: 129.4
A4: 2 | B4: Облицовка ступеней СКБ керамогранитной плиткой с затиркой швов | F4: КР-8. Отделка лестницы амфитеатра и торцов ступеней-сидений | J4: м2 | K4: 45.7

Sheet 336
A1: Ведомость работ
A2: № п.п. | B2: Наименование затрат | F2: Описание | J2: Ед. изм. | K2: Объем
A3: 1 | B3: Облицовка ступеней СКБ керамогранитной плиткой с затиркой швов | F3: 1, 2, 3 этажи. Тип: КР-1.2, Проступь. | J3: м2 | K3: 338.3
A4: 2 | B4: Облицовка ступеней СКБ керамогранитной плиткой с затиркой швов | F4: 1, 2, 3 этажи. Тип: КР-1.3, Подступенок. | J4: м2 | K4: 190.6

Sheet 284
A1: Ведомость работ
A2: № п.п. | B2: Наименование затрат | F2: Описание | J2: Ед. изм. | K2: Объем
A3: 1 | B3: Установка стыковочных профилей | F3: Внешние углы облицовки плиткой. | J3: пог. м | K3: 416.235

Sheet 211
A1: Ведомость работ
A2: № п.п. | B2: Наименование затрат | F2: Описание | J2: Ед. изм. | K2: Объем
A3: 1 | B3: Утепление полов керамзитом | F3: Тип П-8.1 | J3: м3 | K3: 1.415

Sheet 209
A1: Ведомость работ
A2: № п.п. | B2: Наименование затрат | F2: Описание | J2: Ед. изм. | K2: Объем
A3: 1 | B3: Утепление полов керамзитом | F3: Тип П-8.1 | J3: м3 | K3: 1.415

Sheet 207
A1: Ведомость работ
A2: № п.п. | B2: Наименование затрат | F2: Описание | J2: Ед. изм. | K2: Объем
A3: 1 | B3: Устройство тепло-звукоизоляции полов / минвата / в 1 слой | F3: Пол. П-11 | J3: м2 | K3: 1.963

Sheet 196 (2)
A1: Ведомость работ
A2: № п.п. | B2: Наименование затрат | F2: Описание | J2: Ед. изм. | K2: Объем
A3: 1 | B3: Устройство обмазочной гидроизоляции с проклеиванием швов армированной лентой из стекловолокна / в 2 слоя | F3: стены (пилоны) на h=200 мм | J3: м2 | K3: 105.69
A4: 2 | B4: Устройство обмазочной гидроизоляции с проклеиванием швов армированной лентой из стекловолокна / в 2 слоя | F4: Тип П-7, П-11, П-15 в зоне входы в здание площадь стены (пилоны) на h=500 мм | J4: м2 | K4: 12
A5: Пом. | B5: Тип | C5: Площадь | E5: Пом. | F5: Тип | G5: Площадь | I5: Пом. | J5: Тип | K5: Площадь
A6: 1.03 | B6: П-11 | C6: 1.0711073 | E6: 2.09 | F6: П-15 | G6: 1.0913169 | I6: 3.09 | J6: П-15 | K6: 1.0913169
A7: 1.06 | B7: П-11 | C7: 1.2327839 | E7: 2.10 | F7: П-15 | G7: 2.3241008 | I7: 3.10 | J7: П-15 | K7: 3.1526933
A8: 1.13 | B8: П-11 | C8: 3.1526933 | E8: 2.11 | F8: П-15 | G8: 2.3443104 | I8: 3.11 | J8: П-15 | K8: 3.1324837
A9: 1.14 | B9: П-11 | C9: 1.0913169 | E9: 2.13 | F9: П-15 | G9: 2.7485018 | I9: 3.14 | J9: П-15 | K9: 1.0913169
A10: 1.15 | B10: П-11 | C10: 3.1324837 | E10: 2.14 | F10: П-15 | G10: 1.7178136 | I10: 3.15 | J10: П-15 | K10: 2.4049391
A11: 1.16 | B11: П-11 | C11: 0.48502973 | E11: 2.16 | F11: П-15 | G11: 2.1624242 | I11: 3.24 | J11: П-15 | K11: 1.3540413
A12: 1.21 | B12: П-11 | C12: 1.2125743 | E12: 2.17 | F12: П-15 | G12: 2.4655678 | I12: 3.27 | J12: П-15 | K12: 6.002243
A13: 1.22 | B13: П-11 | C13: 0.80838289 | E13: 2.20 | F13: П-15 | G13: 4.7290399 | I13: 3.31 | J13: П-15 | K13: 1.3540413
A14: 1.23 | B14: П-11 | C14: 1.0104786 | E14: 2.22 | F14: П-15 | G14: 1.0913169 | I14: 3.32 | J14: П-15 | K14: 6.002243
A15: 1.37 | B15: П-11 | C15: 2.2230529 | E15: 2.23 | F15: П-15 | G15: 1.9805381 | I15: 3.40 | J15: П-15 | K15: 1.2732031
A16: 1.65 | B16: П-11 | C16: 1.3540413 | E16: 2.24 | F16: П-15 | G16: 3.1526933 | I16: Итог (Пол): | K16: =SUM(K6:K15) -> 26.858522
A17: 1.66 | B17: П-11 | C17: 4.298576 | E17: 2.25 | F17: П-15 | G17: 3.1324837
A18: 1.70 | B18: П-7 | C18: 0.97005947 | E18: 2.26 | F18: П-15 | G18: 1.0913169
A19: 1.71 | B19: П-11 | C19: 1.3540413 | E19: 2.38 | F19: П-15 | G19: 1.3540413
A20: 1.72 | B20: П-11 | C20: 6.0628717 | E20: 2.39 | F20: П-15 | G20: 6.002243
A21: 1.75 | B21: П-11 | C21: 1.2934126 | E21: 2.43 | F21: П-15 | G21: 1.3540413
A22: 1.76 | B22: П-11 | C22: 2.1624242 | E22: 2.46 | F22: П-15 | G22: 6.002243
A23: Итог (Пол): | C23: =SUM(C6:C22) -> 32.91533 | E23: 2.52 | F23: П-15 | G23: 1.1721552 | I23: Пом. | J23: Тип | K23: Площадь
E24: Итог (Пол): | G24: =SUM(G6:G23) -> 45.916148 | I24: 1.01 | J24: П-7 | K24: 12

Sheet 196
A1: Ведомость работ
A2: № п.п. | B2: Наименование затрат | F2: Описание | J2: Ед. изм. | K2: Объем
A3: 1 | B3: Устройство обмазочной гидроизоляции с проклеиванием швов армированной лентой из стекловолокна / в 2 слоя | F3: Пол. Тип П-7, П-11, П-15 | J3: м2 | K3: =K16+G24+C24 -> 536.17
A4: 2 | B4: Устройство обмазочной гидроизоляции с проклеиванием швов армированной лентой из стекловолокна / в 2 слоя | F4: Тип П-7, П-11, П-15 Грунтование мастикой (536,170+105,690+12,000)*0,35=228,85 м2 | J4: м2 | K4: 163.47
A5: Пом. | B5: Тип | C5: Площадь | E5: Пом. | F5: Тип | G5: Площадь | I5: Пом. | J5: Тип | K5: Площадь
A6: 1.01 | B6: П-7 | C6: 13.2 | E6: 2.09 | F6: П-15 | G6: 5.4 | I6: 3.09 | J6: П-15 | K6: 5.4
A7: 1.03 | B7: П-11 | C7: 5.3 | E7: 2.10 | F7: П-15 | G7: 11.5 | I7: 3.10 | J7: П-15 | K7: 15.6
A8: 1.06 | B8: П-11 | C8: 6.1 | E8: 2.11 | F8: П-15 | G8: 11.6 | I8: 3.11 | J8: П-15 | K8: 15.5
A9: 1.13 | B9: П-11 | C9: 15.6 | E9: 2.13 | F9: П-15 | G9: 13.6 | I9: 3.14 | J9: П-15 | K9: 5.4
A10: 1.14 | B10: П-11 | C10: 5.4 | E10: 2.14 | F10: П-15 | G10: 8.5 | I10: 3.15 | J10: П-15 | K10: 11.9
A11: 1.15 | B11: П-11 | C11: 15.5 | E11: 2.16 | F11: П-15 | G11: 10.7 | I11: 3.24 | J11: П-15 | K11: 6.7
A12: 1.16 | B12: П-11 | C12: 2.4 | E12: 2.17 | F12: П-15 | G12: 12.2 | I12: 3.27 | J12: П-15 | K12: 29.7
A13: 1.21 | B13: П-11 | C13: 6 | E13: 2.20 | F13: П-15 | G13: 23.4 | I13: 3.31 | J13: П-15 | K13: 6.7
A14: 1.22 | B14: П-11 | C14: 4 | E14: 2.22 | F14: П-15 | G14: 5.4 | I14: 3.32 | J14: П-15 | K14: 29.7
A15: 1.23 | B15: П-11 | C15: 5 | E15: 2.23 | F15: П-15 | G15: 9.8 | I15: 3.40 | J15: П-15 | K15: 6.3
A16: 1.37 | B16: П-11 | C16: 11 | E16: 2.24 | F16: П-15 | G16: 15.6 | I16: Итог (Пол): | K16: =SUM(K6:K15) -> 132.9
A17: 1.65 | B17: П-11 | C17: 6.7 | E17: 2.25 | F17: П-15 | G17: 15.5
A18: 1.66 | B18: П-11 | C18: 21.27 | E18: 2.26 | F18: П-15 | G18: 5.4
A19: 1.70 | B19: П-7 | C19: 4.8 | E19: 2.38 | F19: П-15 | G19: 6.7
A20: 1.71 | B20: П-11 | C20: 6.7 | E20: 2.39 | F20: П-15 | G20: 29.7
A21: 1.72 | B21: П-11 | C21: 30 | E21: 2.43 | F21: П-15 | G21: 6.7
A22: 1.75 | B22: П-11 | C22: 6.4 | E22: 2.46 | F22: П-15 | G22: 29.7
A23: 1.76 | B23: П-11 | C23: 10.7 | E23: 2.52 | F23: П-15 | G23: 5.8
A24: Итог (Пол): | C24: =SUM(C6:C23) -> 176.07 | E24: Итог (Пол): | G24: =SUM(G6:G23) -> 227.2

Sheet 192
A1: Ведомость работ
A2: № п.п. | B2: Наименование затрат | C2: Описание | D2: Ед. изм. | E2: Объем
A3: 1 | B3: Устройство обмазочной гидроизоляции с проклеиванием швов армированной лентой из стекловолокна / в 2 слоя | C3: Тип П-5. Обмазочная гидроизоляция пола в 2 слоя, площадь заведения стены (пилоны) на h=200 мм. | D3: м2 | E3: 62.228

Sheet 188
A1: Ведомость работ
A2: № п.п. | B2: Наименование затрат | C2: Описание | D2: Ед. изм. | E2: Объем
A3: 1 | B3: Устройство обмазочной гидроизоляции с проклеиванием швов армированной лентой из стекловолокна / в 2 слоя | C3: Тип П-5. Подвал. Обмазочная гидроизоляция пола в 2 слоя. Мастика | D3: м2 | E3: 8.13

Sheet 183
A1: Ведомость работ
A2: № п.п. | B2: Наименование затрат | C2: Описание | D2: Ед. изм. | E2: Объем
A3: 1 | B3: Устройство стяжки СКБ / неармированная с приготовлением раствора от 21 мм до 40 мм | C3: Тип П-3, П-3.1 - межэтажные площадки. Цементно−песчаная стяжка M150 выравнивающая − 25мм. | D3: м2 | E3: 200.6

Sheet 179
A1: Ведомость работ
A2: № п.п. | B2: Наименование затрат | C2: Описание | D2: Ед. изм. | E2: Объем
A3: 1 | B3: Устройство стяжки СКБ / неармированная с приготовлением раствора свыше 61 мм | C3: Наращивание подоконников ЦПС М200 толщиной 100 мм, шириной 200 мм | D3: м2 | E3: 6.22

Sheet 175
A1: Ведомость работ
A2: № п.п. | B2: Наименование затрат | C2: Описание | D2: Ед. изм. | E2: Объем
A3: 1 | B3: Устройство стяжки СКБ / армированная сеткой от 61мм до 80 мм | C3: АРОР № СТ-МФ-1 от 08.05.2026, п.52. Тип П-8, П-9, П-9.1, П-10, П-11. Цементно−песчаная стяжка M200 армированная сеткой 5Bр1 с ячейкой 100x100 − 65мм. Пом. 1.27 | D3: м2 | E3: 25.47

Sheet 170
A1: Ведомость работ
A2: № п.п. | B2: Наименование затрат | C2: Описание | D2: Ед. изм. | E2: Объем
A3: 1 | B3: Устройство стяжки СКБ / армированная сеткой от 41 мм до 60 мм | C3: Тип П-8.2 Цементно−песчаная стяжка M200 армированная сеткой 5Bр1 с ячейкой 100x100 − 50мм. Пом. 1.17 | D3: м2 | E3: 13.8

Sheet 168пдвл
A1: Ведомость работ
A2: № п.п. | B2: Наименование затрат | F2: Описание | H2: Ед. изм. | I2: Объем
A3: 1 | B3: Затирка, уход, полировка полов мех.способом | F3: Тип П-2. Железнение стяжки. | H3: м2 | I3: 3.2

Sheet ВОР
B4: п1 | C4: 1827.2
B5: п9 | C5: 118.8
B6: п9.1 | C6: 395.7
B7: п10 | C7: 259.5
B8: п10.1 | C8: 20.7
B9: п13 | C9: 382.5
B10: п13.1 | C10: 583.2
B11: п13.2 | C11: 1141.4
B12: п13.3 | C12: 954.9
B13: п14 | C13: 434.8

Sheet Общи
I1: АР1.2 | O1: мусор
A2: № п. п. | B2: № пом. | C2: Тип пола | D2: Площадь, м2. | I2: по потолку | J2: ТЕКСТ | K2: ТАБЛИЦА АР1.2
A3: 15 | B3: 0.01 | C3: П-3 | D3: 24.7 | I3: =VALUE(J3) -> 24.7 | J3: =TRIM(RIGHTB(SUBSTITUTE(K3," ",REPT(" ",99)),99)) -> 24,7 | K3: 0.01 337 Лестничная клетка №1 24,7
A4: 18 | B4: 0.02 | C4: П-5 | D4: 57.9 | I4: =VALUE(J4) -> 57.9 | J4: =TRIM(RIGHTB(SUBSTITUTE(K4," ",REPT(" ",99)),99)) -> 57,9 | K4: 0.02 82 Венткамера 57,9
A5: 12 | B5: 0.03 | C5: П-2 | D5: 165.6 | I5: =VALUE(J5) -> 165.6 | J5: =TRIM(RIGHTB(SUBSTITUTE(K5," ",REPT(" ",99)),99)) -> 165,6 | K5: 0.03 339 Коридор 165,6
A6: 19 | B6: 0.04 | C6: П-5 | D6: 58.8 | I6: =VALUE(J6) -> 58.8 | J6: =TRIM(RIGHTB(SUBSTITUTE(K6," ",REPT(" ",99)),99)) -> 58,8 | K6: 0.04 340 Насосная 58,8
A7: 20 | B7: 0.05 | C7: П-5 | D7: 54.4 | I7: =VALUE(J7) -> 54.4 | J7: =TRIM(RIGHTB(SUBSTITUTE(K7," ",REPT(" ",99)),99)) -> 54,4 | K7: 0.05 0.105 Венткамера 54,4
A8: 21 | B8: 0.06 | C8: П-5 | D8: 99.5 | I8: =VALUE(J8) -> 99.5 | J8: =TRIM(RIGHTB(SUBSTITUTE(K8," ",REPT(" ",99)),99)) -> 99,5 | K8: 0.06 342 ИТП 99,5
A9: 22 | B9: 0.07 | C9: П-5 | D9: 40.7 | I9: =VALUE(J9) -> 40.7 | J9: =TRIM(RIGHTB(SUBSTITUTE(K9," ",REPT(" ",99)),99)) -> 40,7 | K9: 0.07 0.113 Венткамера 40,7
A10: 25 | B10: 0.08 | C10: П-6 | D10: 24.2 | I10: =VALUE(J10) -> 24.2 | J10: =TRIM(RIGHTB(SUBSTITUTE(K10," ",REPT(" ",99)),99)) -> 24,2 | K10: 0.08 0.08 Помещение CC1 24,2
A11: 1 | B11: 0.09 | C11: П-1 | D11: 158.3 | I11: =VALUE(J11) -> 158.3 | J11: =TRIM(RIGHTB(SUBSTITUTE(K11," ",REPT(" ",99)),99)) -> 158,3 | K11: 158,3
A12: 2 | B12: 0.1 | C12: П-1 | D12: 272.4 | I12: =VALUE(J12) -> 272.4 | J12: =TRIM(RIGHTB(SUBSTITUTE(K12," ",REPT(" ",99)),99)) -> 272,4 | K12: 272,4
A13: 3 | B13: 0.11 | C13: П-1 | D13: 64.6 | I13: =VALUE(J13) -> 64.6 | J13: =TRIM(RIGHTB(SUBSTITUTE(K13," ",REPT(" ",99)),99)) -> 64,6 | K13: 64,6
A14: 16 | B14: 0.12 | C14: П-3 | D14: 31.1 | I14: =VALUE(J14) -> 31.1 | J14: =TRIM(RIGHTB(SUBSTITUTE(K14," ",REPT(" ",99)),99)) -> 31,1 | K14: 0.12 0.52 Лестничная клетка №5 31,1
B15: 0.13 | C15: П-1 | D15: 17.2 | I15: =VALUE(J15) -> 17.2 | J15: =TRIM(RIGHTB(SUBSTITUTE(K15," ",REPT(" ",99)),99)) -> 17,2 | K15: 17,2
A16: 4 | B16: 0.14 | C16: П-1 | D16: 177.7 | I16: =VALUE(J16) -> 177.7 | J16: =TRIM(RIGHTB(SUBSTITUTE(K16," ",REPT(" ",99)),99)) -> 177,7 | K16: 177,7
A17: 26 | B17: 0.15 | C17: П-6 | D17: 11.8 | I17: =VALUE(J17) -> 11.8 | J17: =TRIM(RIGHTB(SUBSTITUTE(K17," ",REPT(" ",99)),99)) -> 11,8 | K17: 0.15 191 Помещение CC2 11,8
A18: 27 | B18: 0.16 | C18: П-6 | D18: 12.8 | I18: =VALUE(J18) -> 12.8 | J18: =TRIM(RIGHTB(SUBSTITUTE(K18," ",REPT(" ",99)),99)) -> 12,8 | K18: 12,8
A19: 13 | B19: 0.17 | C19: П-2 | D19: 31.1 | I19: =VALUE(J19) -> 31.1 | J19: =TRIM(RIGHTB(SUBSTITUTE(K19," ",REPT(" ",99)),99)) -> 31,1 | K19: 0.17 0.54 Коридор 31,1
A20: 17 | B20: 0.18 | C20: П-3 | D20: 27.1 | I20: =VALUE(J20) -> 27.1 | J20: =TRIM(RIGHTB(SUBSTITUTE(K20," ",REPT(" ",99)),99)) -> 27,1 | K20: 0.18 0.55 Лестничная клетка №6 27,1
A21: 5 | B21: 0.19 | C21: П-1 | D21: 31.4 | I21: =VALUE(J21) -> 31.4 | J21: =TRIM(RIGHTB(SUBSTITUTE(K21," ",REPT(" ",99)),99)) -> 31,4 | K21: 31,4
A22: 6 | B22: 0.2 | C22: П-1 | D22: 289.1 | I22: =VALUE(J22) -> 289.1 | J22: =TRIM(RIGHTB(SUBSTITUTE(K22," ",REPT(" ",99)),99)) -> 289,1 | K22: 289,1
A23: 7 | B23: 0.21 | C23: П-1 | D23: 257.5 | I23: =VALUE(J23) -> 257.5 | J23: =TRIM(RIGHTB(SUBSTITUTE(K23," ",REPT(" ",99)),99)) -> 257,5 | K23: 257,5
A24: 8 | B24: 0.22 | C24: П-1 | D24: 27.1 | I24: =VALUE(J24) -> 27.1 | J24: =TRIM(RIGHTB(SUBSTITUTE(K24," ",REPT(" ",99)),99)) -> 27,1 | K24: 27,1
A25: 23 | B25: 0.23 | C25: П-5 | D25: 126 | I25: =VALUE(J25) -> 126 | J25: =TRIM(RIGHTB(SUBSTITUTE(K25," ",REPT(" ",99)),99)) -> 126,0 | K25: 0.23 0.110 Венткамера 126,0
A26: 24 | B26: 0.24 | C26: П-5 | D26: 71.2 | I26: =VALUE(J26) -> 71.2 | J26: =TRIM(RIGHTB(SUBSTITUTE(K26," ",REPT(" ",99)),99)) -> 71,2 | K26: 0.24 0.111 Венткамера 71,2
A27: 9 | B27: 0.25 | C27: П-1 | D27: 243.9 | I27: =VALUE(J27) -> 243.9 | J27: =TRIM(RIGHTB(SUBSTITUTE(K27," ",REPT(" ",99)),99)) -> 243,9 | K27: 243,9
... A31: 28 | B31: 1.01 | C31: П-7 | D31: 13.2 | I31: =VALUE(J31) -> 13.4 | J31: =TRIM(RIGHTB(SUBSTITUTE(K31," ",REPT(" ",99)),99)) -> 13,4 | K31: 1.01 Тамбур 13,4
A32: 33 | B32: 1.02 | C32: П-8 | D32: 16.4 | E32: =Таблица1[[#This Row],[Площадь, м2.]]-I32 -> 1.5 | F32: 17.6 | G32: =F32-Таблица1[[#This Row],[Площадь, м2.]] -> 1.2 | I32: =VALUE(J32) -> 14.9 | J32: =TRIM(RIGHTB(SUBSTITUTE(K32," ",REPT(" ",99)),99)) -> 14,9 | K32: 14,9
A33: 94 | B33: 1.03 | C33: П-11 | D33: 5.8 | E33: =Таблица1[[#This Row],[Площадь, м2.]]-I33 -> 0 | G33: =F33-Таблица1[[#This Row],[Площадь, м2.]] -> -5.8 | I33: =VALUE(J33) -> 5.8 | J33: =TRIM(RIGHTB(SUBSTITUTE(K33," ",REPT(" ",99)),99)) -> 5,8 | K33: 1.03 Санузел для посетителей 5,8
A34: 34 | B34: 1.04 | C34: П-8 | D34: 43.1 | E34: =Таблица1[[#This Row],[Площадь, м2.]]-I34 -> 0 | F34: 357.2 | G34: =F34-Таблица1[[#This Row],[Площадь, м2.]] -> 314.1 | I34: 43.1 | J34: 0
A35: 55 | B35: 1.05 | C35: П-9 | D35: 22.1 | E35: =Таблица1[[#This Row],[Площадь, м2.]]-I35 -> 0 | G35: =F35-Таблица1[[#This Row],[Площадь, м2.]] -> -22.1 | I35: =VALUE(J35) -> 22.1 | J35: =TRIM(RIGHTB(SUBSTITUTE(K35," ",REPT(" ",99)),99)) -> 22,1 | K35: 22,1
A36: 95 | B36: 1.06 | C36: П-11 | D36: 5.9 | E36: =Таблица1[[#This Row],[Площадь, м2.]]-I36 -> 0 | G36: =F36-Таблица1[[#This Row],[Площадь, м2.]] -> -5.9 | I36: =VALUE(J36) -> 5.9 | J36: =TRIM(RIGHTB(SUBSTITUTE(K36," ",REPT(" ",99)),99)) -> 5,9 | K36: 1.06 Санузел для МГН 5,9
A37: 35 | B37: 1.07 | C37: П-8 | D37: 10 | E37: =Таблица1[[#This Row],[Площадь, м2.]]-I37 -> 0 | F37: 10 | G37: =F37-Таблица1[[#This Row],[Площадь, м2.]] -> 0 | I37: =VALUE(J37) -> 10 | J37: =TRIM(RIGHTB(SUBSTITUTE(K37," ",REPT(" ",99)),99)) -> 10,0 | K37: 1.07 Гардероб для учителей 10,0
A38: 36 | B38: 1.08 | C38: П-8 | D38: 105.4 | E38: =Таблица1[[#This Row],[Площадь, м2.]]-I38 -> 0 | F38: 22.1 | G38: =F38-Таблица1[[#This Row],[Площадь, м2.]] -> -83.3 | I38: =VALUE(J38) -> 105.4 | J38: =TRIM(RIGHTB(SUBSTITUTE(K38," ",REPT(" ",99)),99)) -> 105,4 | K38: 105,4
A39: 56 | B39: 1.09 | C39: П-9 | D39: 62.9 | E39: =Таблица1[[#This Row],[Площадь, м2.]]-I39 -> 0 | G39: =F39-Таблица1[[#This Row],[Площадь, м2.]] -> -62.9 | I39: =VALUE(J39) -> 62.9 | J39: =TRIM(RIGHTB(SUBSTITUTE(K39," ",REPT(" ",99)),99)) -> 62,9 | K39: 1.09 Учебный кабинет 1 класс 62,9
A40: 57 | B40: 1.1 | C40: П-9 | D40: 64.3 | E40: =Таблица1[[#This Row],[Площадь, м2.]]-I40 -> 0 | G40: =F40-Таблица1[[#This Row],[Площадь, м2.]] -> -64.3 | I40: =VALUE(J40) -> 64.3 | J40: =TRIM(RIGHTB(SUBSTITUTE(K40," ",REPT(" ",99)),99)) -> 64,3 | K40: 1.10 Учебный кабинет 1 класс 64,3
A41: 58 | B41: 1.11 | C41: П-9 | D41: 64.4 | E41: =Таблица1[[#This Row],[Площадь, м2.]]-I41 -> 0 | G41: =F41-Таблица1[[#This Row],[Площадь, м2.]] -> -64.4 | I41: =VALUE(J41) -> 64.4 | J41: =TRIM(RIGHTB(SUBSTITUTE(K41," ",REPT(" ",99)),99)) -> 64,4 | K41: 1.11 Учебный кабинет 1 класс 64,4
A42: 59 | B42: 1.12 | C42: П-9 | D42: 131.2 | E42: =Таблица1[[#This Row],[Площадь, м2.]]-I42 -> 0 | G42: =F42-Таблица1[[#This Row],[Площадь, м2.]] -> -131.2 | I42: =VALUE(J42) -> 131.2 | J42: =TRIM(RIGHTB(SUBSTITUTE(K42," ",REPT(" ",99)),99)) -> 131,2 | K42: 131,2
A43: 96 | B43: 1.13 | C43: П-11 | D43: 15.8 | E43: =Таблица1[[#This Row],[Площадь, м2.]]-I43 -> 0 | G43: =F43-Таблица1[[#This Row],[Площадь, м2.]] -> -15.8 | I43: =VALUE(J43) -> 15.8 | J43: =TRIM(RIGHTB(SUBSTITUTE(K43," ",REPT(" ",99)),99)) -> 15,8 | K43: 1.13 Санузел для девочек 15,8
...

Sheet Тип Плиты
B1: 1 | C1: 2 | D1: 3 | E1: Итог
A2: КР-1 | B2: 1041.2 | E2: =SUM(B2:D2) -> 1041.2 | G2: 1132.5
A3: КР-2 | B3: 32.9 | E3: =SUM(B3:D3) -> 32.9 | G3: 31.2
A4: КР-3 | B4: 113 | C4: 267.9 | D4: 156.1 | E4: =SUM(B4:D4) -> 537 | G4: 560.4
A5: КР-4 | B5: 9.4 | C5: 9.2 | D5: 9.4 | E5: =SUM(B5:D5) -> 28 | G5: 28
A6: КР-6 | B6: 371.2 | E6: =SUM(B6:D6) -> 371.2 | G6: 370.9
A7: КР-8 | C7: 45.7 | E7: =SUM(B7:D7) -> 45.7
A8: КР-9 | C8: 129.4 | E8: =SUM(B8:D8) -> 129.4
A9: КР-10 | B9: 120.9 | C9: 43.3 | D9: 42.7 | E9: =SUM(B9:D9) -> 206.9 | G9: 207.1
A16: КР-1 | B16: 1056.6 | C16: 75.7 | D16: 0 | E16: =SUM(B16:D16) -> 1132.3 | G16: 1132.5
A17: КР-2 | B17: 31.2 | C17: 0 | D17: 0 | E17: =SUM(B17:D17) -> 31.2 | G17: 31.2
A18: КР-3 | B18: 127.2 | C18: 277.5 | D18: 155.7 | E18: =SUM(B18:D18) -> 560.4 | G18: 560.4
A19: КР-4 | B19: 9.4 | C19: 9.2 | D19: 9.4 | E19: =SUM(B19:D19) -> 28 | G19: 28
A20: КР-6 | B20: 370.9 | C20: 0 | D20: 0 | E20: =SUM(B20:D20) -> 370.9 | G20: 370.9
A21: КР-8 | B21: 0 | C21: 0 | D21: 0 | E21: =SUM(B21:D21) -> 0
A22: КР-9 | B22: 0 | C22: 0 | D22: 0 | E22: =SUM(B22:D22) -> 0
A23: КР-10 | B23: 121.1 | C23: 43.3 | D23: 42.7 | E23: =SUM(B23:D23) -> 207.1 | G23: 207.1

Sheet 1-Пл
B1: Ведомость работ
A2: № п.п. | B2: Наименование затрат | C2: Описание | D2: Ед. изм. | E2: Объем
A3: 1 | B3: Устройство покрытия пола СКБ с затиркой и укрытием ДВП / из керамогранитной плитки | C3: 1, этаж. Тип: КР-1 | D3: м2 | E3: ='1-пом'!C15 -> 438.7

Sheet 1Шл4в
B1: Спецификация работ
A2: № п.п. | B2: Наименование | D2: Описание | J2: Ед. изм. | K2: Объем
A3: 1 | B3: Шлифование поверхности полов | D3: Типы П-9, П-9.1, П-10, П-10.1, П-13, П-13.1, П-13.2, П-13.3, П-14 (1-3 этаж) | J3: м2 | K3: =C34+G36+K31 -> 4700.026
A5: № пом. | B5: Тип пола | C5: Площадь, м2. | E5: № пом. | F5: Тип пола | G5: Площадь, м2. | I5: № пом. | J5: Тип пола | K5: Площадь, м2.
A6: 1.05 | B6: П-9 | C6: 22.1 | E6: 2.01 | F6: П-13 | G6: 62.2 | I6: 3.01 | J6: П-13 | K6: 62.8
A7: 1.09 | B7: П-9 | C7: 62.9 | E7: 2.02 | F7: П-13 | G7: 89 | I7: 3.02 | J7: П-13 | K7: 89.1
A8: 1.1 | B8: П-9 | C8: 64.3 | E8: 2.03 | F8: П-13 | G8: 39.4 | I8: 3.03 | J8: П-13 | K8: 29.7
A9: 1.11 | B9: П-9 | C9: 64.4 | E9: 2.04 | F9: П-13 | G9: 63 | I9: 3.04 | J9: П-13 | K9: 64.6
A10: 1.12 | B10: П-9 | C10: 131.2 | E10: 2.05 | F10: П-13 | G10: 64.4 | I10: 3.05 | J10: П-13 | K10: 63.8
A11: 1.19 | B11: П-9 | C11: 20.7 | E11: 2.06 | F11: П-13 | G11: 63.3 | I11: 3.06 | J11: П-13 | K11: 65.4
A12: 1.2 | B12: П-9 | C12: 20.4 | E12: 2.07 | F12: П-13 | G12: 63.3 | I12: 3.07 | J12: П-13 | K12: 63.7
A13: 1.24 | B13: П-9 | C13: 10.1 | E13: 2.08 | F13: П-9 | G13: 78.2 | I13: 3.08 | J13: П-13 | K13: 64.3
A14: 1.25 | B14: П-9 | C14: 10.3 | E14: 2.12 | F14: П-13 | G14: 27 | I14: 3.12 | J14: П-13 | K14: 246.5
A15: 1.26 | B15: П-9 | C15: 10.7 | E15: 2.15 | F15: П-13 | G15: 28 | I15: 3.13 | J15: П-13 | K15: 13.3
A16: 1.27 | B16: П-9 | C16: 25.9 | E16: 2.18 | F16: П-13 | G16: 31.5 | I16: 3.18 | J16: П-13 | K16: 107.2
A17: 1.28 | B17: П-9 | C17: 22.1 | E17: 2.19 | F17: П-14 | G17: 359.3 | I17: 3.19 | J17: П-9 | K17: 113.7
A18: 1.29 | B18: П-9 | C18: 28.126 | E18: 2.21 | F18: П-13 | G18: 14 | I18: 3.23 | J18: П-13 | K18: 21.6
A19: 1.3 | B19: П-9 | C19: 92.2 | E19: 2.27 | F19: П-9 | G19: 19.1 | I19: 3.25 | J19: П-13 | K19: 52.1
A20: 1.31 | B20: П-9 | C20: 113 | E20: 2.28 | F20: П-13 | G20: 192.9 | I20: 3.26 | J20: П-10 | K20: 57
A21: 1.46 | B21: П-9 | C21: 9.3 | E21: 2.29 | F21: П-13 | G21: 14.3 | I21: 3.28 | J21: П-13 | K21: 21.6
A22: 1.58 | B22: П-9 | C22: 58.9 | E22: 2.3 | F22: П-9 | G22: 115.5 | I22: 3.29 | J22: П-13 | K22: 51.6
A23: 1.61 | B23: П-9 | C23: 16.8 | E23: 2.37 | F23: П-13 | G23: 21.6 | I23: 3.3 | J23: П-10 | K23: 56.3
A24: 1.64 | B24: П-10 | C24: 24 | E24: 2.4 | F24: П-13 | G24: 51.3 | I24: 3.33 | J24: П-13 | K24: 75.4
A25: 1.67 | B25: П-10 | C25: 51.3 | E25: 2.41 | F25: П-10 | G25: 56.6 | I25: 3.34 | J25: П-13 | K25: 6.9
A26: 1.68 | B26: П-10 | C26: 56.6 | E26: 2.42 | F26: П-13 | G26: 21.5 | I26: 3.35 | J26: П-13 | K26: 74.9
A27: 1.69 | B27: П-10 | C27: 18.5 | E27: 2.44 | F27: П-13 | G27: 51.3 | I27: 3.41 | J27: П-9 | K27: 36.4
A28: 1.73 | B28: П-10 | C28: 51.2 | E28: 2.45 | F28: П-10 | G28: 56.3 | I28: 3.42 | J28: П-9 | K28: 59.7
A29: 1.74 | B29: П-10 | C29: 56.3 | E29: 2.47 | F29: П-13 | G29: 75.6 | I29: 3.44 | J29: П-9 | K29: 21.4
A30: 1.76 | B30: П-9 | C30: 6.3 | E30: 2.48 | F30: П-13 | G30: 7 | I30: 3.45 | J30: П-13 | K30: 82.7
A31: 1.77 | B31: П-9 | C31: 41.2 | E31: 2.49 | F31: П-13 | G31: 75.2 | I31: Итог | K31: =SUM(K6:K30) -> 1601.7
A32: 1.78 | B32: П-9 | C32: 60 | E32: 2.5 | F32: П-13 | G32: 6.2
A33: 1.82 | B33: П-9 | C33: 24.5 | E33: 2.51 | F33: П-9 | G33: 38.7
A34: Итог | C34: =SUM(C6:C33) -> 1173.326 | E34: 2.56 | F34: П-9 | G34: 63.1
E35: 2.58 | F35: П-13 | G35: 76.2
E36: Итог | G36: =SUM(G6:G35) -> 1925

Sheet 1-пом
A1: Спецификация выполненных работ
A2: № п.п. | B2: Помещения: | C2: Объем, м²
A3: 1 | B3: 1.07 Гардероб для учителей 9,8 | C3: 9.1
A4: 2 | B4: 1.23 Помещение уборочного инвентаря 4,3 | C4: 4.3
A5: 3 | B5: 1.27 Коридор 25,5 | C5: 25.5
A6: 4 | B6: 1.31 Коридор 110,3 | C6: 106.5
A7: 5 | B7: 1.37 Умывальная 11,4 | C7: 10
A8: 6 | B8: 1.38 Обеденный зал на 150 мест 165,9 | C8: 161
A9: 7 | B9: 1.60 Вестибюль с зоной для посетителей 86,8 | C9: 88.8
A10: 8 | B10: 1.65 Буфет 6,3 | C10: 6.5
A11: 9 | B11: 1.71 Буфет 6,3 | C11: 6.5
A12: 10 | B12: 1.75 Помещение уборочного инвентаря 5,5 | C12: 5.3
A13: 11 | B13: 1.76 Комната персонала с гардеробом, душем и туалетом 8,2 | C13: 9.4
A14: 12 | B14: 1.81 Лифтовой холл 6,3 | C14: 5.8
B15: сумма: | C15: =SUM(C3:C14) -> 438.7

Sheet 2-Пл
B1: Ведомость работ
A2: № п.п. | B2: Наименование затрат | C2: Описание | D2: Ед. изм. | E2: Объем
A3: 1 | B3: Устройство покрытия пола СКБ с затиркой и укрытием ДВП / из керамогранитной плитки | C3: 1, 2, 3 этажи. Тип: КР-3 | D3: м2 | E3: ='2-пом'!C25 -> 256.98

Sheet 3.5Нлв4в
A1: Ведомость работ
A2: № п.п. | B2: Наименование затрат | F2: Описание | I2: Ед. изм. | J2: Объем
A3: 1 | B3: Устройство наливных полов с огрунтовкой поверхности и проклейкой демпферной лентой / толщ. от 11 мм до 15 мм | F3: Тип П-13.1, П-13.3. Самовыравнивающаяся смесь с последующей шлифовкой − 14мм. | I3: м2 | J3: =G21+C16 -> 1532.571
A5: Пом. | B5: Тип | C5: Объем, м2 | E5: Пом. | F5: Тип | G5: Объем, м2
A6: 2.40 | B6: П-13.1 | C6: 50.787 | E6: 2.01 | F6: П-13.3 | G6: 63.7
A7: 2.41 | B7: П-13.1 | C7: 56.034 | E7: 2.02 | F7: П-13.3 | G7: 90.2
A8: 2.44 | B8: П-13.1 | C8: 50.787 | E8: 2.03 | F8: П-13.3 | G8: 40.1
A9: 2.45 | B9: П-13.1 | C9: 55.737 | E9: 2.04 | F9: П-13.3 | G9: 64
A10: 3.25 | B10: П-13.1 | C10: 51.579 | E10: 2.05 | F10: П-13.3 | G10: 65.4
A11: 3.26 | B11: П-13.1 | C11: 56.43 | E11: 2.06 | F11: П-13.3 | G11: 64.1
A12: 3.29 | B12: П-13.1 | C12: 51.084 | E12: 2.07 | F12: П-13.3 | G12: 64.3
A13: 3.30 | B13: П-13.1 | C13: 55.737 | E13: 3.01 | F13: П-13.3 | G13: 62.8
A14: 3.33 | B14: П-13.1 | C14: 74.745 | E14: 3.02 | F14: П-13.3 | G14: 89.1
A15: 3.35 | B15: П-13.1 | C15: 74.151 | E15: 3.03 | F15: П-13.3 | G15: 29.7
B16: Итог | C16: =SUM(C6:C15) -> 577.071 | E16: 3.04 | F16: П-13.3 | G16: 64.8
E17: 3.05 | F17: П-13.3 | G17: 63.8
E18: 3.06 | F18: П-13.3 | G18: 65.5
E19: 3.07 | F19: П-13.3 | G19: 63.7
E20: 3.08 | F20: П-13.3 | G20: 64.3
F21: Итог | G21: =SUM(G6:G20) -> 955.5

Sheet 3.4Нлв4в
A1: Ведомость работ
A2: № п.п. | B2: Наименование затрат | F2: Описание | H2: Ед. изм. | I2: Объем
A3: 1 | B3: Устройство наливных полов с огрунтовкой поверхности и проклейкой демпферной лентой / толщ. от 11 мм до 15 мм | F3: Тип П-9, П-9.1, П-13, П-13.2. Самовыравнивающаяся смесь с последующей шлифовкой − 13мм. | H3: м2 | I3: =G20+C21 -> 1789.6
A5: Пом. | B5: Тип | C5: Объем, м2 | E5: Пом. | F5: Тип | G5: Объем, м2
A6: 1.61 | B6: П-9 | C6: 16.8 | E6: 2.08 | F6: П-13.2 | G6: 79.7
A7: 1.77 | B7: П-9 | C7: 41.8 | E7: 2.12 | F7: П-13.2 | G7: 27
A8: 1.78 | B8: П-9 | C8: 60.8 | E8: 2.15 | F8: П-13.2 | G8: 28
A9: 1.05 | B9: П-9.1 | C9: 22 | E9: 2.21 | F9: П-13.2 | G9: 14
A10: 1.09 | B10: П-9.1 | C10: 63 | E10: 2.27 | F10: П-13.2 | G10: 19.1
A11: 1.10 | B11: П-9.1 | C11: 64.3 | E11: 2.28 | F11: П-13.2 | G11: 201.1
A12: 1.11 | B12: П-9.1 | C12: 64.4 | E12: 2.30 | F12: П-13.2 | G12: 115.4
A13: 1.12 | B13: П-9.1 | C13: 131.2 | E13: 2.58 | F13: П-13.2 | G13: 76.2
A14: 1.28 | B14: П-9.1 | C14: 22.1 | E14: 3.12 | F14: П-13.2 | G14: 245.9
A15: 1.29 | B15: П-9.1 | C15: 28.7 | E15: 3.13 | F15: П-13.2 | G15: 13.3
A16: 2.48 | B16: П-13 | C16: 7 | E16: 3.18 | F16: П-13.2 | G16: 114.5
A17: 2.50 | B17: П-13 | C17: 6.2 | E17: 3.19 | F17: П-13.2 | G17: 113.1
... A19: 3.41 | B19: П-13 | C19: 37.1 | E19: 3.45 | F19: П-13.2 | G19: 87.5
A20: 3.42 | B20: П-13 | C20: 60.7 | F20: Итог: | G20: =SUM(G6:G19) -> 1156.6
B21: Итог: | C21: =SUM(C6:C20) -> 633

Sheet 3.3Нлв4в
A1: Ведомость работ
A2: № п.п. | B2: Наименование затрат | F2: Описание | I2: Ед. изм. | J2: Объем
A3: 1 | B3: Устройство наливных полов с огрунтовкой поверхности и проклейкой демпферной лентой / толщ. от 11 мм до 15 мм | F3: Тип П-14. Самовыравнивающаяся смесь с последующей шлифовкой − 12мм. | I3: м2 | J3: =C8 -> 431,9
A5: № пом. | B5: Тип пола | C5: Площадь, м2.
A6: 2.19 | B6: П-14 | C6: 431,9
A7: 2.47 | B7: П-14
B8: Итог: | C8: =C6 -> 431,9

Sheet 3.2Нлв4в
A1: Ведомость работ
A2: № п.п. | B2: Наименование затрат | F2: Описание | I2: Ед. изм. | J2: Объем
A3: 1 | B3: Устройство наливных полов с огрунтовкой поверхности и проклейкой демпферной лентой / толщ. от 11 мм до 15 мм | F3: Тип П-10, П-10.1. Самовыравнивающаяся смесь с последующей шлифовкой − 11 мм | I3: м2 | J3: =C13 -> 267.9
A5: № пом. | B5: Тип пола | C5: Площадь, м2.
A6: 1.64 | B6: П-10 | C6: 248.1
A7: 1.67 | B7: П-10
A8: 1.68 | B8: П-10
A9: 1.69 | B9: П-10
A10: 1.73 | B10: П-10
A11: 1.74 | B11: П-10
A12: 1.19 | B12: П-10.1 | C12: 19.8
B13: Итог: | C13: =SUM(C6:C12) -> 267.9

Sheet 3.1-Нал
A1: Ведомость работ
A2: № п.п. | B2: Наименование затрат | C2: Описание | D2: Ед. изм. | E2: Объем
A3: 1 | B3: Устройство наливных полов СКБ / толщ. до 10 мм | C3: АРОР "Черновые отделочные работы" от 19.02.2026. Тип П-9, П-10. | D3: м2 | E3: ='3.1-Пом'!C8 -> 289.5
A4: 2 | B4: Устройство наливных полов СКБ / толщ. до 10 мм | C4: АРОР "Черновые отделочные работы" от 19.02.2026. Тип П-13 | D4: м2 | E4: ='3.1-Пом'!C35 -> 1386.8

Sheet 3.1-Пом
A1: Пом | B1: Тип | C1: Объем, м2.
A2: 1.26 | B2: П-9 | C2: 21
A3: 2.41 | B3: П-10 | C3: 39.25
A4: 2.45 | B4: П-10 | C4: 39.25
A5: 2.51 | B5: П-9 | C5: 47.5
A6: 2.56 | B6: П-9 | C6: 47.5
A7: 3.41 | B7: П-9 | C7: 95
B8: Итог: | C8: =SUM(C2:C7) -> 289.5
A10: Пом | B10: Тип | C10: Объем, м2.
A11: 2.02 | B11: П-13 | C11: 89.5
A12: 2.03 | B12: П-13 | C12: 40
A13: 2.04 | B13: П-13 | C13: 64.5
A14: 2.05 | B14: П-13 | C14: 64.2
A15: 2.06 | B15: П-13 | C15: 64.5
A16: 2.07 | B16: П-13 | C16: 63.5
A17: 2.37 | B17: П-13 | C17: 21.4
A18: 2.40 | B18: П-13 | C18: 39.25
A19: 2.42 | B19: П-13 | C19: 21.4
A20: 2.44 | B20: П-13 | C20: 39.25
A21: 2.47 | B21: П-13 | C21: 80
A22: 2.49 | B22: П-13 | C22: 80
... A34: 3.35 | B34: П-13 | C34: 73
B35: Итог: | C35: =SUM(C11:C34) -> 1386.8

Sheet 4.Защ_вин
A1: Ведомость работ
A2: № п.п. | B2: Наименование затрат | G2: Ед. изм. | H2: Объем
A3: 1 | B3: Защитные мероприятия по защите линолеума и виниловая плитки от повреждений (доска ДВП) | G3: м2 | H3: =C21+G30+K31 -> 4099.5
A5: № пом. | B5: Тип пола | C5: Площадь, м2. | E5: № пом. | F5: Тип пола | G5: Площадь, м2. | I5: № пом. | J5: Тип пола | K5: Площадь, м2.
A6: 1.05 | B6: Л-7 | C6: 22.1 | E6: 2.01 | F6: Л-7 | G6: 62.6 | I6: 3.01 | J6: Л-7 | K6: 62.8
A7: 1.09 | B7: Л-7 | C7: 61.9 | E7: 2.02 | F7: Л-7 | G7: 89 | I7: 3.02 | J7: Л-7 | K7: 89.1
A8: 1.1 | B8: Л-7 | C8: 63.3 | E8: 2.03 | F8: Л-7 | G8: 39.4 | I8: 3.03 | J8: Л-7 | K8: 29.7
A9: 1.11 | B9: Л-7 | C9: 63.4 | E9: 2.04 | F9: Л-7 | G9: 63 | I9: 3.04 | J9: Л-7 | K9: 64.6
A10: 1.12 | B10: Л-7 | C10: 131.2 | E10: 2.05 | F10: Л-7 | G10: 64.4 | I10: 3.05 | J10: Л-7 | K10: 63.8
A11: 1.19 | B11: Л-1 | C11: 20.7 | E11: 2.06 | F11: Л-7 | G11: 63.3 | I11: 3.06 | J11: Л-7 | K11: 65.4
A12: 1.61 | B12: Л-1 | C12: 16.8 | E12: 2.07 | F12: Л-7 | G12: 63.3 | I12: 3.07 | J12: Л-7 | K12: 63.7
A13: 1.64 | B13: Л-1 | C13: 24 | E13: 2.08 | F13: Л-7 | G13: 78.6 | I13: 3.08 | J13: Л-7 | K13: 64.3
A14: 1.67 | B14: Л-1 | C14: 51.3 | E14: 2.12 | F14: Л-7 | G14: 27 | I14: 3.12 | J14: П-11 | K14: 244.5
A15: 1.68 | B15: Л-1 | C15: 54.6 | E15: 2.15 | F15: Л-7 | G15: 28 | I15: 3.13 | J15: Л-7 | K15: 13.3
A16: 1.69 | B16: Л-1 | C16: 18.5 | E16: 2.19 | F16: Л-4 | G16: 359.3 | I16: 3.18 | J16: Л-7 | K16: 107.2
A17: 1.73 | B17: Л-1 | C17: 51.2 | E17: 2.21 | F17: Л-7 | G17: 14 | I17: 3.19 | J17: Л-7 | K17: 113.7
... A20: 1.78 | B20: Л-1 | C20: 59.3 | E20: 2.3 | F20: Л-7 | G20: 115.5 | I20: 3.26 | J20: Л-1 | K20: 57
B21: Итог: | C21: =SUM(C6:C20) -> 734.8 | E21: 2.37 | F21: Л-1 | G21: 21.6 | I21: 3.28 | J21: Л-1 | K21: 21.6
E22: 2.4 | F22: Л-1 | G22: 51.3 | I22: 3.29 | J22: Л-1 | K22: 51.6
E23: 2.41 | F23: Л-1 | G23: 56.6 | I23: 3.3 | J23: Л-1 | K23: 56.3
E24: 2.42 | F24: Л-1 | G24: 21.5 | I24: 3.33 | J24: Л-1 | K24: 75.4
E25: 2.44 | F25: Л-1 | G25: 51.3 | I25: 3.34 | J25: Л-1 | K25: 6.9
E26: 2.45 | F26: Л-1 | G26: 56.3 | I26: 3.35 | J26: Л-1 | K26: 74.9
E27: 2.47 | F27: Л-4 | G27: 75.6 | I27: 3.41 | J27: Л-1 | K27: 36.4
E28: 2.49 | F28: Л-1 | G28: 75.2 | I28: 3.42 | J28: Л-1 | K28: 59.7
E29: 2.58 | F29: Л-7 | G29: 76.2 | I29: 3.44 | J29: Л-7 | K29: 21.4
F30: Итог: | G30: =SUM(G6:G29) -> 1765 | I30: 3.45 | J30: Л-7 | K30: 82.7
J31: Итог: | K31: =SUM(K6:K30) -> 1599.7

Sheet 2-пом
A1: Спецификация выполненных работ
A2: № п.п. | B2: Помещения: | C2: Объем, м²
A3: 1 | B3: 1.06 Санузел для МГН 5,6 | C3: 5.5
A4: 2 | B4: 1.62 Туалет для МГН (для посетителей) 5,9 | C4: 6.3
A5: 3 | B5: 1.66 Туалет (в т.ч. МГН) 28,9 | C5: 28.9
A6: 4 | B6: 1.72 Туалет (в т.ч. МГН) 29,2 | C6: 30.6
A7: 5 | B7: 2.20 Комната инструктора (с душем и туалетом) 16,7 | C7: 5.6
A8: 6 | B8: 2.22 Санузел персонала 4,9 | C8: 5
A9: 7 | B9: 2.23 Помещение уборочного инвентаря 9,3 | C9: 9
A10: 8 | B10: 2.36 Раздаточная 8,0 | C10: 7.6
A11: 9 | B11: 2.38 Буфет 6,3 | C11: 6.5
A12: 10 | B12: 2.39 Туалет (в т.ч. МГН) 28,9 | C12: 30.6
A13: 11 | B13: 2.43 Буфет 6,3 | C13: 6.5
A14: 12 | B14: 2.46 Туалет (в т.ч. МГН) 28,9 | C14: 30.6
... A24: 22 | B24: 3.40 Помещение уборочного инвентаря 6,0 | C24: 6.2
B25: сумма: | C25: =SUM(C3:C24) -> 256.98

Sheet 5.3Л74в
A1: Ведомость работ
A2: № п.п. | B2: Наименование затрат | F2: Описание | H2: Ед. изм. | I2: Объем
A3: 1 | B3: Устройство покрытия пола из кварцвинила / на клею | F3: Л-7. Плитка виниловая | H3: м2 | I3: =G20+C27 -> 2201.1705
A4: 2 | B4: Устройство покрытия пола из кварцвинила / на клею | F4: 3 этаж. П-11. | H4: м2 | I4: =G27 -> 244.7
A6: Пом. | B6: Тип | C6: Площадь | E6: Пом. | F6: Тип | G6: Объем, м2
A7: 1.05 | B7: Л-7 | C7: 21.89 | E7: 3.01 | F7: Л-7 | G7: 62.486
A8: 1.09 | B8: Л-7 | C8: 62.685 | E8: 3.02 | F8: Л-7 | G8: 88.6545
A9: 1.10 | B9: Л-7 | C9: 63.9785 | E9: 3.03 | F9: Л-7 | G9: 29.5515
A10: 1.11 | B10: Л-7 | C10: 64.078 | E10: 3.04 | F10: Л-7 | G10: 64.476
A11: 1.12 | B11: Л-7 | C11: 130.9 | E11: 3.05 | F11: Л-7 | G11: 63.481
A12: 2.01 | B12: Л-7 | C12: 63.3815 | E12: 3.06 | F12: Л-7 | G12: 65.1725
A13: 2.02 | B13: Л-7 | C13: 89.749 | E13: 3.07 | F13: Л-7 | G13: 63.3815
A14: 2.03 | B14: Л-7 | C14: 39.8995 | E14: 3.08 | F14: Л-7 | G14: 64.3
A15: 2.04 | B15: Л-7 | C15: 63.68 | E15: 3.13 | F15: Л-7 | G15: 13.2335
A16: 2.05 | B16: Л-7 | C16: 65.3 | E16: 3.18 | F16: Л-7 | G16: 113.9275
A17: 2.06 | B17: Л-7 | C17: 63.7795 | E17: 3.19 | F17: Л-7 | G17: 112.5345
A18: 2.07 | B18: Л-7 | C18: 64.2 | E18: 3.44 | F18: Л-7 | G18: 21.691
A19: 2.08 | B19: Л-7 | C19: 79.3015 | E19: 3.45 | F19: Л-7 | G19: 87.0625
A20: 2.12 | B20: Л-7 | C20: 26.865 | F20: Итог: | G20: =SUM(G7:G19) -> 849.952
A21: 2.15 | B21: Л-7 | C21: 27.86
A22: 2.21 | B22: Л-7 | C22: 13.93
A23: 2.27 | B23: Л-7 | C23: 19.0045
A24: 2.28 | B24: Л-7 | C24: 200.0945
A25: 2.30 | B25: Л-7 | C25: 114.823
A26: 2.58 | B26: Л-7 | C26: 75.819 | E26: Пом. | F26: Тип | G26: Объем, м2
B27: Итог: | C27: =SUM(C7:C26) -> 1351.2185 | E27: 3.12 | F27: П-11 | G27: 244.7

Sheet 5.2.1Л14в
A1: Ведомость работ
A2: № п.п. | B2: Наименование затрат | G2: Описание | J2: Ед. изм. | K2: Объем
A3: 1 | B3: Устройство покрытия пола из линолеума | G3: 1, 2, 3 этажи. Тип: Л-1 | J3: м2 | K3: =C16+G16+K17 -> 1345.18
A5: № пом. | B5: Тип пола | C5: Площадь, м2. | E5: № пом. | F5: Тип пола | G5: Площадь, м2. | I5: № пом. | J5: Тип пола | K5: Площадь, м2.
A6: 1.19 | B6: Л-1 | C6: 20.7 | E6: 2.37 | F6: Л-1 | G6: 23.4 | I6: 3.23 | J6: Л-1 | K6: 21.6
A7: 1.61 | B7: Л-1 | C7: 16.8 | E7: 2.40 | F7: Л-1 | G7: 50.9 | I7: 3.25 | J7: Л-1 | K7: 52.1
A8: 1.64 | B8: Л-1 | C8: 24 | E8: 2.41 | F8: Л-1 | G8: 55.8 | I8: 3.26 | J8: Л-1 | K8: 57
A9: 1.67 | B9: Л-1 | C9: 51.3 | E9: 2.42 | F9: Л-1 | G9: 23.01 | I9: 3.28 | J9: Л-1 | K9: 21.6
A10: 1.68 | B10: Л-1 | C10: 54.6 | E10: 2.44 | F10: Л-1 | G10: 50.45 | I10: 3.29 | J10: Л-1 | K10: 51.6
A11: 1.69 | B11: Л-1 | C11: 18.5 | E11: 2.45 | F11: Л-1 | G11: 54.22 | I11: 3.3 | J11: Л-1 | K11: 56.3
A12: 1.73 | B12: Л-1 | C12: 51.2 | E12: 2.49 | F12: Л-1 | G12: 73 | I12: 3.33 | J12: Л-1 | K12: 75.4
A13: 1.74 | B13: Л-1 | C13: 55.3 | E13: 2.50 | F13: Л-1 | G13: 6 | I13: 3.34 | J13: Л-1 | K13: 6.9
A14: 1.77 | B14: Л-1 | C14: 41.2 | E14: 2.51 | F14: Л-1 | G14: 42.4 | I14: 3.35 | J14: Л-1 | K14: 74.9
A15: 1.78 | B15: Л-1 | C15: 59.3 | E15: 2.56 | F15: Л-1 | G15: 59.6 | I15: 3.41 | J15: Л-1 | K15: 36.4
B16: Итог: | C16: =SUM(C6:C15) -> 392.9 | F16: Итог: | G16: =SUM(G6:G15) -> 438.78 | I16: 3.42 | J16: Л-1 | K16: 59.7
J17: Итог: | K17: =SUM(K6:K16) -> 513.5

Sheet 5.1-Л4
A1: Ведомость работ
A2: № п.п. | B2: Наименование затрат | C2: Описание | E2: Ед. изм. | F2: Объем
A3: 1 | B3: Устройство покрытия пола из линолеума. Включая защиту ДВП | C3: 2 этаж. Тип: Л-4 | E3: м2 | F3: =F6+F7 -> 431.3
C5: № п/п | D5: № пом | E5: Ед. изм. | F5: Объем
C6: 1 | D6: 2.19 | E6: м2 | F6: 357.18
C7: 2 | D7: 2.47 | E7: м2 | F7: 74.12

Sheet 5.2 Л-1
A1: Ведомость работ
A2: № п.п. | B2: Наименование затрат | G2: Описание | J2: Ед. изм. | K2: Объем
A3: 1 | B3: Защитные мероприятия по защите линолеума и виниловая плитки от повреждений (доска ДВП) | G3: 1, 2, 3 этажи. Тип: Л-1 | J3: м2 | K3: =C16+G12+K17 -> 1165
A5: № пом. | B5: Тип пола | C5: Площадь, м2. | E5: № пом. | F5: Тип пола | G5: Площадь, м2. | I5: № пом. | J5: Тип пола | K5: Площадь, м2.
A6: 1.19 | B6: Л-1 | C6: 20.7 | E6: 2.37 | F6: Л-1 | G6: 21.6 | I6: 3.23 | J6: Л-1 | K6: 21.6
A7: 1.61 | B7: Л-1 | C7: 16.8 | E7: 2.4 | F7: Л-1 | G7: 51.3 | I7: 3.25 | J7: Л-1 | K7: 52.1
A8: 1.64 | B8: Л-1 | C8: 24 | E8: 2.41 | F8: Л-1 | G8: 56.6 | I8: 3.26 | J8: Л-1 | K8: 57
A9: 1.67 | B9: Л-1 | C9: 51.3 | E9: 2.42 | F9: Л-1 | G9: 21.5 | I9: 3.28 | J9: Л-1 | K9: 21.6
A10: 1.68 | B10: Л-1 | C10: 54.6 | E10: 2.44 | F10: Л-1 | G10: 51.3 | I10: 3.29 | J10: Л-1 | K10: 51.6
A11: 1.69 | B11: Л-1 | C11: 18.5 | E11: 2.45 | F11: Л-1 | G11: 56.3 | I11: 3.3 | J11: Л-1 | K11: 56.3
A12: 1.73 | B12: Л-1 | C12: 51.2 | F12: Итог: | G12: =SUM(G6:G11) -> 258.6 | I12: 3.33 | J12: Л-1 | K12: 75.4
A13: 1.74 | B13: Л-1 | C13: 55.3 | I13: 3.34 | J13: Л-1 | K13: 6.9
A14: 1.77 | B14: Л-1 | C14: 41.2 | I14: 3.35 | J14: Л-1 | K14: 74.9
A15: 1.78 | B15: Л-1 | C15: 59.3 | I15: 3.41 | J15: Л-1 | K15: 36.4
B16: Итог: | C16: =SUM(C6:C15) -> 392.9 | I16: 3.42 | J16: Л-1 | K16: 59.7
J17: Итог: | K17: =SUM(K6:K16) -> 513.5

Sheet 2-Пл (2)
B1: Ведомость работ
A2: № п.п. | B2: Наименование затрат | C2: Описание | D2: Ед. изм. | E2: Объем
A3: 1 | B3: Устройство покрытия пола СКБ с затиркой и укрытием ДВП / из керамогранитной плитки | C3: 1, 2, 3 этажи. Тип: КР-3 | D3: м2 | E3: ='2-пом'!C25 -> 256.98

Sheet 2.1КР3
A1: Ведомость работ
A2: № п.п. | B2: Наименование затрат | G2: Описание | J2: Ед. изм. | K2: Объем
A3: 1 | B3: Устройство покрытия пола СКБ с затиркой и укрытием ДВП / из керамогранитной плитки от 0,2м2/шт | G3: 1, 2, 3 этажи. Тип: КР-3 | J3: м2 | K3: =C12+G19+K15 -> 256.52
A4: 1 | B4: Устройство покрытия пола СКБ с затиркой и укрытием ДВП / из керамогранитной плитки от 0,2м2/шт | G4: 1, 2, 3 этажи. Тип: КР-4 | J4: м2 | K4: =C24+G24+K24 -> 27.87
A6: № пом. | B6: Тип пола | C6: Площадь, м2. | E6: № пом. | F6: Тип пола | G6: Площадь, м2. | I6: № пом. | J6: Тип пола | K6: Площадь, м2.
A7: 1.03 | B7: КР-3 | C7: 5.01 | E7: 2.33 | F7: КР-3 | G7: 6.47 | I7: 3.14 | J7: КР-3 | K7: 5.6
A8: 1.22 | B8: КР-3 | C8: 3.76 | E8: 2.24 | F8: КР-3 | G8: 10.18 | I8: 3.15 | J8: КР-3 | K8: 11.7
A9: 1.13 | B9: КР-3 | C9: 10.18 | E9: 2.25 | F9: КР-3 | G9: 10.23 | I9: 3.27 | J9: КР-3 | K9: 29.24
A10: 1.14 | B10: КР-3 | C10: 5.14 | E10: 2.26 | F10: КР-3 | G10: 5.24 | I10: 3.16 | J10: КР-3 | K10: 6.49
A11: 1.15 | B11: КР-3 | C11: 10.23 | E11: 2.09 | F11: КР-3 | G11: 5.11 | I11: 3.09 | J11: КР-3 | K11: 5.48
B12: Итог: | C12: =SUM(C7:C11) -> 34.32 | E12: 2.10 | F12: КР-3 | G12: 11.06 | I12: 3.10 | J12: КР-3 | K12: 10.53
E13: 2.11 | F13: КР-3 | G13: 11.17 | I13: 3.11 | J13: КР-3 | K13: 10.56
E14: 2.13 | F14: КР-3 | G14: 13.28 | I14: 3.22 | J14: КР-3 | K14: 8.51
E15: 2.14 | F15: КР-3 | G15: 8.24 | J15: Итог: | K15: =SUM(K7:K14) -> 88.11
E16: 2.16 | F16: КР-3 | G16: 10.49
E17: 2.17 | F17: КР-3 | G17: 11.84
E18: 2.18 | F18: КР-3 | G18: 30.78
F19: Итог: | G19: =SUM(G7:G18) -> 134.09
A21: № пом. | B21: Тип пола | C21: Площадь, м2. | E21: № пом. | F21: Тип пола | G21: Площадь, м2. | I21: № пом. | J21: Тип пола | K21: Площадь, м2.
A22: 1.13 | B22: КР-4 | C22: 4.73 | E22: 2.24 | F22: КР-4 | G22: 4.58 | I22: 3.10 | J22: КР-4 | K22: 4.69
A23: 1.15 | B23: КР-4 | C23: 4.62 | E23: 2.25 | F23: КР-4 | G23: 4.62 | I23: 3.11 | J23: КР-4 | K23: 4.63
B24: Итог: | C24: =SUM(C22:C23) -> 9.35 | F24: Итог: | G24: =SUM(G22:G23) -> 9.2 | J24: Итог: | K24: =SUM(K22:K23) -> 9.32

Sheet 1.1КР1
A1: Ведомость работ
A2: № п.п. | B2: Наименование затрат | G2: Описание | J2: Ед. изм. | K2: Объем
A3: 1 | B3: Устройство покрытия пола СКБ с затиркой и укрытием ДВП / из керамогранитной плитки от 0,2м2/шт | G3: 1, 2 этажи. Тип: КР-1 | J3: м2 | K3: =C25+G8 -> 678.86
A5: № пом. | B5: Тип пола | C5: Площадь, м2. | E5: № пом. | F5: Тип пола | G5: Площадь, м2.
A6: 1.04 | C6: 257.98 | E6: 1.04 | G6: 57.94
A7: 1.08 | C7: 98.23 | E7: 2.29 | G7: 14.96
A8: 1.24 | C8: 10.04 | F8: Итог: | G8: =SUM(G6:G7) -> 72.9
A9: 1.25 | C9: 10.51
A10: 1.26 | C10: 10.06
A11: 1.30 | C11: 98.59
A12: 1.36 | C12: 7.25
A13: 1.21 | C13: 5.76
A14: 1.20 | C14: 20
A15: 1.17 | C15: 13.53
A16: 1.18 | C16: 13.3
A17: 1.63 | C17: 11.67
A18: 1.54 | C18: 9.72
A19: 1.53 | C19: 3.38
A20: 1.52 | C20: 3.04
... A24: 1.70 | C24: 4.63
B25: Итог: | C25: =SUM(C6:C24) -> 605.96
