Workbook

Sheet ВОР 2 э. шт.
B1: Ведомость работ и используемых материалов (Штукатурка)
A2: № п.п. | B2: Наименование | C2: Ед. изм. | D2: Коэф. расхода | E2: Объем
A3: 1 | B3: Оклейка швов сопряжения бетонных и других поверхностей стен, перегородок (газобетон, ПГП, панели АКОТЕК и др.) стеклохолстом | C3: пог. м | D3: 1 | E3: =(E6+E11+E16+E21)/100 * 71 -> 2378.7414
A4: 1.2 | B4: Шпаклевка гипсовая | C4: кг | D4: 0.3 | E4: =D4*E3 -> 713.62242
A5: 1.3 | B5: Лента армирующая ( серпянка)_/150мм | C5: пог. м | D5: 1.1 | E5: =D5*E3 -> 2616.6155
A6: 2 | B6: Штукатурка стен цементным, цементно-песчаным раствором с предварительной огрунтовкой / толщ. от 21 до 40 мм / высотой от 4,01 до 8 метров - ЧСТ-1 | C6: м2 | D6: 1 | E6: ='Спец 2 э. шт.'!C45 -> 907.3512
A7: 2.1 | B7: Штукатурка цементная | C7: кг | D7: 1.3 | E7: =$E$6*D7*23.077 -> 27220.627
A8: 2.2 | B8: Сетка штукатурная_/пластиковая/10*10 | C8: м2 | D8: 1.1 | E8: =$E$6*D8 -> 998.08632
A9: 2.3 | B9: Профиль маячковый_/ПМ10 | C9: пог. м | D9: 1 | E9: =$E$6*D9 -> 907.3512
A10: 2.4 | B10: Грунтовка БЕТОН-КОНТАКТ_/ | C10: кг | D10: 0.25 | E10: =$E$6*D10 -> 226.8378
A11: 3 | B11: Штукатурка стен цементным, цементно-песчаным раствором с предварительной огрунтовкой / толщ. от 21 до 40 мм / высотой от 4,01 до 8 метров - СТ-5, СТ-5.1 | C11: м2 | D11: 1 | E11: ='Спец 2 э. шт.'!E45 -> 62.38
A12: 3.1 | B12: Грунтовка БЕТОН-КОНТАКТ_/ | C12: кг | D12: 0.25 | E12: =E11*D12 -> 15.595
A13: 3.2 | B13: Профиль маячковый_/ПМ10 | C13: пог. м | D13: 1 | E13: =E11*D13 -> 62.38
A14: 3.3 | B14: Сетка штукатурная_/пластиковая/10*10 | C14: м2 | D14: 1.1 | E14: =E11*D14 -> 68.618
A15: 3.4 | B15: Штукатурка цементная | C15: кг | D15: 1.3 | E15: =E11*D15*23.077 -> 1871.4062
A16: 4 | B16: Штукатурка стен цементным, цементно-песчаным раствором с предварительной огрунтовкой / толщ. от 21 до 40 мм / высотой от 4,01 до 8 метров - СТ-8, СТ-8.1 | C16: м2 | D16: 1 | E16: ='Спец 2 э. шт.'!F45 -> 619.28
A17: 4.1 | B17: Штукатурка цементная | C17: кг | D17: 1.3 | E17: =E16*D17*23.077 -> 18578.462
A18: 4.2 | B18: Сетка штукатурная_/пластиковая/10*10 | C18: м2 | D18: 1.1 | E18: =E16*D18 -> 681.208
A19: 4.3 | B19: Профиль маячковый_/ПМ10 | C19: пог. м | D19: 1 | E19: =E16*D19 -> 619.28
A20: 4.4 | B20: Грунтовка БЕТОН-КОНТАКТ_/ | C20: кг | D20: 0.25 | E20: =E16*D20 -> 154.82
A21: 5 | B21: Штукатурка стен цементным, цементно-песчаным раствором с предварительной огрунтовкой / толщ. от 21 до 40 мм / высотой от 4,01 до 8 метров - ЧСТ-2, ЧСТ-4 | C21: м2 | D21: 1 | E21: ='Спец 2 э. шт.'!D45 -> 1761.3288
A22: 5.1 | B22: Грунтовка универсальный ЛАСТИМИН_ / LP-51 А | C22: кг | D22: 0.15 | E22: =E21*D22 -> 264.19932
A23: 5.2 | B23: Профиль маячковый_/ПМ10 | C23: пог. м | D23: 1 | E23: =E21*D23 -> 1761.3288
A24: 5.3 | B24: Сетка штукатурная_/пластиковая/10*10 | C24: м2 | D24: 1.1 | E24: =E21*D24 -> 1937.4617
A25: 5.4 | B25: Штукатурка цементная | C25: кг | D25: 1.3 | E25: =E21*D25*23.077 -> 52840.04
A26: 6 | B26: Профиль углозащ. оцинков. 31х31 мм 0.5 мм | C26: пог. м | D26: 1 | E26: 315

Sheet Спец 2 э. шт.
A1: Спецификация выполненных работ
A2: Штукатурка стен
C3: ЧСТ-1 | D3: ЧСТ-2, ЧСТ-4 | E3: СТ-5, СТ-5.1 | F3: СТ-8, СТ-8.1 | G3: Итог | J3: ТИП | K3: длина полилинии | L3: *4000
A4: № п.п. | B4: Помещения: | C4: Объем, м² | D4: Объем, м² | E4: Объем, м² | F4: Объем, м² | G4: Объем, м² | O4: Минус окна
A5: 1 | B5: 2.001 | C5: =P5/100*34 -> 40.18035 | D5: =P5/100*66 -> 77.99715 | G5: =SUM(C5:F5) -> 118.1775 | J5: чст-1,2 | K5: 31886.422 | L5: 4000 | M5: =ROUND(K5*L5/1000000, 2) -> 127.55 | O5: 15 | P5: =(M5-O5) / 100 * 5 + (M5-O5) -> 118.1775
A6: 2 | B6: 2.002 | C6: =P6/100*34 -> 38.67024 | D6: =P6/100*66 -> 75.06576 | G6: =SUM(C6:F6) -> 113.736 | K6: 30830.74 | L6: 4000 | M6: =ROUND(K6*L6/1000000, 2) -> 123.32 | O6: 15 | P6: =(M6-O6) / 100 * 5 + (M6-O6) -> 113.736
A7: 3 | B7: 2.003 | C7: =P7/100*34 -> 41.65119 | D7: =P7/100*66 -> 80.85231 | G7: =SUM(C7:F7) -> 122.5035 | K7: 32917.397 | L7: 4000 | M7: =ROUND(K7*L7/1000000, 2) -> 131.67 | O7: 15 | P7: =(M7-O7) / 100 * 5 + (M7-O7) -> 122.5035
A8: 4 | B8: 2.004 | C8: =P8/100*34 -> 106.96434 | D8: =P8/100*66 -> 207.63666 | G8: =SUM(C8:F8) -> 314.601 | K8: 78654.636 | L8: 4000 | M8: =ROUND(K8*L8/1000000, 2) -> 314.62 | O8: 15 | P8: =(M8-O8) / 100 * 5 + (M8-O8) -> 314.601
A9: 5 | B9: 2.005 | C9: =P9/100*34 -> 10.07454 | D9: =P9/100*66 -> 19.55646 | G9: =SUM(C9:F9) -> 29.631 | K9: 12056 | L9: 4000 | M9: =ROUND(K9*L9/1000000, 2) -> 48.22 | O9: 20 | P9: =(M9-O9) / 100 * 5 + (M9-O9) -> 29.631
A10: 6 | B10: 2.007 | C10: =P10/100*34 -> 36.30333 | D10: =P10/100*66 -> 70.47117 | G10: =SUM(C10:F10) -> 106.7745 | K10: 30423 | L10: 4000 | M10: =ROUND(K10*L10/1000000, 2) -> 121.69 | O10: 20 | P10: =(M10-O10) / 100 * 5 + (M10-O10) -> 106.7745
A11: 7 | B11: 2.008 | C11: =P11/100*34 -> 37.9134 | D11: =P11/100*66 -> 73.5966 | G11: =SUM(C11:F11) -> 111.51 | K11: 31549 | L11: 4000 | M11: =ROUND(K11*L11/1000000, 2) -> 126.2 | O11: 20 | P11: =(M11-O11) / 100 * 5 + (M11-O11) -> 111.51
A12: 8 | B12: 2.009 | C12: =P12/100*34 -> 36.30333 | D12: =P12/100*66 -> 70.47117 | G12: =SUM(C12:F12) -> 106.7745 | K12: 30423 | L12: 4000 | M12: =ROUND(K12*L12/1000000, 2) -> 121.69 | O12: 20 | P12: =(M12-O12) / 100 * 5 + (M12-O12) -> 106.7745
A13: 9 | B13: 2.010 | C13: =P13/100*34 -> 31.6302 | D13: =P13/100*66 -> 61.3998 | G13: =SUM(C13:F13) -> 93.03 | K13: 27149 | L13: 4000 | M13: =ROUND(K13*L13/1000000, 2) -> 108.6 | O13: 20 | P13: =(M13-O13) / 100 * 5 + (M13-O13) -> 93.03
A14: 10 | B14: 2.011 | C14: =P14/100*34 -> 36.25692 | D14: =P14/100*66 -> 70.38108 | G14: =SUM(C14:F14) -> 106.638 | K14: 30390 | L14: 4000 | M14: =ROUND(K14*L14/1000000, 2) -> 121.56 | O14: 20 | P14: =(M14-O14) / 100 * 5 + (M14-O14) -> 106.638
A15: 11 | B15: 2.012 | C15: =P15/100*34 -> 79.80735 | D15: =P15/100*66 -> 154.92015 | G15: =SUM(C15:F15) -> 234.7275 | K15: 59638 | L15: 4000 | M15: =ROUND(K15*L15/1000000, 2) -> 238.55 | O15: 15 | P15: =(M15-O15) / 100 * 5 + (M15-O15) -> 234.7275
A16: 12 | B16: 2.013 | C16: =P16/100*34 -> 28.28868 | D16: =P16/100*66 -> 54.91332 | G16: =SUM(C16:F16) -> 83.202 | K16: 24809 | L16: 4000 | M16: =ROUND(K16*L16/1000000, 2) -> 99.24 | O16: 20 | P16: =(M16-O16) / 100 * 5 + (M16-O16) -> 83.202
A17: 13 | B17: 2.014 | F17: 69.49 | G17: =SUM(C17:F17) -> 69.49 | J17: СТ-8, СТ-8.1 | K17: 18723 | L17: 4000 | M17: =ROUND(K17*L17/1000000, 2) -> 74.89 | O17: 5.4 | P17: =(M17-O17) / 100 * 5 + (M17-O17) -> 72.9645
A18: 14 | B18: 2.015 | F18: 87.93 | G18: =SUM(C18:F18) -> 87.93 | J18: СТ-8, СТ-8.1 | K18: 23333 | L18: 4000 | M18: =ROUND(K18*L18/1000000, 2) -> 93.33 | O18: 5.4 | P18: =(M18-O18) / 100 * 5 + (M18-O18) -> 92.3265
A19: 15 | B19: 2.016 | F19: 33.98 | G19: =SUM(C19:F19) -> 33.98 | J19: СТ-8, СТ-8.1 | K19: 8495 | L19: 4000 | M19: =ROUND(K19*L19/1000000, 2) -> 33.98 | P19: =(M19-O19) / 100 * 5 + (M19-O19) -> 35.679
A20: 16 | B20: 2.017 | F20: 16.4 | G20: =SUM(C20:F20) -> 16.4 | J20: СТ-8, СТ-8.1 | K20: 4100 | L20: 4000 | M20: =ROUND(K20*L20/1000000, 2) -> 16.4 | P20: =(M20-O20) / 100 * 5 + (M20-O20) -> 17.22
A21: 17 | B21: 2.162 | E21: 36.46 | G21: =SUM(C21:F21) -> 36.46 | J21: СТ-5, СТ-5.1 | K21: 9115 | L21: 4000 | M21: =ROUND(K21*L21/1000000, 2) -> 36.46 | P21: =(M21-O21) / 100 * 5 + (M21-O21) -> 38.283
A22: 18 | B22: 2.075 | C22: =P22/100*34 -> 96.57921 | D22: =P22/100*66 -> 187.47729 | G22: =SUM(C22:F22) -> 284.0565 | K22: 68290 | L22: 4001 | M22: =ROUND(K22*L22/1000000, 2) -> 273.23 | O22: 2.7 | P22: =(M22-O22) / 100 * 5 + (M22-O22) -> 284.0565
A23: 19 | B23: 2.080 | C23: =P23/100*34 -> 152.13198 | D23: =P23/100*66 -> 295.31502 | G23: =SUM(C23:F23) -> 447.447 | K23: 107884 | L23: 4000 | M23: =ROUND(K23*L23/1000000, 2) -> 431.54 | O23: 5.4 | P23: =(M23-O23) / 100 * 5 + (M23-O23) -> 447.447
A24: 20 | B24: 2.088 | C24: =P24/100*34 -> 18.07848 | D24: =P24/100*66 -> 35.09352 | G24: =SUM(C24:F24) -> 53.172 | K24: 12659 | L24: 4000 | M24: =ROUND(K24*L24/1000000, 2) -> 50.64 | P24: =(M24-O24) / 100 * 5 + (M24-O24) -> 53.172
A25: 21 | B25: 2.089 | F25: 29.16 | G25: =SUM(C25:F25) -> 29.16 | J25: СТ-8, СТ-8.1 | K25: 7290 | L25: 4000 | M25: =ROUND(K25*L25/1000000, 2) -> 29.16 | P25: =(M25-O25) / 100 * 5 + (M25-O25) -> 30.618
A26: 22 | B26: 2.090 | F26: 35.47 | G26: =SUM(C26:F26) -> 35.47 | J26: СТ-8, СТ-8.1 | K26: 8867 | L26: 4000 | M26: =ROUND(K26*L26/1000000, 2) -> 35.47 | P26: =(M26-O26) / 100 * 5 + (M26-O26) -> 37.2435
A27: 23 | B27: 2.091 | F27: 48.34 | G27: =SUM(C27:F27) -> 48.34 | J27: СТ-8, СТ-8.1 | K27: 12084 | L27: 4000 | M27: =ROUND(K27*L27/1000000, 2) -> 48.34 | P27: =(M27-O27) / 100 * 5 + (M27-O27) -> 50.757
A28: 24 | B28: 2.094 | C28: =P28/100*34 -> 15.69372 | D28: =P28/100*66 -> 30.46428 | G28: =SUM(C28:F28) -> 46.158 | K28: =5400+3590+2000 -> 10990 | L28: 4000 | M28: =ROUND(K28*L28/1000000, 2) -> 43.96 | P28: =(M28-O28) / 100 * 5 + (M28-O28) -> 46.158
A29: 25 | B29: 2.095 | F29: 35.2 | G29: =SUM(C29:F29) -> 35.2 | J29: СТ-8, СТ-8.1 | K29: 8800 | L29: 4000 | M29: =ROUND(K29*L29/1000000, 2) -> 35.2 | P29: =(M29-O29) / 100 * 5 + (M29-O29) -> 36.96
A30: 26 | B30: 2.096 | F30: 63.16 | G30: =SUM(C30:F30) -> 63.16 | J30: СТ-8, СТ-8.1 | K30: 15790 | L30: 4000 | M30: =ROUND(K30*L30/1000000, 2) -> 63.16 | P30: =(M30-O30) / 100 * 5 + (M30-O30) -> 66.318
A31: 27 | B31: 2.097 | E31: 13.12 | G31: =SUM(C31:F31) -> 13.12 | J31: СТ-5, СТ-5.1 | K31: =3240+40 -> 3280 | L31: 4000 | M31: =ROUND(K31*L31/1000000, 2) -> 13.12 | P31: =(M31-O31) / 100 * 5 + (M31-O31) -> 13.776
A32: 28 | B32: 2.098 | E32: 12.8 | G32: =SUM(C32:F32) -> 12.8 | J32: СТ-5, СТ-5.1 | K32: 3200 | L32: 4000 | M32: =ROUND(K32*L32/1000000, 2) -> 12.8 | P32: =(M32-O32) / 100 * 5 + (M32-O32) -> 13.44
A33: 29 | B33: 2.099 | C33: =P33/100*34 -> 8.7465 | D33: =P33/100*66 -> 16.9785 | G33: =SUM(C33:F33) -> 25.725 | K33: 6124 | L33: 4000 | M33: =ROUND(K33*L33/1000000, 2) -> 24.5 | P33: =(M33-O33) / 100 * 5 + (M33-O33) -> 25.725
A34: 30 | B34: 2.100 | F34: 44.08 | G34: =SUM(C34:F34) -> 44.08 | J34: СТ-8, СТ-8.1 | K34: 11020 | L34: 4000 | M34: =ROUND(K34*L34/1000000, 2) -> 44.08 | P34: =(M34-O34) / 100 * 5 + (M34-O34) -> 46.284
A35: 31 | B35: 2.101 | F35: 33.04 | G35: =SUM(C35:F35) -> 33.04 | J35: СТ-8, СТ-8.1 | K35: 8260 | L35: 4000 | M35: =ROUND(K35*L35/1000000, 2) -> 33.04 | P35: =(M35-O35) / 100 * 5 + (M35-O35) -> 34.692
A36: 32 | B36: 2.102 | C36: =P36/100*34 -> 10.96704 | D36: =P36/100*66 -> 21.28896 | G36: =SUM(C36:F36) -> 32.256 | K36: 7681 | L36: 4000 | M36: =ROUND(K36*L36/1000000, 2) -> 30.72 | P36: =(M36-O36) / 100 * 5 + (M36-O36) -> 32.256
A37: 33 | B37: 2.103 | C37: =P37/100*34 -> 19.53504 | D37: =P37/100*66 -> 37.92096 | G37: =SUM(C37:F37) -> 57.456 | K37: 13680 | L37: 4000 | M37: =ROUND(K37*L37/1000000, 2) -> 54.72 | P37: =(M37-O37) / 100 * 5 + (M37-O37) -> 57.456
A38: 34 | B38: 2.104 | F38: 15.6 | G38: =SUM(C38:F38) -> 15.6 | J38: СТ-8, СТ-8.1 | K38: 3900 | L38: 4000 | M38: =ROUND(K38*L38/1000000, 2) -> 15.6 | P38: =(M38-O38) / 100 * 5 + (M38-O38) -> 16.38
A39: 35 | B39: 2.105 | F39: 42.99 | G39: =SUM(C39:F39) -> 42.99 | J39: СТ-8, СТ-8.1 | K39: 10748 | L39: 4000 | M39: =ROUND(K39*L39/1000000, 2) -> 42.99 | P39: =(M39-O39) / 100 * 5 + (M39-O39) -> 45.1395
A40: 36 | B40: 2.106 | C40: =P40/100*34 -> 11.3526 | D40: =P40/100*66 -> 22.0374 | G40: =SUM(C40:F40) -> 33.39 | K40: =7500+1800 -> 9300 | L40: 4000 | M40: =ROUND(K40*L40/1000000, 2) -> 37.2 | O40: 5.4 | P40: =(M40-O40) / 100 * 5 + (M40-O40) -> 33.39
...

Sheet ВОР 3 э. шт.
B1: Ведомость работ и используемых материалов (Штукатурка)
A2: № п.п. | B2: Наименование | C2: Ед. изм. | D2: Коэф. расхода | E2: Объем
A3: 1 | B3: Оклейка швов сопряжения бетонных и других поверхностей стен, перегородок (газобетон, ПГП, панели АКОТЕК и др.) стеклохолстом | C3: пог. м | D3: 1 | E3: =(E6+E11+E16+E21)/100 * 71 -> 2134.0328
A4: 1.2 | B4: Шпаклевка гипсовая | C4: кг | D4: 0.3 | E4: =D4*E3 -> 640.20984
A5: 1.3 | B5: Лента армирующая ( серпянка)_/150мм | C5: пог. м | D5: 1.1 | E5: =D5*E3 -> 2347.4361
A6: 2 | B6: Штукатурка стен цементным, цементно-песчаным раствором с предварительной огрунтовкой / толщ. от 21 до 40 мм / высотой от 4,01 до 8 метров - ЧСТ-1 | C6: м2 | D6: 1 | E6: ='Спец 3 э. шт.'!C28 -> 840.61
A7: 2.1 | B7: Штукатурка цементная | C7: кг | D7: 1.3 | E7: =$E$6*D7*23.077 -> 25218.384
A8: 2.2 | B8: Сетка штукатурная_/пластиковая/10*10 | C8: м2 | D8: 1.1 | E8: =$E$6*D8 -> 924.671
A9: 2.3 | B9: Профиль маячковый_/ПМ10 | C9: пог. м | D9: 1 | E9: =$E$6*D9 -> 840.61
A10: 2.4 | B10: Грунтовка БЕТОН-КОНТАКТ_/ | C10: кг | D10: 0.25 | E10: =$E$6*D10 -> 210.1525
A11: 3 | B11: Штукатурка стен цементным, цементно-песчаным раствором с предварительной огрунтовкой / толщ. от 21 до 40 мм / высотой от 4,01 до 8 метров - СТ-5, СТ-5.1 | C11: м2 | D11: 1 | E11: ='Спец 3 э. шт.'!E28 -> 38.59
A12: 3.1 | B12: Грунтовка БЕТОН-КОНТАКТ_/ | C12: кг | D12: 0.25 | E12: =E11*D12 -> 9.6475
A13: 3.2 | B13: Профиль маячковый_/ПМ10 | C13: пог. м | D13: 1 | E13: =E11*D13 -> 38.59
A14: 3.3 | B14: Сетка штукатурная_/пластиковая/10*10 | C14: м2 | D14: 1.1 | E14: =E11*D14 -> 42.449
A15: 3.4 | B15: Штукатурка цементная | C15: кг | D15: 1.3 | E15: =E11*D15*23.077 -> 1157.7039
A16: 4 | B16: Штукатурка стен цементным, цементно-песчаным раствором с предварительной огрунтовкой / толщ. от 21 до 40 мм / высотой от 4,01 до 8 метров - СТ-8, СТ-8.1 | C16: м2 | D16: 1 | E16: ='Спец 3 э. шт.'!F28 -> 261.49
A17: 4.1 | B17: Штукатурка цементная | C17: кг | D17: 1.3 | E17: =E16*D17*23.077 -> 7844.7261
A18: 4.2 | B18: Сетка штукатурная_/пластиковая/10*10 | C18: м2 | D18: 1.1 | E18: =E16*D18 -> 287.639
A19: 4.3 | B19: Профиль маячковый_/ПМ10 | C19: пог. м | D19: 1 | E19: =E16*D19 -> 261.49
A20: 4.4 | B20: Грунтовка БЕТОН-КОНТАКТ_/ | C20: кг | D20: 0.25 | E20: =E16*D20 -> 65.3725
A21: 5 | B21: Штукатурка стен цементным, цементно-песчаным раствором с предварительной огрунтовкой / толщ. от 21 до 40 мм / высотой от 4,01 до 8 метров - ЧСТ-2, ЧСТ-4 | C21: м2 | D21: 1 | E21: ='Спец 3 э. шт.'!D28 -> 1864.99
A22: 5.1 | B22: Грунтовка универсальный ЛАСТИМИН_ / LP-51 А | C22: кг | D22: 0.15 | E22: =E21*D22 -> 279.7485
A23: 5.2 | B23: Профиль маячковый_/ПМ10 | C23: пог. м | D23: 1 | E23: =E21*D23 -> 1864.99
A24: 5.3 | B24: Сетка штукатурная_/пластиковая/10*10 | C24: м2 | D24: 1.1 | E24: =E21*D24 -> 2051.489
A25: 5.4 | B25: Штукатурка цементная | C25: кг | D25: 1.3 | E25: =E21*D25*23.077 -> 55949.886
A26: 6 | B26: Профиль углозащ. оцинков. 31х31 мм 0.5 мм | C26: пог. м | D26: 1 | E26: 315

Sheet Спец 3 э. шт.
A1: Спецификация выполненных работ
A2: Штукатурка стен
C3: ЧСТ-1 | D3: ЧСТ-2, ЧСТ-4 | E3: СТ-5, СТ-5.1 | F3: СТ-8, СТ-8.1 | G3: Итог | H3: ЧСТ-1 | I3: вверх блок 300 | J3: ЧСТ-2, ЧСТ-4 | K3: низ 900 ГАЗОБЛОК | L3: Между окнами 2700 | M3: ТИП | N3: БЕТОН | O3: над окнами ЖБ 0.3 | P3: ПГП | Q3: под окнами ПГП 1 | R3: ПГП между окнами | S3: ДВЕРИ В ПГП | T3: ДВЕРИ В ЖБ | U3: длина полилинии | V3: *4000
A4: № п.п. | B4: Помещения: | C4: Объем, м² | D4: Объем, м² | E4: Объем, м² | F4: Объем, м² | G4: Объем, м² | K4: =I4 -> 0 | Y4: Минус окна
A5: 1 | B5: 3.001 | C5: =ROUND(N5+O5-T5, 2) -> 53.82 | D5: =ROUND(P5+Q5+R5-S5, 2) -> 114.96 | G5: =SUM(C5:F5) -> 168.78 | H5: =ROUND(N5+O5-T5, 2) -> 53.82 | I5: =ROUND(P5+Q5+R5-S5, 2) -> 114.96 | K5: =I5 -> 114.96 | M5: чст-1,2 | N5: 50.3955 | O5: 3.42 | P5: 103.56 | Q5: 11.4 | R5: 0 | S5: 0 | T5: 0 | V5: 4000 | W5: =ROUND(U5*V5/1000000, 2) -> 0 | Y5: 15 | Z5: =(W5-Y5) / 100 * 5 + (W5-Y5) -> -15.75
A6: 2 | B6: 3.002 | C6: =ROUND(N6+O6-T6, 2) -> 14.03 | D6: =ROUND(P6+Q6+R6-S6, 2) -> 91.55 | G6: =SUM(C6:F6) -> 105.58 | I6: =6900+1200 -> 8100 | K6: =I6 -> 8100 | N6: 11.6 | O6: 2.43 | P6: 80.12 | Q6: 8.1 | R6: 3.33 | S6: 0 | T6: 0 | U6: 30830.74 | V6: 4000 | W6: =ROUND(U6*V6/1000000, 2) -> 123.32 | Y6: 15 | Z6: =(W6-Y6) / 100 * 5 + (W6-Y6) -> 113.736
A7: 3 | B7: 3.003 | C7: =ROUND(N7+O7-T7, 2) -> 19.86 | D7: =ROUND(P7+Q7+R7-S7, 2) -> 85.93 | G7: =SUM(C7:F7) -> 105.79 | H7: =(900+900+480+900+1200)*4/1000 -> 17.52 | I7: =4300+3500 -> 7800 | J7: =1010+3530+14190 -> 18730 | K7: =I7 -> 7800 | N7: 17.52 | O7: 2.34 | P7: 74.8 | Q7: 7.8 | R7: 3.33 | S7: 0 | T7: 0 | U7: 32917.397 | V7: 4000 | W7: =ROUND(U7*V7/1000000, 2) -> 131.67 | Y7: 15 | Z7: =(W7-Y7) / 100 * 5 + (W7-Y7) -> 122.5035
A8: 4 | B8: 3.004 | C8: =ROUND(N8+O8-T8, 2) -> 45.58 | D8: =ROUND(P8+Q8+R8-S8, 2) -> 70.93 | G8: =SUM(C8:F8) -> 116.51 | H8: =10460*4/1000 -> 41.84 | I8: =3450+3300 -> 6750 | J8: =15250*4/1000 -> 61 | K8: =I8 -> 6750 | N8: 43.6 | O8: 1.98 | P8: 61 | Q8: 6.6 | R8: 3.33 | S8: 0 | T8: 0 | U8: 78654.636 | V8: 4000 | W8: =ROUND(U8*V8/1000000, 2) -> 314.62 | Y8: 15 | Z8: =(W8-Y8) / 100 * 5 + (W8-Y8) -> 314.601
A9: 5 | B9: 3.005 | C9: =ROUND(N9+O9-T9, 2) -> 159.75 | D9: =ROUND(P9+Q9+R9-S9, 2) -> 242.78 | G9: =SUM(C9:F9) -> 402.53 | K9: =I9 -> 0 | N9: 161.94 | O9: 5.23 | P9: 230.3 | Q9: 17.42 | R9: 0 | S9: 4.9351 | T9: 7.4239 | U9: 12056 | V9: 4000 | W9: =ROUND(U9*V9/1000000, 2) -> 48.22 | Y9: 20 | Z9: =(W9-Y9) / 100 * 5 + (W9-Y9) -> 29.631
A10: 6 | B10: 3.006 | C10: =ROUND(N10+O10-T10, 2) -> 33.93 | D10: =ROUND(P10+Q10+R10-S10, 2) -> 14.8 | G10: =SUM(C10:F10) -> 48.73 | K10: =I10 -> 0 | N10: 41.35 | O10: 0 | P10: 14.8 | Q10: 0 | R10: 0 | S10: 0 | T10: 7.42 | U10: 30423 | V10: 4000 | W10: =ROUND(U10*V10/1000000, 2) -> 121.69 | Y10: 20 | Z10: =(W10-Y10) / 100 * 5 + (W10-Y10) -> 106.7745
A11: 7 | B11: 3.008 | C11: =ROUND(N11+O11-T11, 2) -> 34.19 | D11: =ROUND(P11+Q11+R11-S11, 2) -> 68.38 | G11: =SUM(C11:F11) -> 102.57 | K11: =I11 -> 0 | N11: 32.05 | O11: 2.14 | P11: 57.92 | Q11: 7.13 | R11: 3.33 | S11: 0 | T11: 0 | U11: 30423 | V11: 4000 | W11: =ROUND(U11*V11/1000000, 2) -> 121.69 | Y11: 20 | Z11: =(W11-Y11) / 100 * 5 + (W11-Y11) -> 106.7745
A12: 8 | B12: 3.009 | C12: =ROUND(N12+O12-T12, 2) -> 36.79 | D12: =ROUND(P12+Q12+R12-S12, 2) -> 67.91 | G12: =SUM(C12:F12) -> 104.7 | K12: =I12 -> 0 | N12: 34.48 | O12: 2.31 | P12: 56.88 | Q12: 7.7 | R12: 3.33 | S12: 0 | T12: 0 | U12: 27149 | V12: 4000 | W12: =ROUND(U12*V12/1000000, 2) -> 108.6 | Y12: 20 | Z12: =(W12-Y12) / 100 * 5 + (W12-Y12) -> 93.03
A13: 9 | B13: 3.010 | C13: =ROUND(N13+O13-T13, 2) -> 13.36 | D13: =ROUND(P13+Q13+R13-S13, 2) -> 88.25 | G13: =SUM(C13:F13) -> 101.61 | K13: =I13 -> 0 | N13: 11.2 | O13: 2.16 | P13: 77.72 | Q13: 7.2 | R13: 3.33 | S13: 0 | T13: 0 | U13: 30390 | V13: 4000 | W13: =ROUND(U13*V13/1000000, 2) -> 121.56 | Y13: 20 | Z13: =(W13-Y13) / 100 * 5 + (W13-Y13) -> 106.638
A14: 10 | B14: 3.011 | C14: =ROUND(N14+O14-T14, 2) -> 34.97 | D14: =ROUND(P14+Q14+R14-S14, 2) -> 70.28 | G14: =SUM(C14:F14) -> 105.25 | K14: =I14 -> 0 | N14: 32.76 | O14: 2.21 | P14: 59.6 | Q14: 7.35 | R14: 3.33 | S14: 0 | T14: 0 | U14: 59638 | V14: 4000 | W14: =ROUND(U14*V14/1000000, 2) -> 238.55 | Y14: 15 | Z14: =(W14-Y14) / 100 * 5 + (W14-Y14) -> 234.7275
A15: 11 | B15: 3.012 | C15: =ROUND(N15+O15-T15, 2) -> 15.36 | D15: =ROUND(P15+Q15+R15-S15, 2) -> 89.97 | G15: =SUM(C15:F15) -> 105.33 | K15: =I15 -> 0 | N15: 13.2 | O15: 2.16 | P15: 79.44 | Q15: 7.2 | R15: 3.33 | S15: 0 | T15: 0 | U15: 24809 | V15: 4000 | W15: =ROUND(U15*V15/1000000, 2) -> 99.24 | Y15: 20 | Z15: =(W15-Y15) / 100 * 5 + (W15-Y15) -> 83.202
A16: 12 | B16: 3.013 | C16: =ROUND(N16+O16-T16, 2) -> 42.14 | D16: =ROUND(P16+Q16+R16-S16, 2) -> 59.81 | G16: =SUM(C16:F16) -> 101.95 | K16: =I16 -> 0 | N16: 40.1 | O16: 2.04 | P16: 49.68 | Q16: 6.8 | R16: 3.33 | S16: 0 | T16: 0 | U16: 18723 | V16: 4000 | W16: =ROUND(U16*V16/1000000, 2) -> 74.89 | Y16: 5.4 | Z16: =(W16-Y16) / 100 * 5 + (W16-Y16) -> 72.9645
A17: 13 | B17: 3.014 | C17: =ROUND(N17+O17-T17, 2) -> 63.53 | D17: =ROUND(P17+Q17+R17-S17, 2) -> 157.89 | G17: =SUM(C17:F17) -> 221.42 | K17: =I17 -> 0 | N17: 62.07 | O17: 1.46 | P17: 164.12 | Q17: 4.88 | R17: 0 | S17: 11.11 | T17: 0 | U17: 23333 | V17: 4000 | W17: =ROUND(U17*V17/1000000, 2) -> 93.33 | Y17: 5.4 | Z17: =(W17-Y17) / 100 * 5 + (W17-Y17) -> 92.3265
A18: 14 | B18: 3.015 | F18: =SUM(N18:R18)-SUM(S18:T18) -> 86.31 | G18: =SUM(C18:F18) -> 86.31 | K18: =I18 -> 0 | M18: СТ-8, СТ-8.1 | N18: 33.02 | O18: 0 | P18: 55.58 | Q18: 0 | R18: 0 | S18: 2.29 | T18: 0 | U18: 8495 | V18: 4000 | W18: =ROUND(U18*V18/1000000, 2) -> 33.98 | Z18: =(W18-Y18) / 100 * 5 + (W18-Y18) -> 35.679
A19: 15 | B19: 3.016 | F19: =SUM(N19:R19)-SUM(S19:T19) -> 113.91 | G19: =SUM(C19:F19) -> 113.91 | K19: =I19 -> 0 | M19: СТ-8, СТ-8.1 | N19: 8.08 | O19: 0 | P19: 108.12 | Q19: 0 | R19: 0 | S19: 2.29 | T19: 0 | U19: 4100 | V19: 4000 | W19: =ROUND(U19*V19/1000000, 2) -> 16.4 | Z19: =(W19-Y19) / 100 * 5 + (W19-Y19) -> 17.22
A20: 16 | B20: 3.017 | F20: =SUM(N20:R20)-SUM(S20:T20) -> 36.11 | G20: =SUM(C20:F20) -> 36.11 | K20: =I20 -> 0 | M20: СТ-8, СТ-8.1 | N20: 3.12 | O20: 0 | P20: 35.28 | Q20: 0 | R20: 0 | S20: 2.29 | T20: 0 | U20: 9115 | V20: 4000 | W20: =ROUND(U20*V20/1000000, 2) -> 36.46 | Z20: =(W20-Y20) / 100 * 5 + (W20-Y20) -> 38.283
A21: 17 | B21: 3.018 | F21: =SUM(N21:R21)-SUM(S21:T21) -> 25.16 | G21: =SUM(C21:F21) -> 25.16 | K21: =I21 -> 0 | M21: СТ-8, СТ-8.1 | N21: 4 | O21: 0 | P21: 25.06 | Q21: 0 | R21: 0 | S21: 1.95 | T21: 1.95 | U21: 68290 | V21: 4001 | W21: =ROUND(U21*V21/1000000, 2) -> 273.23 | Y21: 2.7 | Z21: =(W21-Y21) / 100 * 5 + (W21-Y21) -> 284.0565
A22: 18 | B22: 3.019 | C22: =ROUND(N22+O22-T22, 2) -> 78.07 | D22: =ROUND(P22+Q22+R22-S22, 2) -> 205.31 | G22: =SUM(C22:F22) -> 283.38 | K22: =I22 -> 0 | N22: 76.3 | O22: 1.77 | P22: 195.71 | Q22: 5.9 | R22: 3.7 | S22: 0 | T22: 0 | U22: 107884 | V22: 4000 | W22: =ROUND(U22*V22/1000000, 2) -> 431.54 | Y22: 5.4 | Z22: =(W22-Y22) / 100 * 5 + (W22-Y22) -> 447.447
A23: 19 | B23: 3.020 | C23: =ROUND(N23+O23-T23, 2) -> 74.56 | D23: =ROUND(P23+Q23+R23-S23, 2) -> 243.42 | G23: =SUM(C23:F23) -> 317.98 | K23: =I23 -> 0 | N23: 79.26 | O23: 0.52 | P23: 249.17 | Q23: 1.73 | R23: 1.96 | S23: 9.44 | T23: 5.22 | U23: 12659 | V23: 4000 | W23: =ROUND(U23*V23/1000000, 2) -> 50.64 | Z23: =(W23-Y23) / 100 * 5 + (W23-Y23) -> 53.172
A24: 20 | B24: 3.021 | C24: =ROUND(N24+O24-T24, 2) -> 37.6 | D24: =ROUND(P24+Q24+R24-S24, 2) -> 48.09 | G24: =SUM(C24:F24) -> 85.69 | K24: =I24 -> 0 | N24: 37.6 | O24: 0 | P24: 50.4 | Q24: 0 | R24: 0 | S24: 2.31 | T24: 0 | U24: 7290 | V24: 4000 | W24: =ROUND(U24*V24/1000000, 2) -> 29.16 | Z24: =(W24-Y24) / 100 * 5 + (W24-Y24) -> 30.618
A25: 21 | B25: 3.077.2 | C25: =ROUND(N25+O25-T25, 2) -> 69.51 | D25: =ROUND(P25+Q25+R25-S25, 2) -> 95.88 | G25: =SUM(C25:F25) -> 165.39 | K25: =I25 -> 0 | N25: 66.96 | O25: 2.55 | P25: 89.69 | Q25: 8.5 | R25: 0 | S25: 2.31 | T25: 0 | U25: 8867 | V25: 4000 | W25: =ROUND(U25*V25/1000000, 2) -> 35.47 | Z25: =(W25-Y25) / 100 * 5 + (W25-Y25) -> 37.2435
A26: 22 | B26: 3.092 | E26: =SUM(N26:R26)-SUM(S26:T26) -> 38.59 | G26: =SUM(C26:F26) -> 38.59 | K26: =I26 -> 0 | M26: СТ-5, СТ-5.1 | N26: 0 | O26: 0 | P26: 40.88 | Q26: 0 | R26: 0 | S26: 2.29 | T26: 0 | U26: 12084 | V26: 4000 | W26: =ROUND(U26*V26/1000000, 2) -> 48.34 | Z26: =(W26-Y26) / 100 * 5 + (W26-Y26) -> 50.757
A27: 23 | B27: 3.094 | C27: =ROUND(N27+O27-T27, 2) -> 13.56 | D27: =ROUND(P27+Q27+R27-S27, 2) -> 48.85 | G27: =SUM(C27:F27) -> 62.41 | K27: =I27 -> 0 | M27: СТ-5, СТ-5.1 | N27: 13.56 | O27: 0 | P27: 52 | Q27: 0 | R27: 0 | S27: 3.15 | T27: 0 | U27: =5400+3590+2000 -> 10990 | V27: 4000 | W27: =ROUND(U27*V27/1000000, 2) -> 43.96 | Z27: =(W27-Y27) / 100 * 5 + (W27-Y27) -> 46.158
B28: сумма: | C28: =SUM(C5:C27) -> 840.61 | D28: =SUM(D5:D27) -> 1864.99 | E28: =SUM(E5:E27) -> 38.59 | F28: =SUM(F5:F27) -> 261.49 | G28: =SUM(G5:G27) -> 3005.68
