Workbook

Sheet АА

Sheet ВОР 2 эт
B1: Ведомость работ и используемых материалов
A2: № п.п. | B2: Наименование | C2: Тип | D2: Ед. изм. | E2: Коэф. расхода | F2: Объем | G2: Объем
A3: 1 | B3: Устройство стяжки СКБ / армированная сеткой от 41 мм до 60мм | C3: Типы 8.3 | D3: м2 | E3: 1 | F3: ='Спец 2 эт'!E46 -> 27.32 | G3: 122.25 | I3: =F3-G3 -> -94.93 | K3: 6.1 | L3: 7.2 | M3: 8.3 | N3: 9.2
A4: 1.1 | B4: Фиксатор арматуры Звездочка_/15/4-16 | D4: шт | E4: 8 | F4: =ROUND(E4*F3, 0) -> 219 | G4: 978 | I4: =F4-G4 -> -759
A5: 1.2 | B5: Смесь цементно-песчаная сухая_/М200 | D5: кг | E5: 1.8 | F5: =E5*F3*60 -> 2950.56 | G5: 13203 | H5: =G5/G3/E5 -> 60 | I5: =F5-G5 -> -10252.44
A6: 1.3 | B6: Сетка эл/св_/100*100*5 | D6: м2 | E6: 1.1 | F6: =E6*F3 -> 30.052 | G6: 134.475 | I6: =F6-G6 -> -104.423
A7: 1.4 | B7: Лента кромочная демпферная_/8*100мм/20м | D7: пог. м | E7: 1 | F7: =E7*F3 -> 27.32 | G7: 122.25 | I7: =F7-G7 -> -94.93
A8: 2 | B8: Устройство стяжки СКБ / армированная сеткой от 61мм до 80мм | C8: Типы 6.1, 7.2, 9.2 | D8: м2 | E8: 1 | F8: ='Спец 2 эт'!C46+'Спец 2 эт'!D46+'Спец 2 эт'!F46 -> 1530.22 | G8: 5553.92 | I8: =F8-G8 -> -4023.7
A9: 2.1 | B9: Фиксатор арматуры Звездочка_/15/4-16 | D9: шт | E9: 8 | F9: =ROUND(E9*F8, 0) -> 12242 | G9: 44431.36 | I9: =F9-G9 -> -32189.36
A10: 2.2 | B10: Смесь цементно-песчаная сухая_/М200 | D10: кг | E10: 1.8 | F10: =E10*F8*65 -> 179035.74 | G10: 649808.64 | H10: =G10/G8/E10 -> 65 | I10: =F10-G10 -> -470772.9
A11: 2.3 | B11: Сетка эл/св_/100*100*5 | D11: м2 | E11: 1.1 | F11: =E11*F8 -> 1683.242 | G11: 6109.312 | I11: =F11-G11 -> -4426.07
A12: 2.4 | B12: Лента кромочная демпферная_/8*100мм/20м | D12: пог. м | E12: 1 | F12: =E12*F8 -> 1530.22 | G12: 5553.92 | I12: =F12-G12 -> -4023.7

Sheet Спец 2 эт
A1: Спецификация выполненных работ
B2: Типы | C2: 6.1 | D2: 7.2 | E2: 8.3 | F2: 9.2 | G2: Итог | H2: 4.4 | I2: 11 | J2: 11.1
A3: № п.п. | B3: Помещения: | C3: Объем, м² | D3: Объем, м² | E3: Объем, м² | F3: Объем, м² | G3: Объем, м²
A4: 1 | B4: 2.001 | F4: 73.56 | G4: =SUM(C4:F4) -> 73.56
A5: 2 | B5: 2.002 | F5: 72.24 | G5: =SUM(C5:F5) -> 72.24
A6: 3 | B6: 2.003 | F6: 68.26 | G6: =SUM(C6:F6) -> 68.26
A7: 4 | B7: 2.004 | F7: 158.97 | G7: =SUM(C7:F7) -> 158.97
A8: 5 | B8: 2.005 | C8: 13.62 | G8: =SUM(C8:F8) -> 13.62
A9: 6 | B9: 2.007 | F9: 68.3 | G9: =SUM(C9:F9) -> 68.3
A10: 7 | B10: 2.008 | F10: 68.46 | G10: =SUM(C10:F10) -> 68.46
A11: 8 | B11: 2.009 | F11: 68.46 | G11: =SUM(C11:F11) -> 68.46
A12: 9 | B12: 2.010 | F12: 67.53 | G12: =SUM(C12:F12) -> 67.53
A13: 10 | B13: 2.011 | F13: 68.46 | G13: =SUM(C13:F13) -> 68.46
A14: 11 | B14: 2.012 | F14: 149.95 | G14: =SUM(C14:F14) -> 149.95
A15: 12 | B15: 2.013 | F15: 68.46 | G15: =SUM(C15:F15) -> 68.46
A16: 13 | B16: 2.014 | D16: 17.22 | G16: =SUM(C16:F16) -> 17.22
A17: 14 | B17: 2.015 | D17: 21.87 | G17: =SUM(C17:F17) -> 21.87
A18: 15 | B18: 2.016 | D18: 5.06 | G18: =SUM(C18:F18) -> 5.06
A19: 16 | B19: 2.017 | E19: 3.22 | G19: =SUM(C19:F19) -> 3.22
A20: 17 | B20: 2.162 | E20: 5.25 | G20: =SUM(C20:F20) -> 5.25
A21: 18 | B21: 2.075 | F21: 79.79 | G21: =SUM(C21:F21) -> 79.79
A22: 19 | B22: 2.080 | F22: 170.56 | G22: =SUM(C22:F22) -> 170.56
A23: 20 | B23: 2.084 | C23: 16 | G23: =SUM(C23:F23) -> 16
A24: 21 | B24: 2.087 | C24: 19.46 | G24: =SUM(C24:F24) -> 19.46
A25: 22 | B25: 2.088 | F25: 10.24 | G25: =SUM(C25:F25) -> 10.24
A26: 23 | B26: 2.089 | D26: 6.05 | G26: =SUM(C26:F26) -> 6.05
A27: 24 | B27: 2.090 | D27: 12.15 | G27: =SUM(C27:F27) -> 12.15
A28: 25 | B28: 2.091 | D28: 10.63 | G28: =SUM(C28:F28) -> 10.63
A29: 26 | B29: 2.094 | F29: 23.36 | G29: =SUM(C29:F29) -> 23.36
A30: 27 | B30: 2.095 | D30: 8.79 | G30: =SUM(C30:F30) -> 8.79
A31: 28 | B31: 2.096 | D31: 14.39 | G31: =SUM(C31:F31) -> 14.39
A32: 29 | B32: 2.097 | E32: 4.85 | G32: =SUM(C32:F32) -> 4.85
A33: 30 | B33: 2.098 | E33: 4.76 | G33: =SUM(C33:F33) -> 4.76
A34: 31 | B34: 2.099 | F34: 21.09 | G34: =SUM(C34:F34) -> 21.09
A35: 32 | B35: 2.100 | D35: 8.19 | G35: =SUM(C35:F35) -> 8.19
A36: 33 | B36: 2.101 | D36: 12.22 | G36: =SUM(C36:F36) -> 12.22
A37: 34 | B37: 2.102 | E37: 9.24 | G37: =SUM(C37:F37) -> 9.24
A38: 35 | B38: 2.103 | F38: 19.33 | G38: =SUM(C38:F38) -> 19.33
A39: 36 | B39: 2.104 | D39: 8.45 | G39: =SUM(C39:F39) -> 8.45
A40: 37 | B40: 2.105 | D40: 14.25 | G40: =SUM(C40:F40) -> 14.25
...

Sheet ВОР 3 эт
B1: Ведомость работ и используемых материалов
A2: № п.п. | B2: Наименование | C2: Тип | D2: Ед. изм. | E2: Коэф. расхода | F2: Объем | G2: Объем
A3: 1 | B3: Устройство стяжки СКБ / армированная сеткой от 41 мм до 60мм | C3: Типы 8.3 | D3: м2 | E3: 1 | F3: ='Спец 3 эт'!E24 -> 25.92 | G3: 122.25 | I3: =F3-G3 -> -96.33
A4: 1.1 | B4: Фиксатор арматуры Звездочка_/15/4-16 | D4: шт | E4: 8 | F4: =ROUND(E4*F3, 0) -> 207 | G4: 978 | I4: =F4-G4 -> -771
A5: 1.2 | B5: Смесь цементно-песчаная сухая_/М200 | D5: кг | E5: 1.8 | F5: =E5*F3*60 -> 2799.36 | G5: 13203 | H5: =G5/G3/E5 -> 60 | I5: =F5-G5 -> -10403.64
A6: 1.3 | B6: Сетка эл/св_/100*100*5 | D6: м2 | E6: 1.1 | F6: =E6*F3 -> 28.512 | G6: 134.475 | I6: =F6-G6 -> -105.963
A7: 1.4 | B7: Лента кромочная демпферная_/8*100мм/20м | D7: пог. м | E7: 1 | F7: =E7*F3 -> 25.92 | G7: 122.25 | I7: =F7-G7 -> -96.33
A8: 2 | B8: Устройство стяжки СКБ / армированная сеткой от 61мм до 80мм | C8: Типы 6.1, 7.2, 9.2 | D8: м2 | E8: 1 | F8: ='Спец 3 эт'!C24+'Спец 3 эт'!D24+'Спец 3 эт'!F24 -> 1231.23 | G8: 5553.92 | I8: =F8-G8 -> -4322.69
A9: 2.1 | B9: Фиксатор арматуры Звездочка_/15/4-16 | D9: шт | E9: 8 | F9: =ROUND(E9*F8, 0) -> 9850 | G9: 44431.36 | I9: =F9-G9 -> -34581.36
A10: 2.2 | B10: Смесь цементно-песчаная сухая_/М200 | D10: кг | E10: 1.8 | F10: =E10*F8*65 -> 144053.91 | G10: 649808.64 | H10: =G10/G8/E10 -> 65 | I10: =F10-G10 -> -505754.73
A11: 2.3 | B11: Сетка эл/св_/100*100*5 | D11: м2 | E11: 1.1 | F11: =E11*F8 -> 1354.353 | G11: 6109.312 | I11: =F11-G11 -> -4754.959
A12: 2.4 | B12: Лента кромочная демпферная_/8*100мм/20м | D12: пог. м | E12: 1 | F12: =E12*F8 -> 1231.23 | G12: 5553.92 | I12: =F12-G12 -> -4322.69

Sheet 9.2ЛенИнв
A1: Ведомость работ
A2: Наименование затрат | D2: Описание | E2: Ед. изм. | F2: Объем
A3: Устройство покрытия пола из линолеума | D3: Тип 11 | E3: м2 | F3: =B9+F7 -> 2388.7673
A4: № помещения | B4: Площадь, м2 | E4: № помещения | F4: Площадь, м2
A5: 2.111 | B5: =379.31+(84.163-4)*0.1 -> 387.3263 | E5: 2.081 | F5: 295.52
A6: 2.114 | B6: =381.65+(83.53-2.2-1.8)*0.1 -> 389.603 | E6: 2.085 | F6: 169.27
A7: 2.115 | B7: =563.46+(102.28-1.5-2.2)*0.1 -> 573.318 | E7: Сумма, м2: | F7: =SUM(F5:F6) -> 464.79
A8: 2.117 | B8: =563.73+10 -> 573.73
A9: Сумма, м2: | B9: =SUM(B5:B8) -> 1923.9773

Sheet 9.1ЛинИнв
A1: Ведомость работ
A2: Наименование затрат | G2: Ед. изм. | H2: Объем
A3: Устройство покрытия пола из кварцвинила / на клею (линолеум) / тип 9, 9.2 | G3: м2 | H3: =B23+E27+H23 -> 4336.9
A5: 1 эт. отм. 0.000 | D5: 2 эт. отм. +4.200 | G5: 3 эт. отм. +8.400
A6: № пом. | B6: Площадь, м2 | D6: № пом. | E6: Площадь, м2 | G6: № помещения | H6: Площадь, м2
A7: 1.027 | B7: 113.98 | D7: 2.001 | E7: 73.6 | G7: 3.002 | H7: 72.14
A8: 1.028 | B8: 68.63 | D8: 2.002 | E8: 72.22 | G8: 3.003 | H8: 70.83
A9: 1.029 | B9: 69.02 | D9: 2.003 | E9: 68.37 | G9: 3.004 | H9: 67.76
A10: 1.030 | B10: 68.94 | D10: 2.007 | E10: 68.25 | G10: 3.008 | H10: 67.77
A11: 1.031 | B11: 68.85 | D11: 2.008 | E11: 67.71 | G11: 3.009 | H11: 68.07
A12: 1.032 | B12: 67.86 | D12: 2.009 | E12: 68.44 | G12: 3.010 | H12: 67.96
A13: 1.033 | B13: 139.03 | D13: 2.010 | E13: 67.41 | G13: 3.011 | H13: 67.09
A14: 1.026 | B14: 191.9 | D14: 2.011 | E14: 68.59 | G14: 3.012 | H14: 67.1
A15: 1.039 | B15: 146.7 | D15: 2.013 | E15: 68.31 | G15: 3.013 | H15: 67.81
D16: 2.004 | E16: 159.7 | G16: 3.001 | H16: 130.7
A17: 1.040 | B17: 220.07 | D17: 2.012 | E17: 145.8 | G17: 3.005 | H17: 242.6
A18: 1.043 | B18: 60.11 | G18: 3.014 | H18: 145.6
A19: 1.044 | B19: 15.32 | D19: 2.075 | E19: 79.09
A20: 1.049 | B20: 103.1 | D20: 2.080 | E20: 101.14 | G20: 3.019 | H20: 241.2
A21: 1.050 | B21: 21.34 | D21: 2.082 | E21: 100 | G21: 3.020 | H21: 134.8
A22: 1.051 | B22: 30.12 | D22: 2.088 | E22: 9.13 | G22: 3.077.2 | H22: 139.7
A23: Сумма: | B23: =SUM(B7:B22) -> 1384.97 | D23: 2.094 | E23: 23.36 | G23: Сумма: | H23: =SUM(H7:H22) -> 1651.13
D24: 2.099 | E24: 21.09
D25: 2.103 | E25: 19.32
D26: 2.106 | E26: 19.27
D27: Сумма: | E27: =SUM(E7:E26) -> 1300.8

Sheet Налив. пол ВОР
A1: РД | B1: 2.1 По КП
D3: 1 | E3: 1 | F3: 2 | G3: 2 | H3: 3 | I3: 3
C4: этаж | D4: 1 | E4: 4.1 | F4: 1 | G4: 4.1 | H4: 1 | I4: 4.1
C5: 9 | D5: 935.07 | E5: 453.24
C6: 9.1 | D6: 37.5 | E6: 4.2 | J6: 1
C7: 9.2 | F7: 928.87 | G7: 377.244 | H7: 1135.85 | I7: 534.9 | J7: 2
C8: 9.3 | F8: 14.5 | H8: 14.79 | J8: 3
C9: 11 | G9: 299.02
C10: 11.1 | G10: 169.2

Sheet 8.2Лин
A1: Ведомость работ
A2: Наименование затрат | G2: Ед. изм. | H2: Объем
A3: Устройство покрытия пола из кварцвинила / на клею (линолеум) / тип 9, 9.2 | G3: м2 | H3: =B16+E18+H19 -> 2998.74
A5: 1 эт. отм. 0.000 | D5: 2 эт. отм. +4.200 | G5: 3 эт. отм. +8.400
A6: № пом. | B6: Площадь, м2 | D6: № пом. | E6: Площадь, м2 | G6: № помещения | H6: Площадь, м2
A7: 1.027 | B7: 113.98 | D7: 2.001 | E7: 73.6 | G7: 3.002 | H7: 72.14
A8: 1.028 | B8: 68.63 | D8: 2.002 | E8: 72.22 | G8: 3.003 | H8: 70.83
A9: 1.029 | B9: 69.02 | D9: 2.003 | E9: 68.37 | G9: 3.004 | H9: 67.76
A10: 1.030 | B10: 68.94 | D10: 2.007 | E10: 68.25 | G10: 3.008 | H10: 67.77
A11: 1.031 | B11: 68.85 | D11: 2.008 | E11: 67.71 | G11: 3.009 | H11: 68.07
A12: 1.032 | B12: 67.86 | D12: 2.009 | E12: 68.44 | G12: 3.010 | H12: 67.96
A13: 1.033 | B13: 139.03 | D13: 2.010 | E13: 67.41 | G13: 3.011 | H13: 67.09
A14: 1.026 | B14: 191.9 | D14: 2.011 | E14: 68.59 | G14: 3.012 | H14: 67.1
A15: 1.039 | B15: 146.7 | D15: 2.013 | E15: 68.31 | G15: 3.013 | H15: 67.81
A16: Сумма: | B16: =SUM(B7:B15) -> 934.91 | D16: 2.004 | E16: 159.7 | G16: 3.001 | H16: 130.7
D17: 2.012 | E17: 145.8 | G17: 3.005 | H17: 242.6
D18: Сумма: | E18: =SUM(E7:E17) -> 928.4 | G18: 3.014 | H18: 145.6
G19: Сумма: | H19: =SUM(H7:H18) -> 1135.43

Sheet 8.1Нал8в
A1: Ведомость работ
A2: Наименование затрат | G2: Ед. изм. | H2: Объем
A3: Устройство наливных полов с огрунтовкой поверхности и проклейкой демпферной лентой / толщ. до 10 мм | G3: м2 | H3: =B9+E19+H13 -> 2516.2
A5: 1 эт. отм. 0.000 | D5: 2 эт. отм. +4.200 | G5: 3 эт. отм. +8.400
A6: № помещения | B6: Площадь, м2 | D6: № помещения | E6: Площадь, м2 | G6: № помещения | H6: Площадь, м2
A7: 1.026 | B7: 191.8 | D7: 2.004 | E7: 158.7 | G7: 3.001 | H7: 131.7
A8: 1.039 | B8: 146.5 | D8: 2.012 | E8: 145.8 | G8: 3.005 | H8: 243.6
A9: Сумма, м2: | B9: =SUM(B7:B8) -> 338.3 | D9: 2.080 | E9: =201.1-E10 -> 168.5 | G9: 3.014 | H9: 146.6
D10: 2.082 | E10: 32.6 | G10: 3.019 | H10: 238.2
D11: 2.088 | E11: 9.1 | G11: 3.020 | H11: 134.8
D12: 2.075 | E12: 79.1 | G12: 3.077.2 | H12: 139.7
D13: 2.094 | E13: 23.3 | G13: Сумма, м2: | H13: =SUM(H7:H12) -> 1034.6
D14: 2.099 | E14: 21.1
D15: 2.103 | E15: 19.3
D16: 2.106 | E16: 19.2
D17: 2.081 | E17: 298.1
D18: 2.085 | E18: 168.5
D19: Сумма, м2: | E19: =SUM(E7:E18) -> 1143.3

Sheet 4.1к
A1: Ведомость работ
A2: № | B2: Наименование затрат | F2: Описание | G2: Ед. изм. | H2: Объем
A3: 1 | B3: Устройство покрытия пола СКБ с затиркой и укрытием ДВП / из керамогранитной плитки от 0,2м2/шт | F3: 1, 2, 3, этажи, блоки 1 и 4.1. Пол Тип: 6, 7.2 | G3: м2 | H3: =D11 -> 810.21
A5: № Блок | B5: Пом | C5: Тип | D5: Объем, м2:
A6: 4.1 | B6: 1.045 | C6: 6 | D6: 238.43
A7: 4.1 | B7: 1.046 | C7: 6 | D7: 83.81
A8: 4.1 | B8: 1.053 | C8: 6 | D8: 433.72
A9: 4.1 | B9: 1.054 | C9: 7 | D9: 7.73
A10: 4.1 | B10: 1.054 | C10: 7.1 | D10: 46.52
C11: Итог: | D11: =SUM(D6:D10) -> 810.21
A13: Ведомость работ, лестницы
A14: № | B14: Наименование затрат | F14: Описание | G14: Ед. изм. | H14: Объем
A15: 1 | B15: Устройство покрытия пола СКБ с затиркой и укрытием ДВП / из керамогранитной плитки до 0,2м2/шт | F15: Тип: 6, 6.1, 6.2 | G15: м2 | H15: =SUM(D20:D22)+SUM(D26:D28) -> 151.58
A16: 2 | B16: Облицовка ступеней СКБ керамогранитной плиткой с затиркой швов | F16: Тип: 6.3 | G16: м2 | H16: =D23+D29 -> 56.28
A17: 3 | B17: Облицовка ступеней СКБ керамогранитной плиткой с затиркой швов | F17: Тип: 6.4 | G17: м2 | H17: =D24+D30 -> 32.48
A19: № Блок | B19: Пом | C19: Тип | D19: Объем, м2:
A20: 4.1 | B20: ЛК-10 | C20: 6 | D20: 29.89
A21: 4.1 | B21: ЛК-10 | C21: 6.1 | D21: 29.34
A22: 4.1 | B22: ЛК-10 | C22: 6.2 | D22: 16.56
A23: 4.1 | B23: ЛК-10 | C23: 6.3 | D23: 29.58
A24: 4.1 | B24: ЛК-10 | C24: 6.4 | D24: 16.24
A26: 4.1 | B26: ЛК-11 | C26: 6 | D26: 29.89
A27: 4.1 | B27: ЛК-11 | C27: 6.1 | D27: 29.34
A28: 4.1 | B28: ЛК-11 | C28: 6.2 | D28: 16.56
A29: 4.1 | B29: ЛК-11 | C29: 6.3 | D29: 26.7
A30: 4.1 | B30: ЛК-11 | C30: 6.4 | D30: 16.24
C31: Итог: | D31: =SUM(D20:D30) -> 240.34

Sheet 4СУги.изл
A1: Ведомость работ С/У
A2: № | B2: Наименование затрат | F2: Описание | G2: Ед. изм. | H2: Объем
A3: 1 | B3: Устройство обмазочной гидроизоляции с проклеиванием швов армированной лентой из стекловолокна / в 2 слоя | F3: 1, 2, 3, этажи, блок 1. Пол Тип: 8.2 , 8.3, 7.2 | G3: м2 | H3: =D21 -> 157.4
A5: № п.п. | B5: Пом | C5: Тип | D5: Объем, м2:
A6: 1 | B6: 1.037 | C6: 8.2 | D6: 3.14
A7: 2 | B7: 1.038 | C7: 8.2 | D7: 5.25
A8: 3 | B8: 2.017 | C8: 8.3 | D8: 3.16
A9: 4 | B9: 2.162 | C9: 8.3 | D9: 5.29
A10: 5 | B10: 3.018 | C10: 8.3 | D10: 3.18
A11: 6 | B11: 3.092 | C11: 8.3 | D11: 5.25
A12: 7 | B12: 1.034 | C12: 7.2 | D12: 17.06
A13: 8 | B13: 1.035 | C13: 7.2 | D13: 21.33
A14: 9 | B14: 1.036 | C14: 7.2 | D14: 5.69
A15: 10 | B15: 2.014 | C15: 7.2 | D15: 17.08
A16: 11 | B16: 2.015 | C16: 7.2 | D16: 21.31
A17: 12 | B17: 2.016 | C17: 7.2 | D17: 5.68
... A20: 15 | B20: 3.017 | C20: 7.2 | D20: 5.63
C21: Итог: | D21: =SUM(D6:D20) -> 157.4

Sheet 3СУстж
A1: Ведомость работ С/У
A2: № | B2: Наименование затрат | F2: Описание | G2: Ед. изм. | H2: Объем
A3: 1 | B3: Устройство стяжки СКБ / армированная сеткой от 61мм до 80мм | F3: 1, 2, 3, этажи, блок 1. Пол Тип: 8.2 , 8.3, 7.2 | G3: м2 | H3: =D21 -> 157.4
A5: № п.п. | B5: Пом | C5: Тип | D5: Объем, м2:
A6: 1 | B6: 1.037 | C6: 8.2 | D6: 3.14
A7: 2 | B7: 1.038 | C7: 8.2 | D7: 5.25
A8: 3 | B8: 2.017 | C8: 8.3 | D8: 3.16
A9: 4 | B9: 2.162 | C9: 8.3 | D9: 5.29
A10: 5 | B10: 3.018 | C10: 8.3 | D10: 3.18
A11: 6 | B11: 3.092 | C11: 8.3 | D11: 5.25
A12: 7 | B12: 1.034 | C12: 7.2 | D12: 17.06
A13: 8 | B13: 1.035 | C13: 7.2 | D13: 21.33
A14: 9 | B14: 1.036 | C14: 7.2 | D14: 5.69
A15: 10 | B15: 2.014 | C15: 7.2 | D15: 17.08
A16: 11 | B16: 2.015 | C16: 7.2 | D16: 21.31
A17: 12 | B17: 2.016 | C17: 7.2 | D17: 5.68
... A20: 15 | B20: 3.017 | C20: 7.2 | D20: 5.63
C21: Итог: | D21: =SUM(D6:D20) -> 157.4

Sheet 2СУплн
A1: Ведомость работ С/У
A2: № | B2: Наименование затрат | F2: Описание | G2: Ед. изм. | H2: Объем
A3: 1 | B3: Устройство разделительного слоя / из пленки полиэтиленовой / в 1 слой | F3: 1, 2, 3, этажи, блок 1. Пол Тип: 8.2 , 8.3, 7.2 | G3: м2 | H3: =D21 -> 157.4
A5: № п.п. | B5: Пом | C5: Тип | D5: Объем, м2:
A6: 1 | B6: 1.037 | C6: 8.2 | D6: 3.14
A7: 2 | B7: 1.038 | C7: 8.2 | D7: 5.25
A8: 3 | B8: 2.017 | C8: 8.3 | D8: 3.16
A9: 4 | B9: 2.162 | C9: 8.3 | D9: 5.29
A10: 5 | B10: 3.018 | C10: 8.3 | D10: 3.18
A11: 6 | B11: 3.092 | C11: 8.3 | D11: 5.25
A12: 7 | B12: 1.034 | C12: 7.2 | D12: 17.06
A13: 8 | B13: 1.035 | C13: 7.2 | D13: 21.33
A14: 9 | B14: 1.036 | C14: 7.2 | D14: 5.69
A15: 10 | B15: 2.014 | C15: 7.2 | D15: 17.08
A16: 11 | B16: 2.015 | C16: 7.2 | D16: 21.31
A17: 12 | B17: 2.016 | C17: 7.2 | D17: 5.68
... A20: 15 | B20: 3.017 | C20: 7.2 | D20: 5.63
C21: Итог: | D21: =SUM(D6:D20) -> 157.4

Sheet 1СУизл
A1: Ведомость работ С/У
A2: № | B2: Наименование затрат | F2: Описание | G2: Ед. изм. | H2: Объем
A3: 1 | B3: Устройство тепло-звукоизоляции полов / минвата / в 1 слой | F3: 1, 2, 3, этажи, блок 1. Пол Тип: 8.2 , 8.3, 7.2 | G3: м2 | H3: =D21 -> 157.4
A5: № п.п. | B5: Пом | C5: Тип | D5: Объем, м2:
A6: 1 | B6: 1.037 | C6: 8.2 | D6: 3.14
A7: 2 | B7: 1.038 | C7: 8.2 | D7: 5.25
A8: 3 | B8: 2.017 | C8: 8.3 | D8: 3.16
A9: 4 | B9: 2.162 | C9: 8.3 | D9: 5.29
A10: 5 | B10: 3.018 | C10: 8.3 | D10: 3.18
A11: 6 | B11: 3.092 | C11: 8.3 | D11: 5.25
A12: 7 | B12: 1.034 | C12: 7.2 | D12: 17.06
A13: 8 | B13: 1.035 | C13: 7.2 | D13: 21.33
A14: 9 | B14: 1.036 | C14: 7.2 | D14: 5.69
A15: 10 | B15: 2.014 | C15: 7.2 | D15: 17.08
A16: 11 | B16: 2.015 | C16: 7.2 | D16: 21.31
A17: 12 | B17: 2.016 | C17: 7.2 | D17: 5.68
... A20: 15 | B20: 3.017 | C20: 7.2 | D20: 5.63
C21: Итог: | D21: =SUM(D6:D20) -> 157.4

Sheet 0СуПл
A1: Ведомость работ С/У
A2: № | B2: Наименование затрат | F2: Описание | G2: Ед. изм. | H2: Объем
A3: 1 | B3: Устройство покрытия пола СКБ с затиркой и укрытием ДВП / из керамогранитной плитки до 0,2м2/шт | F3: 1, 2, 3, этажи, блок 1. Пол Тип: 8.2 , 8.3 | G3: м2 | H3: =D13 -> 25.27
A4: 2 | B4: Устройство покрытия пола СКБ с затиркой и укрытием ДВП / из керамогранитной плитки от 0,2м2/шт | F4: 1, 2, 3, этажи, блоки 1 и 4.1. Пол Тип: 7.2 | G4: м2 | H4: =D25 -> 132.13
A6: № Блок | B6: Пом | C6: Тип | D6: Объем, м2:
A7: 1 | B7: 1.037 | C7: 8.2 | D7: 3.14
A8: 1 | B8: 1.038 | C8: 8.2 | D8: 5.25
A9: 1 | B9: 2.017 | C9: 8.3 | D9: 3.16
A10: 1 | B10: 2.162 | C10: 8.3 | D10: 5.29
A11: 1 | B11: 3.018 | C11: 8.3 | D11: 3.18
A12: 1 | B12: 3.092 | C12: 8.3 | D12: 5.25
C13: Итог: | D13: =SUM(D7:D12) -> 25.27
A15: № Блок | B15: Пом | C15: Тип | D15: Объем, м2:
A16: 1 | B16: 1.034 | C16: 7.2 | D16: 17.06
A17: 1 | B17: 1.035 | C17: 7.2 | D17: 21.33
A18: 1 | B18: 1.036 | C18: 7.2 | D18: 5.69
A19: 1 | B19: 2.014 | C19: 7.2 | D19: 17.08
A20: 1 | B20: 2.015 | C20: 7.2 | D20: 21.31
A21: 1 | B21: 2.016 | C21: 7.2 | D21: 5.68
A22: 1 | B22: 3.015 | C22: 7.2 | D22: 17.02
A23: 1 | B23: 3.016 | C23: 7.2 | D23: 21.33
A24: 1 | B24: 3.017 | C24: 7.2 | D24: 5.63
C25: Итог: | D25: =SUM(D16:D24) -> 132.13

Sheet 1кСу
A1: Ведомость работ С/У
A2: № | B2: Наименование затрат | F2: Описание | G2: Ед. изм. | H2: Объем
A3: 1 | B3: Устройство покрытия пола СКБ с затиркой и укрытием ДВП / из керамогранитной плитки до 0,2м2/шт | F3: 1, 2, 3, этажи, блок 1. Пол Тип: 8.2 , 8.3 | G3: м2 | H3: =D13 -> 25.27
A4: 2 | B4: Устройство покрытия пола СКБ с затиркой и укрытием ДВП / из керамогранитной плитки от 0,2м2/шт | F4: 1, 2, 3, этажи, блоки 1 и 4.1. Пол Тип: 7.2 | G4: м2 | H4: =D25 -> 132.13
A6: № Блок | B6: Пом | C6: Тип | D6: Объем, м2:
A7: 1 | B7: 1.037 | C7: 8.2 | D7: 3.14
A8: 1 | B8: 1.038 | C8: 8.2 | D8: 5.25
A9: 1 | B9: 2.017 | C9: 8.3 | D9: 3.16
A10: 1 | B10: 2.162 | C10: 8.3 | D10: 5.29
A11: 1 | B11: 3.018 | C11: 8.3 | D11: 3.18
A12: 1 | B12: 3.092 | C12: 8.3 | D12: 5.25
C13: Итог: | D13: =SUM(D7:D12) -> 25.27
A15: № Блок | B15: Пом | C15: Тип | D15: Объем, м2:
A16: 1 | B16: 1.034 | C16: 7.2 | D16: 17.06
A17: 1 | B17: 1.035 | C17: 7.2 | D17: 21.33
A18: 1 | B18: 1.036 | C18: 7.2 | D18: 5.69
A19: 1 | B19: 2.014 | C19: 7.2 | D19: 17.08
A20: 1 | B20: 2.015 | C20: 7.2 | D20: 21.31
A21: 1 | B21: 2.016 | C21: 7.2 | D21: 5.68
A22: 1 | B22: 3.015 | C22: 7.2 | D22: 17.02
A23: 1 | B23: 3.016 | C23: 7.2 | D23: 21.33
A24: 1 | B24: 3.017 | C24: 7.2 | D24: 5.63
C25: Итог: | D25: =SUM(D16:D24) -> 132.13
A28: Спецификация выполненных работ
A29: № п.п. | B29: Наименование | H29: Описание | I29: Ед. изм. | J29: Объем
A30: 1 | B30: Устройство покрытия пола СКБ с затиркой и укрытием ДВП / из керамогранитной плитки от 0,2м2/шт | H30: Тип: 6, 6.1, 6.2 | I30: м2 | J30: =SUM(C37:C39)+SUM(G37:G39)+SUM(J37:J39) -> 216.87
A31: 2 | B31: Облицовка ступеней СКБ керамогранитной плиткой с затиркой швов | H31: Тип: 6.3 | I31: м2 | J31: =C40+G40+J40 -> 85.86
A32: 3 | B32: Облицовка ступеней СКБ керамогранитной плиткой с затиркой швов | H32: Тип: 6.4 | I32: м2 | J32: =C41+G41+J41 -> 48.72
A33: 4 | B33: Устройство плинтуса из керамогранитной плитки СКБ | H33: Тип: ПЛ-3 | I33: пог. м. | J33: =C42+G42+J42 -> 341
A35: ЛК-9 | E35: ЛК-10
A36: № п.п. | B36: Тип | C36: Объем, м² | E36: № п.п. | F36: Пом.: | G36: Объем, м² | I36: Пом.: | J36: Объем, м²
B37: 6 | C37: 26.25 | F37: 6 | G37: 29.89 | I37: 6 | J37: 29.89
B38: 6.1 | C38: 21.92 | F38: 6.1 | G38: 29.34 | I38: 6.1 | J38: 29.34
B39: 6.2 | C39: 17.12 | F39: 6.2 | G39: 16.56 | I39: 6.2 | J39: 16.56
B40: 6.3 | C40: 29.58 | F40: 6.3 | G40: 29.58 | I40: 6.3 | J40: 26.7
B41: 6.4 | C41: 16.24 | F41: 6.4 | G41: 16.24 | I41: 6.4 | J41: 16.24
B42: ПЛ-3, п.м. | C42: 110.3 | F42: ПЛ-3, п.м. | G42: 116.2 | I42: ПЛ-3, п.м. | J42: 114.5
A47: Ведомость работ, лестницы
A48: № | B48: Наименование затрат | F48: Описание | G48: Ед. изм. | H48: Объем
A49: 1 | B49: Устройство покрытия пола СКБ с затиркой и укрытием ДВП / из керамогранитной плитки до 0,2м2/шт | F49: Тип: 6, 6.1, 6.2 | G49: м2 | H49: =D54+D55+D56 -> 65.29
...

Sheet 7.8Пл6
A1: Ведомость работ
A2: № | B2: Наименование затрат | F2: Описание | G2: Ед. изм. | H2: Объем
A3: 1 | B3: Устройство покрытия пола СКБ с затиркой и укрытием ДВП / из керамогранитной плитки от 0,2м2/шт | F3: Пол Тип: 6.1. | G3: м2 | H3: =D9 -> 435.32
A5: № п.п. | B5: Пом | C5: Тип | D5: Объем, м2:
A6: 1 | B6: ММП1 | C6: 6.1 | D6: 158.3
A7: 2 | B7: ММП2 | C7: 6.1 | D7: 152.1
A8: 3 | B8: 2.109 | C8: 6.1 | D8: 124.92
C9: Итог: | D9: =SUM(D6:D8) -> 435.32
D12: 435.32

Sheet 7.7ммп
A1: Ведомость работ
A2: № | B2: Наименование затрат | F2: Ед. изм. | G2: Объем
A3: 1 | B3: Алмазная резка железобетонных конструкций (учтены расходные материалы)_ / 180 мм | F3: пог.м. | G3: =1.144*6+4.1*4+0.9*18 -> 39.464
A5: Ведомость работ
A6: № | B6: Наименование затрат | F6: Ед. изм. | G6: Объем
A7: 2 | B7: Демонтаж бетона с сохранением арматуры | F7: м3 | G7: =0.9*0.03*4.1*4 -> 0.4428
A9: Ведомость работ
A10: № | B10: Наименование затрат | F10: Ед. изм. | G10: Объем
A11: 3 | B11: Устройство кирпичной кирпичной кладки | F11: м3 | G11: =0.34*4.1 -> 1.394
A13: Ведомость работ
A14: № | B14: Наименование затрат | F14: Ед. изм. | G14: Объем
A15: 4 | B15: Устройство монолитных лестничных маршей (М400) | F15: м3 | G15: =0.76*4.1 -> 3.116

Sheet 7.6Плв6
A1: Ведомость работ
A2: № | B2: Поз | C2: Наименование затрат | G2: Описание | H2: Ед. изм. | I2: Объем
A3: 1 | B3: 177 | C3: Устройство покрытия пола СКБ с затиркой и укрытием ДВП / из керамогранитной плитки до 0,2м2/шт | G3: 1, 2, 3, этажи, блок 1. Пол Тип: 8.2 , 8.3 | H3: м2 | I3: =D13 -> 25.27
A4: 2 | B4: 192 | C4: Устройство покрытия пола СКБ с затиркой и укрытием ДВП / из керамогранитной плитки от 0,2м2/шт | G4: 1, 2, 3, этажи, блоки 1 и 4.1. Пол Тип: 6, 7.2 | H4: м2 | I4: =D27 -> 454.37
A6: № Блок | B6: Пом | C6: Тип | D6: Объем, м2:
A7: 1 | B7: 1.037 | C7: 8.2 | D7: 3.14
A8: 1 | B8: 1.038 | C8: 8.2 | D8: 5.25
A9: 1 | B9: 2.017 | C9: 8.3 | D9: 3.16
A10: 1 | B10: 2.162 | C10: 8.3 | D10: 5.29
A11: 1 | B11: 3.018 | C11: 8.3 | D11: 3.18
A12: 1 | B12: 3.092 | C12: 8.3 | D12: 5.25
C13: Итог: | D13: =SUM(D7:D12) -> 25.27
A15: № Блок | B15: Пом | C15: Тип | D15: Объем, м2:
A16: 1 | B16: 1.045 | C16: 6 | D16: 238.43
A17: 1 | B17: 1.046 | C17: 6 | D17: 83.81
A18: 1 | B18: 1.034 | C18: 7.2 | D18: 17.06
A19: 1 | B19: 1.035 | C19: 7.2 | D19: 21.33
A20: 1 | B20: 1.036 | C20: 7.2 | D20: 5.69
A21: 1 | B21: 2.014 | C21: 7.2 | D21: 17.08
A22: 1 | B22: 2.015 | C22: 7.2 | D22: 21.31
A23: 1 | B23: 2.016 | C23: 7.2 | D23: 5.68
A24: 1 | B24: 3.015 | C24: 7.2 | D24: 17.02
A25: 1 | B25: 3.016 | C25: 7.2 | D25: 21.33
A26: 1 | B26: 3.017 | C26: 7.2 | D26: 5.63
C27: Итог: | D27: =SUM(D16:D26) -> 454.37

Sheet 7.5излЛК6в6
A1: Ведомость работ
A2: № | B2: Поз | C2: Наименование затрат | G2: Описание | H2: Ед. изм. | I2: Объем
A3: 1 | B3: 109 | C3: Устройство тепло-звукоизоляции полов / минвата / в 1 слой | G3: НЗ № 8 от 17.11.2025 Отделка лестниц: ЛК9, ЛК10, ЛК11. Полы Тип: 6 | H3: м2 | I3: =D9 -> 84.51
A5: № Блок | B5: Пом | C5: Тип | D5: 1 этаж
A6: 1 | B6: 1.025 | C6: ЛК9, Тип-6 | D6: 25.93
A7: 4.1 | B7: 1.047 | C7: ЛК10, Тип-6 | D7: 29.32
A8: 4.1 | B8: 1.052 | C8: ЛК11, Тип-6 | D8: 29.26
C9: Итог: | D9: =SUM(D6:D8) -> 84.51
K15: 1 | L15: 1 | M15: 4.1
K16: 5 | L16: 1.65 | M16: 2.24
A17: 1 | B17: 1.038 | C17: 5 | D17: 5.24 | K17: 6 | L17: 13.62 | M17: 759.68
K18: 7 | L18: 43.82 | M18: 61.15
K19: 8.1 | L19: 0 | M19: 23.92
K20: 8.2 | L20: 8.55 | M20: 0
K21: 9 | L21: 936.68 | M21: 453.05
K22: 9.1
K27: 2 | L27: 1 | M27: 4.1
K28: 5 | L28: 1.52 | M28: 2.28
K29: 6 | L29: 13.62 | M29: 76.59
K30: 7
K31: 8.1
K32: 8.2
K33: 9
K34: 9.1

Sheet 7.4изл7.1в6
A1: Ведомость работ
A2: № | B2: Поз | C2: Наименование затрат | G2: Описание | H2: Ед. изм. | I2: Объем
A3: 1 | B3: 111 | C3: Устройство тепло-звукоизоляции полов / Пенополистирол / в 1 слой | G3: Тип 7.1 Утеплитель ТЕХНОНИКОЛЬ | H3: м2 | I3: =D7 -> 46.62
A5: № Блок | B5: Пом | C5: Тип | D5: 1 этаж
A6: 4.1 | B6: 1.054 | C6: 7.1 | D6: 46.62
C7: Итог: | D7: =SUM(D6:D6) -> 46.62

Sheet 7.3Пл6
A1: Ведомость работ
A2: № | B2: Поз | C2: Наименование затрат | G2: Описание | H2: Ед. изм. | I2: Объем
A3: 1 | B3: 202 | C3: Устройство покрытия пола СКБ с затиркой и укрытием ДВП / из керамогранитной плитки от 0,2м2/шт | G3: 1этаж, блок 4.1. Пол Тип: 6, 7, 7.1. | H3: м2 | I3: =D9 -> 487.97
A5: № Блок | B5: Пом | C5: Тип | D5: 1 этаж
A6: 4.1 | B6: 1.053 | C6: 6 | D6: 433.72
A7: 4.1 | B7: 1.054 | C7: 7 | D7: 7.73
A8: 4.1 | B8: 1.054 | C8: 7.1 | D8: 46.52
C9: Итог: | D9: =SUM(D6:D8) -> 487.97

Sheet Спец 3 эт
A1: Спецификация выполненных работ
B2: Типы | C2: 6.1 | D2: 7.2 | E2: 8.3 | F2: 9.2 | G2: Итог | H2: 4.4 | I2: 11 | J2: 11.1
A3: № п.п. | B3: Помещения: | C3: Объем, м² | D3: Объем, м² | E3: Объем, м² | F3: Объем, м² | G3: Объем, м²
A4: 1 | B4: 3.006 | C4: 13.62 | G4: =SUM(C4:F4) -> 13.62 | K4: 1
A5: 2 | B5: 3.094 | C5: 15.07 | G5: =SUM(C5:F5) -> 15.07 | K5: 4.1
A6: 3 | B6: 3.015 | D6: 17.21 | G6: =SUM(C6:F6) -> 17.21 | K6: 1
A7: 4 | B7: 3.016 | D7: 21.12 | G7: =SUM(C7:F7) -> 21.12 | K7: 1
A8: 5 | B8: 3.017 | D8: 5.06 | G8: =SUM(C8:F8) -> 5.06 | K8: 1
A9: 6 | B9: 3.018 | E9: 5.06 | G9: =SUM(C9:F9) -> 5.06 | K9: 1
A10: 7 | B10: 3.092 | E10: 5.24 | G10: =SUM(C10:F10) -> 5.24 | K10: 1
A11: 8 | B11: 3.021 | E11: 15.62 | G11: =SUM(C11:F11) -> 15.62 | K11: 4.1
A12: 9 | B12: 3.004 | F12: 67.59 | G12: =SUM(C12:F12) -> 67.59 | K12: 1
A13: 10 | B13: 3.008 | F13: 67.84 | G13: =SUM(C13:F13) -> 67.84 | K13: 1
A14: 11 | B14: 3.009 | F14: 68 | G14: =SUM(C14:F14) -> 68 | K14: 1
A15: 12 | B15: 3.01 | F15: 68 | G15: =SUM(C15:F15) -> 68 | K15: 1
A16: 13 | B16: 3.011 | F16: 67.14 | G16: =SUM(C16:F16) -> 67.14 | K16: 1
A17: 14 | B17: 3.012 | F17: 68 | G17: =SUM(C17:F17) -> 68 | K17: 1
A18: 15 | B18: 3.013 | F18: 68 | G18: =SUM(C18:F18) -> 68 | K18: 1
A19: 16 | B19: 3.014 | F19: 148.61 | G19: =SUM(C19:F19) -> 148.61 | K19: 1
A20: 17 | B20: 3.019 | F20: 244.28 | G20: =SUM(C20:F20) -> 244.28 | K20: 4.1
A21: 18 | B21: 3.02 | F21: 137.73 | G21: =SUM(C21:F21) -> 137.73 | K21: 4.1
A22: 19 | B22: 3.085 | F22: 13.16 | G22: =SUM(C22:F22) -> 13.16 | K22: 4.1
A23: 20 | B23: 3.077.2 | F23: 140.8 | G23: =SUM(C23:F23) -> 140.8 | K23: 4.1
B24: сумма: | C24: =SUM(C4:C23) -> 28.69 | D24: =SUM(D4:D23) -> 43.39 | E24: =SUM(E4:E23) -> 25.92 | F24: =SUM(F4:F23) -> 1159.15 | G24: =SUM(G4:G23) -> 1257.15
H25: 0
I26: 0
J27: 0

Sheet общий (2)
B1: Ведомость работ и используемых материалов
A2: № п.п. | B2: Наименование | C2: Тип | D2: Ед. изм. | E2: Коэф. расхода | F2: Объем | G2: Объем
A3: 6.3.1.5.1.1.3.1 | B3: Устройство наливных полов с огрунтовкой поверхности и проклейкой демпферной лентой / толщ. до 10 мм | C3: Типы 9, 9.1, 9.2, 9.3, 11, 11.1 | D3: м2 | E3: 1 | F3: 4905.38 | G3: 4905.38 | I3: =F3-G3 -> 0
B4: Наливной пол_ / Унифицированный по ПИК-СТАНДАРТ | D4: кг | E4: 1.6 | F4: =E4*F3*10 -> 78486.08 | G4: 78486.08 | I4: =F4-G4 -> 0
B5: Лента кромочная демпферная_/8*100мм/20м | D5: пог. м | E5: 1 | F5: =E5*F3 -> 4905.38 | G5: 4905.38 | I5: =F5-G5 -> 0
B6: Грунтовка универсальный ЛАСТИМИН_ / УНКОНТ ЛЮКС LP51 А | D6: кг | E6: 0.255 | F6: =E6*F3 -> 1250.8719 | G6: 1250.872 | I6: =F6-G6 -> -0.0001
A7: 6.3.1.5.1.1.6.3 | B7: Устройство разделительного слоя / из пленки полиэтиленовой / в 1 слой | C7: Типы 4.4, 5, 5.1, 6, 6.1, 7, 7.1, 7.2, 8.1, 8.2, 9, 9.1 | D7: м2 | E7: 1 | F7: 2785.09 | G7: 2785.09 | I7: =F7-G7 -> 0
B8: Пленка полиэтиленовая_/200мкр | D8: м2 | E8: 1.1 | F8: =E8*F7 -> 3063.599 | G8: 3063.599 | I8: =F8-G8 -> 0
A9: 6.3.1.5.1.1.9.1 | B9: Обработка полов гидрофобизирующим составом | C9: Типы 5, 5.1 - обеспыливание | D9: м2 | E9: 1 | F9: 47.77 | G9: 47.77 | I9: =F9-G9 -> 0
B10: Пропитка для бетонных поверхностей / Элакор МБ1 | D10: кг | E10: 0.3 | F10: =E10*F9 -> 14.331 | G10: 14.331 | I10: =F10-G10 -> 0
B11: Грунтовка силикатная КМ0 Прозрачный | D11: кг | E11: 0.2 | F11: =E11*F9 -> 9.554 | G11: 9.554 | I11: =F11-G11 -> 0
A12: 6.3.1.5.1.1.10.1 | B12: Затирка, уход, полировка полов мех.способом | C12: Тип 4.4 | D12: м2 | E12: 1 | F12: 72.94 | G12: 72.94 | I12: =F12-G12 -> 0
B13: Цемент- / Портланд / М500 | D13: кг | E13: 0.6 | F13: =E13*F12 -> 43.764 | G13: 43.764 | I13: =F13-G13 -> 0
A14: 6.3.1.5.1.1.11.2 | B14: Устройство стяжки СКБ / армированная сеткой от 21 мм до 40мм | C14: Тип 7.1 40мм | D14: м2 | E14: 1 | F14: 46.62 | G14: 46.62 | I14: =F14-G14 -> 0
B15: Фиксатор арматуры Звездочка_/15/4-16 | D15: шт | E15: 8 | F15: =ROUND(E15*F14, 0) -> 373 | G15: 372.96 | I15: =F15-G15 -> 0.04
B16: Смесь цементно-песчаная сухая_/М200 | D16: кг | E16: 1.8 | F16: =E16*F14*40 -> 3356.64 | G16: 3356.64 | H16: =G16/G14/E16 -> 40 | I16: =F16-G16 -> 0
B17: Сетка эл/св_/100*100*5 | D17: м2 | E17: 1.1 | F17: =E17*F14 -> 51.282 | G17: 51.282 | I17: =F17-G17 -> 0
B18: Лента кромочная демпферная_/8*100мм/20м | D18: пог. м | E18: 1 | F18: =E18*F14 -> 46.62 | G18: 46.62 | I18: =F18-G18 -> 0
A19: 6.3.1.5.1.1.11.3 | B19: Устройство стяжки СКБ / армированная сеткой от 41 мм до 60мм | C19: Типы 8.3, 9.1, 9.3 60мм | D19: м2 | E19: 1 | F19: 122.25 | G19: 122.25 | I19: =F19-G19 -> 0
B20: Фиксатор арматуры Звездочка_/15/4-16 | D20: шт | E20: 8 | F20: =ROUND(E20*F19, 0) -> 978 | G20: 978 | I20: =F20-G20 -> 0
B21: Смесь цементно-песчаная сухая_/М200 | D21: кг | E21: 1.8 | F21: =E21*F19*60 -> 13203 | G21: 13203 | H21: =G21/G19/E21 -> 60 | I21: =F21-G21 -> 0
B22: Сетка эл/св_/100*100*5 | D22: м2 | E22: 1.1 | F22: =E22*F19 -> 134.475 | G22: 134.475 | I22: =F22-G22 -> 0
B23: Лента кромочная демпферная_/8*100мм/20м | D23: пог. м | E23: 1 | F23: =E23*F19 -> 122.25 | G23: 122.25 | I23: =F23-G23 -> 0
A24: 6.3.1.5.1.1.11.4 | B24: Устройство стяжки СКБ / армированная сеткой от 61мм до 80мм | C24: Типы 6, 6.1, 7, 7.2, 8.1, 8.2, 9, 9.2 | D24: м2 | E24: 1 | F24: 5553.92 | G24: 5553.92 | I24: =F24-G24 -> 0
B25: Фиксатор арматуры Звездочка_/15/4-16 | D25: шт | E25: 8 | F25: =ROUND(E25*F24, 0) -> 44431 | G25: 44431.36 | I25: =F25-G25 -> -0.36
B26: Смесь цементно-песчаная сухая_/М200 | D26: кг | E26: 1.8 | F26: =E26*F24*65 -> 649808.64 | G26: 649808.64 | H26: =G26/G24/E26 -> 65 | I26: =F26-G26 -> 0
B27: Сетка эл/св_/100*100*5 | D27: м2 | E27: 1.1 | F27: =E27*F24 -> 6109.312 | G27: 6109.312 | I27: =F27-G27 -> 0
B28: Лента кромочная демпферная_/8*100мм/20м | D28: пог. м | E28: 1 | F28: =E28*F24 -> 5553.92 | G28: 5553.92 | I28: =F28-G28 -> 0
A29: 6.3.1.5.1.1.11.4 | B29: Устройство стяжки СКБ / армированная сеткой от 61мм до 80мм | C29: Типы 11, 11.1 68мм | D29: м2 | E29: 1 | F29: 468.22 | G29: 468.22 | I29: =F29-G29 -> 0
B30: Грунтовка БЕТОН-КОНТАКТ_/ | D30: кг | E30: 0.255 | F30: =E30*F29 -> 119.3961 | G30: 119.396 | I30: =F30-G30 -> 0.0001
B31: Лента кромочная демпферная_/8*100мм/20м | D31: пог. м | E31: 1 | F31: =E31*F29 -> 468.22 | G31: 468.22 | I31: =F31-G31 -> 0
B32: Сетка эл/св_/100*100*5 | D32: м2 | E32: 1.1 | F32: =E32*F29 -> 515.042 | G32: 515.042 | I32: =F32-G32 -> 0
B33: Смесь цементно-песчаная сухая_/М200 | D33: кг | E33: 1.8 | F33: =E33*F29*68 -> 57310.128 | G33: 57310.128 | H33: =G33/G29/E33 -> 68 | I33: =F33-G33 -> 0
B34: Фиксатор арматуры Звездочка_/15/4-16 | D34: шт | E34: 8 | F34: =ROUND(E34*F29, 0) -> 3746 | G34: 3745.76 | I34: =F34-G34 -> 0.24
A35: 6.3.1.5.1.1.11.4 | B35: Устройство стяжки СКБ / армированная сеткой от 61мм до 80мм | C35: Тип 5 70мм | D35: м2 | E35: 1 | F35: 19.42 | G35: 19.42 | I35: =F35-G35 -> 0
B36: Фиксатор арматуры Звездочка_/15/4-16 | D36: шт | E36: 8 | F36: =ROUND(E36*F35, 0) -> 155 | G36: 155.36 | I36: =F36-G36 -> -0.36
B37: Смесь цементно-песчаная сухая_/М150 | D37: кг | E37: 1.8 | F37: =E37*F35*70 -> 2446.92 | G37: 2446.92 | H37: =G37/G35/E37 -> 70 | I37: =F37-G37 -> 0
B38: Сетка эл/св_/100*100*4 | D38: м2 | E38: 1.1 | F38: =E38*F35 -> 21.362 | G38: 21.362 | I38: =F38-G38 -> 0
B39: Лента кромочная демпферная_/8*100мм/20м | D39: пог. м | E39: 1 | F39: =E39*F35 -> 19.42 | G39: 19.42 | I39: =F39-G39 -> 0
A40: 6.3.1.5.1.1.11.4 | B40: Устройство стяжки СКБ / армированная сеткой от 61мм до 80мм | C40: Типы 4.4, 5.1 80мм | D40: м2 | E40: 1 | F40: 101.29 | G40: 101.29 | I40: =F40-G40 -> 0
...

Sheet не сделали
A1: 1 | B1: Устройство стяжки СКБ / армированная сеткой от 21 мм до 40мм | C1: Тип 7.1 40мм | D1: м2 | E1: 1 | F1: 46.62
A2: 1.1 | B2: Фиксатор арматуры Звездочка_/15/4-16 | D2: шт | E2: 8 | F2: 372
A3: 1.2 | B3: Смесь цементно-песчаная сухая_/М200 | D3: кг | E3: 1.8 | F3: 3356.64
A4: 1.3 | B4: Сетка эл/св_/100*100*5 | D4: м2 | E4: 1.1 | F4: 51.282
A5: 1.4 | B5: Лента кромочная демпферная_/8*100мм/20м | D5: пог. м | E5: 1 | F5: 46.62
A7: 1 | B7: 4.1 | C7: 2.081 | D7: 11 | E7: 298.28
A8: 2 | B8: Устройство стяжки СКБ / армированная сеткой от 61мм до 80мм | C8: Типы 6.1, 7.2, 9.2 | D8: м2 | E8: 1 | F8: =SUM(F14:F17) -> 514.06 | G8: 5553.92 | I8: =F8-G8 -> -5039.86
A9: 2.1 | B9: Фиксатор арматуры Звездочка_/15/4-16 | D9: шт | E9: 8 | F9: =ROUND(E9*F8, 0) -> 4112 | G9: 44431.36 | I9: =F9-G9 -> -40319.36
A10: 2.2 | B10: Смесь цементно-песчаная сухая_/М200 | D10: кг | E10: 1.8 | F10: =E10*F8*65 -> 60145.02 | G10: 649808.64 | H10: =G10/G8/E10 -> 65 | I10: =F10-G10 -> -589663.62
A11: 2.3 | B11: Сетка эл/св_/100*100*5 | D11: м2 | E11: 1.1 | F11: =E11*F8 -> 565.466 | G11: 6109.312 | I11: =F11-G11 -> -5543.846
A12: 2.4 | B12: Лента кромочная демпферная_/8*100мм/20м | D12: пог. м | E12: 1 | F12: =E12*F8 -> 514.06 | G12: 5553.92 | I12: =F12-G12 -> -5039.86
A14: 9 | B14: 3.001 | F14: 129.68 | G14: =SUM(C14:F14) -> 129.68 | K14: 1
A15: 10 | B15: 3.002 | F15: 73.05 | G15: =SUM(C15:F15) -> 73.05 | K15: 1
A16: 11 | B16: 3.003 | F16: 71.71 | G16: =SUM(C16:F16) -> 71.71 | K16: 1
A17: 13 | B17: 3.005 | F17: 239.62 | G17: =SUM(C17:F17) -> 239.62 | K17: 1

Sheet ВорИзол
B1: Ведомость работ
A2: № п.п. | B2: Наименование | C2: Тип | D2: Ед. изм. | E2: Коэф. расхода | F2: Объем
A3: 1 | B3: Устройство тепло-звукоизоляции полов / минвата / в 1 слой | C3: Типы 5, 6, 7, 7.2, 8.1, 8.2, 9, 9.1 | D3: м2 | E3: 1 | F3: =Из1эт!E29 -> 2263.66
A4: 1.1 | B4: Плита минераловатная_ / Технолайт Экстра | D4: м3 | E4: 1.03 | F4: =E4*F3*50/1000 -> 116.57849

Sheet Из1эт
A1: Спецификация выполненных работ (1 этаж)
A2: № п.п. | B2: Блок | C2: № пом. | D2: Типы | E2: Объем, м²
A3: 1 | B3: 1 | C3: 1.024 | D3: 6 | E3: 13.62
A4: 2 | B4: 4.1 | C4: 1.045 | D4: 6 | E4: 161.78
A5: 3 | B5: 4.1 | C5: 1.046 | D5: 6 | E5: 161.15
A6: 4 | B6: 4.1 | C6: 1.053 | D6: 6 | E6: 443.48
A7: 5 | B7: 1 | C7: 1.034 | D7: 7 | E7: 17.22
A8: 6 | B8: 1 | C8: 1.035 | D8: 7 | E8: 21.63
A9: 7 | B9: 1 | C9: 1.036 | D9: 7 | E9: 5.76
A10: 8 | B10: 4.1 | C10: 1.054 | D10: 7 | E10: 14.54
A11: 9 | B11: 4.1 | C11: 1.048 | D11: 8.1 | E11: 23.92
A12: 10 | B12: 1 | C12: 1.037 | D12: 8.2 | E12: 3.34
A13: 11 | B13: 1 | C13: 1.038 | D13: 8.2 | E13: 5.25
A14: 12 | B14: 1 | C14: 1.026 | D14: 9 | E14: 191.68
... A28: 26 | B28: 4.1 | C28: 1.051 | D28: 9 | E28: 31.58
D29: сумма: | E29: =SUM(E3:E28) -> 2263.66

Sheet Из2эт
A1: Спецификация выполненных работ (2 этаж)
A2: № п.п. | B2: Блок | C2: № пом. | D2: Типы | E2: Объем, м²
A3: 1 | B3: 1 | C3: 2.014 | D3: 7.2 | E3: 0
A4: 2 | B4: 1 | C4: 2.015 | D4: 7.2 | E4: 0
A5: 3 | B5: 1 | C5: 2.016 | D5: 7.2 | E5: 0
A6: 4 | B6: 4.1 | C6: 2.089 | D6: 7.2 | E6: 0
A7: 5 | B7: 4.1 | C7: 2.09 | D7: 7.2 | E7: 0
A8: 6 | B8: 4.1 | C8: 2.091 | D8: 7.2 | E8: 0
A9: 7 | B9: 4.1 | C9: 2.095 | D9: 7.2 | E9: 0
A10: 8 | B10: 4.1 | C10: 2.096 | D10: 7.2 | E10: 0
A11: 9 | B11: 4.1 | C11: 2.1 | D11: 7.2 | E11: 0
A12: 10 | B12: 4.1 | C12: 2.101 | D12: 7.2 | E12: 0
A13: 11 | B13: 4.1 | C13: 2.104 | D13: 7.2 | E13: 0
A14: 12 | B14: 4.1 | C14: 2.105 | D14: 7.2 | E14: 0
... A16: 14 | B16: 4.1 | C16: 2.108 | D16: 7.2 | E16: 0
D17: сумма: | E17: =SUM(E3:E16) -> 0

Sheet ВорПленка
B1: Ведомость работ
A2: № п.п. | B2: Наименование | C2: Тип | D2: Ед. изм. | E2: Коэф. расхода | F2: Объем
A3: 1 | B3: Устройство разделительного слоя / из пленки полиэтиленовой / в 1 слой | C3: Типы 4.4, 6, 6.1, 7, 7.1, 8.1, 8.2, 9 | D3: м2 | E3: 1 | F3: =Плк1э!E30+Плк2э!E23+Плк3э!E8 -> 2708.84
A4: 1.1 | B4: Пленка полиэтиленовая_/200мкр | D4: м2 | E4: 1.1 | F4: =F3*E4 -> 2979.724

Sheet Плк1э
A1: Спецификация выполненных работ. 1 этаж.
A2: № п.п. | B2: Блок | C2: № пом. | D2: Типы | E2: Объем, м²
A3: 1 | B3: 1 | C3: 1.024 | D3: 6 | E3: 13.62
A4: 2 | B4: 4.1 | C4: 1.045 | D4: 6 | E4: 161.78
A5: 3 | B5: 4.1 | C5: 1.046 | D5: 6 | E5: 161.15
A6: 4 | B6: 4.1 | C6: 1.053 | D6: 6 | E6: 443.48
A7: 5 | B7: 1 | C7: 1.034 | D7: 7 | E7: 17.22
A8: 6 | B8: 1 | C8: 1.035 | D8: 7 | E8: 21.63
A9: 7 | B9: 1 | C9: 1.036 | D9: 7 | E9: 5.76
A10: 8 | B10: 4.1 | C10: 1.054 | D10: 7 | E10: 14.54
A11: 9 | B11: 4.1 | C11: 1.054 | D11: 7.1 | E11: 46.62
A12: 10 | B12: 4.1 | C12: 1.048 | D12: 8.1 | E12: 23.92
A13: 11 | B13: 1 | C13: 1.037 | D13: 8.2 | E13: 3.34
A14: 12 | B14: 1 | C14: 1.038 | D14: 8.2 | E14: 5.25
... A29: 27 | B29: 4.1 | C29: 1.051 | D29: 9 | E29: 31.58
D30: сумма: | E30: =SUM(E1:E29) -> 2310.28

Sheet Плк2э
A1: Спецификация выполненных работ. 2 этаж.
A2: № п.п. | B2: Блок | C2: № пом. | D2: Типы | E2: Объем, м²
A3: 1 | B3: 4.1 | C3: 2.16 | D3: 4.4 | E3: 72.64
A4: 2 | B4: 1 | C4: 2.005 | D4: 6.1 | E4: 13.62
A5: 3 | B5: 4.1 | C5: 2.084 | D5: 6.1 | E5: 16
A6: 4 | B6: 4.1 | C6: 2.087 | D6: 6.1 | E6: 19.46
A7: 5 | B7: 4.1 | C7: 2.109 | D7: 6.1 | E7: 33.05
A8: 6 | B8: 4.1 | C8: 2.168 | D8: 6.1 | E8: 8.02
A9: 7 | B9: 1 | C9: 2.014 | D9: 7.2 | E9: 17.22
A10: 8 | B10: 1 | C10: 2.015 | D10: 7.2 | E10: 21.87
A11: 9 | B11: 1 | C11: 2.016 | D11: 7.2 | E11: 5.06
A12: 10 | B12: 4.1 | C12: 2.089 | D12: 7.2 | E12: 6.05
A13: 11 | B13: 4.1 | C13: 2.09 | D13: 7.2 | E13: 12.15
A14: 12 | B14: 4.1 | C14: 2.091 | D14: 7.2 | E14: 10.63
... A22: 20 | B22: 4.1 | C22: 2.108 | D22: 7.2 | E22: 16.28
D23: сумма: | E23: =SUM(E3:E22) -> 326.48

Sheet Плк3э
A1: Спецификация выполненных работ. 3 этаж.
A2: № п.п. | B2: Блок | C2: № пом. | D2: Типы | E2: Объем, м²
A3: 1 | B3: 1 | C3: 3.006 | D3: 6.1 | E3: 13.62
A4: 2 | B4: 4.1 | C4: 3.094 | D4: 6.1 | E4: 15.07
A5: 3 | B5: 1 | C5: 3.015 | D5: 7.2 | E5: 17.21
A6: 4 | B6: 1 | C6: 3.016 | D6: 7.2 | E6: 21.12
A7: 5 | B7: 1 | C7: 3.017 | D7: 7.2 | E7: 5.06
D8: сумма: | E8: =SUM(E3:E7) -> 72.08

Sheet Общ
A1: Спецификация выполненных работ
A2: № п.п. | B2: Блок | C2: № пом. | D2: Типы | E2: Объем, м²
A3: 1 | B3: 1 | C3: 1.024 | D3: 6 | E3: 13.62
A4: 2 | B4: 4.1 | C4: 1.045 | D4: 6 | E4: 161.78
A5: 3 | B5: 4.1 | C5: 1.046 | D5: 6 | E5: 161.15 | G5: =--MID($G$62,IF(ROW(A2)=1,1,FIND("; ",$G$62,FIND("; ",$G$62,1)*(ROW(A2)-1))+2),FIND("; ",$G$62&"; ",IF(ROW(A2)=1,1,FIND("; ",$G$62,FIND("; ",$G$62,1)*(ROW(A2)-1))+2))-IF(ROW(A2)=1,1,FIND("; ",$G$62,FIND("; ",$G$62,1)*(ROW(A2)-1))+2)) -> #VALUE!
A6: 4 | B6: 4.1 | C6: 1.053 | D6: 6 | E6: 443.48 | G6: =--MID($G$62,IF(ROW(A3)=1,1,FIND("; ",$G$62,FIND("; ",$G$62,1)*(ROW(A3)-1))+2),FIND("; ",$G$62&"; ",IF(ROW(A3)=1,1,FIND("; ",$G$62,FIND("; ",$G$62,1)*(ROW(A3)-1))+2))-IF(ROW(A3)=1,1,FIND("; ",$G$62,FIND("; ",$G$62,1)*(ROW(A3)-1))+2)) -> #VALUE!
A7: 5 | B7: 1 | C7: 1.034 | D7: 7 | E7: 17.22 | G7: =--MID($G$62,IF(ROW(A4)=1,1,FIND("; ",$G$62,FIND("; ",$G$62,1)*(ROW(A4)-1))+2),FIND("; ",$G$62&"; ",IF(ROW(A4)=1,1,FIND("; ",$G$62,FIND("; ",$G$62,1)*(ROW(A4)-1))+2))-IF(ROW(A4)=1,1,FIND("; ",$G$62,FIND("; ",$G$62,1)*(ROW(A4)-1))+2)) -> #VALUE!
A8: 6 | B8: 1 | C8: 1.035 | D8: 7 | E8: 21.63 | G8: =--MID($G$62,IF(ROW(A5)=1,1,FIND("; ",$G$62,FIND("; ",$G$62,1)*(ROW(A5)-1))+2),FIND("; ",$G$62&"; ",IF(ROW(A5)=1,1,FIND("; ",$G$62,FIND("; ",$G$62,1)*(ROW(A5)-1))+2))-IF(ROW(A5)=1,1,FIND("; ",$G$62,FIND("; ",$G$62,1)*(ROW(A5)-1))+2)) -> #VALUE!
A9: 7 | B9: 1 | C9: 1.036 | D9: 7 | E9: 5.76 | G9: =--MID($G$62,IF(ROW(A6)=1,1,FIND("; ",$G$62,FIND("; ",$G$62,1)*(ROW(A6)-1))+2),FIND("; ",$G$62&"; ",IF(ROW(A6)=1,1,FIND("; ",$G$62,FIND("; ",$G$62,1)*(ROW(A6)-1))+2))-IF(ROW(A6)=1,1,FIND("; ",$G$62,FIND("; ",$G$62,1)*(ROW(A6)-1))+2)) -> #VALUE!
A10: 8 | B10: 4.1 | C10: 1.054 | D10: 7 | E10: 14.54 | G10: =--MID($G$62,IF(ROW(A7)=1,1,FIND("; ",$G$62,FIND("; ",$G$62,1)*(ROW(A7)-1))+2),FIND("; ",$G$62&"; ",IF(ROW(A7)=1,1,FIND("; ",$G$62,FIND("; ",$G$62,1)*(ROW(A7)-1))+2))-IF(ROW(A7)=1,1,FIND("; ",$G$62,FIND("; ",$G$62,1)*(ROW(A7)-1))+2)) -> #VALUE!
A11: 9 | B11: 4.1 | C11: 1.054 | D11: 7.1 | E11: 46.62 | G11: =--MID($G$62,IF(ROW(A8)=1,1,FIND("; ",$G$62,FIND("; ",$G$62,1)*(ROW(A8)-1))+2),FIND("; ",$G$62&"; ",IF(ROW(A8)=1,1,FIND("; ",$G$62,FIND("; ",$G$62,1)*(ROW(A8)-1))+2))-IF(ROW(A8)=1,1,FIND("; ",$G$62,FIND("; ",$G$62,1)*(ROW(A8)-1))+2)) -> #VALUE!
A12: 10 | B12: 4.1 | C12: 1.048 | D12: 8.1 | E12: 23.92 | G12: =--MID($G$62,IF(ROW(A9)=1,1,FIND("; ",$G$62,FIND("; ",$G$62,1)*(ROW(A9)-1))+2),FIND("; ",$G$62&"; ",IF(ROW(A9)=1,1,FIND("; ",$G$62,FIND("; ",$G$62,1)*(ROW(A9)-1))+2))-IF(ROW(A9)=1,1,FIND("; ",$G$62,FIND("; ",$G$62,1)*(ROW(A9)-1))+2)) -> #VALUE!
A13: 11 | B13: 1 | C13: 1.037 | D13: 8.2 | E13: 3.34 | G13: =--MID($G$62,IF(ROW(A10)=1,1,FIND("; ",$G$62,FIND("; ",$G$62,1)*(ROW(A10)-1))+2),FIND("; ",$G$62&"; ",IF(ROW(A10)=1,1,FIND("; ",$G$62,FIND("; ",$G$62,1)*(ROW(A10)-1))+2))-IF(ROW(A10)=1,1,FIND("; ",$G$62,FIND("; ",$G$62,1)*(ROW(A10)-1))+2)) -> #VALUE!
A14: 12 | B14: 1 | C14: 1.038 | D14: 8.2 | E14: 5.25 | G14: =--MID($G$62,IF(ROW(A11)=1,1,FIND("; ",$G$62,FIND("; ",$G$62,1)*(ROW(A11)-1))+2),FIND("; ",$G$62&"; ",IF(ROW(A11)=1,1,FIND("; ",$G$62,FIND("; ",$G$62,1)*(ROW(A11)-1))+2))-IF(ROW(A11)=1,1,FIND("; ",$G$62,FIND("; ",$G$62,1)*(ROW(A11)-1))+2)) -> #VALUE!
A15: 13 | B15: 1 | C15: 1.026 | D15: 9 | E15: 191.68 | G15: =--MID($G$62,IF(ROW(A12)=1,1,FIND("; ",$G$62,FIND("; ",$G$62,1)*(ROW(A12)-1))+2),FIND("; ",$G$62&"; ",IF(ROW(A12)=1,1,FIND("; ",$G$62,FIND("; ",$G$62,1)*(ROW(A12)-1))+2))-IF(ROW(A12)=1,1,FIND("; ",$G$62,FIND("; ",$G$62,1)*(ROW(A12)-1))+2)) -> #VALUE!
A16: 14 | B16: 1 | C16: 1.027 | D16: 9 | E16: 114.04 | G16: =--MID($G$62,IF(ROW(A13)=1,1,FIND("; ",$G$62,FIND("; ",$G$62,1)*(ROW(A13)-1))+2),FIND("; ",$G$62&"; ",IF(ROW(A13)=1,1,FIND("; ",$G$62,FIND("; ",$G$62,1)*(ROW(A13)-1))+2))-IF(ROW(A13)=1,1,FIND("; ",$G$62,FIND("; ",$G$62,1)*(ROW(A13)-1))+2)) -> #VALUE!
... A18: 16 | B18: 1 | C18: 1.029 | D18: 9 | E18: 68.81 | G18: =--MID($G$62,IF(ROW(A15)=1,1,FIND("; ",$G$62,FIND("; ",$G$62,1)*(ROW(A15)-1))+2),FIND("; ",$G$62&"; ",IF(ROW(A15)=1,1,FIND("; ",$G$62,FIND("; ",$G$62,1)*(ROW(A15)-1))+2))-IF(ROW(A15)=1,1,FIND("; ",$G$62,FIND("; ",$G$62,1)*(ROW(A15)-1))+2)) -> #VALUE!
A19: 17 | B19: 1 | C19: 1.03 | D19: 9 | E19: 68.89
A20: 18 | B20: 1 | C20: 1.031 | D20: 9 | E20: 68.89
A21: 19 | B21: 1 | C21: 1.032 | D21: 9 | E21: 68.07
A22: 20 | B22: 1 | C22: 1.033 | D22: 9 | E22: 139.1
A23: 21 | B23: 1 | C23: 1.039 | D23: 9 | E23: 149.7
A24: 22 | B24: 4.1 | C24: 1.04 | D24: 9 | E24: 220.47
A25: 23 | B25: 4.1 | C25: 1.043 | D25: 9 | E25: 61.99
A26: 24 | B26: 4.1 | C26: 1.044 | D26: 9 | E26: 14.14
A27: 25 | B27: 4.1 | C27: 1.049 | D27: 9 | E27: 103.8
A28: 26 | B28: 4.1 | C28: 1.05 | D28: 9 | E28: 22
A29: 27 | B29: 4.1 | C29: 1.051 | D29: 9 | E29: 31.58
A31: Спецификация выполненных работ
A32: № п.п. | B32: Блок | C32: № пом. | D32: Типы | E32: Объем, м²
A33: 1 | B33: 4.1 | C33: 2.16 | D33: 4.4 | E33: 72.64
A34: 2 | B34: 1 | C34: 2.005 | D34: 6.1 | E34: 13.62 | G34: 73.55
A35: 3 | B35: 4.1 | C35: 2.084 | D35: 6.1 | E35: 16 | G35: 72.24
A36: 4 | B36: 4.1 | C36: 2.087 | D36: 6.1 | E36: 19.46 | G36: 68.26
A37: 5 | B37: 4.1 | C37: 2.109 | D37: 6.1 | E37: 33.05 | G37: 158.71
A38: 6 | B38: 4.1 | C38: 2.168 | D38: 6.1 | E38: 8.02
A39: 7 | B39: 1 | C39: 2.014 | D39: 7.2 | E39: 17.22 | G39: 68.3
A40: 8 | B40: 1 | C40: 2.015 | D40: 7.2 | E40: 21.87 | G40: 68.46
A41: 9 | B41: 1 | C41: 2.016 | D41: 7.2 | E41: 5.06 | G41: 68.46
A42: 10 | B42: 4.1 | C42: 2.089 | D42: 7.2 | E42: 6.05 | G42: 67.64
...

Sheet СКБ-1эт
B1: Ведомость работ
A2: № п.п. | B2: Наименование | C2: Тип | D2: Ед. изм. | E2: Коэф. расхода | F2: Объем
A3: 1 | B3: Устройство стяжки СКБ / армированная сеткой от 41 мм до 60мм | C3: Типы 9.3 60мм | D3: м2 | E3: 1 | F3: ='1эт'!E5+'2эт'!E5+'3эт'!E4 -> 69.01
A4: 1.1 | B4: Фиксатор арматуры Звездочка_/15/4-16 | D4: шт | E4: 8 | F4: =ROUNDDOWN(E4*F3,0) -> 552
A5: 1.2 | B5: Смесь цементно-песчаная сухая_/М200 | D5: кг | E5: 1.8 | F5: =E5*F3*60 -> 7453.08
A6: 1.3 | B6: Сетка эл/св_/100*100*5 | D6: м2 | E6: 1.1 | F6: =E6*F3 -> 75.911
A7: 1.4 | B7: Лента кромочная демпферная_/8*100мм/20м | D7: пог. м | E7: 1 | F7: =E7*F3 -> 69.01
A8: 2 | B8: Устройство стяжки СКБ / армированная сеткой от 61мм до 80мм | C8: Типы 6, 6.1, 7, 7.2, 8.1, 8.2, 9, 9.2 | D8: м2 | E8: 1 | F8: ='1эт'!E41 -> 2263.66
A9: 2.1 | B9: Фиксатор арматуры Звездочка_/15/4-16 | D9: шт | E9: 8 | F9: =ROUNDDOWN(E9*F8,0) -> 18109
A10: 2.2 | B10: Смесь цементно-песчаная сухая_/М200 | D10: кг | E10: 1.8 | F10: =E10*F8*65 -> 264848.22
A11: 2.3 | B11: Сетка эл/св_/100*100*5 | D11: м2 | E11: 1.1 | F11: =E11*F8 -> 2490.026
A12: 2.4 | B12: Лента кромочная демпферная_/8*100мм/20м | D12: пог. м | E12: 1 | F12: =E12*F8 -> 2263.66
A13: 3 | B13: Устройство стяжки СКБ / армированная сеткой от 61мм до 80мм | C13: Типы 11, 11.1 68мм | D13: м2 | E13: 1 | F13: ='2эт'!E16 -> 168.62
A14: 3.1 | B14: Грунтовка БЕТОН-КОНТАКТ_/ | D14: кг | E14: 0.255 | F14: =E14*F13 -> 42.9981
A15: 3.2 | B15: Лента кромочная демпферная_/8*100мм/20м | D15: пог. м | E15: 1 | F15: =E15*F13 -> 168.62
A16: 3.3 | B16: Сетка эл/св_/100*100*5 | D16: м2 | E16: 1.1 | F16: =E16*F13 -> 185.482
A17: 3.4 | B17: Смесь цементно-песчаная сухая_/М200 | D17: кг | E17: 1.8 | F17: =E17*F13*68 -> 20639.088
A18: 3.5 | B18: Фиксатор арматуры Звездочка_/15/4-16 | D18: шт | E18: 8 | F18: =ROUNDDOWN(E18*F13,0) -> 1348
A19: 4 | B19: Устройство стяжки СКБ / армированная сеткой от 61мм до 80мм | C19: Тип 5 70мм | D19: м2 | E19: 1 | F19: ='1эт'!E11 -> 19.42
A20: 4.1 | B20: Фиксатор арматуры Звездочка_/15/4-16 | D20: шт | E20: 8 | F20: =ROUNDDOWN(E20*F19,0) -> 155
A21: 4.2 | B21: Смесь цементно-песчаная сухая_/М150 | D21: кг | E21: 1.8 | F21: =E21*F19*70 -> 2446.92
A22: 4.3 | B22: Сетка эл/св_/100*100*4 | D22: м2 | E22: 1.1 | F22: =E22*F19 -> 21.362
A23: 4.4 | B23: Лента кромочная демпферная_/8*100мм/20м | D23: пог. м | E23: 1 | F23: =E23*F19 -> 19.42
A24: 5 | B24: Устройство стяжки СКБ / армированная сеткой от 61мм до 80мм | C24: Типы 4.4, 5.1 80мм | D24: м2 | E24: 1 | F24: ='2эт'!E12+'3эт'!E10 -> 101.29
A25: 5.1 | B25: Лента кромочная демпферная_/8*100мм/20м | D25: пог. м | E25: 1 | F25: =F24*E25 -> 101.29
A26: 5.2 | B26: Сетка эл/св_/100*100*4 | D26: м2 | E26: 1.1 | F26: =E26*F24 -> 111.419
A27: 5.3 | B27: Смесь цементно-песчаная сухая_/М150 | D27: кг | E27: 1.8 | F27: =E27*F24*80 -> 14585.76
A28: 5.4 | B28: Фиксатор арматуры Звездочка_/15/4-16 | D28: шт | E28: 8 | F28: =ROUNDDOWN(E28*F24,0) -> 810

Sheet 1эт
A1: Спецификация выполненных работ. 1 этаж.
A2: № п.п. | B2: Блок | C2: № пом. | D2: Типы | E2: Объем, м²
A3: 1 | B3: 1 | C3: `- | D3: 9.1 | E3: =37.5-2.48 -> 35.02
A4: 2 | B4: 4.1 | C4: `- | D4: 9.1 | E4: 4.2
D5: сумма | E5: =SUM(E3:E4) -> 39.22
A7: Спецификация выполненных работ. 1 этаж.
A8: № п.п. | B8: Блок | C8: № пом. | D8: Типы | E8: Объем, м²
A9: 1 | B9: 1 | C9: `- | D9: 5 | E9: 11.69
A10: 2 | B10: 4.1 | C10: `- | D10: 5 | E10: 7.73
D11: сумма | E11: =SUM(E9:E10) -> 19.42
A13: Спецификация выполненных работ
A14: № п.п. | B14: Блок | C14: № пом. | D14: Типы | E14: Объем, м²
A15: 1 | B15: 1 | C15: 1.024 | D15: 6 | E15: 13.62
A16: 2 | B16: 4.1 | C16: 1.045 | D16: 6 | E16: 161.78
A17: 3 | B17: 4.1 | C17: 1.046 | D17: 6 | E17: 161.15
A18: 4 | B18: 4.1 | C18: 1.053 | D18: 6 | E18: 443.48
A19: 5 | B19: 1 | C19: 1.034 | D19: 7 | E19: 17.22
A20: 6 | B20: 1 | C20: 1.035 | D20: 7 | E20: 21.63
A21: 7 | B21: 1 | C21: 1.036 | D21: 7 | E21: 5.76
A22: 8 | B22: 4.1 | C22: 1.054 | D22: 7 | E22: 14.54
A23: 9 | B23: 4.1 | C23: 1.048 | D23: 8.1 | E23: 23.92
A24: 10 | B24: 1 | C24: 1.037 | D24: 8.2 | E24: 3.34
A25: 11 | B25: 1 | C25: 1.038 | D25: 8.2 | E25: 5.25
A26: 12 | B26: 1 | C26: 1.026 | D26: 9 | E26: 191.68
... A40: 26 | B40: 4.1 | C40: 1.051 | D40: 9 | E40: 31.58
D41: сумма | E41: =SUM(E15:E40) -> 2263.66

Sheet 2эт
A1: Спецификация выполненных работ. 2 этаж.
A2: № п.п. | B2: Блок | C2: № пом. | D2: Типы | E2: Объем, м²
A3: 1 | B3: 1 | C3: `- | D3: 9.3 | E3: 14.5
A4: 2 | B4: 4.1 | C4: `- | D4: 9.3 | E4: 0.5
D5: сумма | E5: =SUM(E3:E4) -> 15
A7: Спецификация выполненных работ. 2 этаж.
A8: № п.п. | B8: Блок | C8: № пом. | D8: Типы | E8: Объем, м²
A9: 1 | B9: 1 | C9: `- | D9: 5.1 | E9: 8.28
A10: 2 | B10: 4.1 | C10: `- | D10: 5.1 | E10: 8.39
A11: 3 | B11: 4.1 | C11: 2.16 | D11: 4.4 | E11: 72.64
D12: сумма | E12: =SUM(E9:E11) -> 89.31
A14: Спецификация выполненных работ. 2 этаж.
A15: 1 | B15: 4.1 | C15: 2.085 | D15: 11.1 | E15: 168.62
D16: сумма | E16: =SUM(E15:E15) -> 168.62

Sheet 3эт
A1: Спецификация выполненных работ. 3 этаж.
A2: № п.п. | B2: Блок | C2: № пом. | D2: Типы | E2: Объем, м²
A3: 4 | B3: 1 | C3: `- | D3: 9.3 | E3: 14.79
D4: сумма | E4: =SUM(E3:E3) -> 14.79
A6: Спецификация выполненных работ. 3 этаж.
A7: № п.п. | B7: Блок | C7: № пом. | D7: Типы | E7: Объем, м²
A8: 1 | B8: 1 | C8: `- | D8: 5.1 | E8: 6.03
A9: 2 | B9: 4.1 | C9: `- | D9: 5.1 | E9: 5.95
D10: сумма | E10: =SUM(E8:E9) -> 11.98

Sheet КП
A1: Номер п/п | B1: Код узла ИСР | C1: Наименование затрат | D1: Комментарий по ИСР | E1: Комментарий подрядчика | F1: Ед. изм. | G1: Коэф.расхода | H1: Кол-во БО | I1: Общее кол-во | J1: 2-Пл-Л | K1: Столбец1 | L1: Столбец2 | M1: Столбец3 | N1: Столбец4 | O1: Столбец5 | P1: Столбец6 | Q1: Столбец7 | R1: Столбец8
A2: 1.1.2.1.1.1.1.1 | B2: 6.3.1.5.1.1.3.1 | C2: Устройство наливных полов с огрунтовкой поверхности и проклейкой демпферной лентой / толщ. до 10 мм | E2: Типы 9, 9.1, 9.2, 9.3, 11, 11.1 | F2: м2 | G2: 1 | I2: 4905.38 | J2: ='2.1-Нал'!F17 -> 1838.74
A3: 1.1.2.1.1.1.1.1.1 | C3: Наливной пол_ / Унифицированный по ПИК-СТАНДАРТ | F3: кг | G3: 1.6 | I3: 78486.08
A4: 1.1.2.1.1.1.1.1.2 | C4: Лента кромочная демпферная_/8*100мм/20м | F4: пог. м | G4: 1 | I4: 4905.38
A5: 1.1.2.1.1.1.1.1.3 | C5: Грунтовка универсальный ЛАСТИМИН_ / УНКОНТ ЛЮКС LP51 А | F5: кг | G5: 0.255 | I5: 1250.872
A6: 1.1.2.1.1.1.1.2 | B6: 6.3.1.5.1.1.6.3 | C6: Устройство разделительного слоя / из пленки полиэтиленовой / в 1 слой | D6: сделать | E6: Типы 4.4, 5, 5.1, 6, 6.1, 7, 7.1, 7.2, 8.1, 8.2, 9, 9.1 | F6: м2 | G6: 1 | I6: 2785.09
A7: 1.1.2.1.1.1.1.2.1 | C7: Пленка полиэтиленовая_/200мкр | F7: м2 | G7: 1.1 | I7: 3063.599
A8: 1.1.2.1.1.1.1.3 | B8: 6.3.1.5.1.1.9.1 | C8: Обработка полов гидрофобизирующим составом | E8: Типы 5, 5.1 - обеспыливание | F8: м2 | G8: 1 | I8: 47.77
A9: 1.1.2.1.1.1.1.3.1 | C9: Пропитка для бетонных поверхностей / Элакор МБ1 | F9: кг | G9: 0.3 | I9: 14.331
A10: 1.1.2.1.1.1.1.3.2 | C10: Грунтовка силикатная КМ0 Прозрачный | F10: кг | G10: 0.2 | I10: 9.554
A11: 1.1.2.1.1.1.1.4 | B11: 6.3.1.5.1.1.10.1 | C11: Затирка, уход, полировка полов мех.способом | E11: Тип 4.4 | F11: м2 | G11: 1 | I11: 72.94
A12: 1.1.2.1.1.1.1.4.1 | C12: Цемент- / Портланд / М500 | F12: кг | G12: 0.6 | I12: 43.764
A13: 1.1.2.1.1.1.1.5 | B13: 6.3.1.5.1.1.11.2 | C13: Устройство стяжки СКБ / армированная сеткой от 21 мм до 40мм | E13: Тип 7.1 40мм | F13: м2 | G13: 1 | I13: 46.62
A14: 1.1.2.1.1.1.1.5.1 | C14: Фиксатор арматуры Звездочка_/15/4-16 | F14: шт | G14: 8 | I14: 372.96
A15: 1.1.2.1.1.1.1.5.2 | C15: Смесь цементно-песчаная сухая_/М200 | F15: кг | G15: 1.8 | I15: 3356.64
A16: 1.1.2.1.1.1.1.5.3 | C16: Сетка эл/св_/100*100*5 | F16: м2 | G16: 1.1 | I16: 51.282
A17: 1.1.2.1.1.1.1.5.4 | C17: Лента кромочная демпферная_/8*100мм/20м | F17: пог. м | G17: 1 | I17: 46.62
A18: 1.1.2.1.1.1.1.6 | B18: 6.3.1.5.1.1.11.3 | C18: Устройство стяжки СКБ / армированная сеткой от 41 мм до 60мм | E18: Типы 8.3, 9.1, 9.3 60мм | F18: м2 | G18: 1 | I18: 122.25
A19: 1.1.2.1.1.1.1.6.1 | C19: Фиксатор арматуры Звездочка_/15/4-16 | F19: шт | G19: 8 | I19: 978
A20: 1.1.2.1.1.1.1.6.2 | C20: Смесь цементно-песчаная сухая_/М200 | F20: кг | G20: 1.8 | I20: 13203
A21: 1.1.2.1.1.1.1.6.3 | C21: Сетка эл/св_/100*100*5 | F21: м2 | G21: 1.1 | I21: 134.475
A22: 1.1.2.1.1.1.1.6.4 | C22: Лента кромочная демпферная_/8*100мм/20м | F22: пог. м | G22: 1 | I22: 122.25
A23: 1.1.2.1.1.1.1.7 | B23: 6.3.1.5.1.1.11.4 | C23: Устройство стяжки СКБ / армированная сеткой от 61мм до 80мм | E23: Типы 6, 6.1, 7, 7.2, 8.1, 8.2, 9, 9.2 | F23: м2 | G23: 1 | I23: 5553.92
A24: 1.1.2.1.1.1.1.7.1 | C24: Фиксатор арматуры Звездочка_/15/4-16 | F24: шт | G24: 8 | I24: 44431.36
A25: 1.1.2.1.1.1.1.7.2 | C25: Смесь цементно-песчаная сухая_/М200 | F25: кг | G25: 1.8 | H25: =I25/G25/I23 -> 65 | I25: 649808.64
A26: 1.1.2.1.1.1.1.7.3 | C26: Сетка эл/св_/100*100*5 | F26: м2 | G26: 1.1 | I26: 6109.312
A27: 1.1.2.1.1.1.1.7.4 | C27: Лента кромочная демпферная_/8*100мм/20м | F27: пог. м | G27: 1 | I27: 5553.92
A28: 1.1.2.1.1.1.1.8 | B28: 6.3.1.5.1.1.11.4 | C28: Устройство стяжки СКБ / армированная сеткой от 61мм до 80мм | E28: Типы 11, 11.1 68мм | F28: м2 | G28: 1 | I28: 468.22
A29: 1.1.2.1.1.1.1.8.1 | C29: Грунтовка БЕТОН-КОНТАКТ_/ | F29: кг | G29: 0.255 | I29: 119.396
A30: 1.1.2.1.1.1.1.8.2 | C30: Лента кромочная демпферная_/8*100мм/20м | F30: пог. м | G30: 1 | I30: 468.22
A31: 1.1.2.1.1.1.1.8.3 | C31: Сетка эл/св_/100*100*5 | F31: м2 | G31: 1.1 | I31: 515.042
A32: 1.1.2.1.1.1.1.8.4 | C32: Смесь цементно-песчаная сухая_/М200 | F32: кг | G32: 1.8 | I32: 57310.128
A33: 1.1.2.1.1.1.1.8.5 | C33: Фиксатор арматуры Звездочка_/15/4-16 | F33: шт | G33: 8 | I33: 3745.76
A34: 1.1.2.1.1.1.1.9 | B34: 6.3.1.5.1.1.11.4 | C34: Устройство стяжки СКБ / армированная сеткой от 61мм до 80мм | E34: Тип 5 70мм | F34: м2 | G34: 1 | I34: 19.42
A35: 1.1.2.1.1.1.1.9.1 | C35: Фиксатор арматуры Звездочка_/15/4-16 | F35: шт | G35: 8 | I35: 155.36
A36: 1.1.2.1.1.1.1.9.2 | C36: Смесь цементно-песчаная сухая_/М150 | F36: кг | G36: 1.8 | I36: 2446.92
A37: 1.1.2.1.1.1.1.9.3 | C37: Сетка эл/св_/100*100*4 | F37: м2 | G37: 1.1 | I37: 21.362
A38: 1.1.2.1.1.1.1.9.4 | C38: Лента кромочная демпферная_/8*100мм/20м | F38: пог. м | G38: 1 | I38: 19.42
A39: 1.1.2.1.1.1.1.10 | B39: 6.3.1.5.1.1.11.4 | C39: Устройство стяжки СКБ / армированная сеткой от 61мм до 80мм | E39: Типы 4.4, 5.1 80мм | F39: м2 | G39: 1 | I39: 101.29
A40: 1.1.2.1.1.1.1.10.1 | C40: Лента кромочная демпферная_/8*100мм/20м | F40: пог. м | G40: 1 | I40: 101.29
...

Sheet 7.2-Гидр5
A1: Ведомость работ
A2: № | B2: Наименование затрат | F2: Описание | G2: Ед. изм. | H2: Объем
A3: 1 | B3: Обработка полов гидрофобизирующим составом | F3: Тип 5, 5.1 | G3: м2 | H3: =D9 -> 47.74
A4: 2 | B4: Устройство разделительного слоя / из пленки полиэтиленовой / в 1 слой | F4: Тип 5, 5.1 | G4: м2 | H4: =H3 -> 47.74
A6: № Блок | B6: 1 этаж | C6: 2 этаж | D6: 3 этаж
A7: 1 | B7: 11.69 | C7: 8.28 | D7: 6.03
A8: 4.1 | B8: 7.73 | C8: 8.09 | D8: 5.92
C9: Итог: | D9: =SUM(B7:D8) -> 47.74

Sheet 7.1-Шл4.4
A1: Ведомость работ
A2: № | B2: Наименование затрат | C2: Описание | D2: Ед. изм. | E2: Объем
A3: 1 | B3: Затирка, уход, полировка полов мех.способом | C3: Тип 4.4 | D3: м2 | E3: 72.59

Sheet 6.1-Нал.пл
A1: Ведомость работ
A2: Наименование затрат | D2: Описание | E2: Ед. изм. | F2: Объем
A3: Устройство наливных полов с огрунтовкой поверхности и проклейкой демпферной лентой / толщ. до 10 мм | D3: Тип 11 | E3: м2 | F3: =B9 -> 1888.15
A4: № помещения | B4: Площадь, м2
A5: 2.111 | B5: 379.31
A6: 2.114 | B6: 381.65
A7: 2.115 | B7: 563.46
A8: 2.117 | B8: 563.73
A9: Сумма, м2: | B9: =SUM(B5:B8) -> 1888.15

Sheet 5.3СКБ11в6
A1: Ведомость работ
A2: № | B2: Наименование затрат | C2: Описание | D2: Ед. изм. | E2: Объем
A3: 1 | B3: Устройство стяжки СКБ / армированная сеткой от 61мм до 80мм | C3: Типы 11, 11.1 68мм | D3: м2 | E3: 298.1

Sheet 5.2-СКБ7.1
A1: Ведомость работ
A2: № | B2: Наименование затрат | C2: Описание | D2: Ед. изм. | E2: Объем
A3: 1 | B3: Устройство стяжки СКБ / армированная сеткой от 21 мм до 40мм | C3: Тип 7.1 40мм | D3: м2 | E3: 46.52

Sheet 5.1-СКБ
A1: Ведомость работ
A2: Наименование затрат | D2: Описание | E2: Ед. изм. | F2: Объем
A3: Устройство стяжки СКБ / армированная сеткой от 61мм до 80 мм | D3: Тип 6.1, М200, толщиной 65 мм. | E3: м2 | F3: =F11 -> 115.6
A4: Устройство стяжки СКБ / армированная сеткой от 61мм до 80 мм | D4: Тип 11, М200, толщиной 68 мм. | E4: м2 | F4: =B11 -> 1888.15
A5: Тип 11 | E5: Тип 6.1
A6: № помещения | B6: Площадь, м2 | E6: № помещения | F6: Площадь, м2
A7: 2.111 | B7: 379.31 | E7: 2.112 | F7: 37.2
A8: 2.114 | B8: 381.65 | E8: 2.116 | F8: 56.31
A9: 2.115 | B9: 563.46 | E9: 2.166 | F9: 10.12
A10: 2.117 | B10: 563.73 | E10: 2.167 | F10: 11.97
A11: Сумма, м2: | B11: =SUM(B7:B10) -> 1888.15 | E11: Сумма, м2: | F11: =SUM(F7:F10) -> 115.6

Sheet 4.1-Изол
A1: Ведомость работ
A2: Наименование затрат | D2: Описание | E2: Ед. изм. | F2: Объем
A3: Устройство звукоизоляции полов / в 1 слой | D3: Тип 11 нахлест на стены 100 мм. | E3: м2 | F3: =B9 -> 1923.9773
A4: № помещения | B4: Площадь, м2
A5: 2.111 | B5: =379.31+(84.163-4)*0.1 -> 387.3263
A6: 2.114 | B6: =381.65+(83.53-2.2-1.8)*0.1 -> 389.603
A7: 2.115 | B7: =563.46+(102.28-1.5-2.2)*0.1 -> 573.318
A8: 2.117 | B8: =563.73+10 -> 573.73
A9: Сумма, м2: | B9: =SUM(B5:B8) -> 1923.9773

Sheet 3.3ПлнкЛК6в6
A1: Ведомость работ
A2: № | B2: Поз | C2: Наименование затрат | G2: Описание | H2: Ед. изм. | I2: Объем
A3: 1 | B3: 48 | C3: Устройство разделительного слоя / из пленки полиэтиленовой / в 1 слой | G3: НЗ № 8 от 17.11.2025 Отделка лестниц: ЛК9, ЛК10, ЛК11. Полы Тип: 6. | H3: м2 | I3: =D9 -> 84.51
A5: № Блок | B5: Пом | C5: Тип | D5: 1 этаж
A6: 1 | B6: 1.025 | C6: ЛК9, Тип-6 | D6: 25.93
A7: 4.1 | B7: 1.047 | C7: ЛК10, Тип-6 | D7: 29.32
A8: 4.1 | B8: 1.052 | C8: ЛК11, Тип-6 | D8: 29.26
C9: Итог: | D9: =SUM(D6:D8) -> 84.51
K15: 1 | L15: 1 | M15: 4.1
K16: 5 | L16: 1.65 | M16: 2.24
A17: 1 | B17: 1.038 | C17: 5 | D17: 5.24 | K17: 6 | L17: 13.62 | M17: 759.68
K18: 7 | L18: 43.82 | M18: 61.15
K19: 8.1 | L19: 0 | M19: 23.92
K20: 8.2 | L20: 8.55 | M20: 0
K21: 9 | L21: 936.68 | M21: 453.05
K22: 9.1
K27: 2 | L27: 1 | M27: 4.1
K28: 5 | L28: 1.52 | M28: 2.28
K29: 6 | L29: 13.62 | M29: 76.59
K30: 7
K31: 8.1
K32: 8.2
K33: 9
K34: 9.1
K42: 6 | L42: 773.3 | M42: 433.72 | N42: =238.43+83.81 -> 322.24 | P42: =L42-M42-N42 -> 17.34
K43: 6.1 | L43: 118.91 | P43: =L43-M43-N43 -> 118.91
K44: 7 | L44: 104.97 | M44: 7.73 | P44: =L44-M44-N44 -> 97.24
K45: 7.1 | L45: 46.62 | M45: 46.52 | P45: =L45-M45-N45 -> 0.1
K46: 7.2 | L46: 210.29 | N46: =454.37-N42 -> 132.13 | P46: =L46-M46-N46 -> 78.16
K47: ММП6.1 | L47: 436.11 | P47: =L47-M47-N47 -> 436.11
N49: =SUM(N42:N48) -> 454.37 | O49: ='7.8Пл6'!D9 -> 435.32 | Q49: =R49-N49 -> 435.32 | R49: 889.69
L51: 1 | M51: 1 | N51: 2 | O51: 2 | P51: 3 | Q51: 3
L52: 1 | M52: 4.1 | N52: 1 | O52: 4.1 | P52: 1 | Q52: 4.1
K53: 6 | L53: 13.62 | M53: 758.84 | N53: 0 | O53: 0 | P53: 0 | Q53: 0
K54: 6.1 | L54: 0 | M54: 0 | N54: 13.62 | O54: 76.59 | P54: 13.62 | Q54: 15.08
K55: 7 | L55: 43.85 | M55: 14.52 | N55: 0 | O55: 0 | P55: 0 | Q55: 0
K56: 7.1 | L56: 0 | M56: 46.62 | N56: 0 | O56: 0 | P56: 0 | Q56: 0
K57: 7.2 | L57: 0 | M57: 0 | N57: 43.43 | O57: 119.37 | P57: 43.43 | Q57: 0

Sheet 3.2-Плен
A1: Ведомость работ
A2: Наименование затрат | D2: Описание | E2: Ед. изм. | F2: Объем
A3: Устройство разделительного слоя / из пленки полиэтиленовой / в 1 слой | D3: Тип 11 | E3: м2 | F3: =B9 -> 115.6
A4: № помещения | B4: Площадь, м2
A5: 2.112 | B5: 37.2
A6: 2.116 | B6: 56.31
A7: 2.166 | B7: 10.12
A8: 2.167 | B8: 11.97
A9: Сумма, м2: | B9: =SUM(B5:B8) -> 115.6

Sheet 3.1-Плен
A1: 1 эт. отм. 0.000
A2: № помещения | B2: Площадь, м2
A3: 1.027 | B3: 113.98
A4: 1.028 | B4: 68.63
A5: 1.029 | B5: 69.02
A6: 1.030 | B6: 68.94
A7: 1.031 | B7: 68.85
A8: 1.032 | B8: 67.86
A9: 1.033 | B9: 139.03
A10: Сумма, м2: | B10: =SUM(B3:B9) -> 596.31
A13: Ведомость работ
