Workbook

Sheet Table 1
A1: Ведомость отделки помещений подвала
A2: Ном ер пом еще ния | B2: Наименование помещения | C2: СТЕНЫ ИЛИ ПЕРЕГОРОДКИ | M2: Основной тип потолка | O2: ПЛИНТУС | Q2: Примечание
C3: Железобетон | E3: Кирпич | G3: Газобетон | I3: Утеплитель | K3: Финишный слой | M3: Вид отделки | N3: Площадь, м² | O3: Вид отделки | P3: м.п.
C4: Вид отделки | D4: Площадь, м² | E4: Вид отделки | F4: Площадь, м² | G4: Вид отделки | H4: Площадь, м² | I4: Вид отделки | J4: Площадь, м² | K4: Вид отделки | L4: Площадь, м²
A5: 0.01 | B5: Лестничная клетка №1 | C5: - грунтовка "Бетоноконтакт"; - штукатурка цементно-песчаным раствором М100 (армированная стекловолоконной или пластиковой сеткой); - грунтовка глубокого проникновения; - шпатлёвка; - грунтовка глубокого проникновения δ = 25 мм | D5: 64 | E5: - грунтовка глубокого проникновения; - штукатурка цементно-песчаным раствором М100 (армированная стекловолоконной или пластиковой сеткой); - грунтовка глубокого проникновения; - шпатлёвка; - грунтовка глубокого проникновения δ = 25 мм | F5: 25.4 | G5: - | H5: 0 | I5: - | J5: 0 | K5: см. раздел АИ | L5: 89.4 | M5: - затирка; - грунтовка "Бетоноконтакт "; - шпатлёвка; - грунтовка глубокого проникновения δ = 5 мм | N5: 10.7 | O5: см. раздел АИ | P5: 28.8 | Q5: -
A6: 0.02 | B6: Венткамера | C6: - грунтовка "Бетоноконтакт"; - штукатурка цементно-песчаным раствором М100 (армированная стекловолоконной или пластиковой сеткой); - грунтовка глубокого проникновения; - шпатлёвка; - грунтовка глубокого проникновения δ = 25 мм | D6: 21.9 | E6: - грунтовка глубокого проникновения; - штукатурка цементно-песчаным раствором М100 (армированная стекловолоконной или пластиковой сеткой); - грунтовка глубокого проникновения; - шпатлёвка; - грунтовка глубокого проникновения δ = 25 мм | F6: 31.9 | G6: - | H6: 0 | I6: - штукатурка цементно-песчаным раствором М100 (армированная стекловолоконной или пластиковой сеткой); - грунтовка глубокого проникновения; - шпатлёвка; - грунтовка глубокого проникновения δ = 25 мм | J6: 79.7 | K6: см. раздел АИ | L6: 133.5 | M6: - затирка; - грунтовка "Бетоноконтакт "; - шпатлёвка; - грунтовка глубокого проникновения δ = 5 мм | N6: 57.6 | O6: см. раздел АИ | P6: 42.8 | Q6: -
A7: 0.03 | B7: Коридор | C7: - грунтовка "Бетоноконтакт"; - штукатурка цементно-песчаным раствором М100 (армированная стекловолоконной или пластиковой сеткой); - грунтовка глубокого проникновения; - шпатлёвка; - грунтовка глубокого проникновения δ = 25 мм | D7: 140.9 | E7: - грунтовка глубокого проникновения; - штукатурка цементно-песчаным раствором М100 (армированная стекловолоконной или пластиковой сеткой); - грунтовка глубокого проникновения; - шпатлёвка; - грунтовка глубокого проникновения δ = 25 мм | F7: 221.4 | G7: - пропитка гидрофобизирующим составом BOSTIK SMP; - грунтовка глубокого проникновения; - штукатурка цементно-песчаным раствором М100 (армированная стекловолоконной или пластиковой сеткой); - грунтовка глубокого проникновения; - шпатлёвка; - грунтовка глубокого проникновения δ = 25 мм | H7: 5.2 | I7: - | J7: 0 | K7: см. раздел АИ | L7: 367.5 | M7: - затирка; - грунтовка "Бетоноконтакт "; - шпатлёвка; - грунтовка глубокого проникновения δ = 5 мм | N7: 164.4 | O7: см. раздел АИ | P7: 116.4 | Q7: -
A8: 0.04 | B8: Насосная | C8: - грунтовка "Бетоноконтакт"; - штукатурка цементно-песчаным раствором М100 (армированная стекловолоконной или пластиковой сеткой); - грунтовка глубокого проникновения; - шпатлёвка; - грунтовка глубокого проникновения δ = 25 мм | D8: 126.5 | E8: - грунтовка глубокого проникновения; - штукатурка цементно-песчаным раствором М100 (армированная стекловолоконной или пластиковой сеткой); - грунтовка глубокого проникновения; - шпатлёвка; - грунтовка глубокого проникновения δ = 25 мм | F8: 4.9 | G8: - | H8: 0 | I8: - | J8: 0 | K8: см. раздел АИ | L8: 131.3 | M8: - затирка; - грунтовка "Бетоноконтакт "; - шпатлёвка; - грунтовка глубокого проникновения δ = 5 мм | N8: 58.2 | O8: см. раздел АИ | P8: 42.1 | Q8: -
A9: 0.05 | B9: Венткамера | C9: - грунтовка "Бетоноконтакт"; - штукатурка цементно-песчаным раствором М100 (армированная стекловолоконной или пластиковой сеткой); - грунтовка глубокого проникновения; - шпатлёвка; - грунтовка глубокого проникновения δ = 25 мм | D9: 37.7 | E9: - грунтовка глубокого проникновения; - штукатурка цементно-песчаным раствором М100 (армированная стекловолоконной или пластиковой сеткой); - грунтовка глубокого проникновения; - шпатлёвка; - грунтовка глубокого проникновения δ = 25 мм | F9: 29.7 | G9: - | H9: 0 | I9: - | J9: 0 | K9: см. раздел АИ | L9: 67.4 | M9: - затирка; - грунтовка "Бетоноконтакт "; - шпатлёвка; - грунтовка глубокого проникновения δ = 5 мм | N9: 54.2 | O9: см. раздел АИ | P9: 30.1 | Q9: -
A10: 0.06 | B10: ИТП | C10: - грунтовка "Бетоноконтакт"; - штукатурка цементно-песчаным раствором М100 (армированная стекловолоконной или пластиковой сеткой); - грунтовка глубокого проникновения; - шпатлёвка; - грунтовка глубокого проникновения δ = 25 мм | D10: 57.5 | E10: - грунтовка глубокого проникновения; - штукатурка цементно-песчаным раствором М100 (армированная стекловолоконной или пластиковой сеткой); - грунтовка глубокого проникновения; - шпатлёвка; - грунтовка глубокого проникновения δ = 25 мм | F10: 72.2 | G10: - | H10: 0 | I10: - | J10: 0 | K10: см. раздел АИ | L10: 129.7 | M10: - затирка; - грунтовка "Бетоноконтакт "; - шпатлёвка; - грунтовка глубокого проникновения δ = 5 мм | N10: 99.5 | O10: см. раздел АИ | P10: 41.7 | Q10: -
A11: 0.07 | B11: Венткамера | C11: - | D11: 0 | E11: - грунтовка глубокого проникновения; - штукатурка цементно-песчаным раствором М100 (армированная стекловолоконной или пластиковой сеткой); - грунтовка глубокого проникновения; - шпатлёвка; - грунтовка глубокого проникновения δ = 25 мм | F11: 31.4 | G11: - | H11: 0 | I11: - штукатурка цементно-песчаным раствором М100 (армированная стекловолоконной или пластиковой сеткой); - грунтовка глубокого проникновения; - шпатлёвка; - грунтовка глубокого проникновения δ = 25 мм | J11: 64.4 | K11: см. раздел АИ | L11: 95.8 | M11: - затирка; - грунтовка "Бетоноконтакт "; - шпатлёвка; - грунтовка глубокого проникновения δ = 5 мм | N11: 40.7 | O11: см. раздел АИ | P11: 31.4 | Q11: -
A12: 0.08 | B12: Помещение CC1 | C12: - грунтовка "Бетоноконтакт"; - штукатурка цементно-песчаным раствором М100 (армированная стекловолоконной или пластиковой сеткой); - грунтовка глубокого проникновения; - шпатлёвка; - грунтовка глубокого проникновения δ = 25 мм | D12: 44.3 | E12: - грунтовка глубокого проникновения; - штукатурка цементно-песчаным раствором М100 (армированная стекловолоконной или пластиковой сеткой); - грунтовка глубокого проникновения; - шпатлёвка; - грунтовка глубокого проникновения δ = 25 мм | F12: 23.1 | G12: см. раздел АИ | H12: 67.4 | M12: - затирка; - грунтовка "Бетоноконтакт "; - шпатлёвка; - грунтовка глубокого проникновения δ = 5 мм | N12: 24.5 | O12: см. раздел АИ | P12: 21.4 | Q12: -
A13: 0.09 | B13: Помещение для прокладки коммуникаций | C13: - обеспыливание поверхности ж/б грунтовкой глубокого проникновения Политакс 88PU 2/50 (или аналог) | D13: 233.1 | E13: - грунтовка глубокого проникновения; - штукатурка цементно-песчаным раствором М100 (армированная стекловолоконной или пластиковой сеткой); - грунтовка глубокого проникновения; - шпатлёвка; - грунтовка глубокого проникновения δ = 25 мм | F13: 72.4 | G13: - | H13: 305.5 | M13: - обеспыливание | N13: 156.9 | O13: - | P13: 98.5 | Q13: -
A14: 0.10 | B14: Помещение для прокладки коммуникаций | C14: - обеспыливание поверхности ж/б грунтовкой глубокого проникновения Политакс 88PU 2/50 (или аналог) | D14: 387.1 | E14: - грунтовка глубокого проникновения; - штукатурка цементно-песчаным раствором М100 (армированная стекловолоконной или пластиковой сеткой); - грунтовка глубокого проникновения; - шпатлёвка; - грунтовка глубокого проникновения δ = 25 мм | F14: 31.8 | G14: - | H14: 419 | M14: - обеспыливание | N14: 243.4 | O14: - | P14: 135.5 | Q14: -
A15: 0.11 | B15: Помещение для прокладки коммуникаций | C15: - обеспыливание поверхности ж/б грунтовкой глубокого проникновения Политакс 88PU 2/50 (или аналог) | D15: 87.2 | E15: - грунтовка глубокого проникновения; - штукатурка цементно-песчаным раствором М100 (армированная стекловолоконной или пластиковой сеткой); - грунтовка глубокого проникновения; - шпатлёвка; - грунтовка глубокого проникновения δ = 25 мм | F15: 11.1 | G15: - | H15: 98.3 | M15: - обеспыливание | N15: 64.3 | O15: - | P15: 32.3 | Q15: -
A16: 0.12 | B16: Лестничная клетка №5 | C16: - грунтовка "Бетоноконтакт"; - штукатурка цементно-песчаным раствором М100 (армированная стекловолоконной или пластиковой сеткой); - грунтовка глубокого проникновения; - шпатлёвка; - грунтовка глубокого проникновения δ = 25 мм | D16: 89.2 | E16: - грунтовка глубокого проникновения; - штукатурка цементно-песчаным раствором М100 (армированная стекловолоконной или пластиковой сеткой); - грунтовка глубокого проникновения; - шпатлёвка; - грунтовка глубокого проникновения δ = 25 мм | F16: 26.1 | G16: см. раздел АИ | H16: 115.3 | M16: - затирка; - грунтовка "Бетоноконтакт "; - шпатлёвка; - грунтовка глубокого проникновения δ = 5 мм | N16: 17 | O16: см. раздел АИ | P16: 37.3 | Q16: -
A17: 0.13 | B17: Помещение для прокладки коммуникаций | C17: - обеспыливание поверхности ж/б грунтовкой глубокого проникновения Политакс 88PU 2/50 (или аналог) | D17: 49.8 | E17: - грунтовка глубокого проникновения; - штукатурка цементно-песчаным раствором М100 (армированная стекловолоконной или пластиковой сеткой); - грунтовка глубокого проникновения; - шпатлёвка; - грунтовка глубокого проникновения δ = 25 мм | F17: 16.5 | G17: - | H17: 70.4 | M17: - обеспыливание | N17: 16.6 | O17: - | P17: 22.3 | Q17: -
A18: 0.14 | B18: Помещение для прокладки коммуникаций | C18: - обеспыливание поверхности ж/б грунтовкой глубокого проникновения Политакс 88PU 2/50 (или аналог) | D18: 197.8 | E18: - грунтовка глубокого проникновения; - штукатурка цементно-песчаным раствором М100 (армированная стекловолоконной или пластиковой сеткой); - грунтовка глубокого проникновения; - шпатлёвка; - грунтовка глубокого проникновения δ = 25 мм | F18: 25.9 | G18: - | H18: 223.7 | M18: - обеспыливание | N18: 176.6 | O18: - | P18: 68.6 | Q18: -

Sheet Table 2
A1: Ведомость отделки помещений подвала
A2: Ном ер пом еще ния | B2: Наименование помещения | C2: СТЕНЫ ИЛИ ПЕРЕГОРОДКИ | M2: Основной тип потолка | O2: ПЛИНТУС | Q2: Примечание
C3: Железобетон | E3: Кирпич | G3: Газобетон | I3: Утеплитель | K3: Финишный слой | M3: Вид отделки | N3: Площадь, м² | O3: Вид отделки | P3: м.п.
C4: Вид отделки | D4: Площадь, м² | E4: Вид отделки | F4: Площадь, м² | G4: Вид отделки | H4: Площадь, м² | I4: Вид отделки | J4: Площадь, м² | K4: Вид отделки | L4: Площадь, м²
A5: 0.15 | B5: Помещение CC2 | C5: - грунтовка "Бетоноконтакт"; - штукатурка цементно-песчаным раствором М100 (армированная стекловолоконной или пластиковой сеткой); - грунтовка глубокого проникновения; - шпатлёвка; - грунтовка глубокого проникновения δ = 25 мм | D5: 26.3 | E5: - грунтовка глубокого проникновения; - штукатурка цементно-песчаным раствором М100 (армированная стекловолоконной или пластиковой сеткой); - грунтовка глубокого проникновения; - шпатлёвка; - грунтовка глубокого проникновения δ = 25 мм | F5: 18.9 | G5: - | H5: 0 | K5: см. раздел АИ | L5: 45.2 | M5: - затирка; - грунтовка "Бетоноконтакт "; - шпатлёвка; - грунтовка глубокого проникновения δ = 5 мм | N5: 11.8 | O5: см. раздел АИ | P5: 14.3 | Q5: -
A6: 0.16 | B6: Помещение для хранения отработанных ламп | C6: - грунтовка "Бетоноконтакт"; - штукатурка цементно-песчаным раствором М100 (армированная стекловолоконной или пластиковой сеткой); - грунтовка глубокого проникновения; - шпатлёвка; - грунтовка глубокого проникновения δ = 25 мм | D6: 30.7 | E6: - грунтовка глубокого проникновения; - штукатурка цементно-песчаным раствором М100 (армированная стекловолоконной или пластиковой сеткой); - грунтовка глубокого проникновения; - шпатлёвка; - грунтовка глубокого проникновения δ = 25 мм | F6: 11.7 | G6: - | H6: 0 | K6: см. раздел АИ | L6: 42.4 | M6: - затирка; - грунтовка "Бетоноконтакт "; - шпатлёвка; - грунтовка глубокого проникновения δ = 5 мм | N6: 12.4 | O6: см. раздел АИ | P6: 13.4 | Q6: -
A7: 0.17 | B7: Коридор | C7: - грунтовка "Бетоноконтакт"; - штукатурка цементно-песчаным раствором М100 (армированная стекловолоконной или пластиковой сеткой); - грунтовка глубокого проникновения; - шпатлёвка; - грунтовка глубокого проникновения δ = 25 мм | D7: 33.7 | E7: - грунтовка глубокого проникновения; - штукатурка цементно-песчаным раствором М100 (армированная стекловолоконной или пластиковой сеткой); - грунтовка глубокого проникновения; - шпатлёвка; - грунтовка глубокого проникновения δ = 25 мм | F7: 45.4 | G7: - | H7: 0 | K7: см. раздел АИ | L7: 79.1 | M7: - затирка; - грунтовка "Бетоноконтакт "; - шпатлёвка; - грунтовка глубокого проникновения δ = 5 мм | N7: 30.4 | O7: см. раздел АИ | P7: 24.3 | Q7: -
A8: 0.18 | B8: Лестничная клетка №6 | C8: - грунтовка "Бетоноконтакт"; - штукатурка цементно-песчаным раствором М100 (армированная стекловолоконной или пластиковой сеткой); - грунтовка глубокого проникновения; - шпатлёвка; - грунтовка глубокого проникновения δ = 25 мм | D8: 69.9 | E8: - грунтовка глубокого проникновения; - штукатурка цементно-песчаным раствором М100 (армированная стекловолоконной или пластиковой сеткой); - грунтовка глубокого проникновения; - шпатлёвка; - грунтовка глубокого проникновения δ = 25 мм | F8: 24.3 | G8: - | H8: 0 | K8: см. раздел АИ | L8: 94.2 | M8: - затирка; - грунтовка "Бетоноконтакт "; - шпатлёвка; - грунтовка глубокого проникновения δ = 5 мм | N8: 13 | O8: см. раздел АИ | P8: 29.8 | Q8: -
A9: 0.19 | B9: Помещение для прокладки коммуникаций | C9: - обеспыливание поверхности ж/б грунтовкой глубокого проникновения Политакс 88PU 2/50 (или аналог) | D9: 60.3 | E9: - грунтовка глубокого проникновения; - штукатурка цементно-песчаным раствором М100 (армированная стекловолоконной или пластиковой сеткой); - грунтовка глубокого проникновения; - шпатлёвка; - грунтовка глубокого проникновения δ = 25 мм | F9: 29.4 | G9: - | H9: 0 | K9: - | L9: 89.7 | M9: - обеспыливание | N9: 31.4 | O9: - | P9: 28.9 | Q9: -
A10: 0.20 | B10: Помещение для прокладки коммуникаций | C10: - обеспыливание поверхности ж/б грунтовкой глубокого проникновения Политакс 88PU 2/50 (или аналог) | D10: 337.9 | E10: - грунтовка глубокого проникновения; - штукатурка цементно-песчаным раствором М100 (армированная стекловолоконной или пластиковой сеткой); - грунтовка глубокого проникновения; - шпатлёвка; - грунтовка глубокого проникновения δ = 25 мм | F10: 126.9 | G10: - | H10: 0 | K10: - | L10: 464.7 | M10: - обеспыливание | N10: 289.1 | O10: - | P10: 162 | Q10: -
A11: 0.21 | B11: Помещение для прокладки коммуникаций | C11: - обеспыливание поверхности ж/б грунтовкой глубокого проникновения Политакс 88PU 2/50 (или аналог) | D11: 278.8 | E11: - грунтовка глубокого проникновения; - штукатурка цементно-песчаным раствором М100 (армированная стекловолоконной или пластиковой сеткой); - грунтовка глубокого проникновения; - шпатлёвка; - грунтовка глубокого проникновения δ = 25 мм | F11: 64 | G11: - | H11: 0 | K11: - | L11: 342.8 | M11: - обеспыливание | N11: 259.2 | O11: - | P11: 111.1 | Q11: -
A12: 0.22 | B12: Помещение для прокладки коммуникаций | C12: - обеспыливание поверхности ж/б грунтовкой глубокого проникновения Политакс 88PU 2/50 (или аналог) | D12: 32.8 | E12: - грунтовка глубокого проникновения; - штукатурка цементно-песчаным раствором М100 (армированная стекловолоконной или пластиковой сеткой); - грунтовка глубокого проникновения; - шпатлёвка; - грунтовка глубокого проникновения δ = 25 мм | F12: 40.7 | G12: - | H12: 0 | K12: - | L12: 73.5 | M12: - обеспыливание | N12: 26.4 | O12: - | P12: 24.1 | Q12: -
A13: 0.23 | B13: Венткамера | C13: - грунтовка "Бетоноконтакт"; - штукатурка цементно-песчаным раствором М100 (армированная стекловолоконной или пластиковой сеткой); - грунтовка глубокого проникновения; - шпатлёвка; - грунтовка глубокого проникновения δ = 25 мм | D13: 89.7 | E13: - грунтовка глубокого проникновения; - штукатурка цементно-песчаным раствором М100 (армированная стекловолоконной или пластиковой сеткой); - грунтовка глубокого проникновения; - шпатлёвка; - грунтовка глубокого проникновения δ = 25 мм | F13: 52.7 | G13: - | H13: 0 | K13: см. раздел АИ | L13: 142.3 | M13: - затирка; - грунтовка "Бетоноконтакт "; - шпатлёвка; - грунтовка глубокого проникновения δ = 5 мм | N13: 126 | O13: см. раздел АИ | P13: 56.4 | Q13: -
A14: 0.24 | B14: Венткамера | C14: - грунтовка "Бетоноконтакт"; - штукатурка цементно-песчаным раствором М100 (армированная стекловолоконной или пластиковой сеткой); - грунтовка глубокого проникновения; - шпатлёвка; - грунтовка глубокого проникновения δ = 25 мм | D14: 26.4 | E14: - грунтовка глубокого проникновения; - штукатурка цементно-песчаным раствором М100 (армированная стекловолоконной или пластиковой сеткой); - грунтовка глубокого проникновения; - шпатлёвка; - грунтовка глубокого проникновения δ = 25 мм | F14: 92.5 | G14: - | H14: 0 | K14: см. раздел АИ | L14: 118.9 | M14: - затирка; - грунтовка "Бетоноконтакт "; - шпатлёвка; - грунтовка глубокого проникновения δ = 5 мм | N14: 70.7 | O14: см. раздел АИ | P14: 38.8 | Q14: -
A15: 0.25 | B15: Помещение для прокладки коммуникаций | C15: - обеспыливание поверхности ж/б грунтовкой глубокого проникновения Политакс 88PU 2/50 (или аналог) | D15: 210.2 | E15: - грунтовка глубокого проникновения; - штукатурка цементно-песчаным раствором М100 (армированная стекловолоконной или пластиковой сеткой); - грунтовка глубокого проникновения; - шпатлёвка; - грунтовка глубокого проникновения δ = 25 мм | F15: 94.2 | G15: - | H15: 0 | K15: - | L15: 304.3 | M15: - обеспыливание | N15: 242 | O15: - | P15: 99.1 | Q15: -
A16: 0.26 | B16: Коридор | C16: - грунтовка "Бетоноконтакт"; - штукатурка цементно-песчаным раствором М100 (армированная стекловолоконной или пластиковой сеткой); - грунтовка глубокого проникновения; - шпатлёвка; - грунтовка глубокого проникновения δ = 25 мм | D16: 261.6 | E16: - грунтовка глубокого проникновения; - штукатурка цементно-песчаным раствором М100 (армированная стекловолоконной или пластиковой сеткой); - грунтовка глубокого проникновения; - шпатлёвка; - грунтовка глубокого проникновения δ = 25 мм | F16: 130.3 | G16: - пропитка гидрофобизирующим составом BOSTIK SMP; - грунтовка глубокого проникновения; - штукатурка цементно-песчаным раствором М100 (армированная стекловолоконной или пластиковой сеткой); - грунтовка глубокого проникновения; - шпатлёвка; - грунтовка глубокого проникновения δ = 25 мм | H16: 3.8 | K16: см. раздел АИ | L16: 395.7 | M16: - затирка; - грунтовка "Бетоноконтакт "; - шпатлёвка; - грунтовка глубокого проникновения δ = 5 мм | N16: 180.7 | O16: см. раздел АИ | P16: 123.9 | Q16: -
... A19: 0.28 | B19: Помещение для прокладки коммуникаций | C19: - обеспыливание поверхности ж/б грунтовкой глубокого проникновения Политакс 88PU 2/50 (или аналог) | D19: 185.8 | E19: - грунтовка глубокого проникновения; - штукатурка цементно-песчаным раствором М100 (армированная стекловолоконной или пластиковой сеткой); - грунтовка глубокого проникновения; - шпатлёвка; - грунтовка глубокого проникновения δ = 25 мм | F19: 41.3 | G19: - | H19: 0 | K19: - | L19: 227.1 | M19: - обеспыливание | N19: 181.1 | O19: - | P19: 71 | Q19: -

Sheet Table 3
A1: Ведомость отделки помещений подвала
A2: Ном ер пом еще ния | B2: Наименование помещения | C2: СТЕНЫ ИЛИ ПЕРЕГОРОДКИ | Q2: Основной тип потолка | S2: ПЛИНТУС | U2: Примечание
C3: Железобетон | E3: Кирпич | G3: Газобетон | I3: ГСП | K3: ПГП | M3: Утеплитель | O3: Финишный слой | Q3: Вид отделки | R3: Площадь, м² | S3: Вид отделки | T3: м.п.
C4: Вид отделки | D4: Площадь, м² | E4: Вид отделки | F4: Площадь, м² | G4: Вид отделки | H4: Площадь, м² | I4: Вид отделки | J4: Площадь, м² | K4: Вид отделки | L4: Площадь, м² | M4: Вид отделки | N4: Площадь, м² | O4: Вид отделки | P4: Площадь, м²
A5: 1.01 | B5: Тамбур | C5: - грунтовка "Бетоноконтакт"; - гипсовая штукатурка; - грунтовка глубокого проникновения; - шпатлёвка; - грунтовка глубокого проникновения δ = 25 мм | D5: 5.6 | G5: - | H5: 0 | I5: - | J5: 0 | K5: - | L5: 0 | M5: - штукатурка цементно-песчаным раствором М100 (армированная стекловолоконной или пластиковой сеткой); - грунтовка глубокого проникновения; - шпатлёвка; - грунтовка глубокого проникновения δ = 25 мм | N5: 5.4 | O5: см. раздел АИ | P5: 11 | Q5: - затирка; - грунтовка "Бетоноконтакт "; - шпатлёвка; - грунтовка глубокого проникновения δ = 5 мм | R5: 13.4 | S5: см. раздел АИ | T5: 7.7 | U5: Работы по черновой отделке выполнять при необходимост и выравнивания стен
A6: 1.02 | B6: Зона ожидания родителей со стойкой для зарядки мобильных устройств | C6: - грунтовка "Бетоноконтакт"; - гипсовая штукатурка; - грунтовка глубокого проникновения; - шпатлёвка; - грунтовка глубокого проникновения δ = 25 мм | D6: 11.6 | G6: - грунтовка глубокого проникновения; - гипсовая штукатурка; - грунтовка глубокого проникновения; - шпатлёвка; - грунтовка глубокого проникновения δ = 25 мм | H6: 6.3 | I6: - | J6: 0 | K6: - грунтовка глубокого проникновения; - гипсовая штукатурка; - грунтовка глубокого проникновения; - шпатлёвка; - грунтовка глубокого проникновения δ = 25 мм | L6: 15.1 | M6: - | N6: 0 | O6: см. раздел АИ | P6: 32.9 | Q6: - обеспыливание | R6: 17.6 | S6: см. раздел АИ | T6: 14 | U6: Работы по черновой отделке выполнять при необходимост и выравнивания стен
A7: 1.03 | B7: Санузел для посетителей | C7: - | D7: 0 | G7: - | H7: 0 | I7: - | J7: 0 | K7: - грунтовка глубокого проникновения; - штукатурка цементно-песчаным раствором М100 (армированная стекловолоконной или пластиковой сеткой); - грунтовка глубокого проникновения δ = 20 мм | L7: 27.1 | M7: - | N7: 0 | O7: см. раздел АИ | P7: 27.1 | Q7: - затирка; - грунтовка "Бетоноконтакт "; - шпатлёвка; - грунтовка глубокого проникновения δ = 5 мм | R7: 5.8 | S7: см. раздел АИ | T7: 8.5 | U7: Работы по черновой отделке выполнять при необходимост и выравнивания стен
A8: 1.04 | B8: Вестибюль с многофункциональн ым двухсветным пространством с возможностью проведения общественных мероприятий на 200 мест (с эстрадой в уровне пола) | C8: - грунтовка "Бетоноконтакт"; - гипсовая штукатурка; - грунтовка глубокого проникновения; - шпатлёвка; - грунтовка глубокого проникновения δ = 25 мм | D8: 266.7 | G8: - грунтовка глубокого проникновения; - гипсовая штукатурка; - грунтовка глубокого проникновения; - шпатлёвка; - грунтовка глубокого проникновения δ = 25 мм | H8: 166.5 | I8: - грунтовка глубокого проникновения; - шпатлёвка; - грунтовка глубокого проникновения δ = 5 мм | J8: 4.3 | K8: - грунтовка глубокого проникновения; - гипсовая штукатурка; - грунтовка глубокого проникновения; - шпатлёвка; - грунтовка глубокого проникновения δ = 25 мм | L8: 7.1 | M8: - | N8: 0 | O8: см. раздел АИ | P8: 444.7 | Q8: - затирка; - грунтовка "Бетоноконтакт "; - шпатлёвка; - грунтовка глубокого проникновения δ = 5 мм | R8: 357.2 | S8: см. раздел АИ | T8: 88.6 | U8: Работы по черновой отделке выполнять при необходимост и выравнивания стен
A9: 1.05 | B9: Комната охраны с диспетчерским пультом | C9: - грунтовка "Бетоноконтакт"; - гипсовая штукатурка; - грунтовка глубокого проникновения; - шпатлёвка; - грунтовка глубокого проникновения δ = 25 мм | D9: 26.5 | G9: - грунтовка глубокого проникновения; - гипсовая штукатурка; - грунтовка глубокого проникновения; - шпатлёвка; - грунтовка глубокого проникновения δ = 25 мм | H9: 28.2 | I9: - | J9: 0 | K9: - грунтовка глубокого проникновения; - гипсовая штукатурка; - грунтовка глубокого проникновения; - шпатлёвка; - грунтовка глубокого проникновения δ = 25 мм | L9: 14 | M9: - | N9: 0 | O9: см. раздел АИ | P9: 68.7 | Q9: - обеспыливание | R9: 22.1 | S9: см. раздел АИ | T9: 19 | U9: Работы по черновой отделке выполнять при необходимост и выравнивания стен
A10: 1.06 | B10: Санузел для МГН | C10: - | D10: 0 | G10: - грунтовка глубокого проникновения; - штукатурка цементно-песчаным раствором М100 (армированная стекловолоконной или пластиковой сеткой); - грунтовка глубокого проникновения δ = 20 мм | H10: 15 | I10: - | J10: 0 | K10: - грунтовка глубокого проникновения; - штукатурка цементно-песчаным раствором М100 (армированная стекловолоконной или пластиковой сеткой); - грунтовка глубокого проникновения δ = 20 мм | L10: 21.5 | M10: - | N10: 0 | O10: см. раздел АИ | P10: 36.5 | Q10: - затирка; - грунтовка "Бетоноконтакт "; - шпатлёвка; - грунтовка глубокого проникновения δ = 5 мм | R10: 5.9 | S10: см. раздел АИ | T10: 9 | U10: Работы по черновой отделке выполнять при необходимост и выравнивания стен
A11: 1.07 | B11: Гардероб для учителей | C11: - грунтовка "Бетоноконтакт"; - гипсовая штукатурка; - грунтовка глубокого проникновения; - шпатлёвка; - грунтовка глубокого проникновения δ = 25 мм | D11: 12.4 | G11: - грунтовка глубокого проникновения; - гипсовая штукатурка; - грунтовка глубокого проникновения; - шпатлёвка; - грунтовка глубокого проникновения δ = 25 мм | H11: 34.3 | I11: - | J11: 0 | K11: - | L11: 0 | M11: - | N11: 0 | O11: см. раздел АИ | P11: 46.7 | Q11: - обеспыливание | R11: 10 | S11: см. раздел АИ | T11: 11.7 | U11: Работы по черновой отделке выполнять при необходимост и выравнивания стен
A12: 1.08 | B12: Гардероб для начальной школы | C12: - грунтовка "Бетоноконтакт"; - гипсовая штукатурка; - грунтовка глубокого проникновения; - шпатлёвка; - грунтовка глубокого проникновения δ = 25 мм | D12: 72.9 | G12: - грунтовка глубокого проникновения; - гипсовая штукатурка; - грунтовка глубокого проникновения; - шпатлёвка; - грунтовка глубокого проникновения δ = 25 мм | H12: 66.1 | I12: - | J12: 0 | K12: - грунтовка глубокого проникновения; - гипсовая штукатурка; - грунтовка глубокого проникновения; - шпатлёвка; - грунтовка глубокого проникновения δ = 25 мм | L12: 16.5 | M12: - | N12: 0 | O12: см. раздел АИ | P12: 155.5 | Q12: - обеспыливание | R12: 105.4 | S12: см. раздел АИ | T12: 48.2 | U12: Работы по черновой отделке выполнять при необходимост и выравнивания стен
A13: 1.09 | B13: Учебный кабинет 1 класс | C13: - грунтовка "Бетоноконтакт"; - гипсовая штукатурка; - грунтовка глубокого проникновения; - шпатлёвка; - грунтовка глубокого проникновения δ = 25 мм | D13: 40.1 | G13: - грунтовка глубокого проникновения; - гипсовая штукатурка; - грунтовка глубокого проникновения; - шпатлёвка; - грунтовка глубокого проникновения δ = 25 мм | H13: 70.1 | I13: - | J13: 0 | K13: - грунтовка глубокого проникновения; - гипсовая штукатурка; - грунтовка глубокого проникновения; - шпатлёвка; - грунтовка глубокого проникновения δ = 25 мм | L13: 8.4 | M13: - | N13: 0 | O13: см. раздел АИ | P13: 118.6 | Q13: - обеспыливание | R13: 62.9 | S13: см. раздел АИ | T13: 34.6 | U13: Работы по черновой отделке выполнять при необходимост и выравнивания стен

Sheet Table 4
A1: Ведомость отделки помещений подвала
A2: Ном ер пом еще ния | B2: Наименование помещения | C2: СТЕНЫ ИЛИ ПЕРЕГОРОДКИ | Q2: Основной тип потолка | S2: ПЛИНТУС | U2: Примечание
C3: Железобетон | E3: Кирпич | G3: Газобетон | I3: ГСП | K3: ПГП | M3: Утеплитель | O3: Финишный слой | Q3: Вид отделки | R3: Площадь, м² | S3: Вид отделки | T3: м.п.
C4: Вид отделки | D4: Площадь, м² | E4: Вид отделки | F4: Площадь, м² | G4: Вид отделки | H4: Площадь, м² | I4: Вид отделки | J4: Площадь, м² | K4: Вид отделки | L4: Площадь, м² | M4: Вид отделки | N4: Площадь, м² | O4: Вид отделки | P4: Площадь, м²
A5: 1.10 | B5: Учебный кабинет 1 класс | C5: - грунтовка "Бетоноконтакт"; - гипсовая штукатурка; - грунтовка глубокого проникновения; - шпатлёвка; - грунтовка глубокого проникновения δ = 25 мм | D5: 55.6 | G5: - грунтовка глубокого проникновения; - гипсовая штукатурка; - грунтовка глубокого проникновения; - шпатлёвка; - грунтовка глубокого проникновения δ = 25 мм | H5: 47.3 | K5: - грунтовка глубокого проникновения; - гипсовая штукатурка; - грунтовка глубокого проникновения; - шпатлёвка; - грунтовка глубокого проникновения δ = 25 мм | L5: 6.6 | O5: см. раздел АИ | P5: 109.5 | Q5: - обеспыливание | R5: 64.3 | S5: см. раздел АИ | T5: 32.4 | U5: Работы по черновой отделке выполнять при необходимост и выравнивания стен
A6: 1.11 | B6: Учебный кабинет 1 класс | C6: - грунтовка "Бетоноконтакт"; - гипсовая штукатурка; - грунтовка глубокого проникновения; - шпатлёвка; - грунтовка глубокого проникновения δ = 25 мм | D6: 92.6 | G6: - грунтовка глубокого проникновения; - гипсовая штукатурка; - грунтовка глубокого проникновения; - шпатлёвка; - грунтовка глубокого проникновения δ = 25 мм | H6: 11.6 | K6: - грунтовка глубокого проникновения; - гипсовая штукатурка; - грунтовка глубокого проникновения; - шпатлёвка; - грунтовка глубокого проникновения δ = 25 мм | L6: 8.5 | O6: см. раздел АИ | P6: 112.7 | Q6: - обеспыливание | R6: 64.4 | S6: см. раздел АИ | T6: 32.6 | U6: Работы по черновой отделке выполнять при необходимост и выравнивания стен
A7: 1.12 | B7: Игровая с возможностью организации спальных мест | C7: - грунтовка "Бетоноконтакт"; - гипсовая штукатурка; - грунтовка глубокого проникновения; - шпатлёвка; - грунтовка глубокого проникновения δ = 25 мм | D7: 121.5 | G7: - грунтовка глубокого проникновения; - гипсовая штукатурка; - грунтовка глубокого проникновения; - шпатлёвка; - грунтовка глубокого проникновения δ = 25 мм | H7: 24.2 | K7: - грунтовка глубокого проникновения; - гипсовая штукатурка; - грунтовка глубокого проникновения; - шпатлёвка; - грунтовка глубокого проникновения δ = 25 мм | L7: 28.6 | O7: см. раздел АИ | P7: 174.2 | Q7: - обеспыливание | R7: 131.2 | S7: см. раздел АИ | T7: 46 | U7: Работы по черновой отделке выполнять при необходимост и выравнивания стен
A8: 1.13 | B8: Санузел для девочек | C8: - грунтовка "Бетоноконтакт"; - штукатурка цементно-песчаным раствором М100 (армированная стекловолоконной или пластиковой сеткой); - грунтовка глубокого проникновения δ = 20 мм | D8: 50.1 | G8: - | H8: 0 | K8: - грунтовка глубокого проникновения; - штукатурка цементно-песчаным раствором М100 (армированная стекловолоконной или пластиковой сеткой); - грунтовка глубокого проникновения δ = 20 мм | L8: 30.1 | O8: см. раздел АИ | P8: 80.2 | Q8: - затирка; - грунтовка "Бетоноконтакт "; - шпатлёвка; - грунтовка глубокого проникновения δ = 5 мм | R8: 15.8 | S8: см. раздел АИ | T8: 20.3 | U8: Работы по черновой отделке выполнять при необходимост и выравнивания стен
A9: 1.14 | B9: Санузел для МГН | C9: - грунтовка "Бетоноконтакт"; - штукатурка цементно-песчаным раствором М100 (армированная стекловолоконной или пластиковой сеткой); - грунтовка глубокого проникновения δ = 20 мм | D9: 7.2 | G9: - | H9: 0 | K9: - грунтовка глубокого проникновения; - штукатурка цементно-песчаным раствором М100 (армированная стекловолоконной или пластиковой сеткой); - грунтовка глубокого проникновения δ = 20 мм | L9: 27.6 | O9: см. раздел АИ | P9: 34.8 | Q9: - затирка; - грунтовка "Бетоноконтакт "; - шпатлёвка; - грунтовка глубокого проникновения δ = 5 мм | R9: 5.4 | S9: см. раздел АИ | T9: 8.2 | U9: Работы по черновой отделке выполнять при необходимост и выравнивания стен
A10: 1.15 | B10: Санузел для мальчиков | C10: - грунтовка "Бетоноконтакт"; - штукатурка цементно-песчаным раствором М100 (армированная стекловолоконной или пластиковой сеткой); - грунтовка глубокого проникновения δ = 20 мм | D10: 49.9 | G10: - | H10: 0 | K10: - грунтовка глубокого проникновения; - штукатурка цементно-песчаным раствором М100 (армированная стекловолоконной или пластиковой сеткой); - грунтовка глубокого проникновения δ = 20 мм | L10: 30.4 | O10: см. раздел АИ | P10: 80.3 | Q10: - затирка; - грунтовка "Бетоноконтакт "; - шпатлёвка; - грунтовка глубокого проникновения δ = 5 мм | R10: 15.8 | S10: см. раздел АИ | T10: 20.2 | U10: Работы по черновой отделке выполнять при необходимост и выравнивания стен
A11: 1.16 | B11: С/у (медблок) | C11: - грунтовка "Бетоноконтакт"; - штукатурка цементно-песчаным раствором М100 (армированная стекловолоконной или пластиковой сеткой); - грунтовка глубокого проникновения δ = 20 мм | D11: 1.1 | G11: - грунтовка глубокого проникновения; - штукатурка цементно-песчаным раствором М100 (армированная стекловолоконной или пластиковой сеткой); - грунтовка глубокого проникновения δ = 20 мм | H11: 4.8 | K11: - грунтовка глубокого проникновения; - штукатурка цементно-песчаным раствором М100 (армированная стекловолоконной или пластиковой сеткой); - грунтовка глубокого проникновения δ = 20 мм | L11: 16.7 | O11: см. раздел АИ | P11: 22.7 | Q11: - обеспыливание | R11: 2.4 | S11: см. раздел АИ | T11: 5.3 | U11: Работы по черновой отделке выполнять при необходимост и выравнивания стен
A12: 1.17 | B12: Процедурный кабинет | C12: - грунтовка "Бетоноконтакт"; - штукатурка цементно-песчаным раствором М100 (армированная стекловолоконной или пластиковой сеткой); - грунтовка глубокого проникновения δ = 20 мм | D12: 18.6 | G12: - | H12: 0 | K12: - грунтовка глубокого проникновения; - штукатурка цементно-песчаным раствором М100 (армированная стекловолоконной или пластиковой сеткой); - грунтовка глубокого проникновения δ = 20 мм | L12: 40.8 | O12: см. раздел АИ | P12: 59.4 | Q12: - затирка; - грунтовка "Бетоноконтакт "; - шпатлёвка; - грунтовка глубокого проникновения δ = 5 мм | R12: 13.9 | S12: см. раздел АИ | T12: 16.2 | U12: Работы по черновой отделке выполнять при необходимост и выравнивания стен
A13: 1.18 | B13: Прививочный кабинет | C13: - грунтовка "Бетоноконтакт"; - штукатурка цементно-песчаным раствором М100 (армированная стекловолоконной или пластиковой сеткой); - грунтовка глубокого проникновения δ = 20 мм | D13: 7.2 | G13: - | H13: 0 | K13: - грунтовка глубокого проникновения; - штукатурка цементно-песчаным раствором М100 (армированная стекловолоконной или пластиковой сеткой); - грунтовка глубокого проникновения δ = 20 мм | L13: 50.8 | O13: см. раздел АИ | P13: 58 | Q13: - затирка; - грунтовка "Бетоноконтакт "; - шпатлёвка; - грунтовка глубокого проникновения δ = 5 мм | R13: 13.9 | S13: см. раздел АИ | T13: 15.4 | U13: Работы по черновой отделке выполнять при необходимост и выравнивания стен
A14: 1.20 | B14: Холл | C14: - грунтовка "Бетоноконтакт"; - гипсовая штукатурка; - грунтовка глубокого проникновения; - шпатлёвка; - грунтовка глубокого проникновения δ = 25 мм | D14: 7.4 | G14: - грунтовка глубокого проникновения; - гипсовая штукатурка; - грунтовка глубокого проникновения; - шпатлёвка; - грунтовка глубокого проникновения δ = 25 мм | H14: 24.1 | K14: - грунтовка глубокого проникновения; - гипсовая штукатурка; - грунтовка глубокого проникновения; - шпатлёвка; - грунтовка глубокого проникновения δ = 25 мм | L14: 35.7 | O14: см. раздел АИ | P14: 67.2 | Q14: - обеспыливание | R14: 20.4 | S14: см. раздел АИ | T14: 15.9 | U14: Работы по черновой отделке выполнять при необходимост и выравнивания стен
A15: 1.21 | B15: Помещение для приготовления дезинфицирующих растворов | C15: - грунтовка "Бетоноконтакт"; - штукатурка цементно-песчаным раствором М100 (армированная стекловолоконной или пластиковой сеткой); - грунтовка глубокого проникновения δ = 20 мм | D15: 7.7 | G15: - грунтовка глубокого проникновения; - штукатурка цементно-песчаным раствором М100 (армированная стекловолоконной или пластиковой сеткой); - грунтовка глубокого проникновения δ = 20 мм | H15: 14.3 | K15: - грунтовка глубокого проникновения; - штукатурка цементно-песчаным раствором М100 (армированная стекловолоконной или пластиковой сеткой); - грунтовка глубокого проникновения δ = 20 мм | L15: 21.7 | O15: см. раздел АИ | P15: 43.7 | Q15: - затирка; - грунтовка "Бетоноконтакт "; - шпатлёвка; - грунтовка глубокого проникновения δ = 5 мм | R15: 6 | S15: см. раздел АИ | T15: 10.7 | U15: Работы по черновой отделке выполнять при необходимост и выравнивания стен
A16: 1.22 | B16: Санузел персонала | C16: - грунтовка "Бетоноконтакт"; - штукатурка цементно-песчаным раствором М100 (армированная стекловолоконной или пластиковой сеткой); - грунтовка глубокого проникновения δ = 20 мм | D16: 3.2 | G16: - грунтовка глубокого проникновения; - штукатурка цементно-песчаным раствором М100 (армированная стекловолоконной или пластиковой сеткой); - грунтовка глубокого проникновения δ = 20 мм | H16: 9 | K16: - грунтовка глубокого проникновения; - штукатурка цементно-песчаным раствором М100 (армированная стекловолоконной или пластиковой сеткой); - грунтовка глубокого проникновения δ = 20 мм | L16: 20.9 | O16: см. раздел АИ | P16: 33 | Q16: - затирка; - грунтовка "Бетоноконтакт "; - шпатлёвка; - грунтовка глубокого проникновения δ = 5 мм | R16: 4.7 | S16: см. раздел АИ | T16: 8 | U16: Работы по черновой отделке выполнять при необходимост и выравнивания стен
... A22: 1.28 | B22: Серверная | C22: - грунтовка "Бетоноконтакт"; - гипсовая штукатурка; - грунтовка глубокого проникновения; - шпатлёвка; - грунтовка глубокого проникновения δ = 25 мм | D22: 42.4 | G22: - грунтовка глубокого проникновения; - гипсовая штукатурка; - грунтовка глубокого проникновения; - шпатлёвка; - грунтовка глубокого проникновения δ = 25 мм | H22: 39.3 | K22: - | L22: 0 | O22: см. раздел АИ | P22: 81.7 | Q22: - обеспыливание | R22: 35.8 | S22: см. раздел АИ | T22: 22 | U22: Работы по черновой отделке выполнять при необходимост и выравнивания стен

Sheet Table 5
A1: Ведомость отделки помещений подвала
A2: Ном ер пом еще ния | B2: Наименование помещения | C2: СТЕНЫ ИЛИ ПЕРЕГОРОДКИ | Q2: Основной тип потолка | S2: ПЛИНТУС | U2: Примечание
C3: Железобетон | E3: Кирпич | G3: Газобетон | I3: ГСП | K3: ПГП | M3: Утеплитель | O3: Финишный слой | Q3: Вид отделки | R3: Площадь, м² | S3: Вид отделки | T3: м.п.
C4: Вид отделки | D4: Площадь, м² | E4: Вид отделки | F4: Площадь, м² | G4: Вид отделки | H4: Площадь, м² | I4: Вид отделки | J4: Площадь, м² | K4: Вид отделки | L4: Площадь, м² | M4: Вид отделки | N4: Площадь, м² | O4: Вид отделки | P4: Площадь, м²
A5: 1.29 | B5: Электрощитовая | C5: - грунтовка "Бетоноконтакт"; - гипсовая штукатурка; - грунтовка глубокого проникновения; - шпатлёвка; - грунтовка глубокого проникновения δ = 25 мм | D5: 31.2 | E5: - | F5: 0 | G5: - грунтовка глубокого проникновения; - гипсовая штукатурка; - грунтовка глубокого проникновения; - шпатлёвка; - грунтовка глубокого проникновения δ = 25 мм | H5: 59.7 | K5: - | L5: 0 | O5: см. раздел АИ | P5: 90.9 | Q5: - затирка; - грунтовка "Бетоноконтакт "; - шпатлёвка; - грунтовка глубокого проникновения δ = 5 мм | R5: 45.9 | S5: см. раздел АИ | T5: 24.9 | U5: Работы по черновой отделке выполнять при необходимост и выравнивания стен
A6: 1.30 | B6: Рекреация коридорного типа | C6: - грунтовка "Бетоноконтакт"; - гипсовая штукатурка; - грунтовка глубокого проникновения; - шпатлёвка; - грунтовка глубокого проникновения δ = 25 мм | D6: 64.9 | E6: - | F6: 0 | G6: - грунтовка глубокого проникновения; - гипсовая штукатурка; - грунтовка глубокого проникновения; - шпатлёвка; - грунтовка глубокого проникновения δ = 25 мм | H6: 88.7 | K6: - грунтовка глубокого проникновения; - гипсовая штукатурка; - грунтовка глубокого проникновения; - шпатлёвка; - грунтовка глубокого проникновения δ = 25 мм | L6: 23.7 | O6: см. раздел АИ | P6: 177.2 | Q6: - затирка; - грунтовка "Бетоноконтакт "; - шпатлёвка; - грунтовка глубокого проникновения δ = 5 мм | R6: 180.7 | S6: см. раздел АИ | T6: 38.3 | U6: Работы по черновой отделке выполнять при необходимост и выравнивания стен
A7: 1.31 | B7: Коридор | C7: - грунтовка "Бетоноконтакт"; - гипсовая штукатурка; - грунтовка глубокого проникновения; - шпатлёвка; - грунтовка глубокого проникновения δ = 25 мм | D7: 130.2 | E7: - | F7: 0 | G7: - грунтовка глубокого проникновения; - гипсовая штукатурка; - грунтовка глубокого проникновения; - шпатлёвка; - грунтовка глубокого проникновения δ = 25 мм | H7: 128.2 | K7: - грунтовка глубокого проникновения; - гипсовая штукатурка; - грунтовка глубокого проникновения; - шпатлёвка; - грунтовка глубокого проникновения δ = 25 мм | L7: 4.6 | O7: см. раздел АИ | P7: 263.1 | Q7: - затирка; - грунтовка "Бетоноконтакт "; - шпатлёвка; - грунтовка глубокого проникновения δ = 5 мм | R7: 113 | S7: см. раздел АИ | T7: 51.4 | U7: Работы по черновой отделке выполнять при необходимост и выравнивания стен
A8: 1.32 | B8: Лестничная клетка №1 (Тип Н2) | C8: - грунтовка "Бетоноконтакт"; - гипсовая штукатурка; - грунтовка глубокого проникновения; - шпатлёвка; - грунтовка глубокого проникновения δ = 25 мм | D8: 73.9 | E8: - грунтовка глубокого проникновения; - гипсовая штукатурка; - грунтовка глубокого проникновения; - шпатлёвка; - грунтовка глубокого проникновения δ = 25 мм | F8: 36.8 | G8: - | H8: 0 | K8: - | L8: 0 | O8: см. раздел АИ | P8: 110.6 | Q8: - затирка; - грунтовка "Бетоноконтакт "; - шпатлёвка; - грунтовка глубокого проникновения δ = 5 мм | R8: 14.4 | S8: см. раздел АИ | T8: 26.9 | U8: Работы по черновой отделке выполнять при необходимост и выравнивания стен
A9: 1.33 | B9: Лестничная клетка №2 (Тип Н2) | C9: - грунтовка "Бетоноконтакт"; - гипсовая штукатурка; - грунтовка глубокого проникновения; - шпатлёвка; - грунтовка глубокого проникновения δ = 25 мм | D9: 82.3 | E9: - | F9: 0 | G9: - | H9: 0 | K9: - | L9: 0 | O9: см. раздел АИ | P9: 82.3 | Q9: - затирка; - грунтовка "Бетоноконтакт "; - шпатлёвка; - грунтовка глубокого проникновения δ = 5 мм | R9: 17.9 | S9: см. раздел АИ | T9: 20 | U9: Работы по черновой отделке выполнять при необходимост и выравнивания стен
A10: 1.34 | B10: Лестничная клетка №3 (Тип Н2) | C10: - грунтовка "Бетоноконтакт"; - гипсовая штукатурка; - грунтовка глубокого проникновения; - шпатлёвка; - грунтовка глубокого проникновения δ = 25 мм | D10: 78.4 | E10: - | F10: 0 | G10: - | H10: 0 | K10: - | L10: 0 | O10: см. раздел АИ | P10: 78.4 | Q10: - затирка; - грунтовка "Бетоноконтакт "; - шпатлёвка; - грунтовка глубокого проникновения δ = 5 мм | R10: 15.5 | S10: см. раздел АИ | T10: 18.8 | U10: Работы по черновой отделке выполнять при необходимост и выравнивания стен
A11: 1.35 | B11: Лестничная клетка №4 (Тип Н2) | C11: - грунтовка "Бетоноконтакт"; - гипсовая штукатурка; - грунтовка глубокого проникновения; - шпатлёвка; - грунтовка глубокого проникновения δ = 25 мм | D11: 82.6 | E11: - | F11: 0 | G11: - | H11: 0 | K11: - грунтовка глубокого проникновения; - гипсовая штукатурка; - грунтовка глубокого проникновения; - шпатлёвка; - грунтовка глубокого проникновения δ = 25 мм | L11: 13.7 | O11: см. раздел АИ | P11: 96.3 | Q11: - затирка; - грунтовка "Бетоноконтакт "; - шпатлёвка; - грунтовка глубокого проникновения δ = 5 мм | R11: 23.4 | S11: см. раздел АИ | T11: 23.1 | U11: Работы по черновой отделке выполнять при необходимост и выравнивания стен
A12: 1.36 | B12: Лифтовой холл | C12: - грунтовка "Бетоноконтакт"; - гипсовая штукатурка; - грунтовка глубокого проникновения; - шпатлёвка; - грунтовка глубокого проникновения δ = 25 мм | D12: 32.8 | E12: - | F12: 0 | G12: - грунтовка глубокого проникновения; - гипсовая штукатурка; - грунтовка глубокого проникновения; - шпатлёвка; - грунтовка глубокого проникновения δ = 25 мм | H12: 22 | K12: - | L12: 0 | O12: см. раздел АИ | P12: 54.8 | Q12: - затирка; - грунтовка "Бетоноконтакт "; - шпатлёвка; - грунтовка глубокого проникновения δ = 5 мм | R12: 25.9 | S12: см. раздел АИ | T12: 15.2 | U12: Работы по черновой отделке выполнять при необходимост и выравнивания стен
A13: 1.37 | B13: Умывальная | C13: - грунтовка "Бетоноконтакт"; - штукатурка цементно-песчаным раствором М100 (армированная стекловолоконной или пластиковой сеткой); - грунтовка глубокого проникновения δ = 20 мм | D13: 11 | E13: - | F13: 0 | G13: - | H13: 0 | K13: - грунтовка глубокого проникновения; - штукатурка цементно-песчаным раствором М100 (армированная стекловолоконной или пластиковой сеткой); - грунтовка глубокого проникновения δ = 20 мм | L13: 38.9 | O13: см. раздел АИ | P13: 49.9 | Q13: - затирка; - грунтовка "Бетоноконтакт "; - шпатлёвка; - грунтовка глубокого проникновения δ = 5 мм | R13: 11.8 | S13: см. раздел АИ | T13: 12.2 | U13: Работы по черновой отделке выполнять при необходимост и выравнивания стен
A14: 1.38 | B14: Обеденный зал на 150 мест | C14: - грунтовка "Бетоноконтакт"; - гипсовая штукатурка; - грунтовка глубокого проникновения; - шпатлёвка; - грунтовка глубокого проникновения δ = 25 мм | D14: 116.4 | E14: - | F14: 0 | G14: - грунтовка глубокого проникновения; - гипсовая штукатурка; - грунтовка глубокого проникновения; - шпатлёвка; - грунтовка глубокого проникновения δ = 25 мм | H14: 87.3 | K14: - грунтовка глубокого проникновения; - гипсовая штукатурка; - грунтовка глубокого проникновения; - шпатлёвка; - грунтовка глубокого проникновения δ = 25 мм | L14: 22.5 | O14: см. раздел АИ | P14: 226.1 | Q14: - затирка; - грунтовка "Бетоноконтакт "; - шпатлёвка; - грунтовка глубокого проникновения δ = 5 мм | R14: 170.4 | S14: см. раздел АИ | T14: 62.7 | U14: Работы по черновой отделке выполнять при необходимост и выравнивания стен

Sheet Table 6
A1: Ведомость отделки помещений подвала
A2: Ном ер пом еще ния | B2: Наименование помещения | C2: СТЕНЫ ИЛИ ПЕРЕГОРОДКИ | Q2: Основной тип потолка | S2: ПЛИНТУС | U2: Примечание
C3: Железобетон | E3: Кирпич | G3: Газобетон | I3: ГСП | K3: ПГП | M3: Утеплитель | O3: Финишный слой | Q3: Вид отделки | R3: Площадь, м² | S3: Вид отделки | T3: м.п.
C4: Вид отделки | D4: Площадь, м² | E4: Вид отделки | F4: Площадь, м² | G4: Вид отделки | H4: Площадь, м² | I4: Вид отделки | J4: Площадь, м² | K4: Вид отделки | L4: Площадь, м² | M4: Вид отделки | N4: Площадь, м² | O4: Вид отделки | P4: Площадь, м²
A5: 1.39 | B5: Моечная столовой посуды | C5: - грунтовка "Бетоноконтакт"; - штукатурка цементно-песчаным раствором М100 (армированная стекловолоконной или пластиковой сеткой); - грунтовка глубокого проникновения δ = 20 мм | D5: 20.5 | E5: - | F5: 0 | G5: - грунтовка глубокого проникновения; - штукатурка цементно-песчаным раствором М100 (армированная стекловолоконной или пластиковой сеткой); - грунтовка глубокого проникновения δ = 20 мм | H5: 102.4 | K5: - грунтовка глубокого проникновения; - штукатурка цементно-песчаным раствором М100 (армированная стекловолоконной или пластиковой сеткой); - грунтовка глубокого проникновения δ = 20 мм | L5: 2 | O5: см. раздел АИ | P5: 125 | Q5: - затирка; - грунтовка "Бетоноконтакт "; - шпатлёвка; - грунтовка глубокого проникновения δ = 5 мм | R5: 36.4 | S5: см. раздел АИ | T5: 32.2 | U5: Работы по черновой отделке выполнять при необходимост и выравнивания стен
A6: 1.40 | B6: Холодный цех | C6: - грунтовка "Бетоноконтакт"; - штукатурка цементно-песчаным раствором М100 (армированная стекловолоконной или пластиковой сеткой); - грунтовка глубокого проникновения δ = 20 мм | D6: 5 | E6: - грунтовка глубокого проникновения; - штукатурка цементно-песчаным раствором М100 (армированная стекловолоконной или пластиковой сеткой); - грунтовка глубокого проникновения δ = 20 мм | F6: 1.4 | G6: - грунтовка глубокого проникновения; - штукатурка цементно-песчаным раствором М100 (армированная стекловолоконной или пластиковой сеткой); - грунтовка глубокого проникновения δ = 20 мм | H6: 22.3 | K6: - грунтовка глубокого проникновения; - штукатурка цементно-песчаным раствором М100 (армированная стекловолоконной или пластиковой сеткой); - грунтовка глубокого проникновения δ = 20 мм | L6: 27.9 | O6: см. раздел АИ | P6: 56.7 | Q6: - затирка; - грунтовка "Бетоноконтакт "; - шпатлёвка; - грунтовка глубокого проникновения δ = 5 мм | R6: 15 | S6: см. раздел АИ | T6: 12.6 | U6: Работы по черновой отделке выполнять при необходимост и выравнивания стен
A7: 1.41 | B7: Горячий цех | C7: - грунтовка "Бетоноконтакт"; - штукатурка цементно-песчаным раствором М100 (армированная стекловолоконной или пластиковой сеткой); - грунтовка глубокого проникновения δ = 20 мм | D7: 53.6 | E7: - грунтовка глубокого проникновения; - штукатурка цементно-песчаным раствором М100 (армированная стекловолоконной или пластиковой сеткой); - грунтовка глубокого проникновения δ = 20 мм | F7: 5.5 | G7: - грунтовка глубокого проникновения; - штукатурка цементно-песчаным раствором М100 (армированная стекловолоконной или пластиковой сеткой); - грунтовка глубокого проникновения δ = 20 мм | H7: 62.9 | K7: - грунтовка глубокого проникновения; - штукатурка цементно-песчаным раствором М100 (армированная стекловолоконной или пластиковой сеткой); - грунтовка глубокого проникновения δ = 20 мм | L7: 69.3 | O7: см. раздел АИ | P7: 191.3 | Q7: - затирка; - грунтовка "Бетоноконтакт "; - шпатлёвка; - грунтовка глубокого проникновения δ = 5 мм | R7: 89.2 | S7: см. раздел АИ | T7: 44 | U7: Работы по черновой отделке выполнять при необходимост и выравнивания стен
A8: 1.42 | B8: Моечная кухонной посуды | C8: - грунтовка "Бетоноконтакт"; - штукатурка цементно-песчаным раствором М100 (армированная стекловолоконной или пластиковой сеткой); - грунтовка глубокого проникновения δ = 20 мм | D8: 6.7 | E8: - | F8: 0 | G8: - | H8: 0 | K8: - грунтовка глубокого проникновения; - штукатурка цементно-песчаным раствором М100 (армированная стекловолоконной или пластиковой сеткой); - грунтовка глубокого проникновения δ = 20 мм | L8: 61.5 | O8: см. раздел АИ | P8: 68.2 | Q8: - затирка; - грунтовка "Бетоноконтакт "; - шпатлёвка; - грунтовка глубокого проникновения δ = 5 мм | R8: 13.6 | S8: см. раздел АИ | T8: 16.2 | U8: Работы по черновой отделке выполнять при необходимост и выравнивания стен
A9: 1.43 | B9: Кладовая сухих продуктов | C9: - грунтовка "Бетоноконтакт"; - штукатурка цементно-песчаным раствором М100 (армированная стекловолоконной или пластиковой сеткой); - грунтовка глубокого проникновения δ = 20 мм | D9: 5.2 | E9: - | F9: 0 | G9: - | H9: 0 | K9: - грунтовка глубокого проникновения; - штукатурка цементно-песчаным раствором М100 (армированная стекловолоконной или пластиковой сеткой); - грунтовка глубокого проникновения δ = 20 мм | L9: 51.6 | O9: см. раздел АИ | P9: 56.8 | Q9: - затирка; - грунтовка "Бетоноконтакт "; - шпатлёвка; - грунтовка глубокого проникновения δ = 5 мм | R9: 12.1 | S9: см. раздел АИ | T9: 14.2 | U9: Работы по черновой отделке выполнять при необходимост и выравнивания стен
A10: 1.44 | B10: Помещение с холодильным оборудованием | C10: - грунтовка "Бетоноконтакт"; - штукатурка цементно-песчаным раствором М100 (армированная стекловолоконной или пластиковой сеткой); - грунтовка глубокого проникновения δ = 20 мм | D10: 11.2 | E10: - | F10: 0 | G10: - | H10: 0 | K10: - грунтовка глубокого проникновения; - штукатурка цементно-песчаным раствором М100 (армированная стекловолоконной или пластиковой сеткой); - грунтовка глубокого проникновения δ = 20 мм | L10: 86.5 | O10: см. раздел АИ | P10: 97.6 | Q10: - затирка; - грунтовка "Бетоноконтакт "; - шпатлёвка; - грунтовка глубокого проникновения δ = 5 мм | R10: 29.7 | S10: см. раздел АИ | T10: 23.8 | U10: Работы по черновой отделке выполнять при необходимост и выравнивания стен
A11: 1.45 | B11: Кладовая овощей | C11: - грунтовка "Бетоноконтакт"; - штукатурка цементно-песчаным раствором М100 (армированная стекловолоконной или пластиковой сеткой); - грунтовка глубокого проникновения δ = 20 мм | D11: 2 | E11: - | F11: 0 | G11: - | H11: 0 | K11: - грунтовка глубокого проникновения; - штукатурка цементно-песчаным раствором М100 (армированная стекловолоконной или пластиковой сеткой); - грунтовка глубокого проникновения δ = 20 мм | L11: 52.8 | O11: см. раздел АИ | P11: 54.8 | Q11: - затирка; - грунтовка "Бетоноконтакт "; - шпатлёвка; - грунтовка глубокого проникновения δ = 5 мм | R11: 10.8 | S11: см. раздел АИ | T11: 13.4 | U11: Работы по черновой отделке выполнять при необходимост и выравнивания стен
A12: 1.46 | B12: Помещение персонала | C12: - грунтовка "Бетоноконтакт"; - штукатурка цементно-песчаным раствором М100 (армированная стекловолоконной или пластиковой сеткой); - грунтовка глубокого проникновения δ = 20 мм | D12: 6.5 | E12: - | F12: 0 | G12: - | H12: 0 | K12: - грунтовка глубокого проникновения; - штукатурка цементно-песчаным раствором М100 (армированная стекловолоконной или пластиковой сеткой); - грунтовка глубокого проникновения δ = 20 мм | L12: 48.2 | O12: см. раздел АИ | P12: 54.7 | Q12: - затирка; - грунтовка "Бетоноконтакт "; - шпатлёвка; - грунтовка глубокого проникновения δ = 5 мм | R12: 9.3 | S12: см. раздел АИ | T12: 13.5 | U12: Работы по черновой отделке выполнять при необходимост и выравнивания стен
A13: 1.47 | B13: Помещение временного хранения отходов | C13: - | D13: 0 | E13: - | F13: 0 | G13: - | H13: 0 | K13: - грунтовка глубокого проникновения; - штукатурка цементно-песчаным раствором М100 (армированная стекловолоконной или пластиковой сеткой); - грунтовка глубокого проникновения δ = 20 мм | L13: 54.7 | O13: см. раздел АИ | P13: 54.7 | Q13: - затирка; - грунтовка "Бетоноконтакт "; - шпатлёвка; - грунтовка глубокого проникновения δ = 5 мм | R13: 9.7 | S13: см. раздел АИ | T13: 13.1 | U13: Работы по черновой отделке выполнять при необходимост и выравнивания стен
A14: 1.48 | B14: Раздаточная | C14: - грунтовка "Бетоноконтакт"; - гипсовая штукатурка; - грунтовка глубокого проникновения; - шпатлёвка; - грунтовка глубокого проникновения δ = 25 мм | D14: 10.6 | E14: - | F14: 0 | G14: - грунтовка глубокого проникновения; - гипсовая штукатурка; - грунтовка глубокого проникновения; - шпатлёвка; - грунтовка глубокого проникновения δ = 25 мм | H14: 8.5 | K14: - грунтовка глубокого проникновения; - гипсовая штукатурка; - грунтовка глубокого проникновения; - шпатлёвка; - грунтовка глубокого проникновения δ = 25 мм | L14: 22.5 | O14: см. раздел АИ | P14: 41.6 | Q14: - затирка; - грунтовка "Бетоноконтакт "; - шпатлёвка; - грунтовка глубокого проникновения δ = 5 мм | R14: 7.7 | S14: см. раздел АИ | T14: 9.8 | U14: Работы по черновой отделке выполнять при необходимост и выравнивания стен | AF14: 0,000 = 163,65

Sheet Table 7
A1: Ведомость отделки помещений подвала
A2: Ном ер пом еще ния | B2: Наименование помещения | C2: СТЕНЫ ИЛИ ПЕРЕГОРОДКИ | Q2: Основной тип потолка | S2: ПЛИНТУС | U2: Примечание
C3: Железобетон | E3: Кирпич | G3: Газобетон | I3: ГСП | K3: ПГП | M3: Утеплитель | O3: Финишный слой | Q3: Вид отделки | R3: Площадь, м² | S3: Вид отделки | T3: м.п.
C4: Вид отделки | D4: Площадь, м² | E4: Вид отделки | F4: Площадь, м² | G4: Вид отделки | H4: Площадь, м² | I4: Вид отделки | J4: Площадь, м² | K4: Вид отделки | L4: Площадь, м² | M4: Вид отделки | N4: Площадь, м² | O4: Вид отделки | P4: Площадь, м²
A5: 1.49 | B5: Санузел персонала | C5: - грунтовка "Бетоноконтакт"; - штукатурка цементно-песчаным раствором М100 (армированная стекловолоконной или пластиковой сеткой); - грунтовка глубокого проникновения δ = 20 мм | D5: 11.7 | E5: - | F5: 0 | G5: - | H5: 0 | K5: - грунтовка глубокого проникновения; - штукатурка цементно-песчаным раствором М100 (армированная стекловолоконной или пластиковой сеткой); - грунтовка глубокого проникновения δ = 20 мм | L5: 18.8 | M5: - | N5: 0 | O5: см. раздел АИ | P5: 30.5 | Q5: - затирка; - грунтовка "Бетоноконтакт "; - шпатлёвка; - грунтовка глубокого проникновения δ = 5 мм | R5: 3.3 | S5: см. раздел АИ | T5: 7.2 | U5: Работы по черновой отделке выполнять при необходимост и выравнивания стен
A6: 1.50 | B6: Моечная оборотной тары | C6: - грунтовка "Бетоноконтакт"; - штукатурка цементно-песчаным раствором М100 (армированная стекловолоконной или пластиковой сеткой); - грунтовка глубокого проникновения δ = 20 мм | D6: 26.2 | E6: - | F6: 0 | G6: - | H6: 0 | K6: - грунтовка глубокого проникновения; - штукатурка цементно-песчаным раствором М100 (армированная стекловолоконной или пластиковой сеткой); - грунтовка глубокого проникновения δ = 20 мм | L6: 23.8 | M6: - | N6: 0 | O6: см. раздел АИ | P6: 50 | Q6: - затирка; - грунтовка "Бетоноконтакт "; - шпатлёвка; - грунтовка глубокого проникновения δ = 5 мм | R6: 8.7 | S6: см. раздел АИ | T6: 11.9 | U6: Работы по черновой отделке выполнять при необходимост и выравнивания стен
A7: 1.51 | B7: Загрузочная | C7: - | D7: 0 | E7: - | F7: 0 | G7: - | H7: 0 | K7: - | L7: 0 | M7: - штукатурка цементно-песчаным раствором М100 по сетке δ = 20 мм | N7: 42.1 | O7: см. раздел АИ | P7: 42.1 | Q7: - затирка; - грунтовка "Бетоноконтакт "; - шпатлёвка; - грунтовка глубокого проникновения δ = 5 мм | R7: 8.3 | S7: см. раздел АИ | T7: 10.7 | U7: Работы по черновой отделке выполнять при необходимост и выравнивания стен
A8: 1.52 | B8: Тамбур | C8: - | D8: 0 | E8: - | F8: 0 | G8: - | H8: 0 | K8: - | L8: 0 | M8: - штукатурка цементно-песчаным раствором М100 по сетке δ = 20 мм | N8: 19.7 | O8: см. раздел АИ | P8: 19.7 | Q8: - затирка; - грунтовка "Бетоноконтакт "; - шпатлёвка; - грунтовка глубокого проникновения δ = 5 мм | R8: 2.2 | S8: см. раздел АИ | T8: 5.1 | U8: -
A9: 1.53 | B9: Помещение уборочного инвентаря | C9: - | D9: 0 | E9: - | F9: 0 | G9: - | H9: 0 | K9: - грунтовка глубокого проникновения; - штукатурка цементно-песчаным раствором М100 (армированная стекловолоконной или пластиковой сеткой); - грунтовка глубокого проникновения δ = 20 мм | L9: 26.5 | M9: - | N9: 0 | O9: см. раздел АИ | P9: 26.5 | Q9: - затирка; - грунтовка "Бетоноконтакт "; - шпатлёвка; - грунтовка глубокого проникновения δ = 5 мм | R9: 3.3 | S9: см. раздел АИ | T9: 6.3 | U9: Работы по черновой отделке выполнять при необходимост и выравнивания стен
A10: 1.54 | B10: Гардероб персонала с душем | C10: - грунтовка "Бетоноконтакт"; - гипсовая штукатурка; - грунтовка глубокого проникновения; - шпатлёвка; - грунтовка глубокого проникновения δ = 25 мм | D10: 8.3 | E10: - | F10: 0 | G10: - | H10: 0 | K10: - грунтовка глубокого проникновения; - гипсовая штукатурка; - грунтовка глубокого проникновения; - шпатлёвка; - грунтовка глубокого проникновения δ = 25 мм | L10: 40 | M10: - | N10: 0 | O10: см. раздел АИ | P10: 48.4 | Q10: - затирка; - грунтовка "Бетоноконтакт "; - шпатлёвка; - грунтовка глубокого проникновения δ = 5 мм | R10: 10.2 | S10: см. раздел АИ | T10: 12.8 | U10: Работы по черновой отделке выполнять при необходимост и выравнивания стен
A11: 1.55 | B11: Цех первичной обработки | C11: - грунтовка "Бетоноконтакт"; - штукатурка цементно-песчаным раствором М100 (армированная стекловолоконной или пластиковой сеткой); - грунтовка глубокого проникновения δ = 20 мм | D11: 10.6 | E11: - | F11: 0 | G11: - | H11: 0 | K11: - грунтовка глубокого проникновения; - штукатурка цементно-песчаным раствором М100 (армированная стекловолоконной или пластиковой сеткой); - грунтовка глубокого проникновения δ = 20 мм | L11: 35.3 | M11: - | N11: 0 | O11: см. раздел АИ | P11: 45.9 | Q11: - затирка; - грунтовка "Бетоноконтакт "; - шпатлёвка; - грунтовка глубокого проникновения δ = 5 мм | R11: 13.9 | S11: см. раздел АИ | T11: 13.2 | U11: Работы по черновой отделке выполнять при необходимост и выравнивания стен
A12: 1.56 | B12: Цех вторичной обработки | C12: - грунтовка "Бетоноконтакт"; - штукатурка цементно-песчаным раствором М100 (армированная стекловолоконной или пластиковой сеткой); - грунтовка глубокого проникновения δ = 20 мм | D12: 10.8 | E12: - | F12: 0 | G12: - | H12: 0 | K12: - грунтовка глубокого проникновения; - штукатурка цементно-песчаным раствором М100 (армированная стекловолоконной или пластиковой сеткой); - грунтовка глубокого проникновения δ = 20 мм | L12: 34.2 | M12: - | N12: 0 | O12: см. раздел АИ | P12: 45 | Q12: - затирка; - грунтовка "Бетоноконтакт "; - шпатлёвка; - грунтовка глубокого проникновения δ = 5 мм | R12: 12.2 | S12: см. раздел АИ | T12: 12.6 | U12: Работы по черновой отделке выполнять при необходимост и выравнивания стен
A13: 1.57 | B13: Мясо-рыбный цех | C13: - грунтовка "Бетоноконтакт"; - штукатурка цементно-песчаным раствором М100 (армированная стекловолоконной или пластиковой сеткой); - грунтовка глубокого проникновения δ = 20 мм | D13: 15.4 | E13: - | F13: 0 | G13: - | H13: 0 | K13: - грунтовка глубокого проникновения; - штукатурка цементно-песчаным раствором М100 (армированная стекловолоконной или пластиковой сеткой); - грунтовка глубокого проникновения δ = 20 мм | L13: 51.8 | M13: - | N13: 0 | O13: см. раздел АИ | P13: 67.2 | Q13: - затирка; - грунтовка "Бетоноконтакт "; - шпатлёвка; - грунтовка глубокого проникновения δ = 5 мм | R13: 21.4 | S13: см. раздел АИ | T13: 19.5 | U13: Работы по черновой отделке выполнять при необходимост и выравнивания стен
