Workbook

Sheet 9.7оргПлт
A1: Ведомость работ и используемых материалов
A2: № п.п. | B2: Наименование затрат | H2: Описание | I2: Ед. изм. | J2: Объем
A3: 1 | B3: Защитные мероприятия по защите пола от повреждений | H3: 1, 2, 3 этаж. Оргалит Защита плитки от покраски потолка | I3: м2 | J3: =C9 -> 3374.4
A5: № п. п. | B5: № эт. | C5: Площадь, м2.
A6: 1 | B6: 1 | C6: 2996.1
A7: 2 | B7: 2 | C7: 165.4
A8: 3 | B8: 3 | C8: 212.9
A9: Итог: | C9: =SUM(C6:C8) -> 3374.4

Sheet 9.5Мср
A1: Ведомость работ и используемых материалов
A2: № п.п. | B2: Наименование затрат | H2: Описание | I2: Ед. изм. | J2: Объем
A3: 1 | B3: Уборка мусора / ММП1, ММП2, обед-ый зал, подвал, спорт-зал 1, спорт-зал 2. | H3: подвал 1, 2, 3 этаж. | I3: т. | J3: =C12 -> 884
A4: 2 | B4: Талоны / контейнер / 8 м3 | H4: 504 т. | I4: шт. | J4: 63
A5: 3 | B5: Талоны / контейнер / 20 м3 | H5: 380 т. | I5: шт. | J5: 19
A7: № п. п. | B7: № эт. | C7: Площадь, т.
A8: 1 | B8: подв. | C8: 299
A9: 2 | B9: 1 | C9: 186
A10: 3 | B10: 2 | C10: 219
A11: 4 | B11: 3 | C11: 180
A12: Итог: | C12: =SUM(C8:C11) -> 884

Sheet 9.4орг
A1: Ведомость работ и используемых материалов
A2: № п.п. | B2: Наименование затрат | H2: Описание | J2: Ед. изм. | K2: Объем
A3: 1 | B3: Защитные мероприятия по защите пола от повреждений | H3: 1, 2, 3 этаж. Оргалит | J3: м2 | K3: =C9 -> 9308.8
A5: № п. п. | B5: № эт. | C5: Площадь, м2.
A6: 1 | B6: 1 | C6: 1731.1
A7: 2 | B7: 2 | C7: 4073.1
A8: 3 | B8: 3 | C8: 3504.6
A9: Итог: | C9: =SUM(C6:C8) -> 9308.8

Sheet 9.2плтк
A1: Ведомость работ
A2: № п.п. | B2: Наименование | E2: Описание | F2: Ед. изм. | G2: Объем, м2
A3: 1 | B3: Устройство покрытия пола из керамогранитной плитки | E3: 1-2 этаж Керамогранит, Kerama Marazzi Про Матрикс DD602020R серый светлый, 600х600х9мм | F3: м2 | G3: =C16 -> 120.35
A4: 2 | B4: Устройство покрытия пола из ПВХ плитки | E4: 1 этаж 500х500х2,55 мм Виниловая ПВХ плитка, Forbo Effekta Professional 8061 T Natural Concrete PRO, | F4: м2 | G4: =C19 -> 7.15
A5: 3 | B5: Устройство плинтуса из керамогранитной плитки | E5: 1-2 этаж Плинтус из керамогранита, Kerama Marazzi Про Матрикс DD602020R/6BT, 600х95(h)х9мм, серый светлый, затирка Ceresit CE 33, 04 серебристо-серый, НГ | F5: м2 | G5: =D16 -> 122.15
A6: 4 | B6: Установка напольного плинтуса ПВХ | E6: 1 этаж Гибкий плинтус ПВХ, Dollken WL 100 Серый 146, высота 100мм, В1, Д2, Т2, РП1, Г1 (КМ2) | F6: м2 | G6: =D19 -> 9.9
A8: Керамогранитная плитка и плинтус
A9: № п.п | B9: пом. | C9: объем, м2. | D9: плинтус, пог.м.
A10: 1 | B10: 1.052 | C10: 15.2 | D10: 14.8
A11: 2 | B11: 1.031 | C11: 5.75 | D11: =2.25+5.7 -> 7.95
A12: 3 | B12: 1.032 | C12: 32.7 | D12: 35.2
A13: 4 | B13: 1.072 | C13: 21.4 | D13: 19.8
A14: 5 | B14: 2.007 | C14: =23.6+1 -> 24.6 | D14: 24.1
A15: 6 | B15: 2.057 | C15: =19.7+1 -> 20.7 | D15: 20.3
A16: Итог: | C16: =SUM(C10:C15) -> 120.35 | D16: =SUM(D10:D15) -> 122.15
A18: ПВХ плитка и плинтус
A19: 1 | B19: 1.088 | C19: 7.15 | D19: 9.9

Sheet 9.1шлфк
A1: Ведомость работ и используемых материалов
A2: № п.п. | B2: Наименование затрат | D2: Описание | E2: Ед. изм. | F2: Объем
A3: 1 | B3: Площадь шлифования наливного пола | D3: 1, 2, 3 этаж. | E3: м2 | F3: =B9 -> 9482.4
A5: № этажа | B5: Площадь, м2.
A6: 1 | B6: =1581.9+140.9 -> 1722.8
A7: 2 | B7: 4179.3
A8: 3 | B8: 3580.3
A9: Итог: | B9: =SUM(B6:B8) -> 9482.4

Sheet 8.1_орг
A1: Ведомость работ и используемых материалов
A2: № п.п. | B2: Наименование затрат | H2: Описание | J2: Ед. изм. | K2: Объем
A3: 1 | B3: Защитные мероприятия по защите пола от повреждений | H3: 1, 2, 3 этаж. Оргалит | J3: м2 | K3: =C32+G36+K29 -> 1235.3
A5: № п. п. | B5: № пом. | C5: Площадь, м2. | E5: № п. п. | F5: № пом. | G5: Площадь, м2. | I5: № п. п. | J5: № пом. | K5: Площадь, м2.
A6: 1 | B6: 1.052 | C6: 25.1 | E6: 27 | F6: 2.008 | G6: 13.4 | I6: 57 | J6: 3.006 | K6: 13.4
A7: 2 | B7: 1.012 | C7: 12.5 | E7: 28 | F7: 2.009 | G7: 10.26 | I7: 58 | J7: 3.007 | K7: 10.1
A8: 3 | B8: 1.014 | C8: 5.4 | E8: 29 | F8: 2.010 | G8: 23.4 | I8: 59 | J8: 3.008 | K8: 4.55
A9: 4 | B9: 1.013 | C9: 21 | E9: 30 | F9: 2.011 | G9: 4.67 | I9: 60 | J9: 3.009 | K9: 23.1
A10: 5 | B10: 1.025 | C10: 5.8 | E10: 31 | F10: 2.018 | G10: 19.24 | I10: 61 | J10: 3.015 | K10: 19.26
A11: 6 | B11: 1.026 | C11: 32.2 | E11: 32 | F11: 2.019 | G11: 19.83 | I11: 62 | J11: 3.016 | K11: 19.83
A12: 7 | B12: 1.031 | C12: 12.2 | E12: 33 | F12: 2.020 | G12: 10.25 | I12: 63 | J12: 3.017 | K12: 10.25
A13: 8 | B13: 1.033 | C13: 7.5 | E13: 34 | F13: 2.021 | G13: 5.44 | I13: 64 | J13: 3.018 | K13: 5.48
A14: 9 | B14: 1.018 | C14: 8.2 | E14: 35 | F14: 2.059 | G14: 4.55 | I14: 65 | J14: 3.029 | K14: 4.38
A15: 10 | B15: 1.019 | C15: 8.9 | E15: 36 | F15: 2.070 | G15: 15.17 | I15: 66 | J15: 3.067 | K15: 15.17
A16: 11 | B16: 1.020 | C16: 15.2 | E16: 37 | F16: 2.023 | G16: 10.79 | I16: 67 | J16: 3.020 | K16: 10.4
A17: 12 | B17: 1.021 | C17: 14 | E17: 38 | F17: 2.024 | G17: 10.34 | I17: 68 | J17: 3.024 | K17: 10.72
... A28: 23 | B28: 1.107 | C28: 37.4 | E28: 49 | F28: 2.055 | G28: 9.07 | I28: 79 | J28: 3.052 | K28: 11.03
A29: 24 | B29: 1.108 | C29: 13.1 | E29: 50 | F29: 2.026 | G29: 16.56 | J29: Итог: | K29: =SUM(K6:K28) -> 280.47
A30: 25 | B30: 1.109 | C30: 16.9 | E30: 51 | F30: 2.027 | G30: 8.12
A31: 26 | B31: 1.046 | C31: 104 | E31: 52 | F31: 2.031 | G31: 8.89
B32: Итог: | C32: =SUM(C6:C31) -> 592.28 | E32: 53 | F32: 2.032 | G32: 9.69
E33: 54 | F33: 2.065 | G33: 4.19
E34: 55 | F34: 2.028 | G34: 19.78
E35: 56 | F35: 2.029 | G35: 8.25
F36: Итог: | G36: =SUM(G6:G35) -> 362.55

Sheet 7-Кер
A1: Ведомость работ и используемых материалов
A2: № п.п. | B2: Наименование затрат | E2: Описание | G2: Ед. изм. | H2: Объем
A3: 1 | B3: Утепление полов керамзитом | E3: 2 и 3 этаж 47,6*0,15+16*0,615+18,5*0,375 | G3: м2 | H3: =E13 -> 23.9025
A5: № пом. | B5: Тип пола | C5: Площадь, м2. | D5: Высота, м | E5: Объем, м3
A6: 2.007 | B6: П-18.1 | C6: 18.5 | D6: 0.375 | E6: =C6*D6 -> 6.9375
A7: 2.057 | B7: П-18 | C7: 16 | D7: 0.615 | E7: =C7*D7 -> 9.84
A8: 2.061 | B8: П-16 | C8: 9.5 | D8: 0.15 | E8: =C8*D8 -> 1.425
A9: 2.061 | B9: П-16 | C9: 9.3 | D9: 0.15 | E9: =C9*D9 -> 1.395
A10: 3.038 | B10: П-16 | C10: 10.3 | D10: 0.15 | E10: =C10*D10 -> 1.545
A11: 3.050 | B11: П-16 | C11: 9.2 | D11: 0.15 | E11: =C11*D11 -> 1.38
A12: 3.058 | B12: П-16 | C12: 9.2 | D12: 0.15 | E12: =C12*D12 -> 1.38
D13: Итог: | E13: =SUM(E6:E12) -> 23.9025

Sheet 6.3_ост
A1: Ведомость работ и используемых материалов
A2: № п.п. | B2: Наименование затрат | H2: Описание | J2: Ед. изм. | K2: Объем
A3: 1 | B3: Устройство покрытия пола СКБ с затиркой и укрытием ДВП / из керамогранитной плитки от 0,2м2/шт | H3: 2 этаж. КР-1 | J3: м2 | K3: =C28 -> 331
A4: 2 | B4: Устройство покрытия пола СКБ с затиркой и укрытием ДВП / из керамогранитной плитки до 0,2м2/шт | H4: 2 этаж. КР-4 | J4: м2 | K4: =G12 -> 25.7
A6: № пом. | B6: Тип пола | C6: Площадь, м2. | E6: № пом. | F6: Тип пола | G6: Площадь, м2.
A7: 2.008 | B7: КР-1 | C7: 17.3 | E7: 2.011 | F7: КР-4 | G7: 4.8
A8: 2.009 | B8: КР-1 | C8: 10.5 | E8: 2.035 | F8: КР-4 | G8: 7.5
A9: 2.010 | B9: КР-1 | C9: 22.3 | E9: 2.052 | F9: КР-4 | G9: 4.5
A10: 2.018 | B10: КР-1 | C10: 19 | E10: 2.059 | F10: КР-4 | G10: 4.6
A11: 2.019 | B11: КР-1 | C11: 30.2 | E11: 2.065 | F11: КР-4 | G11: 4.3
A12: 2.020 | B12: КР-1 | C12: 10.1 | F12: Итог: | G12: =SUM(G7:G11) -> 25.7
A13: 2.021 | B13: КР-1 | C13: 5.6
A14: 2.022 | B14: КР-1 | C14: 3.1
A15: 2.023 | B15: КР-1 | C15: 15.8
A16: 2.024 | B16: КР-1 | C16: 15.8
A17: 2.033 | B17: КР-1 | C17: 33.1
A18: 2.034 | B18: КР-1 | C18: 8.2
A19: 2.043 | B19: КР-1 | C19: 10.9
A20: 2.044 | B20: КР-1 | C20: 21.1
A21: 2.051 | B21: КР-1 | C21: 21.2
A22: 2.053 | B22: КР-1 | C22: 5.6
A23: 2.054 | B23: КР-1 | C23: 25.4
A24: 2.055 | B24: КР-1 | C24: 10.5
... A27: 2.070 | B27: КР-1 | C27: 15.7
B28: Итог: | C28: =SUM(C7:C27) -> 331
A31: Ведомость работ и используемых материалов
A32: № п.п. | B32: Наименование затрат | H32: Описание | J32: Ед. изм. | K32: Объем
A33: 1 | B33: Устройство покрытия пола СКБ с затиркой и укрытием ДВП / из керамогранитной плитки от 0,2м2/шт | H33: 3 этаж. КР-1 | J33: м2 | K33: =C60 -> 339.1
A34: 2 | B34: Устройство покрытия пола СКБ с затиркой и укрытием ДВП / из керамогранитной плитки до 0,2м2/шт | H34: 3 этаж. КР-4 | J34: м2 | K34: =G44 -> 54
A36: № пом. | B36: Тип пола | C36: Площадь, м2. | E36: № пом. | F36: Тип пола | G36: Площадь, м2.
A37: 3.006 | B37: КР-1 | C37: 13.2 | E37: 3.008 | F37: КР-4 | G37: 4.8
A38: 3.007 | B38: КР-1 | C38: 9.6 | E38: 3.026 | F38: КР-4 | G38: 7.5
A39: 3.009 | B39: КР-1 | C39: 21.9 | E39: 3.029 | F39: КР-4 | G39: 4.5
A40: 3.015 | B40: КР-1 | C40: 19.6 | E40: 3.044 | F40: КР-4 | G40: 4.5
A41: 3.016 | B41: КР-1 | C41: 19.7 | E41: 3.060 | F41: КР-4 | G41: 7.7
A42: 3.017 | B42: КР-1 | C42: 10.5 | E42: 3.061 | F42: КР-4 | G42: 13
A43: 3.018 | B43: КР-1 | C43: 5.6 | E43: 3.062 | F43: КР-4 | G43: 12
A44: 3.020 | B44: КР-1 | C44: 10.2 | F44: Итог: | G44: =SUM(G37:G43) -> 54
A45: 3.024 | B45: КР-1 | C45: 10.6
A46: 3.025 | B46: КР-1 | C46: 8.2
...

Sheet 5.3_нал_пл
A1: Ведомость работ и используемых материалов
A2: № п.п. | B2: Наименование затрат | H2: Описание | J2: Ед. изм. | K2: Объем
A3: 1 | B3: Устройство наливных полов с огрунтовкой поверхности и проклейкой демпферной лентой / толщ. до 10 мм | H3: 2 этаж | J3: м2 | K3: =G10+C41 -> 4271.5
A5: № пом. | B5: Тип пола | C5: Площадь, м2. | E5: № пом. | F5: Тип пола | G5: Площадь, м2.
A6: 2.001 | B6: П-13 | C6: 80.6 | E6: 2.007 | F6: П-18.1 | G6: 24.5
A7: 2.002 | B7: П-13 | C7: 64.8 | E7: 2.037 | F7: П-14 | G7: 543.1
A8: 2.003 | B8: П-13 | C8: 218.7 | E8: 2.038 | F8: П-14 | G8: 66.2
A9: 2.004 | B9: П-13 | C9: 45.7 | E9: 2.057 | F9: П-18 | G9: 20.3
A10: 2.005 | B10: П-13 | C10: 18.9 | F10: Итог: | G10: =SUM(G6:G9) -> 654.1
A11: 2.012 | B11: П-13 | C11: 63.3
A12: 2.013 | B12: П-13 | C12: 64.3
A13: 2.014 | B13: П-13 | C13: 64.9
A14: 2.015 | B14: П-13 | C14: 63.5
A15: 2.016 | B15: П-13 | C15: 64
A16: 2.017 | B16: П-13 | C16: 237
A17: 2.022 | B17: П-13 | C17: 478.6
A18: 2.025 | B18: П-13 | C18: 28.5
A19: 2.030 | B19: П-13 | C19: 42.7
A20: 2.031 | B20: П-13 | C20: 12.6
A21: 2.032 | B21: П-13 | C21: 10.2
A22: 2.036 | B22: П-13 | C22: 89
... A40: 2.071 | B40: П-13 | C40: 129.6
B41: Итог: | C41: =SUM(C6:C40) -> 3617.4
A43: Ведомость работ и используемых материалов
A44: № п.п. | B44: Наименование затрат | H44: Описание | J44: Ед. изм. | K44: Объем
A45: 1 | B45: Устройство наливных полов с огрунтовкой поверхности и проклейкой демпферной лентой / толщ. до 10 мм | H45: 3 этаж | J45: м2 | K45: =C65+G66 -> 3659.1
A47: № пом. | B47: Тип пола | C47: Площадь, м2. | E47: № пом. | F47: Тип пола | G47: Площадь, м2.
A48: 3.001 | B48: П-13 | C48: 82.2 | E48: 3.031 | F48: П-13 | G48: 64.5
A49: 3.002 | B49: П-13 | C49: 63.6 | E49: 3.032 | F49: П-13 | G49: 64.4
A50: 3.003 | B50: П-13 | C50: 85.1 | E50: 3.035 | F50: П-13 | G50: 63.6
A51: 3.004 | B51: П-13 | C51: 96.7 | E51: 3.036 | F51: П-13 | G51: 63
A52: 3.005 | B52: П-13 | C52: 19 | E52: 3.037 | F52: П-13 | G52: 118.8
A53: 3.010 | B53: П-13 | C53: 103.5 | E53: 3.038 | F53: П-13 | G53: 198.2
A54: 3.011 | B54: П-13 | C54: 90.3 | E54: 3.039 | F54: П-13 | G54: 20.6
A55: 3.012 | B55: П-13 | C55: 237 | E55: 3.040 | F55: П-13 | G55: 122.4
A56: 3.013 | B56: П-13 | C56: 63.3 | E56: 3.041 | F56: П-13 | G56: 167.2
A57: 3.014 | B57: П-13 | C57: 64 | E57: 3.048 | F57: П-13 | G57: 96.8
A58: 3.019 | B58: П-13 | C58: 319.7 | E58: 3.049 | F58: П-13 | G58: 54.7
A59: 3.021 | B59: П-13 | C59: 24.7 | E59: 3.050 | F59: П-13 | G59: 147.1
... A64: 3.030 | B64: П-13 | C64: 63.9 | E64: 3.063 | F64: П-13 | G64: 72.9
...

Sheet 4.3_ост
A1: Ведомость работ и используемых материалов
A2: № п.п. | B2: Наименование затрат | H2: Описание | J2: Ед. изм. | K2: Объем
A3: 1 | B3: Устройство обмазочной гидроизоляции с проклеиванием швов армированной лентой из стекловолокна / в 2 слоя | H3: 2 этаж Тип П-15 | J3: м2 | K3: =C26 -> 218
A4: 2 | B4: Устройство тепло-звукоизоляции полов / Рулонный материал / в 1 слой | H4: 2 этаж (2.033, 2.037, 2.038) | J4: м2 | K4: =G10 -> 630.4
A6: № пом. | B6: Тип пола | C6: Площадь, м2. | E6: № пом. | F6: Тип пола | G6: Площадь, м2.
A7: 2.010 | B7: П-15 | C7: 23.5 | E7: 2.033 | F7: П-14 | G7: 32.1
A8: 2.011 | B8: П-15 | C8: 4.8 | E8: 2.037 | F8: П-14 | G8: 535.1
A9: 2.018 | B9: П-15 | C9: 19.5 | E9: 2.038 | F9: П-14 | G9: 63.2
A10: 2.020 | B10: П-15 | C10: 10.3 | F10: Итог: | G10: =SUM(G7:G9) -> 630.4
A11: 2.021 | B11: П-15 | C11: 5.6
A12: 2.026 | B12: П-15 | C12: 16.6
A13: 2.027 | B13: П-15 | C13: 8.2
A14: 2.028 | B14: П-15 | C14: 19.8
A15: 2.029 | B15: П-15 | C15: 8.3
A16: 2.031 | B16: П-15 | C16: 8.9
A17: 2.032 | B17: П-15 | C17: 9.8
A18: 2.034 | B18: П-15 | C18: 8.2
A19: 2.035 | B19: П-15 | C19: 7.6
A20: 2.051 | B20: П-15 | C20: 22.2
A21: 2.052 | B21: П-15 | C21: 4.5
A22: 2.053 | B22: П-15 | C22: 5.8
... A25: 2.065 | B25: П-15 | C25: 4.3
B26: Итог: | C26: =SUM(C7:C25) -> 218
A28: Ведомость работ и используемых материалов
A29: № п.п. | B29: Наименование затрат | H29: Описание | J29: Ед. изм. | K29: Объем
A30: 1 | B30: Устройство обмазочной гидроизоляции с проклеиванием швов армированной лентой из стекловолокна / в 2 слоя | H30: 3 этаж Тип П-15 | J30: м2 | K30: =C50 -> 182.1
A31: 2 | B31: Устройство тепло-звукоизоляции полов / Рулонный материал / в 1 слой | H31: 3 этаж (3.053, 3.059) | J31: м2 | K31: =G36 -> 242.3
A33: № пом. | B33: Тип пола | C33: Площадь, м2. | E33: № пом. | F33: Тип пола | G33: Площадь, м2.
A34: 3.008 | B34: П-15 | C34: 4.8 | E34: 3.053 | F34: П-14 | G34: 202.4
A35: 3.009 | B35: П-15 | C35: 23.6 | E35: 3.059 | F35: П-14 | G35: 39.9
A36: 3.015 | B36: П-15 | C36: 19.6 | F36: Итог: | G36: =SUM(G34:G35) -> 242.3
A37: 3.017 | B37: П-15 | C37: 10.5
A38: 3.018 | B38: П-15 | C38: 5.6
A39: 3.025 | B39: П-15 | C39: 8.2
A40: 3.026 | B40: П-15 | C40: 7.6
A41: 3.029 | B41: П-15 | C41: 4.5
A42: 3.042 | B42: П-15 | C42: 22.4
A43: 3.043 | B43: П-15 | C43: 22.4
A44: 3.044 | B44: П-15 | C44: 4.5
A45: 3.045 | B45: П-15 | C45: 5.8
...

Sheet КП
A1: Номер п/п | B1: Код узла ИСР | C1: Наименование затрат | D1: Комментарий по ИСР | E1: Комментарий подрядчика | F1: Ед. изм. | G1: Коэф.расхода | H1: Кол-во БО | I1: Общее кол-во | J1: Осталось | K1: 1.1-Пл | L1: 2.1-Пл | M1: 3.1-Пл | N1: 4-Пл | O1: 4.1-Из | P1: 4.2-Из | Q1: 5.1-Нал | R1: 5.2-Нал | S1: 6.1-Пл | T1: 6.2-Пл
A2: 1.1.1.1.1.1 | B2: 6.3.1.5.1 | C2: Полы
A3: 1.1.1.1.1.1.1 | B3: 6.3.1.5.1.1 | C3: Подготовка полов под финишное покрытие
A4: 1.1.1.1.1.1.1.1 | B4: 6.3.1.5.1.1.3.1 | C4: Устройство наливных полов с огрунтовкой поверхности и проклейкой демпферной лентой / толщ. до 10 мм | D4: Вне зависимости от способа выполнения работ механизировано или вручную. | E4: 2 этаж | F4: м2 | G4: 1 | I4: 0
A5: 1.1.1.1.1.1.1.1.1 | C5: Наливной пол_ / Унифицированный по ПИК-СТАНДАРТ | F5: кг | G5: 1.6 | I5: 0
A6: 1.1.1.1.1.1.1.1.2 | C6: Грунтовка универсальный ЛАСТИМИН_ / УНКОНТ ЛЮКС LP51 А | F6: кг | G6: 0.255 | I6: 0
A7: 1.1.1.1.1.1.1.2 | B7: 6.3.1.5.1.1.3.1 | C7: Устройство наливных полов с огрунтовкой поверхности и проклейкой демпферной лентой / толщ. до 10 мм | D7: Вне зависимости от способа выполнения работ механизировано или вручную. | E7: 3 этаж | F7: м2 | G7: 1 | I7: 0
A8: 1.1.1.1.1.1.1.2.1 | C8: Грунтовка универсальный ЛАСТИМИН_ / УНКОНТ ЛЮКС LP51 А | F8: кг | G8: 0.255 | I8: 0
A9: 1.1.1.1.1.1.1.2.2 | C9: Лента кромочная демпферная_/8*100мм/20м | F9: пог. м | G9: 1 | I9: 0
A10: 1.1.1.1.1.1.1.2.3 | C10: Наливной пол_ / Унифицированный по ПИК-СТАНДАРТ | F10: кг | G10: 1.6 | I10: 0
A11: 1.1.1.1.1.1.1.3 | B11: 6.3.1.5.1.1.3.1 | C11: Устройство наливных полов с огрунтовкой поверхности и проклейкой демпферной лентой / толщ. до 10 мм | D11: Вне зависимости от способа выполнения работ механизировано или вручную. | E11: 2 этаж | F11: м2 | G11: 1 | I11: 4263.2 | J11: =Таблица1[[#This Row],[Общее кол-во]]- SUM(Таблица1[[#This Row],[1.1-Пл]:[5.2-Нал]]) -> 3453 | Q11: ='5.1'!K3 -> 810.2
A12: 1.1.1.1.1.1.1.3.1 | C12: Наливной пол_ / Унифицированный по ПИК-СТАНДАРТ | F12: кг | G12: 1.6 | I12: 68211.2
A13: 1.1.1.1.1.1.1.3.2 | C13: Грунтовка универсальный ЛАСТИМИН_ / УНКОНТ ЛЮКС LP51 А | F13: кг | G13: 0.255 | I13: 1087.116
A14: 1.1.1.1.1.1.1.4 | B14: 6.3.1.5.1.1.3.1 | C14: Устройство наливных полов с огрунтовкой поверхности и проклейкой демпферной лентой / толщ. до 10 мм | D14: Вне зависимости от способа выполнения работ механизировано или вручную. | E14: 3 этаж | F14: м2 | G14: 1 | I14: 3740.2 | J14: =Таблица1[[#This Row],[Общее кол-во]]- SUM(Таблица1[[#This Row],[1.1-Пл]:[5.2-Нал]]) -> 2840.7 | R14: ='5.2'!K3 -> 899.5
A15: 1.1.1.1.1.1.1.4.1 | C15: Грунтовка универсальный ЛАСТИМИН_ / УНКОНТ ЛЮКС LP51 А | F15: кг | G15: 0.255 | I15: 953.751
A16: 1.1.1.1.1.1.1.4.2 | C16: Наливной пол_ / Унифицированный по ПИК-СТАНДАРТ | F16: кг | G16: 1.6 | I16: 59843.2
A17: 1.1.1.1.1.1.1.5 | B17: 6.3.1.5.1.1.7.1 | C17: Замоноличивание мест прохождения стояков труб | E17: Замоноличивание проходок инж. сетей в перекрытиях 2-3 этаж, 3 этаж-кровля. | F17: м3 | G17: 1 | I17: 0
A18: 1.1.1.1.1.1.1.5.1 | C18: Смесь цементно-песчаная М200 | F18: кг | G18: 1700 | I18: 0
A19: 1.1.1.1.1.1.1.6 | B19: 6.3.1.5.1.1.7.1 | C19: Замоноличивание мест прохождения стояков труб | E19: Замоноличивание проходок инж. сетей в перекрытиях 2-3 этаж, 3 этаж-кровля. | F19: м3 | G19: 1 | I19: 2.88
A20: 1.1.1.1.1.1.1.6.1 | C20: Смесь цементно-песчаная М200 | F20: кг | G20: 1700 | I20: 4896
A21: 1.1.1.1.1.1.1.7 | B21: 6.3.1.5.1.1.11.3 | C21: Устройство стяжки СКБ / армированная сеткой от 41 мм до 60мм | E21: 2 этаж. Стяжка полусухая армированная, толщиной 50 мм. Тип: П18, П-18.1 | F21: м2 | G21: 1 | I21: 0
A22: 1.1.1.1.1.1.1.7.1 | C22: Фиксатор арматуры Звездочка_/15/4-16 | F22: шт | G22: 8 | I22: 0
A23: 1.1.1.1.1.1.1.7.2 | C23: Фиброволокно_/7-12мм | F23: кг | G23: 0.001 | I23: 0
A24: 1.1.1.1.1.1.1.7.3 | C24: Сетка эл/св_/100*100*5 | F24: м2 | G24: 1.1 | I24: 0
A25: 1.1.1.1.1.1.1.7.4 | C25: Портландцемент_/М500 | F25: кг | G25: 0.32 | I25: 0
A26: 1.1.1.1.1.1.1.7.5 | C26: Песок_ / речной / мытый | F26: м3 | G26: 0.001 | I26: 0
A27: 1.1.1.1.1.1.1.7.6 | C27: Лента кромочная демпферная_/8*100мм/20м | F27: пог. м | G27: 1 | I27: 0
A28: 1.1.1.1.1.1.1.7.7 | C28: Грунтовка универсальный ЛАСТИМИН_ / УНКОНТ ЛЮКС LP51 А | F28: кг | G28: 0.2 | I28: 0
A29: 1.1.1.1.1.1.1.8 | B29: 6.3.1.5.1.1.11.3 | C29: Устройство стяжки СКБ / армированная сеткой от 41 мм до 60мм | E29: 2 этаж. Стяжка полусухая армированная, толщиной 60 мм | F29: м2 | G29: 1 | I29: 0
A30: 1.1.1.1.1.1.1.8.1 | C30: Грунтовка универсальный ЛАСТИМИН_ / УНКОНТ ЛЮКС LP51 А | F30: кг | G30: 0.2 | I30: 0
A31: 1.1.1.1.1.1.1.8.2 | C31: Лента кромочная демпферная_/8*100мм/20м | F31: пог. м | G31: 1 | I31: 0
A32: 1.1.1.1.1.1.1.8.3 | C32: Песок_ / речной / мытый | F32: м3 | G32: 0.001 | I32: 0
A33: 1.1.1.1.1.1.1.8.4 | C33: Портландцемент_/М500 | F33: кг | G33: 0.32 | I33: 0
A34: 1.1.1.1.1.1.1.8.5 | C34: Сетка эл/св_/100*100*5 | F34: м2 | G34: 1.1 | I34: 0
A35: 1.1.1.1.1.1.1.8.6 | C35: Фиброволокно_/7-12мм | F35: кг | G35: 0.001 | I35: 0
A36: 1.1.1.1.1.1.1.8.7 | C36: Фиксатор арматуры Звездочка_/15/4-16 | F36: шт | G36: 8 | I36: 0
A37: 1.1.1.1.1.1.1.9 | B37: 6.3.1.5.1.1.11.3 | C37: Устройство стяжки СКБ / армированная сеткой от 41 мм до 60 мм | E37: 3 этаж. Стяжка толщиной 60 мм. Тип: П-14 | F37: м2 | G37: 1 | I37: 0
A38: 1.1.1.1.1.1.1.9.1 | C38: Фиксатор арматуры Звездочка_/15/4-16 | F38: шт | G38: 8 | I38: 0
A39: 1.1.1.1.1.1.1.9.2 | C39: Смесь цементно-песчаная сухая_/М150 | F39: кг | G39: 1.8 | I39: 0
A40: 1.1.1.1.1.1.1.9.3 | C40: Сетка эл/св_/100*100*5 | F40: м2 | G40: 1.1 | I40: 0
...

Sheet Пом
A1: Этаж | B1: Тип | C1: Тип2 | D1: № пом. | E1: Марка | F1: Объем
A2: 2 | B2: класс | C2: П-13 | D2: 2.001 | E2: Л-1 | F2: 80.6
A3: 2 | B3: класс | C3: П-13 | D3: 2.002 | E3: Л-1 | F3: 64.8
A4: 2 | B4: коридор | C4: П-13 | D4: 2.003 | E4: Л-1 | F4: 218.7
A5: 2 | B5: класс | C5: П-13 | D5: 2.004 | E5: Л-1 | F5: 45.7
A6: 2 | B6: класс | C6: П-13 | D6: 2.005 | E6: Л-1 | F6: 18.9
A7: 2 | B7: верхн ряды | C7: П-12 | D7: 2.006
A8: 2 | B8: склад | C8: П-18.1 | D8: 2.007 | E8: Л-1 | F8: =23.7 -> 23.7
A9: 2 | B9: склад | C9: П-18.1 | D9: 2.007 | E9: КР-3 | F9: 0.8
A10: 2 | B10: лестница | C10: П-12 | D10: 2.008 | E10: КР-1 | F10: 17.6
A11: 2 | B11: лестница | C11: П-12 | D11: 2.008 | E11: КР-2 | F11: 25.1
A12: 2 | B12: лестница | C12: П-12 | D12: 2.008 | E12: КР-3 | F12: 6.5
A13: 2 | B13: лифт | C13: П-12 | D13: 2.009 | E13: КР-1 | F13: 10.5
A14: 2 | B14: санузел | C14: П-15 | D14: 2.010 | E14: КР-1 | F14: 23.5
A15: 2 | B15: инвентарь | C15: П-15 | D15: 2.011 | E15: КР-4 | F15: 4.8
A16: 2 | B16: класс | C16: П-13 | D16: 2.012 | E16: Л-1 | F16: 63.3
A17: 2 | B17: класс | C17: П-13 | D17: 2.013 | E17: Л-1 | F17: 64.3
A18: 2 | B18: класс | C18: П-13 | D18: 2.014 | E18: Л-1 | F18: 64.9
A19: 2 | B19: класс | C19: П-13 | D19: 2.015 | E19: Л-1 | F19: 63.5
A20: 2 | B20: класс | C20: П-13 | D20: 2.016 | E20: Л-1 | F20: 64
... A37: 2 | B37: коридор | C37: П-13 | D37: 2.025 | E37: Л-1 | F37: 28.5
A38: 2 | B38: санузел | C38: П-15 | D38: 2.026 | E38: КР-6 | F38: =16.6 -> 16.6
A39: 2 | B39: санузел | C39: П-15 | D39: 2.027 | E39: КР-6 | F39: 8.2
A40: 2 | B40: санузел | C40: П-15 | D40: 2.028 | E40: КР-6 | F40: 19.8
A41: 2 | B41: санузел | C41: П-15 | D41: 2.029 | E41: КР-6 | F41: 8.3
A42: 2 | B42: коридор | C42: П-13 | D42: 2.030 | E42: Л-1 | F42: 42.7
A43: 2 | B43: коридор | C43: П-13 | D43: 2.031 | E43: Л-1 | F43: 12.6
A44: 2 | B44: санузел | C44: П-15 | D44: 2.031 | E44: КР-6 | F44: 8.9
A45: 2 | B45: коридор | C45: П-13 | D45: 2.032 | E45: Л-1 | F45: =20-F46 -> 10.2
A46: 2 | B46: санузел | C46: П-15 | D46: 2.032 | E46: КР-6 | F46: 9.8
A47: 2 | B47: склад | C47: П-14 | D47: 2.033 | E47: КР-1 | F47: 33.1
A48: 2 | B48: санузел | C48: П-15 | D48: 2.034 | E48: КР-1 | F48: 8.2
A49: 2 | B49: инвентарь | C49: П-15 | D49: 2.035 | E49: КР-4 | F49: 7.6
A50: 2 | B50: класс | C50: П-13 | D50: 2.036 | E50: Л-1 | F50: 89
A51: 2 | B51: спортзал | C51: П-14 | D51: 2.037 | E51: Л-4 | F51: 543.1
A52: 2 | B52: класс | C52: П-14 | D52: 2.038 | E52: Л-1 | F52: 66.2
A53: 2 | B53: класс | C53: П-13 | D53: 2.039 | E53: Л-1 | F53: 62.5
A54: 2 | B54: класс | C54: П-13 | D54: 2.040 | E54: Л-1 | F54: 64.5
A55: 2 | B55: класс | C55: П-13 | D55: 2.041 | E55: Л-1 | F55: 64.2
A56: 2 | B56: коридор | C56: П-13 | D56: 2.042 | E56: Л-1 | F56: 100.5
...

Sheet Лист2
A1: Этаж | B1: Тип | C1: Тип2 | D1: № пом. | E1: Марка | F1: Объем
A2: 2 | B2: класс | C2: П-13 | D2: 2.001 | E2: Л-1 | F2: 80.6
A3: 2 | B3: класс | C3: П-13 | D3: 2.002 | E3: Л-1 | F3: 64.8
A4: 2 | B4: коридор | C4: П-13 | D4: 2.003 | E4: Л-1 | F4: 218.7
A5: 2 | B5: класс | C5: П-13 | D5: 2.004 | E5: Л-1 | F5: 45.7
A6: 2 | B6: класс | C6: П-13 | D6: 2.005 | E6: Л-1 | F6: 18.9
A7: 2 | B7: склад | C7: П-18.1 | D7: 2.007 | E7: Л-1 | F7: 24.5
A8: 2 | B8: класс | C8: П-13 | D8: 2.012 | E8: Л-1 | F8: 63.3
A9: 2 | B9: класс | C9: П-13 | D9: 2.013 | E9: Л-1 | F9: 64.3
A10: 2 | B10: класс | C10: П-13 | D10: 2.014 | E10: Л-1 | F10: 64.9
A11: 2 | B11: класс | C11: П-13 | D11: 2.015 | E11: Л-1 | F11: 63.5
A12: 2 | B12: класс | C12: П-13 | D12: 2.016 | E12: Л-1 | F12: 64
A13: 2 | B13: коридор | C13: П-13 | D13: 2.017 | E13: Л-1 | F13: 237
... A34: 2 | B34: класс | C34: П-13 | D34: 2.061 | E34: Л-1 | F34: 168.9
A35: 2 | B35: подиум | C35: П-16 | D35: 2.061 | E35: Л-1 | F35: Н/Н
A36: 2 | B36: коридор | C36: П-13 | D36: 2.062 | E36: Л-1 | F36: 216
A37: 2 | B37: класс | C37: П-13 | D37: 2.064 | E37: Л-1 | F37: 66.3
A38: 2 | B38: класс | C38: П-13 | D38: 2.066 | E38: Л-1 | F38: 93.1
A39: 2 | B39: коридор | C39: П-13 | D39: 2.067 | E39: Л-1 | F39: 91.8
A40: 2 | B40: учительская | C40: П-13 | D40: 2.068 | E40: Л-1 | F40: 114
A41: 2 | B41: коридор | C41: П-13 | D41: 2.071 | E41: Л-1 | F41: 129.6

Sheet Типы
B1: П-12 | C1: 323.4
B2: П-13 | C2: 7057
B3: П-14 | C3: 689.5
B4: П-15 | C4: 413.5
B5: П-16 | C5: 58.9
B6: П-18 | C6: 16
B7: П-18.1 | C7: 18.5
F8: 02 Этаж | G8: 03 Этаж
D9: П-12 | E9: КР-1 | F9: 331.7 | G9: 339.3
D10: П-15 | E10: КР-2 | F10: 109.2 | G10: 0.9
D11: П-14, п-13 | E11: КР-3 | F11: 36.8 | G11: 0
D12: Лестницы | E12: КР3.1 | F12: 12.9 | G12: 0
E13: КР-4 | F13: 25.8 | G13: 54.1
E14: КР-6 | F14: 72.9 | G14: 0
E15: Л-1 | F15: 3723.5 | G15: 3665.1
E16: Л-4 | F16: 543.1 | G16: 0

Sheet 5.1
A1: Ведомость работ и используемых материалов
A2: № п.п. | B2: Наименование затрат | H2: Описание | J2: Ед. изм. | K2: Объем
A3: 1 | B3: Устройство наливных полов с огрунтовкой поверхности и проклейкой демпферной лентой / толщ. до 10 мм | H3: 2 этаж | J3: м2 | K3: =C18 -> 810.2
A4: № пом. | B4: Тип пола | C4: Площадь, м2.
A5: 2.001 | B5: П-13 | C5: 80.6
A6: 2.002 | B6: П-13 | C6: 64.8
A7: 2.004 | B7: П-13 | C7: 45.7
A8: 2.005 | B8: П-13 | C8: 18.9
A9: 2.012 | B9: П-13 | C9: 63.3
A10: 2.013 | B10: П-13 | C10: 64.3
A11: 2.014 | B11: П-13 | C11: 64.9
A12: 2.015 | B12: П-13 | C12: 63.5
A13: 2.016 | B13: П-13 | C13: 64
A14: 2.036 | B14: П-13 | C14: 89
A15: 2.039 | B15: П-13 | C15: 62.5
A16: 2.040 | B16: П-13 | C16: 64.5
A17: 2.041 | B17: П-13 | C17: 64.2
B18: Итог: | C18: =SUM(C5:C17) -> 810.2

Sheet 5.2
A1: Ведомость работ и используемых материалов
A2: № п.п. | B2: Наименование затрат | H2: Описание | J2: Ед. изм. | K2: Объем
A3: 1 | B3: Устройство наливных полов с огрунтовкой поверхности и проклейкой демпферной лентой / толщ. до 10 мм | H3: 3 этаж | J3: м2 | K3: =C17 -> 899.5
A4: № пом. | B4: Тип пола | C4: Площадь, м2.
A5: 3.001 | B5: П-13 | C5: 82.2
A6: 3.002 | B6: П-13 | C6: 63.6
A7: 3.003 | B7: П-13 | C7: 85.1
A8: 3.010 | B8: П-13 | C8: 103.5
A9: 3.011 | B9: П-13 | C9: 90.3
A10: 3.013 | B10: П-13 | C10: 63.3
A11: 3.014 | B11: П-13 | C11: 64
A12: 3.027 | B12: П-13 | C12: 90.9
A13: 3.028 | B13: П-13 | C13: 63.8
A14: 3.030 | B14: П-13 | C14: 63.9
A15: 3.031 | B15: П-13 | C15: 64.5
A16: 3.032 | B16: П-13 | C16: 64.4
B17: Итог: | C17: =SUM(C5:C16) -> 899.5

Sheet 6.1
A1: Ведомость работ и используемых материалов
A2: № п.п. | B2: Наименование затрат | H2: Описание | J2: Ед. изм. | K2: Объем
A3: 1 | B3: Устройство покрытия пола СКБ с затиркой и укрытием ДВП / из керамогранитной плитки от 0,2м2/шт | H3: 2 этаж. КР-1 | J3: м2 | K3: =C14 -> 91.4
A4: 2 | B4: Устройство покрытия пола СКБ с затиркой и укрытием ДВП / из керамогранитной плитки до 0,2м2/шт | H4: 2 этаж. КР-4 | J4: м2 | K4: =G10 -> 16.9
A6: № пом. | B6: Тип пола | C6: Площадь, м2. | E6: № пом. | F6: Тип пола | G6: Площадь, м2.
A7: 2.009 | B7: КР-1 | C7: 10.5 | E7: 2.011 | F7: КР-4 | G7: 4.8
A8: 2.010 | B8: КР-1 | C8: 22.3 | E8: 2.035 | F8: КР-4 | G8: 7.5
A9: 2.018 | B9: КР-1 | C9: 19 | E9: 2.059 | F9: КР-4 | G9: 4.6
A10: 2.020 | B10: КР-1 | C10: 10.1 | F10: Итог: | G10: =SUM(G7:G9) -> 16.9
A11: 2.021 | B11: КР-1 | C11: 5.6
A12: 2.034 | B12: КР-1 | C12: 8.2
A13: 2.070 | B13: КР-1 | C13: 15.7
B14: Итог: | C14: =SUM(C7:C13) -> 91.4

Sheet 6.2
A1: Ведомость работ и используемых материалов
A2: № п.п. | B2: Наименование затрат | H2: Описание | J2: Ед. изм. | K2: Объем
A3: 1 | B3: Устройство покрытия пола СКБ с затиркой и укрытием ДВП / из керамогранитной плитки от 0,2м2/шт | H3: 3 этаж. КР-1 | J3: м2 | K3: =C14 -> 91.1
A4: 2 | B4: Устройство покрытия пола СКБ с затиркой и укрытием ДВП / из керамогранитной плитки до 0,2м2/шт | H4: 3 этаж. КР-4 | J4: м2 | K4: =G10 -> 16.8
A6: № пом. | B6: Тип пола | C6: Площадь, м2. | E6: № пом. | F6: Тип пола | G6: Площадь, м2.
A7: 3.007 | B7: КР-1 | C7: 9.6 | E7: 3.008 | F7: КР-4 | G7: 4.8
A8: 3.009 | B8: КР-1 | C8: 21.9 | E8: 3.026 | F8: КР-4 | G8: 7.5
A9: 3.015 | B9: КР-1 | C9: 19.6 | E9: 3.029 | F9: КР-4 | G9: 4.5
A10: 3.017 | B10: КР-1 | C10: 10.5 | F10: Итог: | G10: =SUM(G7:G9) -> 16.8
A11: 3.018 | B11: КР-1 | C11: 5.6
A12: 3.025 | B12: КР-1 | C12: 8.2
A13: 3.067 | B13: КР-1 | C13: 15.7
B14: Итог: | C14: =SUM(C7:C13) -> 91.1

Sheet 4.1
A1: Ведомость работ и используемых материалов
A2: № п.п. | B2: Наименование затрат | H2: Описание | J2: Ед. изм. | K2: Объем
A3: 1 | B3: Устройство обмазочной гидроизоляции с проклеиванием швов армированной лентой из стекловолокна / в 2 слоя | H3: 2 этаж Тип П-15 | J3: м2 | K3: =C13 -> 84.2
A4: № пом. | B4: Тип пола | C4: Площадь, м2.
A5: 2.010 | B5: П-15 | C5: 23.5
A6: 2.011 | B6: П-15 | C6: 4.8
A7: 2.018 | B7: П-15 | C7: 19.5
A8: 2.020 | B8: П-15 | C8: 10.3
A9: 2.021 | B9: П-15 | C9: 5.6
A10: 2.034 | B10: П-15 | C10: 8.2
A11: 2.035 | B11: П-15 | C11: 7.6
A12: 2.059 | B12: П-15 | C12: 4.7
B13: Итог: | C13: =SUM(C5:C12) -> 84.2

Sheet 4.2
A1: Ведомость работ и используемых материалов
A2: № п.п. | B2: Наименование затрат | H2: Описание | J2: Ед. изм. | K2: Объем
A3: 1 | B3: Устройство обмазочной гидроизоляции с проклеиванием швов армированной лентой из стекловолокна / в 2 слоя | H3: 3 этаж Тип П-15 | J3: м2 | K3: =C13 -> 84.4
A4: № пом. | B4: Тип пола | C4: Площадь, м2.
A5: 3.008 | B5: П-15 | C5: 4.8
A6: 3.009 | B6: П-15 | C6: 23.6
A7: 3.015 | B7: П-15 | C7: 19.6
A8: 3.017 | B8: П-15 | C8: 10.5
A9: 3.018 | B9: П-15 | C9: 5.6
A10: 3.025 | B10: П-15 | C10: 8.2
A11: 3.026 | B11: П-15 | C11: 7.6
A12: 3.029 | B12: П-15 | C12: 4.5
B13: Итог: | C13: =SUM(C5:C12) -> 84.4
