Workbook

Sheet КП
A1: Номер п/п | B1: Код узла ИСР | C1: Наименование затрат | D1: Комментарий по ИСР | E1: Описание | F1: Ед. изм. | G1: Коэф.расхода | H1: Кол-во БО | I1: Общее кол-во
A2: 1.1.3.1.1.3 | B2: 6.3.1.5.3 | C2: Потолки
A3: 1.1.3.1.1.3.1 | B3: 6.3.1.5.3.1 | C3: Черновые работы по поверхности потолков
A4: 1.1.3.1.1.3.1.1 | B4: 6.3.1.5.3.1.4.1 | C4: Простая штукатурка потолка сухими смесями с предварительной огрунтовкой поверхности / толщ. до 6,5 мм | E4: Подвал, 1-4 этажи. Выравнивание цементными смесями до 5 мм с грунтом глубокого проникновения. Тип: ЧНП-2 | F4: м2 | G4: 1 | I4: 1171.2
A5: 1.1.3.1.1.3.1.1.1 | C5: Штукатурка цементная | F5: кг | G5: 1.3 | I5: 7612.8
A6: 1.1.3.1.1.3.1.1.2 | C6: Грунтовка универсальный ЛАСТИМИН_ / УНКОНТ ЛЮКС LP51 А | F6: кг | G6: 0.15 | I6: 175.68
A7: 1.1.3.1.1.3.1.2 | B7: 6.3.1.5.3.1.4.1 | C7: Простая штукатурка потолка сухими смесями с предварительной огрунтовкой поверхности / толщ. до 6,5 мм | E7: Подвал, 1-4 этажи. Выравнивание гипсовыми смесями до 5 мм с бетоноконтактом. Тип: ЧНП-5 | F7: м2 | G7: 1 | I7: 7010.2
A8: 1.1.3.1.1.3.1.2.1 | C8: Грунтовка БЕТОН-КОНТАКТ_/ | F8: кг | G8: 0.25 | I8: 1752.55
A9: 1.1.3.1.1.3.1.2.2 | C9: Штукатурка гипсовая_ / Унифицированная по ПИК-СТАНДАРТ, 30кг | F9: кг | G9: 1 | I9: 35051
A10: 1.1.3.1.1.3.1.3 | B10: 6.3.1.5.3.1.6.4 | C10: Подготовка поверхности СКБ / стен / ГКЛ, ПГП / 2мм | E10: 1-4 этажи. Шпаклевка гипсовая базовая т.2 мм. Тип: ЧНП-3, ЧНП-6, ЧНП-7 | F10: м2 | G10: 1 | I10: 827.7
A11: 1.1.3.1.1.3.1.3.1 | C11: Шпатлевка гипсовая_ / белая / Унифицированная по ПИК-СТАНДАРТ, 30кг | F11: кг | G11: 1.5 | I11: 1241.55
A12: 1.1.3.1.1.3.1.3.2 | C12: Грунтовка универсальный ЛАСТИМИН_ / LP-51 А | F12: кг | G12: 0.15 | I12: 124.155
A13: 1.1.3.1.1.3.1.4 | B13: 6.3.1.5.3.1.6.4 | C13: Подготовка поверхности СКБ / стен / ГКЛ, ПГП / 2мм | E13: 1-4 этажи. Шпаклевка гипсовая базовая т.2 мм. Тип: ЧНП-3, ЧНП-6, ЧНП-7 | F13: м2 | G13: 1 | I13: 827.7
A14: 1.1.3.1.1.3.1.4.1 | C14: Грунтовка универсальный ЛАСТИМИН_ / LP-51 А | F14: кг | G14: 0.15 | I14: 124.155
A15: 1.1.3.1.1.3.1.4.2 | C15: Шпатлевка гипсовая_ / белая / Унифицированная по ПИК-СТАНДАРТ, 30кг | F15: кг | G15: 1.5 | I15: 1241.55
A16: 1.1.3.1.1.3.1.5 | B16: 6.3.1.5.3.1.6.5 | C16: Подготовка поверхности СКБ / стен / по штукатурке / 2мм | E16: Подвал, 1-4 этажи. Шпаклевка цементная базовая т.2 мм. Тип: ЧНП-2 | F16: м2 | G16: 1 | I16: 1171.2
A17: 1.1.3.1.1.3.1.5.1 | C17: Шпатлевка цементная | F17: кг | G17: 2 | I17: 2342.4
A18: 1.1.3.1.1.3.1.5.2 | C18: Грунтовка универсальный ЛАСТИМИН_ / LP-51 А | F18: кг | G18: 0.15 | I18: 175.68
A19: 1.1.3.1.1.3.1.6 | B19: 6.3.1.5.3.1.6.5 | C19: Подготовка поверхности СКБ / стен / по штукатурке / 2мм | E19: Подвал, 1-4 этажи. Шпаклевка цементная финишная т.2 мм. Тип: ЧНП-2 | F19: м2 | G19: 1 | I19: 1171.2
A20: 1.1.3.1.1.3.1.6.1 | C20: Грунтовка универсальный ЛАСТИМИН_ / LP-51 А | F20: кг | G20: 0.15 | I20: 175.68
A21: 1.1.3.1.1.3.1.6.2 | C21: Шпатлевка цементная | F21: кг | G21: 2 | I21: 2342.4
A22: 1.1.3.1.1.3.1.7 | B22: 6.3.1.5.3.1.6.6 | C22: Подготовка поверхности СКБ / потолка / по штукатурке / 2мм | E22: Подвал, 1-4 этажи. Шпаклевка гипсовая базовая т.2 мм. Тип: ЧНП-5 | F22: м2 | G22: 1 | I22: 7010.2
A23: 1.1.3.1.1.3.1.7.1 | C23: Шпатлевка гипсовая_ / белая / Унифицированная по ПИК-СТАНДАРТ, 30кг (BIM) | F23: кг | G23: 1.8 | I23: 12618.36
A24: 1.1.3.1.1.3.1.7.2 | C24: Грунтовка универсальный ЛАСТИМИН_ / УНКОНТ ЛЮКС LP51 А | F24: кг | G24: 0.15 | I24: 1051.53
A25: 1.1.3.1.1.3.1.8 | B25: 6.3.1.5.3.1.6.6 | C25: Подготовка поверхности СКБ / потолка / по штукатурке / 2мм | E25: Подвал, 1-4 этажи. Шпаклевка гипсовая финишная т.2 мм. Тип: ЧНП-5 | F25: м2 | G25: 1 | I25: 7010.2
A26: 1.1.3.1.1.3.1.8.1 | C26: Грунтовка универсальный ЛАСТИМИН_ / УНКОНТ ЛЮКС LP51 А | F26: кг | G26: 0.15 | I26: 1051.53
A27: 1.1.3.1.1.3.1.8.2 | C27: Шпатлевка гипсовая_ / белая / Унифицированная по ПИК-СТАНДАРТ, 30кг (BIM) | F27: кг | G27: 1.8 | I27: 12618.36
A28: 1.1.3.1.1.3.2 | B28: 6.3.1.5.3.2 | C28: Чистовые работы по поверхности потолков
A29: 1.1.3.1.1.3.2.1 | B29: 6.3.1.5.3.2.3.2 | C29: Лакокрасочные работы СКБ / окраска потолков / в 2 слоя | E29: Тип: ПТ-1. Матовая водно-дисперсионная моющаяся краска ANTEGA СТРОИТЕЛЬ, Класс ПБ: KM1, Износостойкость: 2 класс истирания | F29: м2 | G29: 1 | I29: 47.78
A30: 1.1.3.1.1.3.2.1.1 | C30: Краска негорючая моющаяся Protect Decor_ / RAL 9003 | F30: кг | G30: 0.3 | I30: 14.334
A31: 1.1.3.1.1.3.2.1.2 | C31: Грунтовка универсальный ЛАСТИМИН_ / LP-51 А | F31: кг | G31: 0.15 | I31: 7.167
A32: 1.1.3.1.1.3.2.2 | B32: 6.3.1.5.3.2.3.2 | C32: Лакокрасочные работы СКБ / окраска потолков / в 2 слоя | E32: Тип: ПТ-1.2. Матовая водно-дисперсионная моющаяся краска ANTEGA СТРОИТЕЛЬ, Класс ПБ: KM1, Износостойкость: 2 класс истирания | F32: м2 | G32: 1 | I32: 727.11
A33: 1.1.3.1.1.3.2.2.1 | C33: Грунтовка универсальный ЛАСТИМИН_ / LP-51 А | F33: кг | G33: 0.15 | I33: 109.067
A34: 1.1.3.1.1.3.2.2.2 | C34: Краска негорючая моющаяся Protect Decor_ / RAL 9003 | F34: кг | G34: 0.3 | I34: 218.133
A35: 1.1.3.1.1.3.2.3 | B35: 6.3.1.5.3.2.3.2 | C35: Лакокрасочные работы СКБ / окраска потолков / в 2 слоя | E35: Тип: ПТ-2. Матовая водно-дисперсионная моющаяся краска ANTEGA СТРОИТЕЛЬ, Класс ПБ: KM1, Износостойкость: 2 класс истирания, Цвет: RAL 7044/серый шелк | F35: м2 | G35: 1 | I35: 503.14
A36: 1.1.3.1.1.3.2.3.1 | C36: Краска негорючая моющаяся Protect Decor_ / RAL 9003 | F36: кг | G36: 0.3 | I36: 150.942
A37: 1.1.3.1.1.3.2.3.2 | C37: Грунтовка универсальный ЛАСТИМИН_ / LP-51 А | F37: кг | G37: 0.15 | I37: 75.471
A38: 1.1.3.1.1.3.2.4 | B38: 6.3.1.5.3.2.3.2 | C38: Лакокрасочные работы СКБ / окраска потолков / в 2 слоя | E38: Тип: ПТ-2.1. Матовая водно-дисперсионная моющаяся краска ANTEGA СТРОИТЕЛЬ, Класс ПБ: НГ, Износостойкость: 1 класс истирания, Цвет: | F38: м2 | G38: 1 | I38: 2411.18
A39: 1.1.3.1.1.3.2.4.1 | C39: Грунтовка универсальный ЛАСТИМИН_ / LP-51 А | F39: кг | G39: 0.15 | I39: 361.677
A40: 1.1.3.1.1.3.2.4.2 | C40: Краска негорючая моющаяся Protect Decor_ / RAL 9003 | F40: кг | G40: 0.3 | I40: 723.354
...

Sheet Расчет
B1: В конце РД рев F есть ведомость по каждому помещению
B3: Рев F
C4: 1 | D4: 1 | E4: 2 | F4: 2 | G4: 3 | H4: 3 | I4: 4 | Q4: Экспликация помещений 4-го этажа
B5: ЧНП | C5: 1 | D5: 2.3 | E5: 1 | F5: 2.3 | G5: 1 | H5: 2.3 | I5: 3 | Q5: Номер пом. | R5: Площадь, м²
B6: 2 | C6: 28.6 | D6: 309.5 | E6: 44.4 | F6: 31.5 | G6: 34.4 | H6: 10 | I6: 62.8 | J6: =SUM(C6:I6) -> 521.2 | L6: ЧНП-2 | M6: 1171.2 | Q6: 4001 | R6: 68.8 | S6: ЧНП-4
B7: 4 | C7: 404.1 | D7: 501.6 | E7: 377 | F7: 695.5 | G7: 502.3 | H7: 528.1 | I7: 69.5 | J7: =SUM(C7:I7) -> 3078.1 | Q7: 4002 | R7: 26.9 | S7: ЧНП-5
B8: 5 | C8: 418.1 | D8: 1554.8 | E8: 334.2 | F8: 1730.3 | G8: 335.1 | H8: 2263.2 | I8: 327.6 | J8: =SUM(C8:I8) -> 6963.3 | L8: ЧНП-5 | M8: 7010.2 | Q8: 4003 | R8: 43.9 | S8: ЧНП-4
B9: 6 | C9: 0 | D9: 37.6 | E9: 0 | F9: 0 | G9: 0 | H9: 0 | I9: 0 | J9: =SUM(C9:I9) -> 37.6 | Q9: 4004 | R9: 54.8 | S9: ЧНП-4
B10: 7 | C10: 15.4 | D10: 71.3 | E10: 15.5 | F10: 23.9 | G10: 15.5 | H10: 23.9 | I10: 0 | J10: =SUM(C10:I10) -> 165.5 | Q10: 4005 | R10: 52 | S10: ЧНП-4
B11: 8 | C11: 44.1 | D11: 191.4 | E11: 51.1 | F11: 200.1 | G11: 50.9 | H11: 53.6 | I11: 46.9 | J11: =SUM(C11:I11) -> 638.1 | L11: ЧНП-3, ЧНП-6, ЧНП-7 | M11: 827.7 | Q11: 4006 | R11: 56.6 | S11: ЧНП-4
Q12: 4007 | R12: 19.2 | S12: ЧНП-4
Q13: 4008 | R13: 95.5 | S13: ЧНП-4
Q14: 4009 | R14: 30.6 | S14: ЧНП-2
Q15: 4010 | R15: 241.6 | S15: ЧНП-5
Q16: 4.010а | R16: 72.4 | S16: ЧНП-5
Q17: 4011 | R17: 14 | S17: ЧНП-8
Q18: 4012 | R18: 4.2 | S18: ЧНП-8
B19: ЧНП-8 | J19: ззеленый | Q19: 4013 | R19: 6.7 | S19: ЧНП-8
B20: 1.009 | C20: 18.5 | H20: 4.011 | I20: 14 | Q20: 4014 | R20: 9.8 | S20: ЧНП-5
B21: 1.012 | C21: 19 | H21: 4.012 | I21: 4.2 | Q21: 4015 | R21: 16.2 | S21: ЧНП-8
B22: 1.014 | C22: 7.1 | H22: 4.013 | I22: 6.7 | Q22: 4016 | R22: 4.9 | S22: ЧНП-2
H23: 4.015 | I23: 16.2 | Q23: 4017 | R23: 4.8 | S23: ЧНП-8
H24: 4.017 | I24: 4.8 | Q24: 4018 | R24: 32 | S24: ЧНП-2
Q25: 855
B26: ЧНП-5 | J26: фиолетовое
B27: 1.007 | C27: 98.5 | D27: 2.014 | E27: 130.4 | F27: 16 | G27: 130.7 | H27: 4.010а | I27: 72.4 | K27: Красное не забрал | Q27: 1.2 | R27: 243.2 | S27: =SUMIF($S$6:$S$24,Q27,$R$6:$R$24) -> 0 | T27: =R27-S27 -> 243.2
B28: 1.015 | C28: 117.6 | D28: 2.015 | E28: 200.9 | F28: 17 | G28: 201.3 | H28: 4.010 | I28: 241.6 | Q28: 4 | R28: 69.5 | S28: =SUMIF($S$6:$S$24,Q28,$R$6:$R$24) -> 0 | T28: =R28-S28 -> 69.5
B29: 1.016 | C29: 203.1 | Q29: ЧНП-2 | R29: 62.8 | S29: =SUMIF($S$6:$S$24,Q29,$R$6:$R$24) -> 67.5 | T29: =R29-S29 -> -4.7
Q30: ЧНП-4 | R30: 69.5 | S30: =SUMIF($S$6:$S$24,Q30,$R$6:$R$24) -> 390.8 | T30: =R30-S30 -> -321.3
Q31: ЧНП-5 | R31: 327.6 | S31: =SUMIF($S$6:$S$24,Q31,$R$6:$R$24) -> 350.7 | T31: =R31-S31 -> -23.1
Q32: ЧНП-8 | R32: 46.9 | S32: =SUMIF($S$6:$S$24,Q32,$R$6:$R$24) -> 45.9 | T32: =R32-S32 -> 1
B37: Рев E
C38: 1 | D38: 1 | E38: 2 | F38: 2 | G38: 3 | H38: 3 | I38: 4
B39: ЧНП | C39: 1 | D39: 2.3 | E39: 1 | F39: 2.3 | G39: 1 | H39: 2.3 | I39: 3 | J39: Сумма
B40: 1.1 | C40: 121.3 | D40: 689.9 | E40: 31.4 | F40: 153 | G40: 28.3 | H40: 760.7 | I40: 57.8 | J40: =SUM(C40:I40) -> 1842.4
B41: 1.2 | C41: 319.6 | D41: 863.6 | E41: 334.2 | F41: 798.9 | G41: 335.1 | H41: 741 | I41: 556.9 | J41: =SUM(C41:I41) -> 3949.3
B42: 1.3 | C42: 0 | D42: 0 | E42: 0 | F42: 501.8 | G42: 0 | H42: 0 | I42: 0 | J42: =SUM(C42:I42) -> 501.8
B43: 1.4 | C43: 0 | D43: 98.2 | E43: 0 | F43: 486.3 | G43: 0 | H43: 1232 | I43: 0 | J43: =SUM(C43:I43) -> 1816.5
B44: 1.5 | C44: 0 | D44: 0 | E44: 0 | F44: 186.1 | G44: 0 | H44: 0 | I44: 0 | J44: =SUM(C44:I44) -> 186.1
B45: 2 | C45: 0 | D45: 61.3 | E45: 0 | F45: 0 | G45: 0 | H45: 0 | I45: 0 | J45: =SUM(C45:I45) -> 61.3
...

Sheet 2.3в3
A1: Номер п/п | B1: Наименование работ | C1: Описание | D1: Ед. изм. | E1: Общее кол-во
A2: 1 | B2: Лакокрасочные работы СКБ / окраска потолков / в 2 слоя | C2: Тип: ПТ-2.15. | D2: м2 | E2: =D9 -> 128.68
A3: 2 | B3: Лакокрасочные работы СКБ / окраска потолков / в 2 слоя | C3: Тип: ПТ-2.1. | D3: м2 | E3: =D13 -> 15.43
A5: Номер п/п | B5: Описание | C5: Ед. изм. | D5: Общее кол-во
A6: 1 | B6: 1.011 | C6: м2 | D6: 15.32
A7: 2 | B7: 1.007 | C7: м2 | D7: 97.9
A8: 3 | B8: 2.010 | C8: м2 | D8: 15.46
B9: Итог: | C9: м2 | D9: =SUM(D6:D8) -> 128.68
A11: Номер п/п | B11: Описание | C11: Ед. изм. | D11: Общее кол-во
A12: 3 | B12: 3.012 | C12: м2 | D12: 15.43
B13: Итог: | C13: м2 | D13: =SUM(D12:D12) -> 15.43

Sheet 1.4ШпЧНП7_3вып
A1: Номер п/п | B1: Наименование работ | C1: Описание | D1: Ед. изм. | E1: Общее кол-во
A2: 1 | B2: Подготовка поверхности СКБ / стен / ГКЛ, ПГП / 2мм | C2: 1-3 этажи. Шпаклевка гипсовая базовая т.2 мм. Тип: ЧНП-7 | D2: м2 | E2: =E9 -> 46.21
A3: 2 | B3: Подготовка поверхности СКБ / стен / ГКЛ, ПГП / 2мм | C3: 1-3 этажи. Шпаклевка гипсовая финишная т.2 мм. Тип: ЧНП-7 | D3: м2 | E3: =E2 -> 46.21
A5: Номер п/п | B5: Пом | C5: Тип | D5: Ед. изм. | E5: Общее кол-во
A6: 1 | B6: 1.011 | C6: ЧНП-7 | D6: м2 | E6: 15.32
A7: 2 | B7: 2.010 | C7: ЧНП-7 | D7: м2 | E7: 15.46
A8: 3 | B8: 3.012 | C8: ЧНП-7 | D8: м2 | E8: 15.43
C9: Итог: | D9: м2 | E9: =SUM(E6:E8) -> 46.21

Sheet 1.3ШпЧНП5_3вып
A1: Номер п/п | B1: Наименование работ | C1: Описание | D1: Ед. изм. | E1: Общее кол-во
A2: 1 | B2: Подготовка поверхности СКБ / потолка / по штукатурке / 2мм | C2: 1 этаж. Шпаклевка гипсовая базовая т.2 мм. Тип: ЧНП-5 | D2: м2 | E2: =E9 -> 285.2
A3: 2 | B3: Подготовка поверхности СКБ / потолка / по штукатурке / 2мм | C3: 1 этаж. Шпаклевка гипсовая финишная т.2 мм. Тип: ЧНП-5 | D3: м2 | E3: =E2 -> 285.2
A5: Номер п/п | B5: Пом | C5: Тип | D5: Ед. изм. | E5: Общее кол-во
A6: 1 | B6: 1.007 | C6: ЧНП-5 | D6: м2 | E6: 97.9
A7: 2 | B7: 1.025 | C7: ЧНП-5 | D7: м2 | E7: 162.9
A8: 3 | B8: 1.059 | C8: ЧНП-5 | D8: м2 | E8: 24.4
C9: Итог: | D9: м2 | E9: =SUM(E6:E8) -> 285.2

Sheet 0.3-Шт3вып
A1: Номер п/п | B1: Наименование работ | D1: Описание | E1: Ед. изм. | F1: Общее кол-во
A2: 1 | B2: Простая штукатурка потолка сухими смесями с предварительной огрунтовкой поверхности / толщ. до 6,5 мм | D2: 1 этаж. Тип: ЧНП-5 | E2: м2 | F2: =E8 -> 285.2
A4: Номер п/п | B4: Пом | C4: Тип | D4: Ед. изм. | E4: Общее кол-во
A5: 1 | B5: 1.007 | C5: ЧНП-5 | D5: м2 | E5: 97.9
A6: 2 | B6: 1.025 | C6: ЧНП-5 | D6: м2 | E6: 162.9
A7: 3 | B7: 1.059 | C7: ЧНП-5 | D7: м2 | E7: 24.4
B8: Итог: | D8: м2 | E8: =SUM(E5:E7) -> 285.2

Sheet 2.2-Пт
A1: Номер п/п | B1: Наименование работ | C1: Описание | D1: Ед. изм. | E1: Общее кол-во
A2: 1 | B2: Лакокрасочные работы СКБ / окраска потолков / в 2 слоя | C2: Тип: ПТ-2.15. Матовая водно-дисперсионная моющаяся краска ANTEGA СТРОИТЕЛЬ, Класс ПБ: НГ, Износостойкость: 1 класс истирания, Цвет: RAL 7016 | D2: м2 | E2: =D8 -> 891.64
A4: Номер п/п | B4: Описание | C4: Ед. изм. | D4: Общее кол-во
A5: 1 | B5: ='1.2-Пт'!B6 -> 1.094, 1.94а | C5: м2 | D5: ='1.2-Пт'!D6 -> 294.16
A6: 2 | B6: ='1.2-Пт'!B7 -> 2.047, 2.047а, 2.047б | C6: м2 | D6: ='1.2-Пт'!D7 -> 285.6
A7: 3 | B7: ='1.2-Пт'!B8 -> 3.047, 3.047а, 3.047б | C7: м2 | D7: ='1.2-Пт'!D8 -> 311.88
B8: Итог: | C8: м2 | D8: =SUM(D5:D7) -> 891.64

Sheet 2.1-Пт
A1: Номер п/п | B1: Наименование работ | C1: Описание | D1: Ед. изм. | E1: Общее кол-во
A2: 1 | B2: Лакокрасочные работы СКБ / окраска потолков / в 2 слоя | C2: Тип: ПТ-2.15. Матовая водно-дисперсионная моющаяся краска ANTEGA СТРОИТЕЛЬ, Класс ПБ: НГ, Износостойкость: 1 класс истирания, Цвет: RAL 7016 | D2: м2 | E2: =D11 -> 979.8
A4: Номер п/п | B4: Описание | C4: Ед. изм. | D4: Общее кол-во
A5: 1 | B5: 1.015 | C5: м2 | D5: 116.4
A6: 2 | B6: 1.016 | C6: м2 | D6: 202.5
A7: 3 | B7: 2.014 | C7: м2 | D7: 129.8
A8: 4 | B8: 2.015 | C8: м2 | D8: 200.1
A9: 5 | B9: 3.016 | C9: м2 | D9: 130.3
A10: 6 | B10: 3.017 | C10: м2 | D10: 200.7
B11: Итог: | C11: м2 | D11: =SUM(D5:D10) -> 979.8

Sheet 1.2-Пт
A1: Номер п/п | B1: Наименование работ | C1: Описание | D1: Ед. изм. | E1: Общее кол-во
A2: 1 | B2: Подготовка поверхности СКБ / потолка / по штукатурке / 2мм | C2: 1-3 этажи. Шпаклевка гипсовая базовая т.2 мм. Тип: ЧНП-5 | D2: м2 | E2: =D9 -> 891.64
A3: 2 | B3: Подготовка поверхности СКБ / потолка / по штукатурке / 2мм | C3: 1-3 этажи. Шпаклевка гипсовая финишная т.2 мм. Тип: ЧНП-5 | D3: м2 | E3: =E2 -> 891.64
A5: Номер п/п | B5: Описание | C5: Ед. изм. | D5: Общее кол-во
A6: 1 | B6: 1.094, 1.94а | C6: м2 | D6: 294.16
A7: 2 | B7: 2.047, 2.047а, 2.047б | C7: м2 | D7: 285.6
A8: 3 | B8: 3.047, 3.047а, 3.047б | C8: м2 | D8: 311.88
B9: Итог: | C9: м2 | D9: =SUM(D6:D8) -> 891.64

Sheet 1.1-Пт
A1: Номер п/п | B1: Наименование работ | C1: Описание | D1: Ед. изм. | E1: Общее кол-во
A2: 1 | B2: Подготовка поверхности СКБ / потолка / по штукатурке / 2мм | C2: 1-3 этажи. Шпаклевка гипсовая базовая т.2 мм. Тип: ЧНП-5 | D2: м2 | E2: =D12 -> 979.8
A3: 2 | B3: Подготовка поверхности СКБ / потолка / по штукатурке / 2мм | C3: 1-3 этажи. Шпаклевка гипсовая финишная т.2 мм. Тип: ЧНП-5 | D3: м2 | E3: =E2 -> 979.8
A5: Номер п/п | B5: Описание | C5: Ед. изм. | D5: Общее кол-во
A6: 1 | B6: 1.015 | C6: м2 | D6: 116.4
A7: 2 | B7: 1.016 | C7: м2 | D7: 202.5
A8: 3 | B8: 2.014 | C8: м2 | D8: 129.8
A9: 4 | B9: 2.015 | C9: м2 | D9: 200.1
A10: 5 | B10: 3.016 | C10: м2 | D10: 130.3
A11: 6 | B11: 3.017 | C11: м2 | D11: 200.7
B12: Итог: | C12: м2 | D12: =SUM(D6:D11) -> 979.8

Sheet 0.2-Шт
A1: Номер п/п | B1: Наименование работ | C1: Описание | D1: Ед. изм. | E1: Общее кол-во
A2: 1 | B2: Простая штукатурка потолка сухими смесями с предварительной огрунтовкой поверхности / толщ. до 6,5 мм | C2: 1-3 этажи. Тип: ЧНП-5 | D2: м2 | E2: =D8 -> 891.64
A4: Номер п/п | B4: Описание | C4: Ед. изм. | D4: Общее кол-во
A5: 1 | B5: ='1.2-Пт'!B6 -> 1.094, 1.94а | C5: м2 | D5: ='1.2-Пт'!D6 -> 294.16
A6: 2 | B6: ='1.2-Пт'!B7 -> 2.047, 2.047а, 2.047б | C6: м2 | D6: ='1.2-Пт'!D7 -> 285.6
A7: 3 | B7: ='1.2-Пт'!B8 -> 3.047, 3.047а, 3.047б | C7: м2 | D7: ='1.2-Пт'!D8 -> 311.88
B8: Итог: | C8: м2 | D8: =SUM(D5:D7) -> 891.64

Sheet 0.1-Шт
A1: Номер п/п | B1: Наименование работ | C1: Описание | D1: Ед. изм. | E1: Общее кол-во
A2: 1 | B2: Простая штукатурка потолка сухими смесями с предварительной огрунтовкой поверхности / толщ. до 6,5 мм | C2: 1-3 этажи. Тип: ЧНП-5 | D2: м2 | E2: =D11 -> 979.8
A4: Номер п/п | B4: Описание | C4: Ед. изм. | D4: Общее кол-во
A5: 1 | B5: 1.015 | C5: м2 | D5: 116.4
A6: 2 | B6: 1.016 | C6: м2 | D6: 202.5
A7: 3 | B7: 2.014 | C7: м2 | D7: 129.8
A8: 4 | B8: 2.015 | C8: м2 | D8: 200.1
A9: 5 | B9: 3.016 | C9: м2 | D9: 130.3
A10: 6 | B10: 3.017 | C10: м2 | D10: 200.7
B11: Итог: | C11: м2 | D11: =SUM(D5:D10) -> 979.8
