Workbook

Sheet 10.4ЛкХам
A1: Ведомость работ
A2: № п.п. | B2: Наименование затрат | C2: Описание | D2: Ед. изм. | E2: Объем
A3: 1 | B3: Установка люков / в стене | C3: 1-3 эт. лючок "Хаммер". | D3: шт | E3: 60
A5: № эт | B5: Кол-во люков, шт
A6: 1 | B6: 20
A7: 2 | B7: 18
A8: 3 | B8: 22
A9: Итог: | B9: =SUM(B6:B8) -> 60

Sheet 10.3отк
A1: Ведомость работ
A2: № п.п. | B2: Наименование затрат | G2: Описание | J2: Ед. изм. | K2: Объем
A3: 1 | B3: Устройство откосов из ГКЛ на клеевом составе / в 2 слой | G3: 1-3 эт. Откосы, витражи файерборд | J3: м2 | K3: ='10.3отк1'!F60 -> 195.415
A4: 2 | B4: Устройство откосов из ГКЛ на металлическом каркасе / в 2 слоя | G4: 1-3 эт. Откосы, двери витражнык файерборд | J4: м2 | K4: ='10.3отк3'!G19 -> 106.10325
A5: 3 | B5: Устройство откосов из ГКЛ на металлическом каркасе / в 2 слоя | G5: 1-3 эт. Откосы, окна. Файерборд | J5: м2 | K5: ='10.3отк2'!J16 -> 930.67225
A6: 4 | B6: Устройство откосов из ГКЛ на металлическом каркасе / в 2 слоя | G6: 1-3 эт. Откосы, двери файерборд | J6: м2 | K6: ='10.3отк4'!G18 -> 288.321
A7: 5 | B7: Устройство тепло-звукоизоляции оконных откосов в 1 слой (ТЕХНОФАС ОПТИМА 50 мм) | G7: 1-3 этаж. Оконные откосы | J7: м2 | K7: 930.67225
A8: 6 | B8: Выравнивание поверхностей откосов толщ. до 5 мм с предварительной огрунтовкой поверхности | G8: 1-3 эт. Шпаклевка базовая | J8: м2 | K8: =SUM(K3:K6) -> 1520.5115
A9: 7 | B9: Выравнивание поверхностей откосов толщ. до 5 мм с предварительной огрунтовкой поверхности ( | G9: 1-3 эт. Шпаклевка финишная | J9: м2 | K9: =K8 -> 1520.5115
A10: 8 | B10: Лакокрасочные работы СКБ / окраска откосов / в 2 слоя | G10: 1-3 эт. | J10: м2 | K10: =K8 -> 1520.5115

Sheet 10.3отк1
A1: Витражи
A2: (Ширина + Высота*2) * Кол-во * 2 стороны = Итог
A3: Марка | B3: Ширина, м | C3: Высота, м | D3: Кол-во | E3: Глубина, м | F3: Итог, м2
A4: ВВ-1* | B4: 1.7 | C4: 2.7 | D4: 6 | E4: 0.15 | F4: =(B4+C4*2)*E4*D4*2 -> 12.78
A5: ВВ-2* | B5: 1.8 | C5: 2.7 | D5: 1 | E5: 0.1 | F5: =(B5+C5*2)*E5*D5*2 -> 1.44
A6: ВВ-3* | B6: 2.1 | C6: 2.7 | D6: 2 | E6: 0.2 | F6: =(B6+C6*2)*E6*D6*2 -> 6
A7: ВВ-4* | B7: 2.1 | C7: 2.7 | D7: 2 | E7: 0.2 | F7: =(B7+C7*2)*E7*D7*2 -> 6
A8: ВВ-5* | B8: 2.4 | C8: 2.7 | D8: 1 | E8: 0.1 | F8: =(B8+C8*2)*E8*D8*2 -> 1.56
A9: ВВ-6* | B9: 2.8 | C9: 2.7 | D9: 1 | E9: 0.13 | F9: =(B9+C9*2)*E9*D9*2 -> 2.132
A10: ВВ-7* | B10: 2.7 | C10: 2.7 | D10: 1 | E10: 0.24 | F10: =(B10+C10*2)*E10*D10*2 -> 3.888
A11: ВВ-8* | B11: 2.8 | C11: 2.7 | D11: 1 | E11: 0.1 | F11: =(B11+C11*2)*E11*D11*2 -> 1.64
A12: ВВ-9* | B12: 3 | C12: 2.7 | D12: 1 | E12: 0.1 | F12: =(B12+C12*2)*E12*D12*2 -> 1.68
A13: ВВ-10* | B13: 3.2 | C13: 2.7 | D13: 2 | E13: 0.2 | F13: =(B13+C13*2)*E13*D13*2 -> 6.88
A14: ВВ-11* | B14: 3.7 | C14: 2.7 | D14: 1 | E14: 0.235 | F14: =(B14+C14*2)*E14*D14*2 -> 4.277
A15: ВВ-12* | B15: 4.2 | C15: 2.7 | D15: 1 | E15: 0.1 | F15: =(B15+C15*2)*E15*D15*2 -> 1.92
... A59: УДВВ-2.2* | B59: 5.4 | C59: 2.7 | D59: 1 | E59: 0.08 | F59: =(B59+C59*2)*E59*D59*2 -> 1.728
D60: Итог, м2: | F60: =SUM(F4:F59) -> 195.415

Sheet 10.3отк3
A1: Двери витражные
A2: Марка окна | B2: Размер (ШхВ), м | C2: Всего, шт. | D2: Периметр откоса, м.п. | E2: Глубина откоса, м. | F2: Площадь одного откоса, м2 | G2: Общая площадь откосов, м2
A3: ДВН-1, ДВН-1.1, ДВН-12*, ДВН-12.1*, ДВН-12.2* | B3: 1,4х3,3 | C3: =1+1+2+4+1 -> 9 | D3: =1.4+3.3*2 -> 8 | E3: 0.33 | F3: =D3*E3 -> 2.64 | G3: =F3*C3 -> 23.76
A4: ДВН-2 | B4: 1,75х3,3 | C4: 1 | D4: =1.75+3.3*2 -> 8.35 | E4: =E3 -> 0.33 | F4: =D4*E4 -> 2.7555 | G4: =F4*C4 -> 2.7555
A5: ДВН-3 | B5: 1,875х3,3 | C5: 1 | D5: =1.875+3.3*2 -> 8.475 | E5: =E4 -> 0.33 | F5: =D5*E5 -> 2.79675 | G5: =F5*C5 -> 2.79675
A6: ДВН-4, ДВН-4.1, ДВН-14* | B6: 2,1х3,3 | C6: =1+5+1 -> 7 | D6: =2.1+3.3*2 -> 8.7 | E6: =E5 -> 0.33 | F6: =D6*E6 -> 2.871 | G6: =F6*C6 -> 20.097
A7: ДВН-5 | B7: 2,56х3,88 | C7: 1 | D7: =2.56+3.88*2 -> 10.32 | E7: =E6 -> 0.33 | F7: =D7*E7 -> 3.4056 | G7: =F7*C7 -> 3.4056
A8: ДВН-6 | B8: 3,85х3,3 | C8: 1 | D8: =3.85+3.3*2 -> 10.45 | E8: =E7 -> 0.33 | F8: =D8*E8 -> 3.4485 | G8: =F8*C8 -> 3.4485
A9: ДВН-7 | B9: 4,8х3,3 | C9: 1 | D9: =4.8+3.3*2 -> 11.4 | E9: =E8 -> 0.33 | F9: =D9*E9 -> 3.762 | G9: =F9*C9 -> 3.762
A10: ДВН-8 | B10: 5,095х3,88 | C10: 1 | D10: =5.095+3.88*2 -> 12.855 | E10: =E9 -> 0.33 | F10: =D10*E10 -> 4.24215 | G10: =F10*C10 -> 4.24215
A11: ДВН-9 | B11: 5,245х3,88 | C11: 1 | D11: =5.245+3.88*2 -> 13.005 | E11: =E10 -> 0.33 | F11: =D11*E11 -> 4.29165 | G11: =F11*C11 -> 4.29165
A12: ДВН-10 | B12: 7,8х3,3 | C12: 1 | D12: =7.8+3.3*2 -> 14.4 | E12: =E11 -> 0.33 | F12: =D12*E12 -> 4.752 | G12: =F12*C12 -> 4.752
A13: ДВН-11 | B13: 10,8х3,3 | C13: 1 | D13: =10.8+3.3*2 -> 17.4 | E13: =E12 -> 0.33 | F13: =D13*E13 -> 5.742 | G13: =F13*C13 -> 5.742
A14: ДВН-13* | B14: 1,8х3,3 | C14: 1 | D14: =1.8+3.3*2 -> 8.4 | E14: =E13 -> 0.33 | F14: =D14*E14 -> 2.772 | G14: =F14*C14 -> 2.772
A15: ДВН-15* | B15: 11,95х3,3 | C15: 1 | D15: =11.95+3.3*2 -> 18.55 | E15: =E14 -> 0.33 | F15: =D15*E15 -> 6.1215 | G15: =F15*C15 -> 6.1215
A16: ДВН-16* | B16: 33,2х3,88 | C16: 1 | D16: =33.2+3.3*2 -> 39.8 | E16: =E15 -> 0.33 | F16: =D16*E16 -> 13.134 | G16: =F16*C16 -> 13.134
A17: ДН-1* | B17: 1,3х2,76 | C17: 1 | D17: =1.3+2.76*2 -> 6.82 | E17: =E16 -> 0.33 | F17: =D17*E17 -> 2.2506 | G17: =F17*C17 -> 2.2506
A18: ДН-2* | B18: 1,8х3,3 | C18: 1 | D18: =1.8+3.3*2 -> 8.4 | E18: =E17 -> 0.33 | F18: =D18*E18 -> 2.772 | G18: =F18*C18 -> 2.772
A19: ИТОГО, м2 | G19: =SUM(G3:G18) -> 106.10325

Sheet 10.3отк2
A1: Окна
A2: Размер проема (ШхВ), м | B2: 1 эт., шт. | C2: 2 эт., шт. | D2: 3 эт., шт. | E2: Всего, шт. | F2: Наличие подоконика | G2: Периметр откоса, м.п. | H2: Глубина откоса, м. | I2: Площадь одного откоса, м2 | J2: Общая площадь откосов, м2
A3: 1х2,7 | B3: =2+2 -> 4 | C3: =3+1+1+4+1 -> 10 | D3: =3+1+1+4+1 -> 10 | E3: =SUM(B3:D3) -> 24 | F3: да | G3: =1+2*2.6 -> 6.2 | H3: 0.33 | I3: =G3*H3 -> 2.046 | J3: =I3*E3 -> 49.104
A4: 1,8х2,7 | B4: =17+10+11+20+14+11+4 -> 87 | C4: =18+4+12+20+15+11+11+5 -> 96 | D4: =18+4+10+20+15+13+11+5+8 -> 104 | E4: =SUM(B4:D4) -> 287 | F4: да | G4: =1.8+2*2.6 -> 7 | H4: =H3-0.005 -> 0.325 | I4: =G4*H4 -> 2.275 | J4: =I4*E4-2 -> 650.925
A5: 7,8х2,7 | B5: =2 -> 2 | C5: =1+2 -> 3 | D5: =1+1 -> 2 | E5: =SUM(B5:D5) -> 7 | F5: да | G5: =7.8+2*2.6 -> 13 | H5: =H4 -> 0.325 | I5: =G5*H5 -> 4.225 | J5: =I5*E5 -> 29.575
A6: 4,8х2,7 | B6: =1+1 -> 2 | C6: =1+2+2 -> 5 | D6: =1+1+3+2 -> 7 | E6: =SUM(B6:D6) -> 14 | F6: да | G6: =4.8+2*2.6 -> 10 | H6: =H5 -> 0.325 | I6: =G6*H6 -> 3.25 | J6: =I6*E6 -> 45.5
A7: 4,65х2,7 | C7: =1 -> 1 | E7: =SUM(B7:D7) -> 1 | F7: да | G7: =4.65+2*2.6 -> 9.85 | H7: =H6 -> 0.325 | I7: =G7*H7 -> 3.20125 | J7: =I7*E7 -> 3.20125
A8: 1,8х6,9 | C8: 7 | E8: =SUM(B8:D8) -> 7 | F8: нет | G8: =(1.8+6.8)*2 -> 17.2 | H8: =H7 -> 0.325 | I8: =G8*H8 -> 5.59 | J8: =I8*E8 -> 39.13
A9: 1,8х6,9 | C9: 4 | E9: =SUM(B9:D9) -> 4 | F9: да | G9: =1.8+2*6.8 -> 15.4 | H9: =H8 -> 0.325 | I9: =G9*H9 -> 5.005 | J9: =I9*E9 -> 20.02
A10: 9,5х6,9 | C10: =1 -> 1 | E10: =SUM(B10:D10) -> 1 | F10: да | G10: =9.5+2*6.8 -> 23.1 | H10: =H9 -> 0.325 | I10: =G10*H10 -> 7.5075 | J10: =I10*E10 -> 7.5075
A11: 10,8х2,7 | B11: =1 -> 1 | E11: =SUM(B11:D11) -> 1 | F11: да | G11: =10.8+2*2.6 -> 16 | H11: =H10 -> 0.325 | I11: =G11*H11 -> 5.2 | J11: =I11*E11 -> 5.2
A12: 13,7х6,9 | C12: =1 -> 1 | E12: =SUM(B12:D12) -> 1 | F12: да | G12: =13.7+2*6.8 -> 27.3 | H12: =H11 -> 0.325 | I12: =G12*H12 -> 8.8725 | J12: =I12*E12 -> 8.8725
A13: 1,7х6,9 | C13: =10 -> 10 | E13: =SUM(B13:D13) -> 10 | F13: да | G13: =1.7+2*6.8 -> 15.3 | H13: =H12 -> 0.325 | I13: =G13*H13 -> 4.9725 | J13: =I13*E13 -> 49.725
A14: 1,8х1,5 | C14: 8 | E14: =SUM(B14:D14) -> 8 | F14: нет | G14: =(1.8+1.5)*2 -> 6.6 | H14: =H13 -> 0.325 | I14: =G14*H14 -> 2.145 | J14: =I14*E14 -> 17.16
A15: 7,8х3,3 | B15: 1 | C15: 0 | D15: 0 | E15: 1 | F15: да | G15: 14.4 | H15: 0.33 | I15: 4.752 | J15: 4.752
J16: =SUM(J3:J15) -> 930.67225

Sheet 10.3отк4
A1: Двери
A2: Марка окна | B2: Размер (ШхВ), м | C2: Всего, шт. | D2: Периметр откоса, м.п. | E2: Глубина откоса, м. | F2: Площадь одного откоса, м2 | G2: Общая площадь откосов, м2
A3: Д-1* | B3: 0,7х1,8 | C3: 60 | D3: =0.7+2*1.8 -> 4.3 | E3: 0.13 | F3: =D3*E3 -> 0.559 | G3: =F3*C3 -> 33.54
A4: Д-2*(л) | B4: 0,7х2,1 | C4: 3 | D4: =0.7+2*2.1 -> 4.9 | E4: 0.13 | F4: =D4*E4 -> 0.637 | G4: =F4*C4 -> 1.911
A5: Д-3, Д-3(л), Д-3.1 | B5: 0,9х2,1 | C5: =1+1+1 -> 3 | D5: =0.9+2*2.1 -> 5.1 | E5: 0.13 | F5: =D5*E5 -> 0.663 | G5: =F5*C5 -> 1.989
A6: Д-4, Д-4(л), Д-5, Д-5(л), Д-6(л), Д-7(л), Д-8, Д-8(л) | B6: 1,0х2,1 | C6: =1+1+10+4+1+1+3+1 -> 22 | D6: =1+2*2.1 -> 5.2 | E6: 0.13 | F6: =D6*E6 -> 0.676 | G6: =F6*C6 -> 14.872
A7: Д-9, Д-9(л), Д-10*, Д-10*(л) | B7: 1,1х2,1 | C7: =5+3+4+5 -> 17 | D7: =1.1+2*2.1 -> 5.3 | E7: 0.13 | F7: =D7*E7 -> 0.689 | G7: =F7*C7 -> 11.713
A8: Д-11, Д-11(л), Д-11.1, Д-11.1(л), Д-11.2, Д-11.2(л), Д-12, Д-12(л), Д-13, Д-13(л), Д-14*, Д-15*, Д-15*(л), Д-16, Д-16(л), Д-17*, Д-17*(л), Д-18, Д-19*(л), Д-20*, Д-21, Д-22*, Д-22*(л), Д-23, Д-24, Д-25 | B8: 1,15х2,1 | C8: =5+3+1+1+6+4+10+4+4+4+4+5+1+5+3+15+4+1+1+2+2+2+2+3+2+1 -> 95 | D8: =1.15+2*2.1 -> 5.35 | E8: 0.13 | F8: =D8*E8 -> 0.6955 | G8: =F8*C8 -> 66.0725
A9: Д-26* | B9: 1,2х2,1 | C9: 2 | D9: =1.2+2*2.1 -> 5.4 | E9: 0.13 | F9: =D9*E9 -> 0.702 | G9: =F9*C9 -> 1.404
A10: Д-27*(л) | B10: 1,4х2,1 | C10: 1 | D10: =1.4+2*2.1 -> 5.6 | E10: 0.13 | F10: =D10*E10 -> 0.728 | G10: =F10*C10 -> 0.728
A11: Д-28*, Д-29*, Д-29*(л), Д-30* | B11: 1,45х2,1 | C11: =6+6+2+1 -> 15 | D11: =1.45+2*2.1 -> 5.65 | E11: 0.13 | F11: =D11*E11 -> 0.7345 | G11: =F11*C11 -> 11.0175
A12: Д-31*, Д-31*(л) | B12: 1,6х2,1 | C12: =25+8 -> 33 | D12: =1.6+2*2.1 -> 5.8 | E12: 0.18 | F12: =D12*E12 -> 1.044 | G12: =F12*C12 -> 34.452
A13: Д-32(л), Д-33* | B13: 1,65х2,4 | C13: =1+1 -> 2 | D13: =1.65+2*2.4 -> 6.45 | E13: 0.18 | F13: =D13*E13 -> 1.161 | G13: =F13*C13 -> 2.322
A14: Д-34* | B14: 2,2х2,4 | C14: 2 | D14: =2.2+2*2.4 -> 7 | E14: 0.18 | F14: =D14*E14 -> 1.26 | G14: =F14*C14 -> 2.52
A15: ДО-1, ДО-1(л), ДО-1.1* | B15: 1,7х2,4 | C15: =51+2+17 -> 70 | D15: =1.7+2*2.4 -> 6.5 | E15: 0.18 | F15: =D15*E15 -> 1.17 | G15: =F15*C15 -> 81.9
A16: ДО-2*, ДО-2.1* | B16: 2,0х2,4 | C16: =3+1 -> 4 | D16: =2+2*2.4 -> 6.8 | E16: 0.33 | F16: =D16*E16 -> 2.244 | G16: =F16*C16 -> 8.976
A17: ДО-3*, ДО-3.1*, ДО-3.2*, ДО-3.3*, ДО-3.4*, ДО-3.5* | B17: 2,1х2,4 | C17: =1+3+2+2+2+2 -> 12 | D17: =2.1+2*2.4 -> 6.9 | E17: 0.18 | F17: =D17*E17 -> 1.242 | G17: =F17*C17 -> 14.904
A18: ИТОГО, м2 | C18: =SUM(C3:C17) -> 341 | G18: =SUM(G3:G17) -> 288.321

Sheet Лист1
B1: 1.6 | C1: 1000 | D1: 2700 | G1: 4
B2: 1.7 | C2: 1800 | D2: 2700 | G2: 87
B3: 1.9 | C3: 2060 | D3: 3230 | G3: 1
B4: 1.10 | C4: 2150 | D4: 2700 | G4: 1
B5: 1.11 | C5: 2150 | D5: 3430 | G5: 3
B6: 1.14 | C6: 2800 | D6: 3430 | G6: 1
B7: 1.18 | C7: 3300 | D7: 2700 | G7: 1
B8: 1.27 | C8: 4800 | D8: 2700 | G8: 2
B9: 1.29 | C9: 4800 | D9: 3430 | G9: 1
B10: 1.33 | C10: 5150 | D10: 2700 | G10: 1
B11: 1.34 | C11: 5150 | D11: 3430 | G11: 2
B12: 1.38 | C12: 6550 | D12: 2930 | G12: 1
B13: 1.39 | C13: 6800 | D13: 2300 | G13: 1
A16: Устройство витражных откосов.
A17: эт. | B17: шт | C17: верхняя пл-ть, общая, м2 | F17: боковая пл-тьь, общая, м2 | H17: высота откоса, м. | I17: Глубина откоса, м. | J17: Площадь одного откоса, м2 | K17: Итог, м2
A18: 1 эт | B18: 33 | C18: 35.79 | F18: =B18*2*3.8*0.13 -> 32.604 | H18: 3.85 | I18: 0.13 | K18: =SUM(C18:F18) -> 68.394
A19: 2 эт | B19: 17 | C19: 13.03 | F19: =B19*2*3.8*0.13 -> 16.796 | H19: 3.85 | I19: 0.13 | K19: =SUM(C19:F19) -> 29.826
A20: 3 эт | B20: 25 | C20: 16.06 | F20: =B20*2*3.8*0.13 -> 24.7 | H20: 3.85 | I20: 0.13 | K20: =SUM(C20:F20) -> 40.76
A21: Итог: | K21: =SUM(K18:K20) -> 138.98
B33: 2.4 | C33: 1000 | D33: 2700 | G33: 4
B34: 2.5 | C34: 1500 | D34: 2700 | G34: 1
B35: 2.6 | C35: 1700 | D35: 2700 | G35: 10
B36: 2.7 | C36: 1800 | D36: 1500 | G36: 6
B37: 2.8 | C37: 1800 | D37: 2700 | G37: 108
B38: 2.10 | C38: 1930 | D38: 2700 | G38: 1
B39: 2.13 | C39: 2370 | D39: 2700 | G39: 1
B40: 2.14 | C40: 2800 | D40: 2700 | G40: 1
B41: 2.17 | C41: 3000 | D41: 1200 | G41: 1
B42: 2.18 | C42: 3000 | D42: 1200 | G42: 1
B43: 2.20 | C43: 3300 | D43: 2700 | G43: 1
B44: 2.26 | C44: 4650 | D44: 2700 | G44: 1
... B68: 3.31 | C68: 5350 | D68: 4200 | G68: 1

Sheet 10.2плны
A1: Ведомость работ
A2: № п.п. | B2: Наименование затрат | H2: Ед. изм. | I2: Объем
A3: 1 | B3: Штукатурка поверхностей откосов сухими смесями с предварительной огрунтовкой поверхности | H3: м2 | I3: =C15 -> 1688.585
A4: 2 | B4: Выравнивание поверхностей откосов толщ. до 5 мм с предварительной огрунтовкой поверхности (базовая шпаклевка) | H4: м2 | I4: =I3 -> 1688.585
A5: 3 | B5: Выравнивание поверхностей откосов толщ. до 5 мм с предварительной огрунтовкой поверхности (финишная шпаклевка) | H5: м2 | I5: =I4 -> 1688.585
A6: 4 | B6: Лакокрасочные работы СКБ / окраска откосов / 2 слоя / СТ-2.1 | H6: м2 | I6: =C21 -> 203.451
A7: 5 | B7: Лакокрасочные работы СКБ / окраска откосов / 2 слоя / СТ-2.16 | H7: м2 | I7: =C28 -> 72.609
A8: 6 | B8: Лакокрасочные работы СКБ / окраска откосов / 2 слоя / СТ-1.1 | H8: м2 | I8: =C35 -> 1374.697
A9: 7 | B9: Лакокрасочные работы СКБ / окраска откосов / 2 слоя / СТ-2.3 | H9: м2 | I9: =I21 -> 37.828
A11: № п.п. | B11: № эт. | C11: Объем, м2:
A12: 1 | B12: 1 | C12: =C18+I18+C25+C32 -> 631.9
A13: 2 | B13: 2 | C13: =C19+I19+C26+C33 -> 559.504
A14: 3 | B14: 3 | C14: =C20+I20+C27+C34 -> 497.181
A15: Итог: | C15: =SUM(C12:C14) -> 1688.585
A16: СТ-2.1 | G16: СТ-2.3
A17: № п.п. | B17: № эт. | C17: Объем, м2: | G17: № п.п. | H17: № эт. | I17: Объем, м2:
A18: 1 | B18: 1 | C18: =3.38*8+(1.5*4 + 1.1*4)*3.3+(6.8+9.19)*3.3 -> 114.127 | G18: 1 | H18: 1 | I18: =(1.5*4 + 1.1*4)*0.7 -> 7.28
A19: 2 | B19: 2 | C19: =8*2.8+7.2*3.3 -> 46.16 | G19: 2 | H19: 2 | I19: =7.2*0.7+12.14*0.7 -> 13.538
A20: 3 | B20: 3 | C20: =3.38*7.8+4.2*4 -> 43.164 | G20: 3 | H20: 3 | I20: =24.3*0.7 -> 17.01
A21: Итог: | C21: =SUM(C18:C20) -> 203.451 | G21: Итог: | I21: =SUM(I18:I20) -> 37.828
A23: СТ-2.16
A24: № п.п. | B24: № эт. | C24: Объем, м2:
A25: 1 | B25: 1 | C25: =0.62*8+1.1*4+6.9*0.7+(6.8+9.19)*0.7 -> 25.383
A26: 2 | B26: 2 | C26: =2.2*0.7 -> 1.54
A27: 3 | B27: 3 | C27: =2.16*4+0.62*7.8+0.7*1.8+5*4+4*0.62+12.1*0.7 -> 45.686
A28: Итог: | C28: =SUM(C25:C27) -> 72.609
A30: СТ-1.1
A31: № п.п. | B31: № эт. | C31: Объем, м2:
A32: 1 | B32: 1 | C32: =3.38*3+6.9*3.3+16.25*12.2+7.75*12.2+12.3*8+15.25*4 -> 485.11
A33: 2 | B33: 2 | C33: =4*15.2+1.6*8+1.3*3.38+4.2*4+12.14*3.3+14.35*4+5.6*8+24.13*4+17.3*9.1+2.2*3.3 -> 498.266
A34: 3 | B34: 3 | C34: =6*4+24.77*3.3+24.3*3.3+36.5*4+1.8*3.3+4*3.38+12.1*3.3 -> 391.321
A35: Итог: | C35: =SUM(C32:C34) -> 1374.697

Sheet 8.7штр
A1: Ведомость работ
A2: № п.п. | B2: Наименование затрат | G2: Ед. изм. | H2: Объем
A3: 1 | B3: Заделка штроб | G3: пог. м. | H3: =B39+E19+H41+K39+N39+Q37 -> 5679
A5: Пом. | B5: п.м | D5: Пом. | E5: п.м | G5: Пом. | H5: п.м | J5: Пом. | K5: п.м | M5: Пом. | N5: п.м | P5: Пом. | Q5: п.м
A6: 1006 | B6: 7 | D6: 1112 | E6: 8 | G6: 2001 | H6: 22.8 | J6: 2036 | K6: 88.8 | M6: 3001 | N6: 40 | P6: 3034 | Q6: 6
A7: 1004 | B7: 4 | D7: 1062 | E7: 34 | G7: 2002 | H7: 57.6 | J7: 2037 | K7: 151.2 | M7: 3002 | N7: 40 | P7: 3035 | Q7: 48
A8: 1005 | B8: 3 | D8: 1061 | E8: 24 | G8: 2003 | H8: 112.8 | J8: 2038 | K8: 57.6 | M8: 3003 | N8: 36 | P8: 3036 | Q8: 16
A9: 1007 | B9: 20 | D9: 1067 | E9: 15 | G9: 2004 | H9: 45.6 | J9: 2039 | K9: 50.4 | M9: 3004 | N9: 88 | P9: 3037 | Q9: 77
A10: 1009 | B10: 9 | D10: 1073 | E10: 21 | G10: 2005 | H10: 40.8 | J10: 2040 | K10: 36 | M10: 3005 | N10: 17 | P10: 3038 | Q10: 122
A11: 1052 | B11: 2 | D11: 1070 | E11: 9 | G11: 2006 | H11: 9.6 | J11: 2041 | K11: 48 | M11: 3006 | N11: 39 | P11: 3039 | Q11: 22
A12: 1088 | B12: 7 | D12: 1079 | E12: 8 | G12: 2007 | H12: 14.4 | J12: 2042 | K12: 69.6 | M12: 3007 | N12: 34 | P12: 3040 | Q12: 88
A13: 1011 | B13: 6 | D13: 1084 | E13: 5 | G13: 2008 | H13: 9.6 | J13: 2043 | K13: 31.2 | M13: 3008 | N13: 2 | P13: 3041 | Q13: 132
A14: 1012 | B14: 15 | D14: 1080 | E14: 15 | G14: 2009 | H14: 31.2 | J14: 2044 | K14: 0 | M14: 3009 | N14: 5 | P14: 3042 | Q14: 5
A15: 1002 | B15: 19 | D15: 1068 | E15: 14 | G15: 2010 | H15: 6 | J15: 2045 | K15: 112.8 | M15: 3010 | N15: 82 | P15: 3043 | Q15: 8
A16: 1008 | B16: 9 | D16: 1057 | E16: 25 | G16: 2011 | H16: 2.4 | J16: 2046 | K16: 148.8 | M16: 3011 | N16: 60 | P16: 3044 | Q16: 2
A17: 1016 | B17: 4 | D17: 1048 | E17: 18 | G17: 2012 | H17: 74.4 | J17: 2047 | K17: 14.4 | M17: 3012 | N17: 126 | P17: 3045 | Q17: 20
A18: 1085 | B18: 27 | D18: 1045 | E18: 23 | G18: 2013 | H18: 52.8 | J18: 2048 | K18: 45.6 | M18: 3013 | N18: 40 | P18: 3046 | Q18: 22
A19: 1026 | B19: 3 | D19: Итог: | E19: =SUM(E6:E18) -> 219 | G19: 2014 | H19: 57.6 | J19: 2049 | K19: 96 | M19: 3014 | N19: 56 | P19: 3047 | Q19: 33
A20: 1027 | B20: 3 | G20: 2015 | H20: 52.8 | J20: 2050 | K20: 7.2 | M20: 3015 | N20: 12 | P20: 3048 | Q20: 65
A21: 1024 | B21: 3 | G21: 2016 | H21: 48 | J21: 2053 | K21: 14.4 | M21: 3016 | N21: 35 | P21: 3049 | Q21: 30
A22: 1017 | B22: 3 | G22: 2017 | H22: 151.2 | J22: 2054 | K22: 3.6 | M22: 3017 | N22: 10 | P22: 3050 | Q22: 82
A23: 1022 | B23: 7 | G23: 2018 | H23: 2.4 | J23: 2055 | K23: 18 | M23: 3018 | N23: 12 | P23: 3051 | Q23: 61
A24: 1036 | B24: 21 | G24: 2019 | H24: 2.4 | J24: 2056 | K24: 9.6 | M24: 3019 | N24: 140 | P24: 3052 | Q24: 0
A25: 1015 | B25: 34 | G25: 2020 | H25: 15.6 | J25: 2057 | K25: 9.6 | M25: 3020 | N25: 0 | P25: 3053 | Q25: 88
A26: 1023 | B26: 16 | G26: 2021 | H26: 6 | J26: 2058 | K26: 4.8 | M26: 3021 | N26: 20 | P26: 3054 | Q26: 44
A27: 1028 | B27: 17 | G27: 2022 | H27: 151.2 | J27: 2059 | K27: 2.4 | M27: 3022 | N27: 36 | P27: 3055 | Q27: 5
A28: 1029 | B28: 15 | G28: 2023 | H28: 2.4 | J28: 2060 | K28: 4.8 | M28: 3023 | N28: 83 | P28: 3057 | Q28: 5
A29: 1030 | B29: 10 | G29: 2024 | H29: 0 | J29: 2061 | K29: 57.6 | M29: 3024 | N29: 0 | P29: 3058 | Q29: 54
A30: 1050 | B30: 4 | G30: 2025 | H30: 16.8 | J30: 2062 | K30: 43.2 | M30: 3025 | N30: 5 | P30: 3059 | Q30: 104
A31: 1053 | B31: 8 | G31: 2026 | H31: 2.4 | J31: 2063 | K31: 0 | M31: 3026 | N31: 2 | P31: 3061 | Q31: 2
... A36: 1059 | B36: 11 | G36: 2031 | H36: 21.6 | J36: 2068 | K36: 38.4 | M36: 3031 | N36: 54 | P36: 3067 | Q36: 20
A37: 1087 | B37: 3 | G37: 2032 | H37: 45.6 | J37: 2070 | K37: 52.8 | M37: 3032 | N37: 42 | P37: Итог: | Q37: =SUM(Q6:Q36) -> 1228
A38: 1051 | B38: 4 | G38: 2033 | H38: 7.2 | J38: 2071 | K38: 93.6 | M38: 3033 | N38: 28
A39: Итог: | B39: =SUM(B6:B38) -> 348 | G39: 2034 | H39: 4.8 | J39: Итог: | K39: =SUM(K6:K38) -> 1446 | M39: Итог: | N39: =SUM(N6:N38) -> 1346
G40: 2035 | H40: 2.4
G41: Итог: | H41: =SUM(H6:H40) -> 1092

Sheet 7.5.1лес
A1: Ведомость работ
A2: № п.п. | B2: Наименование затрат | E2: Ед. изм. | F2: Объем
A3: 1 | B3: Монтаж, демонтаж, аренда строительных лесов | E3: м2 | F3: =C9 -> 2292
A5: № п.п. | B5: № эт. | C5: Объем, м2:
A6: 1 | B6: 1 | C6: =252+660 -> 912
A7: 2 | B7: 2 | C7: =378+608+322 -> 1308
A8: 3 | B8: 3 | C8: =12*3*2 -> 72
A9: Итог: | C9: =SUM(C6:C8) -> 2292

Sheet 8.6отв
A1: Ведомость работ
A2: № п.п. | B2: Наименование затрат | J2: Ед. изм. | K2: Объем
A3: 1 | B3: Заделка отверстий в стенах в местах прохода коммуникации / до 500 см2 | J3: шт | K3: 746

Sheet 8.5дфрг
A1: Ведомость работ
A2: № п.п. | B2: Наименование затрат | J2: Ед. изм. | K2: Объем
A3: 1 | B3: Заделка мест прохождения воздуховодов | J3: м3 | K3: =Q35+N36+K36+H37+B37+E21 -> 86.9952
A4: 2 | B4: Заделка стояков отопления | J4: м3 | K4: =292*(0.15*0.15*0.25) -> 1.6425
A5: Итог (м3): | K5: =SUM(K3:K4) -> 88.6377
A7: Пом. | B7: Объем, м3: | D7: Пом. | E7: Объем, м3: | G7: Пом. | H7: Объем, м3: | J7: Пом. | K7: Объем, м3: | M7: Пом. | N7: Объем, м3: | P7: Пом. | Q7: Объем, м3:
A8: 1.005 | B8: 0.09456 | D8: 1.112 | E8: 0.37824 | G8: 2.001 | H8: 0.66192 | J8: 2.036 | K8: 1.13472 | M8: 3.001 | N8: 0.66192 | P8: 3.033 | Q8: 0.4728
A9: 1.007 | B9: 0.37824 | D9: 1.061 | E9: 0.56736 | G9: 2.002 | H9: 0.75648 | J9: 2.038 | K9: 0.56736 | M9: 3.002 | N9: 0.66192 | P9: 3.035 | Q9: 0.66192
A10: 1.009 | B10: 0.18912 | D10: 1.063 | E10: 0.18912 | G10: 2.003 | H10: 0.66192 | J10: 2.039 | K10: 0.56736 | M10: 3.003 | N10: 0.66192 | P10: 3.036 | Q10: 0.56736
A11: 1.015 | B11: 0.09456 | D11: 1.064 | E11: 0.09456 | G11: 2.004 | H11: 0.75648 | J11: 2.040 | K11: 0.56736 | M11: 3.004 | N11: 1.13472 | P11: 3.037 | Q11: 1.60752
A12: 1.024 | B12: 0.18912 | D12: 1.097 | E12: 0.18912 | G12: 2.005 | H12: 0.37824 | J12: 2.041 | K12: 0.56736 | M12: 3.005 | N12: 0.18912 | P12: 3.038 | Q12: 1.70208
A13: 1.027 | B13: 0.09456 | D13: 1.069 | E13: 0.4728 | G13: 2.009 | H13: 0.4728 | J13: 2.042 | K13: 1.70208 | M13: 3.007 | N13: 0.4728 | P13: 3.039 | Q13: 0.18912
A14: 1.031 | B14: 0.18912 | D14: 1.070 | E14: 0.4728 | G14: 2.010 | H14: 0.18912 | J14: 2.043 | K14: 0.4728 | M14: 3.008 | N14: 0.37824 | P14: 3.040 | Q14: 0.9456
A15: 1.032 | B15: 0.18912 | D15: 1.073 | E15: 0.9456 | G15: 2.011 | H15: 0.18912 | J15: 2.045 | K15: 1.70208 | M15: 3.009 | N15: 0.09456 | P15: 3.041 | Q15: 1.8912
A16: 1.028 | B16: 0.09456 | D16: 1.072 | E16: 0.09456 | G16: 2.012 | H16: 0.66192 | J16: 2.046 | K16: 1.60752 | M16: 3.010 | N16: 1.13472 | P16: 3.042 | Q16: 0.18912
A17: 1.044 | B17: 0.09456 | D17: 1.083 | E17: 0.4728 | G17: 2.013 | H17: 0.66192 | J17: 2.047 | K17: 1.04016 | M17: 3.011 | N17: 1.13472 | P17: 3.043 | Q17: 0.18912
A18: 1.043 | B18: 0.09456 | D18: 1.078 | E18: 0.66192 | G18: 2.014 | H18: 0.66192 | J18: 2.048 | K18: 1.4184 | M18: 3.012 | N18: 2.08032 | P18: 3.044 | Q18: 0.18912
A19: 1.092 | B19: 0.09456 | D19: 1.075 | E19: 0.56736 | G19: 2.015 | H19: 0.66192 | J19: 2.049 | K19: 1.04016 | M19: 3.013 | N19: 0.56736 | P19: 3.045 | Q19: 0.18912
A20: 1.042 | B20: 0.37824 | D20: 1.076 | E20: 0.75648 | G20: 2.016 | H20: 0.66192 | J20: 2.050 | K20: 0.56736 | M20: 3.014 | N20: 0.66192 | P20: 3.046 | Q20: 0.4728
A21: 1.050 | B21: 0.28368 | D21: Итог: | E21: =SUM(E8:E20) -> 5.86272 | G21: 2.017 | H21: 1.22928 | J21: 2.051 | K21: 0.28368 | M21: 3.015 | N21: 0.28368 | P21: 3.048 | Q21: 0.56736
A22: 1.105 | B22: 0.09456 | G22: 2.018 | H22: 0.18912 | J22: 2.052 | K22: 0.37824 | M22: 3.017 | N22: 0.09456 | P22: 3.049 | Q22: 0.37824
A23: 1.106 | B23: 0.09456 | G23: 2.020 | H23: 0.18912 | J23: 2.053 | K23: 0.18912 | M23: 3.018 | N23: 0.09456 | P23: 3.050 | Q23: 0.66192
A24: 1.109 | B24: 0.18912 | G24: 2.021 | H24: 0.18912 | J24: 2.054 | K24: 0.28368 | M24: 3.019 | N24: 1.8912 | P24: 3.051 | Q24: 0.66192
A25: 1.046 | B25: 0.28368 | G25: 2.022 | H25: 1.60752 | J25: 2.055 | K25: 0.56736 | M25: 3.021 | N25: 0.18912 | P25: 3.053 | Q25: 1.32384
A26: 1.107 | B26: 0.09456 | G26: 2.025 | H26: 0.75648 | J26: 2.060 | K26: 1.04016 | M26: 3.022 | N26: 0.66192 | P26: 3.054 | Q26: 0.37824
A27: 1.047 | B27: 0.28368 | G27: 2.026 | H27: 0.09456 | J27: 2.061 | K27: 1.98576 | M27: 3.023 | N27: 1.51296 | P27: 3.055 | Q27: 0.18912
A28: 1.049 | B28: 0.28368 | G28: 2.027 | H28: 0.09456 | J28: 2.062 | K28: 1.70208 | M28: 3.025 | N28: 0.09456 | P28: 3.057 | Q28: 0.09456
A29: 1.060 | B29: 0.28368 | G29: 2.028 | H29: 0.18912 | J29: 2.064 | K29: 0.18912 | M29: 3.026 | N29: 0.09456 | P29: 3.058 | Q29: 0.18912
A30: 1.081 | B30: 0.09456 | G30: 2.029 | H30: 0.09456 | J30: 2.065 | K30: 0.28368 | M30: 3.027 | N30: 1.13472 | P30: 3.059 | Q30: 0.09456
A31: 1.082 | B31: 0.18912 | G31: 2.030 | H31: 0.75648 | J31: 2.066 | K31: 1.70208 | M31: 3.028 | N31: 0.66192 | P31: 3.063 | Q31: 0.75648
A32: 1.054 | B32: 0.09456 | G32: 2.031 | H32: 0.37824 | J32: 2.067 | K32: 1.8912 | M32: 3.029 | N32: 0.09456 | P32: 3.064 | Q32: 0.09456
A33: 1.058 | B33: 0.18912 | G33: 2.032 | H33: 0.66192 | J33: 2.068 | K33: 1.60752 | M33: 3.030 | N33: 0.66192 | P33: 3.066 | Q33: 1.4184
A34: 1.059 | B34: 0.28368 | G34: 2.033 | H34: 0.09456 | J34: 2.070 | K34: 0.4728 | M34: 3.031 | N34: 0.66192 | P34: 3.067 | Q34: 0.4728
A35: 1.087 | B35: 0.09456 | G35: 2.034 | H35: 0.09456 | J35: 2.071 | K35: 1.13472 | M35: 3.032 | N35: 0.66192 | P35: Итог: | Q35: =SUM(Q8:Q34) -> 16.548
A36: 1.051 | B36: 0.18912 | G36: 2.035 | H36: 0.09456 | J36: Итог: | K36: =SUM(K8:K35) -> 26.66592 | M36: Итог: | N36: =SUM(N8:N35) -> 18.62832
A37: Итог: | B37: =SUM(B8:B36) -> 5.2008 | G37: Итог: | H37: =SUM(H8:H36) -> 14.08944

Sheet 8.4отк.лк
A1: Ведомость работ
A2: № п.п. | B2: Наименование затрат | F2: Описание | G2: Ед. изм. | H2: Объем
A3: 1 | B3: Устройство проемов из файерборд / в 1 слои | F3: 1-3 эт. Откосы лючков "Хаммер". | G3: м2 | H3: =E12 -> 51.6
A4: 2 | B4: Подготовка поверхности СКБ / 2мм | F4: 1-3 эт. Шпаклевка откосов базовая. Откосы лючков "Хаммер". | G4: м2 | H4: =H3 -> 51.6
A5: 3 | B5: Подготовка поверхности СКБ / 2мм | F5: 1-3 эт. Шпаклевка откосов финишная. Откосы лючков "Хаммер". | G5: м2 | H5: =H4 -> 51.6
A6: 4 | B6: Лакокрасочные работы СКБ / окраска откосов / в 2 слоя | F6: 1-3 эт. Откосы лючков "Хаммер". | G6: м2 | H6: =H5 -> 51.6
A8: № эт | B8: Кол-во люков, шт | C8: Периметр (п.м.). | D8: Ширина, м. | E8: Сумма, м2.
A9: 1 | B9: 20 | C9: 0,7+(1,8*2) | D9: 0.2 | E9: =((0.7+(1.8*2))*0.2)*B9 -> 17.2
A10: 2 | B10: 18 | C10: 0,7+(1,8*2) | D10: 0.2 | E10: =((0.7+(1.8*2))*0.2)*B10 -> 15.48
A11: 3 | B11: 22 | C11: 0,7+(1,8*2) | D11: 0.2 | E11: =((0.7+(1.8*2))*0.2)*B11 -> 18.92
B12: =SUM(B9:B11) -> 60 | D12: Итог: | E12: =SUM(E9:E11) -> 51.6

Sheet 8.3шп.лк
A1: Ведомость работ
A2: № п.п. | B2: Наименование затрат | F2: Описание | G2: Ед. изм. | H2: Объем
A3: 1 | B3: Подготовка поверхности СКБ / 2мм | F3: 1-3 эт. Шпаклевка базовая лючков "Хаммер" | G3: м2 | H3: =D11 -> 65.394
A4: 2 | B4: Подготовка поверхности СКБ / 2мм | F4: 1-3 эт. Шпаклевка финишная лючков "Хаммер" | G4: м2 | H4: =H3 -> 65.394
A5: 3 | B5: Лакокрасочные работы СКБ / окраска стен / в 2 слоя | F5: 1-3 эт. Лючки "Хаммер" | G5: м2 | H5: =H4 -> 65.394
A7: № эт | B7: Кол-во люков, шт | C7: Габариты (м*м). | D7: Сумма, м2.
A8: 1 | B8: 20 | C8: 0,63х1,730 | D8: =0.63*1.73*B8 -> 21.798
A9: 2 | B9: 18 | C9: 0,63х1,730 | D9: =0.63*1.73*B9 -> 19.6182
A10: 3 | B10: 22 | C10: 0,63х1,730 | D10: =0.63*1.73*B10 -> 23.9778
B11: =SUM(B8:B10) -> 60 | C11: Итог: | D11: =SUM(D8:D10) -> 65.394

Sheet 8.2умнь.дв
A1: Ведомость работ
A2: № п.п. | B2: Наименование затрат | D2: Описание | F2: Ед. изм. | G2: Объем
A3: 1 | B3: Устройство проемов из файерборд / в 2 слоя | D3: 1-3 эт. Дверные откосы. Уменьшение дверных проемов. /файерборд | F3: м2 | G3: =E10 -> 12.66696
A5: Расчет
A6: Этаж | B6: Кол-во, шт. | C6: Ср. ширина, м | D6: Ср. длина, м | E6: Сумма, м2
A7: 1 | B7: 20 | C7: 0.155 | D7: 1.13 | E7: =C7*D7*B7 -> 3.503
A8: 2 | B8: 13 | C8: 0.189 | D8: 1.4 | E8: =C8*D8*B8 -> 3.4398
A9: 3 | B9: 26 | C9: 0.172 | D9: 1.28 | E9: =C9*D9*B9 -> 5.72416
A10: Итог, м2: | E10: =SUM(E7:E9) -> 12.66696

Sheet 8.1дврн.откс
A1: Ведомость работ
A2: № п.п. | B2: Наименование затрат | C2: Описание | D2: Ед. изм. | E2: Объем
A3: 1 | B3: Устройство откосов из ГКЛ / в 2 слоя | C3: 1-3 эт. Дверные откосы. Фаиерборд. | D3: м2 | E3: 20.85
A4: 2 | B4: Подготовка поверхности СКБ / стен / по ГКЛ / 2мм | C4: 1-3 эт. Шпаклевка базовая | D4: м2 | E4: =E3 -> 20.85
A5: 3 | B5: Подготовка поверхности СКБ / стен / по ГКЛ / 2мм | C5: 1-3 эт. Шпаклевка финишная | D5: м2 | E5: =E4 -> 20.85

Sheet 7.8фрхв
A1: Ведомость работ
A2: № п.п. | B2: Наименование затрат | F2: Ед. изм. | G2: Объем
A3: 1 | B3: Устройство металлоконструкций фахверков, стоек, рам, балок, опорных конструкций и усилений с учетом крепления, огрунтовки и окрашивания | F3: т | G3: 4.773
A4: 2 | B4: Устройство металлоконструкций фахверков, стоек, рам, балок, опорных конструкций и усилений с учетом крепления, огрунтовки и окрашивания | F4: т | G4: 1.977
A6: № п.п. | B6: № фархверки | C6: Кол-во, шт. | D6: вес, кг | E6: общ. вес, кг.
A7: 1 | B7: Ф-250.3 | C7: 42.64 | D7: 156 | E7: =C7*D7-29.76 -> 6622.08
A8: 2 | B8: Ф-250.3.1 | C8: 42.64 | D8: 3 | E8: =C8*D8 -> 127.92
D9: Итог: | E9: =SUM(E7:E8) -> 6750

Sheet 7.7внеш.блк
A1: Ведомость работ
A2: № п.п. | B2: Наименование затрат | F2: Ед. изм. | G2: Объем
A3: 1 | B3: Кладка наружных стен из блоков ячеистого бетона без устройства перемычек, включая армирование, устройство примыканий | F3: м3 | G3: 11.7
A4: 2 | B4: Кладка наружных стен из блоков ячеистого бетона без устройства перемычек, включая армирование, устройство примыканий | F4: м3 | G4: 9.54
A5: 3 | B5: Кладка наружных стен из блоков ячеистого бетона без устройства перемычек, включая армирование, устройство примыканий | F5: м3 | G5: 11.8

Sheet 7.6прмч
A1: Ведомость работ
A2: № п.п. | B2: Наименование затрат | F2: Ед. изм. | G2: Объем
A3: 1 | B3: Устройство перемычек металлических с огрунтовкой и окраской | F3: т | G3: 0.589
A4: 2 | B4: Устройство перемычек металлических с огрунтовкой и окраской | F4: т | G4: 0.373
A5: 3 | B5: Устройство перемычек металлических с огрунтовкой и окраской | F5: т | G5: 0.484
A6: № п.п. | B6: № перемч | C6: Кол-во, шт. | D6: вес, кг | E6: общ. вес, кг.
A7: 1 | B7: ПР-21 | C7: 1 | D7: =23.43+0.68 -> 24.11 | E7: =C7*D7 -> 24.11
A8: 2 | B8: ПР-27 | C8: 1 | D8: =33.07+1.13+1.38 -> 35.58 | E8: =C8*D8 -> 35.58
A9: 3 | B9: ПР-30 | C9: 1 | D9: =63.7+1.13+2.45 -> 67.28 | E9: =C9*D9-10.8 -> 56.48
A10: 4 | B10: ПР-33 | C10: 3 | D10: =13.79+0.87+3.45 -> 18.11 | E10: =C10*D10 -> 54.33
A11: 5 | B11: ПР-34 | C11: 1 | D11: =17.19+1.16+3.45 -> 21.8 | E11: =C11*D11 -> 21.8
A12: 6 | B12: ПР-35 | C12: 5 | D12: =44.1+1.16+3.45 -> 48.71 | E12: =C12*D12 -> 243.55
A13: 7 | B13: ПР-36 | C13: 2 | D13: =44.1+1.16+3.45 -> 48.71 | E13: =C13*D13 -> 97.42
A14: 8 | B14: ПР-37 | C14: 1 | D14: =50.84+1.44+3.45 -> 55.73 | E14: =C14*D14 -> 55.73
D15: Итог: | E15: =SUM(E7:E14) -> 589
A16: 9 | B16: ПР-5 | C16: 1 | D16: =13.09+0.68+1.38 -> 15.15 | E16: =C16*D16 -> 15.15
A17: 10 | B17: ПР-6 | C17: 3 | D17: =9.65+0.65+2.76 -> 13.06 | E17: =C17*D17 -> 39.18
A18: 11 | B18: ПР-10 | C18: 1 | D18: =20.67+0.68 -> 21.35 | E18: =C18*D18 -> 21.35
A19: 12 | B19: ПР-12 | C19: 1 | D19: =22.74+0.68 -> 23.42 | E19: =C19*D19 -> 23.42
A20: 13 | B20: ПР-13 | C20: 1 | D20: =19.29+0.68+1.38 -> 21.35 | E20: =C20*D20 -> 21.35
A21: 14 | B21: ПР-17 | C21: 4 | D21: =28.25+0.9+1.38 -> 30.53 | E21: =C21*D21-13.44 -> 108.68
A22: 15 | B22: ПР-18 | C22: 1 | D22: =28.25+0.9+1.38 -> 30.53 | E22: =C22*D22 -> 30.53
A23: 16 | B23: ПР-20 | C23: 1 | D23: =23.43+0.9+2.76 -> 27.09 | E23: =C23*D23 -> 27.09
A24: 17 | B24: ПР-30 | C24: 1 | D24: =53.9+1.13+2.76 -> 57.79 | E24: =C24*D24 -> 57.79
A25: 18 | B25: ПР-32 | C25: 1 | D25: =24.8+0.9+2.76 -> 28.46 | E25: =C25*D25 -> 28.46
D26: Итог: | E26: =SUM(E16:E25) -> 373
A27: 19 | B27: ПР-4 | C27: 2 | D27: =13.09+0.68+2.76 -> 16.53 | E27: =C27*D27 -> 33.06
A28: 20 | B28: ПР-5 | C28: 3 | D28: =9.65+0.65+2.76 -> 13.06 | E28: =C28*D28-7.92 -> 31.26
A29: 21 | B29: ПР-7 | C29: 1 | D29: =19.29+0.68 -> 19.97 | E29: =C29*D29 -> 19.97
A30: 22 | B30: ПР-9 | C30: 1 | D30: =20.76+0.68 -> 21.44 | E30: =C30*D30 -> 21.44
A31: 23 | B31: ПР-12 | C31: 1 | D31: =19.29+0.68+1.38 -> 21.35 | E31: =C31*D31 -> 21.35
A32: 24 | B32: ПР-15 | C32: 6 | D32: =28.25+0.9+1.38 -> 30.53 | E32: =C32*D32 -> 183.18
A33: 25 | B33: ПР-16 | C33: 1 | D33: =28.28+0.9+1.38 -> 30.56 | E33: =C33*D33 -> 30.56
A34: 26 | B34: ПР-18 | C34: 1 | D34: =23.43+0.9+2.76 -> 27.09 | E34: =C34*D34 -> 27.09
A35: 27 | B35: ПР-25 | C35: 1 | D35: =24.8+0.9+2.76 -> 28.46 | E35: =C35*D35 -> 28.46
A36: 28 | B36: ПР-27 | C36: 1 | D36: =27.56+0.9+1.38 -> 29.84 | E36: =C36*D36 -> 29.84
A37: 29 | B37: ПР-28 | C37: 1 | D37: =53.9+1.13+2.76 -> 57.79 | E37: =C37*D37 -> 57.79
D38: Итог: | E38: =SUM(E27:E37) -> 484

Sheet КП
