Workbook

Sheet ВОР 2 э. шт.
B1: Ведомость работ и используемых материалов (2, 3 этаж)
A2: № п.п. | B2: Наименование | C2: Ед. изм. | D2: Коэф. расхода | E2: Объем
A3: 1 | B3: Подготовка поверхности СКБ / потолка / ЖБ / 5 мм тип П-6 | C3: м2 | D3: 1 | E3: ='Спец 2 э. шт.'!C35 -> 1500.73
A4: 1.2 | B4: Шпатлевка гипсовая | C4: кг | D4: 4.5 | E4: =D4*E3 -> 6753.285
A5: 1.3 | B5: Грунтовка БЕТОН-КОНТАКТ | C5: кг | D5: 0.15 | E5: =D5*E3 -> 225.1095
A6: 2 | B6: Подготовка поверхности СКБ / потолка / ЖБ / 5 мм тип П-9 | C6: м2 | D6: 1 | E6: ='Спец 2 э. шт.'!D35 -> 232.12
A7: 2.1 | B7: Шпатлевка гипсовая | C7: кг | D7: 4.5 | E7: =D7*E6 -> 1044.54
A8: 2.2 | B8: Грунтовка БЕТОН-КОНТАКТ | C8: кг | D8: 0.15 | E8: =D8*E6 -> 34.818
A9: 3 | B9: Подготовка поверхности СКБ / стен / ГКЛ, ПГП / 2мм тип П-15 | C9: м2 | D9: 1 | E9: ='Спец 2 э. шт.'!E35 -> 29.909
A10: 3.1 | B10: Грунтовка универсальный ЛАСТИМИН_ / LP-51 А | C10: кг | D10: 0.15 | E10: =D10*E9 -> 4.48635
A11: 3.2 | B11: Уголок малярный_/перфорированный/25*25*3000мм | C11: шт | D11: 0.3 | E11: =D11*E9 -> 8.9727
A12: 3.3 | B12: Шпатлевка гипсовая_ / белая / Унифицированная по ПИК-СТАНДАРТ, 30кг | C12: кг | D12: 1.5 | E12: =D12*E9 -> 44.8635

Sheet Спец 2 э. шт.
A1: Спецификация выполненных работ (2, 3 этаж)
A2: Шпаклевка потолка
C3: П-6 | D3: П-9 | E3: П-15 | F3: Итог | J3: ТИП
A4: № п.п. | B4: Помещения: | C4: Объем, м² | D4: Объем, м² | E4: Объем, м² | F4: Объем, м²
A5: 1 | B5: 2.004 | C5: 171.644 | F5: =SUM(C5:E5) -> 171.644 | H5: 156.04
A6: 2 | B6: 2.005 | E6: 15.026 | F6: =SUM(C6:E6) -> 15.026 | J6: 13.66
A7: 3 | B7: 2.012 | C7: 162.118 | F7: =SUM(C7:E7) -> 162.118 | H7: 147.38
A8: 4 | B8: 2.014 | D8: 18.909 | F8: =SUM(C8:E8) -> 18.909 | I8: 17.19
A9: 5 | B9: 2.015 | D9: 23.309 | F9: =SUM(C9:E9) -> 23.309 | I9: 21.19
A10: 6 | B10: 2.016 | D10: 6.303 | F10: =SUM(C10:E10) -> 6.303 | I10: 5.73
A11: 7 | B11: 2.017 | D11: 3.531 | F11: =SUM(C11:E11) -> 3.531 | I11: 3.21
A12: 8 | B12: 2.075 | C12: 87.296 | F12: =SUM(C12:E12) -> 87.296 | H12: 79.36
A13: 9 | B13: 2.080 | C13: 160.842 | F13: =SUM(C13:E13) -> 160.842 | H13: 146.22
A14: 10 | B14: 2.082 | C14: 59.191 | F14: =SUM(C14:E14) -> 59.191 | H14: 53.81
A15: 11 | B15: 2.089 | D15: 6.655 | F15: =SUM(C15:E15) -> 6.655 | I15: 6.05
A16: 12 | B16: 2.090 | D16: 13.365 | F16: =SUM(C16:E16) -> 13.365 | I16: 12.15
A17: 13 | B17: 2.091 | D17: 11.737 | F17: =SUM(C17:E17) -> 11.737 | I17: 10.67
A18: 14 | B18: 2.095 | D18: 9.669 | F18: =SUM(C18:E18) -> 9.669 | I18: 8.79
A19: 15 | B19: 2.096 | D19: 15.719 | F19: =SUM(C19:E19) -> 15.719 | I19: 14.29
A20: 16 | B20: 2.100 | D20: 8.767 | F20: =SUM(C20:E20) -> 8.767 | I20: 7.97
A21: 17 | B21: 2.101 | D21: 13.189 | F21: =SUM(C21:E21) -> 13.189 | I21: 11.99
A22: 18 | B22: 2.104 | D22: 9.152 | F22: =SUM(C22:E22) -> 9.152 | I22: 8.32
A23: 19 | B23: 2.105 | D23: 15.499 | F23: =SUM(C23:E23) -> 15.499 | I23: 14.09
A24: 20 | B24: 2.107 | D24: 8.13 | F24: =SUM(C24:E24) -> 8.13 | I24: 0
A25: 21 | B25: 2.108 | D25: 16.09 | F25: =SUM(C25:E25) -> 16.09 | I25: 0
A26: 22 | B26: 3.005 | C26: 272.019 | F26: =SUM(C26:E26) -> 272.019 | H26: 247.29
A27: 23 | B27: 3.006 | E27: 14.883 | F27: =SUM(C27:E27) -> 14.883 | J27: 13.53
A28: 24 | B28: 3.014 | C28: 163.35 | F28: =SUM(C28:E28) -> 163.35 | H28: 148.5
A29: 25 | B29: 3.015 | D29: 18.986 | F29: =SUM(C29:E29) -> 18.986 | I29: 17.26
A30: 26 | B30: 3.016 | D30: 23.287 | F30: =SUM(C30:E30) -> 23.287 | I30: 21.17
A31: 27 | B31: 3.017 | D31: 6.303 | F31: =SUM(C31:E31) -> 6.303 | I31: 5.73
A32: 28 | B32: 3.018 | D32: 3.52 | F32: =SUM(C32:E32) -> 3.52 | I32: 3.2
A33: 29 | B33: 3.019 | C33: 275.209 | F33: =SUM(C33:E33) -> 275.209 | H33: 250.19
A34: 30 | B34: 3.020 | C34: 149.061 | F34: =SUM(C34:E34) -> 149.061 | H34: 135.51
B35: сумма: | C35: =SUM(C5:C34) -> 1500.73 | D35: =SUM(D5:D34) -> 232.12 | E35: =SUM(E5:E34) -> 29.909 | F35: =SUM(F5:F34) -> 1762.759

Sheet Спец 2 эт. шлиф.
A1: Спецификация выполненных работ (2 этаж)
A2: Шлифовка поверхностей потолка.
A3: № п.п. | B3: № помещения: | C3: Объем, м²
A4: 1 | B4: 2.001 | C4: 78.238
A5: 2 | B5: 2.002 | C5: 79.464
A6: 3 | B6: 2.003 | C6: 76.086
A7: 4 | B7: 2.004 | C7: 171.644
A8: 5 | B8: 2.005 | C8: 15.026
A9: 6 | B9: 2.006 | C9: 26.3025
A10: 7 | B10: 2.007 | C10: 72.715
A11: 8 | B11: 2.008 | C11: 72.883
A12: 9 | B12: 2.009 | C12: 72.883
A13: 10 | B13: 2.010 | C13: 71.9065
A14: 11 | B14: 2.011 | C14: 71.883
A15: 12 | B15: 2.012 | C15: 162.118
... A47: 44 | B47: 2.168 | C47: 8.421
B48: Итог: | C48: =SUM(C4:C47) -> 1859.466

Sheet 1этВор
B1: Ведомость работ и используемых материалов
A2: № п.п. | B2: Наименование | E2: Объем
A3: 1 | B3: Шлифование бетонных поверхностей | C3: м² | E3: =SUM('1эт спец'!D25+'1эт спец'!D23+'1эт спец'!D21+'1эт спец'!D19+'1эт спец'!D17+'1эт спец'!D15+'1эт спец'!D13+'1эт спец'!D8+'1эт спец'!D3) -> 1268.47
A4: 2 | B4: Штукатурка цементным составом толщиной 21-40 мм | C4: м² | E4: 58.52
A5: 2.1 | B5: Грунтовка универсальный ЛАСТИМИН / LP-51 А | C5: кг | E5: =E4*0.25 -> 14.63
A6: 2.2 | B6: Штукатурка цементная | C6: кг | E6: =E4*0.15 -> 8.778
A7: 2.3 | B7: Сетка штукатурная стеклопакетная 10х10 мм | C7: м² | E7: 58.52
A8: 2.4 | B8: Профиль углозащитный оцинкованный 31х31 мм 0,5 мм | C8: п.м | E8: 111.69
A9: 3 | B9: Подготовка поверхности потолка СКБ | C9: м² | E9: 1268.47
A10: 3.1 | B10: Шпатлевка гипсовая белая | C10: кг | E10: =E9*4.5 -> 5708.115
A11: 3.2 | B11: Грунт универсальный ЛАСТИМИН | C11: кг | E11: =E9*0.15 -> 190.2705
B13: Ведомость работ и используемых материалов
A14: № п.п. | B14: Наименование | C14: Ед. изм. | D14: Коэф. расхода | E14: Объем
A15: 1 | B15: Шлифование бетонных поверхностей | C15: м² | D15: 1 | E15: =E17 -> 1268.47
A16: 2 | B16: Штукатурка цементным составом толщиной 21-40 мм | C16: м² | D16: 1 | E16: 58.52
A17: 3 | B17: Подготовка поверхности потолка СКБ | C17: м² | D17: 1 | E17: 1268.47
A18: 3.1 | B18: Шпатлевка гипсовая белая | C18: кг | D18: 4.5 | E18: =E17*4.5 -> 5708.115
A19: 3.2 | B19: Грунтовка БЕТОН-КОНТАКТ | C19: кг | D19: 0.15 | E19: =E17*0.15 -> 190.2705

Sheet 1эт спец
C1: Спецификация выполненных работ
A2: № п.п. | B2: Помещения: | C2: Наименование | D2: Объем, м²
A3: 1 | B3: 1.045, 1.046 | C3: Шлифование бетонных поверхностей | D3: 336.4
B4: П-6 | C4: Штукатурка цементным составом толщиной 21-40 мм | D4: 30.2
C5: Сетка штукатурная стеклопакетная 10х10 мм | D5: =D4 -> 30.2
C6: Профиль углозащитный оцинкованный 31х31 мм 0,5 мм | D6: 60.41 п.м.
C7: Подготовка поверхности потолка СКБ | D7: =D3 -> 336.4
A8: 2 | B8: 1.053, 1.054 | C8: Шлифование бетонных поверхностей | D8: 543.35
B9: П-6, П-12 | C9: Штукатурка цементным составом толщиной 21-40 мм | D9: 28.32
C10: Сетка штукатурная стеклопакетная 10х10 мм | D10: =D9 -> 28.32
C11: Профиль углозащитный оцинкованный 31х31 мм 0,5 мм | D11: 51.28 п.м.
C12: Подготовка поверхности потолка СКБ | D12: =D8 -> 543.35
A13: 3 | B13: 1.039 | C13: Шлифование бетонных поверхностей | D13: 143.86
B14: П-6 | C14: Подготовка поверхности потолка СКБ | D14: =D13 -> 143.86
A15: 4 | B15: 1.038 | C15: Шлифование бетонных поверхностей | D15: 5.24
B16: П-5 | C16: Подготовка поверхности потолка СКБ | D16: =D15 -> 5.24
A17: 5 | B17: 1.037 | C17: Шлифование бетонных поверхностей | D17: 12.32
B18: П-9 | C18: Подготовка поверхности потолка СКБ | D18: =D17 -> 12.32
A19: 6 | B19: 1.036 | C19: Шлифование бетонных поверхностей | D19: 5.67
B20: П-9 | C20: Подготовка поверхности потолка СКБ | D20: =D19 -> 5.67
A21: 7 | B21: 1.035 | C21: Шлифование бетонных поверхностей | D21: 12.01
B22: П-9.1 | C22: Подготовка поверхности потолка СКБ | D22: =D21 -> 12.01
A23: 8 | B23: 1.034 | C23: Шлифование бетонных поверхностей | D23: 17.24
B24: П-9 | C24: Подготовка поверхности потолка СКБ | D24: =D23 -> 17.24
A25: 9 | B25: 1.026 | C25: Шлифование бетонных поверхностей | D25: 192.38
B26: П-6 | C26: Подготовка поверхности потолка СКБ | D26: =D25 -> 192.38

Sheet Вор2Вып

Sheet 9.3П8
A1: Спецификация выполненных работ
A2: № п.п. | B2: Наименование | G2: Описание | I2: Ед. изм. | K2: Объем
A3: 1 | B3: Монтаж подвесного потолка / из акустических древесных плит | G3: Тип П-8 | I3: м2 | K3: =C13+C19+G15+K16 -> 2125.22
A5: № п.п. | B5: Пом.: | C5: Объем, м² | E5: № п.п. | F5: Пом.: | G5: Объем, м² | I5: № п.п. | J5: Пом.: | K5: Объем, м²
A6: 1 | B6: 1.027 | C6: 114.46 | E6: 1 | F6: 2.001 | G6: 73.85 | I6: 1 | J6: 3.001 | K6: 127.87
A7: 2 | B7: 1.028 | C7: 69 | E7: 2 | F7: 2.002 | G7: 72.41 | I7: 2 | J7: 3.002 | K7: 73.17
A8: 3 | B8: 1.029 | C8: 69.06 | E8: 3 | F8: 2.003 | G8: 68.52 | I8: 3 | J8: 3.003 | K8: 71.7
A9: 4 | B9: 1.030 | C9: 69.32 | E9: 4 | F9: 2.007 | G9: 68.55 | I9: 4 | J9: 3.004 | K9: 67.69
A10: 5 | B10: 1.031 | C10: 69.03 | E10: 5 | F10: 2.008 | G10: 68.64 | I10: 5 | J10: 3.008 | K10: 67.83
A11: 6 | B11: 1.032 | C11: 68.28 | E11: 6 | F11: 2.009 | G11: 68.46 | I11: 6 | J11: 3.009 | K11: 68.18
A12: 7 | B12: 1.033 | C12: 137.83 | E12: 7 | F12: 2.010 | G12: 67.58 | I12: 7 | J12: 3.010 | K12: 68.01
B13: Итог: | C13: =SUM(C6:C12) -> 596.98 | E13: 8 | F13: 2.011 | G13: 68.46 | I13: 8 | J13: 3.011 | K13: 67.14
E14: 9 | F14: 2.013 | G14: 68.27 | I14: 9 | J14: 3.012 | K14: 68
A15: № п.п. | B15: Пом.: | C15: Объем, м² | F15: Итог: | G15: =SUM(G6:G14) -> 624.74 | I15: 10 | J15: 3.013 | K15: 67.81
A16: 1 | B16: 1.049 | C16: 103.08 | J16: Итог: | K16: =SUM(K6:K15) -> 747.4
A17: 2 | B17: 1.050 | C17: 22.05
A18: 3 | B18: 1.051 | C18: 30.97
B19: Итог: | C19: =SUM(C16:C18) -> 156.1

Sheet 7.2КрсИнж
A1: Спецификация выполненных работ
A2: № п.п. | B2: Наименование | E2: Описание | G2: Ед. изм. | H2: Объем
A3: 1 | B3: Лакокрасочные работы СКБ / окраска потолков / | E3: окраска инженерных коммуникации / | G3: м2 | H3: =C14 -> 1205.9
A5: № п.п. | B5: Пом.: | C5: Итог Объем, м²
A6: 1 | B6: 1.053 | C6: 411.5
A7: 2 | B7: 1.046 | C7: 128.1
A8: 3 | B8: 1.045 | C8: 134.3
A9: 4 | B9: 2.075 | C9: 53.4
A10: 5 | B10: 2.080 | C10: 144.4
A11: 6 | B11: 2.082 | C11: 6.4
A12: 7 | B12: 3.019 | C12: 216.1
A13: 8 | B13: 3.020 | C13: 111.7
B14: Итог: | C14: =SUM(C6:C13) -> 1205.9

Sheet 7.1КрсИнж
A1: Спецификация выполненных работ
A2: № п.п. | B2: Наименование | E2: Описание | G2: Ед. изм. | H2: Объем
A3: 1 | B3: Лакокрасочные работы СКБ / окраска потолков / | E3: окраска инженерных коммуникации | G3: м2 | H3: =C12 -> 1482.242
A5: № п.п. | B5: Пом.: | C5: Итог Объем, м²
A6: 1 | B6: 1.026 | C6: =191.78+15.6*3+0.4*0.4*6.2+13*0.1*2*4+0.942*13 -> 262.218
A7: 2 | B7: 1.039 | C7: =146.45+59.6+0.942*13 -> 218.296
A8: 3 | B8: 2.004 | C8: =158.69+15.6*3+0.4*0.4*6.2+13*0.1*2*4+0.942*13 -> 229.128
A9: 4 | B9: 2.012 | C9: =145.8+59.6+0.942*13 -> 217.646
A10: 5 | B10: 3.005 | C10: =243.62+15.6*3+0.4*0.4*6.2+13*0.1*2*4+0.942*13 -> 314.058
A11: 6 | B11: 3.014 | C11: =146.65+59.6+22.4+0.942*13 -> 240.896
B12: Итог: | C12: =SUM(C6:C11) -> 1482.242

Sheet 6.5П7,10 (2)
A1: Спецификация выполненных работ
A2: № п.п. | B2: Наименование | G2: Описание | I2: Ед. изм. | K2: Объем
A3: 1 | B3: Монтаж подвесного потолка / из ГКЛ в 1 слой с применением профиля ПП | G3: Тип П-7 | I3: м2 | K3: =C7 -> 167.53
A5: № п.п. | B5: Пом.: | C5: Объем, м²
A6: 1 | B6: 2.085 | C6: 167.53
A7: Итог: | B7: Тип П-7 | C7: =SUM(C6:C6) -> 167.53

Sheet 6.4П8
A1: Спецификация выполненных работ
A2: № п.п. | B2: Наименование | G2: Описание | I2: Ед. изм. | K2: Объем
A3: 1 | B3: Монтаж подвесного потолка / из акустических древесных плит | G3: Тип П-8 | I3: м2 | K3: =C9 -> 155.35
A5: № п.п. | B5: Пом.: | C5: Объем, м²
A6: 1 | B6: 1.049 | C6: 102.83
A7: 2 | B7: 1.050 | C7: 21.8
A8: 3 | B8: 1.051 | C8: 30.72
B9: Итог: | C9: =SUM(C6:C8) -> 155.35

Sheet 6.3П8
A1: Спецификация выполненных работ
A2: № п.п. | B2: Наименование | G2: Описание | I2: Ед. изм. | K2: Объем
A3: 1 | B3: Монтаж подвесного потолка / из акустических древесных плит | G3: Тип П-8 | I3: м2 | K3: =C13+G15+K16 -> 1966.37
A4: Не забудьте взять позицуию Надбавку. Она в кп чуть ниже
A5: № п.п. | B5: Пом.: | C5: Объем, м² | E5: № п.п. | F5: Пом.: | G5: Объем, м² | I5: № п.п. | J5: Пом.: | K5: Объем, м²
A6: 1 | B6: 1.027 | C6: 114.21 | E6: 1 | F6: 2.001 | G6: 73.6 | I6: 1 | J6: 3.001 | K6: 127.87
A7: 2 | B7: 1.028 | C7: 68.75 | E7: 2 | F7: 2.002 | G7: 72.16 | I7: 2 | J7: 3.002 | K7: 73.17
A8: 3 | B8: 1.029 | C8: 68.81 | E8: 3 | F8: 2.003 | G8: 68.27 | I8: 3 | J8: 3.003 | K8: 71.7
A9: 4 | B9: 1.030 | C9: 69.07 | E9: 4 | F9: 2.007 | G9: 68.3 | I9: 4 | J9: 3.004 | K9: 67.69
A10: 5 | B10: 1.031 | C10: 68.78 | E10: 5 | F10: 2.008 | G10: 68.64 | I10: 5 | J10: 3.008 | K10: 67.83
A11: 6 | B11: 1.032 | C11: 68.03 | E11: 6 | F11: 2.009 | G11: 68.46 | I11: 6 | J11: 3.009 | K11: 68.18
A12: 7 | B12: 1.033 | C12: 137.58 | E12: 7 | F12: 2.010 | G12: 67.58 | I12: 7 | J12: 3.010 | K12: 68.01
B13: Итог: | C13: =SUM(C6:C12) -> 595.23 | E13: 8 | F13: 2.011 | G13: 68.46 | I13: 8 | J13: 3.011 | K13: 67.14
E14: 9 | F14: 2.013 | G14: 68.27 | I14: 9 | J14: 3.012 | K14: 68
F15: Итог: | G15: =SUM(G6:G14) -> 623.74 | I15: 10 | J15: 3.013 | K15: 67.81
J16: Итог: | K16: =SUM(K6:K15) -> 747.4

Sheet 6.2П7,10
A1: Спецификация выполненных работ
A2: № п.п. | B2: Наименование | G2: Описание | I2: Ед. изм. | K2: Объем
A3: 1 | B3: Монтаж подвесного потолка / из ГКЛ в 1 слой с применением профиля ПП | G3: Тип П-10 | I3: м2 | K3: =C9 -> 292.98
A4: Не забудьте взять позицуию Надбавку. Она в кп чуть ниже
A5: № п.п. | B5: Пом.: | C5: Объем, м²
A6: 1 | B6: 1.040 | C6: 219.5
A7: 2 | B7: 1.043 | C7: 59.48
A8: 3 | B8: 1.044 | C8: 14
A9: Итог: | B9: Тип П-10 | C9: =SUM(C6:C8) -> 292.98

Sheet 6.1П9
A1: Спецификация выполненных работ
A2: № п.п. | B2: Наименование | G2: Описание | I2: Ед. изм. | K2: Объем
A3: 1 | B3: Монтаж подвесного потолка / типа Грильято | G3: Тип П-9 | I3: м2 | K3: =C10+G21+K10 -> 258.1
A4: Не забудьте взять позицуию Надбавку. Она в кп чуть ниже
A5: № п.п. | B5: Пом.: | C5: Объем, м² | E5: № п.п. | F5: Пом.: | G5: Объем, м² | I5: № п.п. | J5: Пом.: | K5: Объем, м²
A6: 1 | B6: 1.014 | C6: 17.2 | E6: 1 | F6: 2.014 | G6: 17.2 | I6: 1 | J6: 3.015 | K6: 17.2
A7: 2 | B7: 1.015 | C7: 20.7 | E7: 2 | F7: 2.015 | G7: 20.7 | I7: 2 | J7: 3.016 | K7: 20.7
A8: 3 | B8: 1.016 | C8: 5.5 | E8: 3 | F8: 2.016 | G8: 5.5 | I8: 3 | J8: 3.017 | K8: 5.5
A9: 4 | B9: 1.017 | C9: 3 | E9: 4 | F9: 2.017 | G9: 3 | I9: 4 | J9: 3.018 | K9: 3
B10: Итог: | C10: =SUM(C6:C9) -> 46.4 | E10: 5 | F10: 2.089 | G10: 6.08 | J10: Итог: | K10: =SUM(K6:K9) -> 46.4
E11: 6 | F11: 2.090 | G11: 12.15
E12: 7 | F12: 2.091 | G12: 10.67
E13: 8 | F13: 2.095 | G13: 8.81
E14: 9 | F14: 2.096 | G14: 14.23
E15: 10 | F15: 2.100 | G15: 8.13
E16: 11 | F16: 2.101 | G16: 12.22
E17: 12 | F17: 2.104 | G17: 8.35
E18: 13 | F18: 2.105 | G18: 14.03
E19: 12 | F19: 2.107 | G19: 8.03
E20: 13 | F20: 2.108 | G20: 16.2
F21: Итог: | G21: =SUM(G6:G20) -> 165.3

Sheet Общий
A1: Спецификация выполненных работ | G1: Спецификация выполненных работ
A2: № п.п. | B2: Блок | C2: № пом. | D2: Типы | E2: Объем. м² | G2: № п.п. | H2: Блок | I2: Типы | J2: Объем. м²
A3: 1 | B3: 1 | C3: 1.038 | D3: 5 | E3: 5.25 | H3: 1 | I3: 5 | J3: 5.24
A4: 2 | B4: 4.1 | C4: 1.048 | D4: 5 | E4: 23.92 | F4: 191.68 | H4: 4.1 | I4: 5 | J4: 23.92
A5: 3 | B5: 1 | C5: 1.024 | D5: 6 | E5: 13.62 | F5: 114.04 | H5: 1 | I5: 6 | J5: 352.16
A6: 4 | B6: 1 | C6: 1.026 | D6: 6 | E6: 191.68 | F6: 68.81 | H6: 4.1 | I6: 6 | J6: 762.49 | L6: 3.015; 3.016; 3.017; 3.018
A7: 5 | B7: 1 | C7: 1.039 | D7: 6 | E7: 149.7 | F7: 68.81 | H7: 1 | I7: 7 | J7: 38.21 | L7: =--MID($L$6,IF(ROW(A1)=1,1,FIND("; ",$L$6,FIND("; ",$L$6,1)*(ROW(A1)-1))+2),FIND("; ",$L$6&"; ",IF(ROW(A1)=1,1,FIND("; ",$L$6,FIND("; ",$L$6,1)*(ROW(A1)-1))+2))-IF(ROW(A1)=1,1,FIND("; ",$L$6,FIND("; ",$L$6,1)*(ROW(A1)-1))+2)) -> #VALUE!
A8: 6 | B8: 4.1 | C8: 1.045 | D8: 6 | E8: 161.78 | F8: 68.89 | H8: 1 | I8: 8 | J8: 596.26 | L8: =--MID($L$6,IF(ROW(A2)=1,1,FIND("; ",$L$6,FIND("; ",$L$6,1)*(ROW(A2)-1))+2),FIND("; ",$L$6&"; ",IF(ROW(A2)=1,1,FIND("; ",$L$6,FIND("; ",$L$6,1)*(ROW(A2)-1))+2))-IF(ROW(A2)=1,1,FIND("; ",$L$6,FIND("; ",$L$6,1)*(ROW(A2)-1))+2)) -> #VALUE!
A9: 7 | B9: 4.1 | C9: 1.046 | D9: 6 | E9: 161.15 | F9: 68.89 | H9: 4.1 | I9: 8 | J9: 156.6 | L9: =--MID($L$6,IF(ROW(A3)=1,1,FIND("; ",$L$6,FIND("; ",$L$6,1)*(ROW(A3)-1))+2),FIND("; ",$L$6&"; ",IF(ROW(A3)=1,1,FIND("; ",$L$6,FIND("; ",$L$6,1)*(ROW(A3)-1))+2))-IF(ROW(A3)=1,1,FIND("; ",$L$6,FIND("; ",$L$6,1)*(ROW(A3)-1))+2)) -> #VALUE!
A10: 8 | B10: 4.1 | C10: 1.053 | D10: 6 | E10: 443.48 | F10: 68.07 | H10: 1 | I10: 9 | J10: 46.57 | L10: =--MID($L$6,IF(ROW(A4)=1,1,FIND("; ",$L$6,FIND("; ",$L$6,1)*(ROW(A4)-1))+2),FIND("; ",$L$6&"; ",IF(ROW(A4)=1,1,FIND("; ",$L$6,FIND("; ",$L$6,1)*(ROW(A4)-1))+2))-IF(ROW(A4)=1,1,FIND("; ",$L$6,FIND("; ",$L$6,1)*(ROW(A4)-1))+2)) -> #VALUE!
A11: 9 | B11: 1 | C11: 1.027 | D11: 8 | E11: 114.04 | F11: 139.1 | H11: 4.1 | I11: 10 | J11: 296.76 | L11: =--MID($L$6,IF(ROW(A5)=1,1,FIND("; ",$L$6,FIND("; ",$L$6,1)*(ROW(A5)-1))+2),FIND("; ",$L$6&"; ",IF(ROW(A5)=1,1,FIND("; ",$L$6,FIND("; ",$L$6,1)*(ROW(A5)-1))+2))-IF(ROW(A5)=1,1,FIND("; ",$L$6,FIND("; ",$L$6,1)*(ROW(A5)-1))+2)) -> #VALUE!
A12: 10 | B12: 1 | C12: 1.028 | D12: 8 | E12: 68.81 | F12: 17.22 | H12: 4.1 | I12: 12 | J12: 58.61 | L12: =--MID($L$6,IF(ROW(A6)=1,1,FIND("; ",$L$6,FIND("; ",$L$6,1)*(ROW(A6)-1))+2),FIND("; ",$L$6&"; ",IF(ROW(A6)=1,1,FIND("; ",$L$6,FIND("; ",$L$6,1)*(ROW(A6)-1))+2))-IF(ROW(A6)=1,1,FIND("; ",$L$6,FIND("; ",$L$6,1)*(ROW(A6)-1))+2)) -> #VALUE!
A13: 11 | B13: 1 | C13: 1.029 | D13: 8 | E13: 68.81 | F13: 21.63 | L13: =--MID($L$6,IF(ROW(A7)=1,1,FIND("; ",$L$6,FIND("; ",$L$6,1)*(ROW(A7)-1))+2),FIND("; ",$L$6&"; ",IF(ROW(A7)=1,1,FIND("; ",$L$6,FIND("; ",$L$6,1)*(ROW(A7)-1))+2))-IF(ROW(A7)=1,1,FIND("; ",$L$6,FIND("; ",$L$6,1)*(ROW(A7)-1))+2)) -> #VALUE!
A14: 12 | B14: 1 | C14: 1.03 | D14: 8 | E14: 68.89 | F14: 5.76 | L14: =--MID($L$6,IF(ROW(A8)=1,1,FIND("; ",$L$6,FIND("; ",$L$6,1)*(ROW(A8)-1))+2),FIND("; ",$L$6&"; ",IF(ROW(A8)=1,1,FIND("; ",$L$6,FIND("; ",$L$6,1)*(ROW(A8)-1))+2))-IF(ROW(A8)=1,1,FIND("; ",$L$6,FIND("; ",$L$6,1)*(ROW(A8)-1))+2)) -> #VALUE!
A15: 13 | B15: 1 | C15: 1.031 | D15: 8 | E15: 68.89 | F15: 3.34 | L15: =--MID($L$6,IF(ROW(A9)=1,1,FIND("; ",$L$6,FIND("; ",$L$6,1)*(ROW(A9)-1))+2),FIND("; ",$L$6&"; ",IF(ROW(A9)=1,1,FIND("; ",$L$6,FIND("; ",$L$6,1)*(ROW(A9)-1))+2))-IF(ROW(A9)=1,1,FIND("; ",$L$6,FIND("; ",$L$6,1)*(ROW(A9)-1))+2)) -> #VALUE!
A16: 14 | B16: 1 | C16: 1.032 | D16: 8 | E16: 68.07 | F16: 5.25 | L16: =--MID($L$6,IF(ROW(A10)=1,1,FIND("; ",$L$6,FIND("; ",$L$6,1)*(ROW(A10)-1))+2),FIND("; ",$L$6&"; ",IF(ROW(A10)=1,1,FIND("; ",$L$6,FIND("; ",$L$6,1)*(ROW(A10)-1))+2))-IF(ROW(A10)=1,1,FIND("; ",$L$6,FIND("; ",$L$6,1)*(ROW(A10)-1))+2)) -> #VALUE!
A17: 15 | B17: 1 | C17: 1.033 | D17: 8 | E17: 139.1 | L17: =--MID($L$6,IF(ROW(A11)=1,1,FIND("; ",$L$6,FIND("; ",$L$6,1)*(ROW(A11)-1))+2),FIND("; ",$L$6&"; ",IF(ROW(A11)=1,1,FIND("; ",$L$6,FIND("; ",$L$6,1)*(ROW(A11)-1))+2))-IF(ROW(A11)=1,1,FIND("; ",$L$6,FIND("; ",$L$6,1)*(ROW(A11)-1))+2)) -> #VALUE!
A18: 16 | B18: 4.1 | C18: 1.049 | D18: 8 | E18: 103.8 | L18: =--MID($L$6,IF(ROW(A12)=1,1,FIND("; ",$L$6,FIND("; ",$L$6,1)*(ROW(A12)-1))+2),FIND("; ",$L$6&"; ",IF(ROW(A12)=1,1,FIND("; ",$L$6,FIND("; ",$L$6,1)*(ROW(A12)-1))+2))-IF(ROW(A12)=1,1,FIND("; ",$L$6,FIND("; ",$L$6,1)*(ROW(A12)-1))+2)) -> #VALUE!
A19: 17 | B19: 4.1 | C19: 1.05 | D19: 8 | E19: 22 | L19: =--MID($L$6,IF(ROW(A13)=1,1,FIND("; ",$L$6,FIND("; ",$L$6,1)*(ROW(A13)-1))+2),FIND("; ",$L$6&"; ",IF(ROW(A13)=1,1,FIND("; ",$L$6,FIND("; ",$L$6,1)*(ROW(A13)-1))+2))-IF(ROW(A13)=1,1,FIND("; ",$L$6,FIND("; ",$L$6,1)*(ROW(A13)-1))+2)) -> #VALUE!
A20: 18 | B20: 4.1 | C20: 1.051 | D20: 8 | E20: 31.58
A21: 21 | B21: 1 | C21: 1.034 | D21: 9 | E21: 17.22
A22: 22 | B22: 1 | C22: 1.035 | D22: 9 | E22: 21.63
A23: 20 | B23: 1 | C23: 1.036 | D23: 9 | E23: 5.76
A24: 19 | B24: 1 | C24: 1.037 | D24: 9 | E24: 3.34
A25: 23 | B25: 4.1 | C25: 1.04 | D25: 10 | E25: 220.47
A26: 24 | B26: 4.1 | C26: 1.043 | D26: 10 | E26: 61.99
A27: 25 | B27: 4.1 | C27: 1.044 | D27: 10 | E27: 14.14 | K27: =296.76-E25-E26 -> 14.3
A28: 26 | B28: 4.1 | C28: 1.054 | D28: 12 | E28: 58.14
A31: Спецификация выполненных работ | G31: Спецификация выполненных работ
A32: № п.п. | B32: Блок | C32: № пом. | D32: Типы | E32: Объем. м² | G32: № п.п. | H32: Блок | I32: Типы | J32: Объем. м²
A33: 28 | B33: 1 | C33: 2.001 | D33: 8 | E33: 73.55 | F33: 1.049 | H33: 4.1 | I33: 4 | J33: 115.28
A34: 27 | B34: 1 | C34: 2.002 | D34: 8 | E34: 72.24 | F34: 1.05 | H34: 1 | I34: 5 | J34: 5.24
A35: 21 | B35: 1 | C35: 2.003 | D35: 8 | E35: 68.26 | F35: 1.051 | H35: 4.1 | I35: 5 | J35: 180.8
A36: 14 | B36: 1 | C36: 2.004 | D36: 6 | E36: 158.71 | H36: 1 | I36: 6 | J36: 306.63
A37: 43 | B37: 1 | C37: 2.005 | D37: 15 | E37: 13.62 | H37: 4.1 | I37: 6 | J37: 282.87
A38: 23 | B38: 1 | C38: 2.007 | D38: 8 | E38: 68.3 | H38: 4.1 | I38: 7 | J38: 169.2
A39: 26 | B39: 1 | C39: 2.008 | D39: 8 | E39: 68.46 | H39: 1 | I39: 8 | J39: 625.17
A40: 25 | B40: 1 | C40: 2.009 | D40: 8 | E40: 68.46 | H40: 1 | I40: 9 | J40: 46.57
A41: 20 | B41: 1 | C41: 2.01 | D41: 8 | E41: 67.64 | H41: 4.1 | I41: 9 | J41: 119.43
A42: 24 | B42: 1 | C42: 2.011 | D42: 8 | E42: 68.46 | H42: 4.1 | I42: 13 | J42: 299.02
...

Sheet 4.СКБвор
B1: Ведомость работ и используемых материалов
A2: № п.п. | B2: Наименование | C2: Ед. изм. | D2: Коэф. расхода | E2: Объем
A3: 1 | B3: Подготовка поверхности СКБ / потолка / ЖБ / 5 мм тип П-6, П-13, П-14, П-16 | C3: м2 | D3: 1 | E3: ='4.СКБспец'!E9 -> 637
A4: 1.2 | B4: Шпатлевка гипсовая | C4: кг | D4: 4.5 | E4: =D4*E3 -> 2866.5
A5: 1.3 | B5: Грунтовка БЕТОН-КОНТАКТ | C5: кг | D5: 0.15 | E5: =D5*E3 -> 95.55

Sheet 4.СКБспец
A1: Спецификация выполненных работ
A2: № п.п. | B2: Блок | C2: № пом. | D2: Типы | E2: Объем. м²
A3: 1 | B3: 1 | C3: 1.024 | D3: 6 | E3: 11.62
A4: 2 | B4: 4.1 | C4: 2.081 | D4: 13 | E4: 228.82
A5: 3 | B5: 4.1 | C5: 3.021 | D5: 13 | E5: 13.72
A6: 4 | B6: 4.1 | C6: 3.077.2 | D6: 14 | E6: 110.8
A7: 5 | B7: 4.1 | C7: 3.085 | D7: 16 | E7: 13.16
A8: 6 | B8: 4.1 | C8: 2.079 | D8: 16 | E8: 258.88
D9: сумма | E9: =SUM(E3:E8) -> 637

Sheet 5.Кр-Пт
B1: Ведомость работ и используемых материалов
A2: № п.п. | B2: Наименование | C2: Тип | D2: Ед. изм. | E2: Коэф. расхода | F2: Объем
A3: 1 | B3: Лакокрасочные работы СКБ / окраска потолков / в 2 слоя | C3: Тип-9 | D3: м2 | E3: 1 | F3: =ПокрПом!E28 -> 196.12
A4: 1.2 | B4: Огнестойкая краска КМ-0, Краска НГ | D4: кг | E4: 0.3 | F4: =E4*F3 -> 58.836
A5: 1.3 | B5: Грунтовка универсальный ЛАСТИМИН_ / LP-51 А | D5: кг | E5: 0.15 | F5: =E5*F3 -> 29.418
A6: 2 | B6: Лакокрасочные работы СКБ / окраска потолков / в 2 слоя | C6: тип П-13, П-16 | D6: м2 | E6: 1 | F6: =ПокрПом!E39 -> 631.62
A7: 2.1 | B7: Грунтовка универсальный ЛАСТИМИН_ / LP-51 А | D7: кг | E7: 0.15 | F7: =E7*F6 -> 94.743
A8: 2.2 | B8: Матовая огнестойкая краска для высококачественной отделки стен и потолков, RAL 9003 (белый) КМ0/НГ | D8: кг | E8: 0.3 | F8: =E8*F6 -> 189.486
A9: 3 | B9: Лакокрасочные работы СКБ / окраска потолков / в 2 слоя | C9: тип П-6 | D9: м2 | E9: 1 | F9: =ПокрПом!E66 -> 2468.63
A10: 3.1 | B10: матовая огнестойкая краска, Краска НГ RAL 7016 КМ0/НГ | D10: кг | E10: 0.3 | F10: =E10*F9 -> 740.589
A11: 3.2 | B11: Грунтовка универсальный ЛАСТИМИН_ / LP-51 А | D11: кг | E11: 0.15 | F11: =E11*F9 -> 370.2945
A12: 4 | B12: Лакокрасочные работы СКБ / окраска потолков / в 2 слоя | C12: тип П-14 | D12: м2 | E12: 1 | F12: =ПокрПом!E70 -> 132.71
A13: 4.1 | B13: Грунтовка универсальный ЛАСТИМИН_ / LP-51 А | D13: кг | E13: 0.15 | F13: =E13*F12 -> 19.9065
A14: 4.2 | B14: матовая водно-дисперсионная краска RAL 7044 (серый шелк) КМ1/Г1 | D14: кг | E14: 0.3 | F14: =E14*F12 -> 39.813
A15: 5 | B15: Лакокрасочные работы СКБ / окраска потолков / в 2 слоя | C15: П-7, П-10 | D15: м2 | E15: 1 | F15: =ПокрПом!E82 -> 456.2
A16: 5.1 | B16: матовая огнестойкая краска RAL 9003 (белый) КМ0/НГ | D16: кг | E16: 0.3 | F16: =E16*F15 -> 136.86
A17: 5.2 | B17: Грунтовка универсальный ЛАСТИМИН_ / LP-51 А | D17: кг | E17: 0.15 | F17: =E17*F15 -> 68.43
A18: 6 | B18: Лакокрасочные работы СКБ / окраска потолков / в 2 слоя | C18: Тип П-12, П-15 | D18: м2 | E18: 1 | F18: =ПокрПом!E98 -> 106.37
A19: 6.1 | B19: Грунтовка универсальный ЛАСТИМИН_ / LP-51 А | D19: кг | E19: 0.15 | F19: =E19*F18 -> 15.9555
A20: 6.2 | B20: ANTEGA СТРОИТЕЛЬ RAL 9003 (белый) КМ0/НГ | D20: кг | E20: 0.3 | F20: =E20*F18 -> 31.911

Sheet ПокрПом
A1: Спецификация выполненных работ
A2: № п.п. | B2: Блок | C2: № пом. | D2: Типы | E2: Объем. м²
A3: 1 | B3: 1 | C3: 1.034 | D3: 9 | E3: 17.12
A4: 2 | B4: 1 | C4: 1.035 | D4: 9 | E4: 21.34
A5: 3 | B5: 1 | C5: 1.036 | D5: 9 | E5: 5.76
A6: 4 | B6: 1 | C6: 1.037 | D6: 9 | E6: 3.34
D7: Итог: | E7: =SUM(E3:E6) -> 47.56
A8: Спецификация выполненных работ
A9: № п.п. | B9: Блок | C9: № пом. | D9: Типы | E9: Объем. м²
A10: 5 | B10: 1 | C10: 2.014 | D10: 9 | E10: 17.22
A11: 6 | B11: 1 | C11: 2.015 | D11: 9 | E11: 20.93
A12: 7 | B12: 1 | C12: 2.016 | D12: 9 | E12: 5.06
A13: 8 | B13: 1 | C13: 2.017 | D13: 9 | E13: 3.22
A14: 9 | B14: 4.1 | C14: 2.09 | D14: 9 | E14: 12.15
A15: 10 | B15: 4.1 | C15: 2.091 | D15: 9 | E15: 10.63
A16: 11 | B16: 4.1 | C16: 2.095 | D16: 9 | E16: 8.46
A17: 12 | B17: 4.1 | C17: 2.1 | D17: 9 | E17: 8.19
A18: 13 | B18: 4.1 | C18: 2.104 | D18: 9 | E18: 8.32
A19: 14 | B19: 4.1 | C19: 2.107 | D19: 9 | E19: 8.14
D20: Итог: | E20: =SUM(E10:E19) -> 102.32
A21: Спецификация выполненных работ
A22: № п.п. | B22: Блок | C22: № пом. | D22: Типы | E22: Объем. м²
A23: 15 | B23: 1 | C23: 3.015 | D23: 9 | E23: 17.21
A24: 16 | B24: 1 | C24: 3.016 | D24: 9 | E24: 20.87
A25: 17 | B25: 1 | C25: 3.017 | D25: 9 | E25: 5.06
A26: 18 | B26: 1 | C26: 3.018 | D26: 9 | E26: 3.1
D27: Итог: | E27: =SUM(E23:E26) -> 46.24
D28: Сумма: | E28: =E27+E20+E7 -> 196.12
A30: Спецификация выполненных работ
A31: № п.п. | B31: Блок | C31: № пом. | D31: Типы | E31: Объем. м²
A32: 1 | B32: 4.1 | C32: 2.081 | D32: 13 | E32: 295.85
A33: Спецификация выполненных работ
A34: № п.п. | B34: Блок | C34: № пом. | D34: Типы | E34: Объем. м²
A35: 2 | B35: 4.1 | C35: 3.021 | D35: 13 | E35: 15.37
A36: 3 | B36: 4.1 | C36: 3.085 | D36: 16 | E36: 13.08
A37: 4 | B37: 4.1 | C37: 2.079 | D37: 16 | E37: 307.32
D38: сумма: | E38: =SUM(E35:E37) -> 335.77
D39: Итог: | E39: =E38+E32 -> 631.62
A42: Спецификация выполненных работ
A43: № п.п. | B43: Блок | C43: № пом. | D43: Типы | E43: Объем. м²
...
