Workbook

Sheet ВедомостьОбщая
F1: 2эт | G1: 2эт | H1: 2эт | I1: 2эт | J1: 2эт | K1: 2эт | L1: 2эт
B2: 2эт | C2: общая | D2: текущь | E2: остаток | F2: 7 | G2: 6 | H2: 5 | I2: 4 | J2: 3 | K2: 2 | L2: 1 | M2: Что осталось | N2: Спортзал
B3: Штукатурка стен сухими смесями с установкой маяков с предварительной огрунтовкой / толщ. от 21 до 40 мм (Штукатурка по ж/б поверхностям) | C3: 3617.6 | D3: =SUM(F3:L3) -> 1991.3285 | E3: =C3-D3 -> 1626.2715 | F3: ='1.n2'!E6 -> 410.02 | G3: ='2.n2'!E6 -> 333.82 | H3: ='3.n2'!E6 -> 161.17 | I3: ='4.n2'!E6 -> 361.91848 | K3: ='7.n2'!E6 -> 724.4 | L3: - | M3: Библиотека и спорт зал | N3: ='8.n2'!E6 -> 292.2
B4: Штукатурка стен сухими смесями с установкой маяков с предварительной огрунтовкой / толщ. от 21 до 40 мм (Штукатурка по газобетонному блоку и ПГП) | C4: 4510.8 | D4: =SUM(F4:L4) -> 3293.4998 | E4: =C4-D4 -> 1217.3002 | F4: ='1.n2'!E10 -> 603.16 | G4: ='2.n2'!E10 -> 502.91 | H4: ='3.n2'!E10 -> 341.47 | I4: ='4.n2'!E10 -> 697.45979 | K4: ='7.n2'!E10 -> 1148.5 | L4: - | N4: ='8.n2'!E10 -> 240.6
B5: сумма | C5: =SUM(C3:C4) -> 8128.4 | D5: =SUM(D3:D4) -> 5284.8283 | E5: =SUM(E3:E4) -> 2843.5717
B8: 3эт
B9: Штукатурка стен сухими смесями с установкой маяков с предварительной огрунтовкой / толщ. от 21 до 40 мм (Штукатурка по ж/б поверхностям) | C9: 3125.2 | D9: =SUM(F9:L9) -> 2109.6395 | E9: =C9-D9 -> 1015.5605 | F9: ='5.n3'!E6 -> 1389.7395 | G9: - | H9: - | I9: - | K9: ='6.n3э'!E6 -> 719.9 | L9: -
B10: Штукатурка стен сухими смесями с установкой маяков с предварительной огрунтовкой / толщ. от 21 до 40 мм (Штукатурка по газобетонному блоку и ПГП) | C10: 4248.8 | D10: =SUM(F10:L10) -> 3666.3019 | E10: =C10-D10 -> 582.49808 | F10: ='5.n3'!E10 -> 2747.8019 | G10: - | H10: - | I10: - | K10: ='6.n3э'!E10 -> 918.5 | L10: -
C11: =SUM(C9:C10) -> 7374 | D11: =SUM(D9:D10) -> 5775.9415 | E11: =SUM(E9:E10) -> 1598.0585

Sheet 1.n2
B1: Ведомость работ и используемых материалов (Штукатурка)
A2: № п.п. | B2: Наименование | C2: Ед. изм. | D2: Коэф. расхода | E2: Объем
A3: 1 | B3: Оклейка швов сопряжения бетонных и других поверхностей стен, перегородок (газобетон, ПГП, панели АКОТЕК и др.) стеклохолстом | C3: пог. м | D3: 1 | E3: 267.16
A4: 1.2 | B4: Штукатурка гипсовая | C4: кг | D4: 0.1 | E4: =D4*E3 -> 26.716
A5: 1.3 | B5: Лента армирующая ( серпянка)_/150мм | C5: пог. м | D5: 1.1 | E5: =D5*E3 -> 293.876
A6: 1 | B6: Штукатурка стен гипсовыми смесями с предварительной огрунтовкой СКБ / толщ. от 21 до 40 мм / высотой от 4,01 до 8 метров (Штукатурка по ж/б поверхностям) | C6: м² | D6: 1 | E6: 410.02
A7: 1.1 | B7: Грунтовка БЕТОН-КОНТАКТ | C7: кг | D7: 0.25 | E7: =$E$6*D7 -> 102.505
A8: 1.2 | B8: Профиль маячковый_/ПМ6 | C8: пог. м | D8: 1 | E8: =$E$6*D8 -> 410.02
A9: 1.3 | B9: Штукатурка гипсовая | C9: кг | D9: 1 | E9: =$E$6*D9 -> 410.02
A10: 2 | B10: Штукатурка стен гипсовыми смесями с предварительной огрунтовкой СКБ / толщ. от 21 до 40 мм / высотой от 4,01 до 8 метров (Штукатурка по газобетонному блоку и ПГП) | C10: м² | D10: 1 | E10: 603.16
A11: 2.1 | B11: Штукатурка гипсовая | C11: кг | D11: 1 | E11: =$E$10*D11 -> 603.16
A12: 2.2 | B12: Грунтовка универсальный ЛАСТИМИН_ / LP-51 А | C12: кг | D12: 0.15 | E12: =$E$10*D12 -> 90.474
A13: 2.3 | B13: Профиль маячковый_/ПМ6 | C13: пог. м | D13: 1 | E13: =$E$10*D13 -> 603.16
A14: 2.4 | B14: Профиль углозащитный оцинкованный 31х31 мм 0,5 мм | C14: пог. м | D14: 1 | E14: 295.41
B16: Ведомость работ и используемых материалов (Шпаклевка базовая)
A17: № п.п. | B17: Наименование | C17: Ед. изм. | D17: Коэф. расхода | E17: Объем
A18: 1 | B18: Подготовка поверхности СКБ / стен / по штукатурке / 2мм (Шпаклевка базовая) | C18: м² | D18: 1 | E18: =E10+E6 -> 1013.18
A19: 1.1 | B19: Грунтовка универсальный ЛАСТИМИН_ / LP-51 А | C19: кг | D19: 0.15 | E19: =$E$18*D19 -> 151.977
A20: 1.2 | B20: Шпатлевка гипсовая_ / белая | C20: кг | D20: 1.8 | E20: =$E$18*D20 -> 1823.724
A21: 1.3 | B21: Уголок малярный | C21: пог. м | D21: 0.3 | E21: 24.01

Sheet 1.n;п.
A1: Спецификация выполненных работ
A2: Штукатурка стен и базовая шпаклевка
C3: по ж/б поверхностям | D3: по газобетонному блоку и ПГП | E3: Итог
A4: № п.п. | B4: Помещения: | C4: Объем, м² | D4: Объем, м²
A5: 1 | B5: 2057 | C5: 10.8 | D5: 48.9 | E5: 59.7
A6: 2 | B6: 2058 | C6: 143.5 | D6: 105.9 | E6: 249.4
A7: 3 | B7: 2060 | C7: 20.5 | D7: 67.1 | E7: 87.6
A8: 4 | B8: 2061 | C8: 61 | D8: 152.8 | E8: 213.8
A9: 5 | B9: 2062 | C9: 110.2 | D9: 159.9 | E9: 270.1
A10: 6 | B10: 2064 | C10: 58.5 | D10: 53.6 | E10: 112.1
A11: 7 | B11: 2066 | C11: 67.5 | D11: 91.7 | E11: 159.2
B12: сумма: | C12: =SUM(C5:C11) -> 472 | D12: =SUM(D5:D11) -> 679.9 | E12: =SUM(E5:E11) -> 1151.9

Sheet 2.n2
B1: Ведомость работ и используемых материалов (Штукатурка)
A2: № п.п. | B2: Наименование | C2: Ед. изм. | D2: Коэф. расхода | E2: Объем
A3: 1 | B3: Оклейка швов сопряжения бетонных и других поверхностей стен, перегородок (газобетон, ПГП, панели АКОТЕК и др.) стеклохолстом | C3: пог. м | D3: 1 | E3: 233
A4: 1.2 | B4: Штукатурка гипсовая | C4: кг | D4: 0.1 | E4: =D4*E3 -> 23.3
A5: 1.3 | B5: Лента армирующая ( серпянка)_/150мм | C5: пог. м | D5: 1.1 | E5: =D5*E3 -> 256.3
A6: 2 | B6: ='1.n2'!B6 -> Штукатурка стен гипсовыми смесями с предварительной огрунтовкой СКБ / толщ. от 21 до 40 мм / высотой от 4,01 до 8 метров (Штукатурка по ж/б поверхностям) | C6: м² | D6: 1 | E6: ='спец 6с'!C13 -> 333.82
A7: 2.1 | B7: Грунтовка БЕТОН-КОНТАКТ | C7: кг | D7: 0.25 | E7: =$E$6*D7 -> 83.455
A8: 2.2 | B8: Профиль маячковый_/ПМ6 | C8: пог. м | D8: 1 | E8: =$E$6*D8 -> 333.82
A9: 2.3 | B9: Штукатурка гипсовая | C9: кг | D9: 1 | E9: =$E$6*D9*28.57 -> 9537.2374
A10: 3 | B10: ='1.n2'!B10 -> Штукатурка стен гипсовыми смесями с предварительной огрунтовкой СКБ / толщ. от 21 до 40 мм / высотой от 4,01 до 8 метров (Штукатурка по газобетонному блоку и ПГП) | C10: м² | D10: 1 | E10: ='спец 6с'!D13 -> 502.91
A11: 3.1 | B11: Штукатурка гипсовая | C11: кг | D11: 1 | E11: =$E$10*D11*32.51 -> 16349.604
A12: 3.2 | B12: Грунтовка универсальный ЛАСТИМИН_ / LP-51 А | C12: кг | D12: 0.15 | E12: =$E$10*D12 -> 75.4365
A13: 3.3 | B13: Профиль маячковый_/ПМ6 | C13: пог. м | D13: 1 | E13: =$E$10*D13 -> 502.91
A14: 3.4 | B14: Профиль углозащитный оцинкованный 31х31 мм 0,5 мм | C14: пог. м | D14: 1 | E14: 97.47
B16: Ведомость работ и используемых материалов (Шпаклевка базовая)
A17: № п.п. | B17: Наименование | C17: Ед. изм. | D17: Коэф. расхода | E17: Объем
A18: 1 | B18: ='1.n2'!B18 -> Подготовка поверхности СКБ / стен / по штукатурке / 2мм (Шпаклевка базовая) | C18: м² | D18: 1 | E18: =E10+E6 -> 836.73
A19: 1.1 | B19: Грунтовка универсальный ЛАСТИМИН_ / LP-51 А | C19: кг | D19: 0.15 | E19: =$E$18*D19 -> 125.5095
A20: 1.2 | B20: Шпатлевка гипсовая_ / белая | C20: кг | D20: 1.8 | E20: =$E$18*D20 -> 1506.114
A21: 1.3 | B21: Уголок малярный | C21: пог. м | D21: 0.3 | E21: 24.01

Sheet спец 6с
A1: Спецификация выполненных работ
A2: Штукатурка стен и базовая шпаклевка
C3: по ж/б поверхностям | D3: по газобетонному блоку и ПГП | E3: Итог
A4: № п.п. | B4: Помещения: | C4: Объем, м² | D4: Объем, м²
A5: 1 | B5: 2.048 | C5: 41.24 | D5: 153.84 | E5: =C5+D5 -> 195.08
A6: 2 | B6: 2.049 | C6: 153.37 | D6: 103.52 | E6: =C6+D6 -> 256.89
A7: 3 | B7: 2.050 | C7: 40.34 | D7: 48.01 | E7: =C7+D7 -> 88.35
A8: 4 | B8: 2.051 | C8: 15.91 | D8: 70.86 | E8: =C8+D8 -> 86.77
A9: 5 | B9: 2.052 | C9: 3.2 | D9: 29.57 | E9: =C9+D9 -> 32.77
A10: 6 | B10: 2.053 | C10: 0 | D10: 35.28 | E10: =C10+D10 -> 35.28
A11: 7 | B11: 2.054-2.069 | C11: 43.07 | D11: 48.19 | E11: =C11+D11 -> 91.26
A12: 8 | B12: 2.055 | C12: 36.69 | D12: 13.64 | E12: =C12+D12 -> 50.33
B13: сумма: | C13: =SUM(C5:C12) -> 333.82 | D13: =SUM(D5:D12) -> 502.91 | E13: =SUM(E5:E12) -> 836.73

Sheet 3.n2
B1: Ведомость работ и используемых материалов (Штукатурка)
A2: № п.п. | B2: Наименование | C2: Ед. изм. | D2: Коэф. расхода | E2: Объем
A3: 1 | B3: Оклейка швов сопряжения бетонных и других поверхностей стен, перегородок (газобетон, ПГП, панели АКОТЕК и др.) стеклохолстом | C3: пог. м | D3: 1 | E3: 323.32
A4: 1.2 | B4: Штукатурка гипсовая | C4: кг | D4: 0.1 | E4: =D4*E3 -> 32.332
A5: 1.3 | B5: Лента армирующая ( серпянка)_/150мм | C5: пог. м | D5: 1.1 | E5: =D5*E3 -> 355.652
A6: 2 | B6: ='1.n2'!B6 -> Штукатурка стен гипсовыми смесями с предварительной огрунтовкой СКБ / толщ. от 21 до 40 мм / высотой от 4,01 до 8 метров (Штукатурка по ж/б поверхностям) | C6: м² | D6: 1 | E6: ='спец 5с'!C8 -> 161.17
A7: 2.1 | B7: Грунтовка БЕТОН-КОНТАКТ | C7: кг | D7: 0.25 | E7: =$E$6*D7 -> 40.2925
A8: 2.2 | B8: Профиль маячковый_/ПМ6 | C8: пог. м | D8: 1 | E8: =$E$6*D8 -> 161.17
A9: 2.3 | B9: Штукатурка гипсовая | C9: кг | D9: 1 | E9: =$E$6*D9*28.57 -> 4604.6269
A10: 3 | B10: ='1.n2'!B10 -> Штукатурка стен гипсовыми смесями с предварительной огрунтовкой СКБ / толщ. от 21 до 40 мм / высотой от 4,01 до 8 метров (Штукатурка по газобетонному блоку и ПГП) | C10: м² | D10: 1 | E10: ='спец 5с'!D8 -> 341.47
A11: 3.1 | B11: Штукатурка гипсовая | C11: кг | D11: 1 | E11: =$E$10*D11*32.51 -> 11101.19
A12: 3.2 | B12: Грунтовка универсальный ЛАСТИМИН_ / LP-51 А | C12: кг | D12: 0.15 | E12: =$E$10*D12 -> 51.2205
A13: 3.3 | B13: Профиль маячковый_/ПМ6 | C13: пог. м | D13: 1 | E13: =$E$10*D13 -> 341.47
A14: 3.4 | B14: Профиль углозащитный оцинкованный 31х31 мм 0,5 мм | C14: пог. м | D14: 1 | E14: 97.97
B16: Ведомость работ и используемых материалов (Шпаклевка базовая)
A17: № п.п. | B17: Наименование | C17: Ед. изм. | D17: Коэф. расхода | E17: Объем
A18: 1 | B18: ='1.n2'!B18 -> Подготовка поверхности СКБ / стен / по штукатурке / 2мм (Шпаклевка базовая) | C18: м² | D18: 1 | E18: =E10+E6 -> 502.64
A19: 1.1 | B19: Грунтовка универсальный ЛАСТИМИН_ / LP-51 А | C19: кг | D19: 0.15 | E19: =$E$18*D19 -> 75.396
A20: 1.2 | B20: Шпатлевка гипсовая_ / белая | C20: кг | D20: 1.8 | E20: =$E$18*D20 -> 904.752
A21: 1.3 | B21: Уголок малярный | C21: пог. м | D21: 0.3 | E21: 24.01

Sheet спец 5с
A1: Спецификация выполненных работ
A2: Штукатурка стен и базовая шпаклевка
C3: по ж/б поверхностям | D3: по газобетонному блоку и ПГП | E3: Итог
A4: № п.п. | B4: Помещения: | C4: Объем, м² | D4: Объем, м²
A5: 1 | B5: 2.045 | C5: 82.77 | D5: 145.32 | E5: =C5+D5 -> 228.09
A6: 2 | B6: 2.046 | C6: 71.44 | D6: 123.07 | E6: =C6+D6 -> 194.51
A7: 3 | B7: 2.047 | C7: 6.96 | D7: 73.08 | E7: =C7+D7 -> 80.04
B8: сумма: | C8: =SUM(C5:C7) -> 161.17 | D8: =SUM(D5:D7) -> 341.47 | E8: =SUM(E5:E7) -> 502.64

Sheet 4.n2
B1: Ведомость работ и используемых материалов (Штукатурка)
A2: № п.п. | B2: Наименование | C2: Ед. изм. | D2: Коэф. расхода | E2: Объем
A3: 1 | B3: Оклейка швов сопряжения бетонных и других поверхностей стен, перегородок (газобетон, ПГП, панели АКОТЕК и др.) стеклохолстом | C3: пог. м | D3: 1 | E3: 396.86
A4: 1.2 | B4: Штукатурка гипсовая | C4: кг | D4: 0.1 | E4: =D4*E3 -> 39.686
A5: 1.3 | B5: Лента армирующая ( серпянка)_/150мм | C5: пог. м | D5: 1.1 | E5: =D5*E3 -> 436.546
A6: 2 | B6: ='1.n2'!B6 -> Штукатурка стен гипсовыми смесями с предварительной огрунтовкой СКБ / толщ. от 21 до 40 мм / высотой от 4,01 до 8 метров (Штукатурка по ж/б поверхностям) | C6: м² | D6: 1 | E6: ='спец 4с'!C14 -> 361.91848
A7: 2.1 | B7: Грунтовка БЕТОН-КОНТАКТ | C7: кг | D7: 0.25 | E7: =$E$6*D7 -> 90.479619
A8: 2.2 | B8: Профиль маячковый_/ПМ6 | C8: пог. м | D8: 1 | E8: =$E$6*D8 -> 361.91848
A9: 2.3 | B9: Штукатурка гипсовая | C9: кг | D9: 1 | E9: =$E$6*D9*28.57 -> 10340.011
A10: 3 | B10: ='1.n2'!B10 -> Штукатурка стен гипсовыми смесями с предварительной огрунтовкой СКБ / толщ. от 21 до 40 мм / высотой от 4,01 до 8 метров (Штукатурка по газобетонному блоку и ПГП) | C10: м² | D10: 1 | E10: ='спец 4с'!D14 -> 697.45979
A11: 3.1 | B11: Штукатурка гипсовая | C11: кг | D11: 1 | E11: =$E$10*D11*32.51 -> 22674.418
A12: 3.2 | B12: Грунтовка универсальный ЛАСТИМИН_ / LP-51 А | C12: кг | D12: 0.15 | E12: =$E$10*D12 -> 104.61897
A13: 3.3 | B13: Профиль маячковый_/ПМ6 | C13: пог. м | D13: 1 | E13: =$E$10*D13 -> 697.45979
A14: 3.4 | B14: Профиль углозащитный оцинкованный 31х31 мм 0,5 мм | C14: пог. м | D14: 1 | E14: =15*3.98 -> 59.7
B16: Ведомость работ и используемых материалов (Шпаклевка базовая)
A17: № п.п. | B17: Наименование | C17: Ед. изм. | D17: Коэф. расхода | E17: Объем
A18: 1 | B18: ='1.n2'!B18 -> Подготовка поверхности СКБ / стен / по штукатурке / 2мм (Шпаклевка базовая) | C18: м² | D18: 1 | E18: =E10+E6 -> 1059.3783
A19: 1.1 | B19: Грунтовка универсальный ЛАСТИМИН_ / LP-51 А | C19: кг | D19: 0.15 | E19: =$E$18*D19 -> 158.90674
A20: 1.2 | B20: Шпатлевка гипсовая_ / белая | C20: кг | D20: 1.8 | E20: =$E$18*D20 -> 1906.8809
A21: 1.3 | B21: Уголок малярный | C21: пог. м | D21: 0.3 | E21: 24.01

Sheet спец 4с
A1: Спецификация выполненных работ
A2: Штукатурка стен и базовая шпаклевка
C3: по ж/б поверхностям | D3: по газобетонному блоку и ПГП | E3: Итог
A4: № п.п. | B4: Помещения: | C4: Объем, м² | D4: Объем, м²
A5: 1 | B5: 2.036 | C5: 27.473939 | D5: 100.70855 | E5: =C5+D5 -> 128.18249
A6: 2 | B6: 2.038 | C6: 49.624981 | D6: 56.044551 | E6: =C6+D6 -> 105.66953
A7: 3 | B7: 2.039 | C7: 42.740829 | D7: 59.509028 | E7: =C7+D7 -> 102.24986
A8: 4 | B8: 2.040 | C8: 69.465545 | D8: 36.453381 | E8: =C8+D8 -> 105.91893
A9: 5 | B9: 2.041 | C9: 70.613545 | D9: 36.04662 | E9: =C9+D9 -> 106.66017
A10: 6 | B10: 2.042 | C10: 18.623237 | D10: 171.03722 | E10: =C10+D10 -> 189.66046
A11: 7 | B11: 2.043 | C11: 36.7 | D11: 13.64 | E11: =C11+D11 -> 50.34
A12: 8 | B12: 2.046 | C12: 31.8764 | D12: 105.47421 | E12: =C12+D12 -> 137.35061
A13: 9 | B13: 2.071 | C13: 14.8 | D13: 118.54623 | E13: =C13+D13 -> 133.34623
B14: сумма: | C14: =SUM(C5:C13) -> 361.91848 | D14: =SUM(D5:D13) -> 697.45979 | E14: =SUM(C14:D14) -> 1059.3783

Sheet 5.n3
B1: Ведомость работ и используемых материалов (Штукатурка)
A2: № п.п. | B2: Наименование | C2: Ед. изм. | D2: Коэф. расхода | E2: Объем
A3: 1 | B3: Оклейка швов сопряжения бетонных и других поверхностей стен, перегородок (газобетон, ПГП, панели АКОТЕК и др.) стеклохолстом | C3: пог. м | D3: 1 | E3: =290*3.8 -> 1102
A4: 1.2 | B4: Штукатурка гипсовая | C4: кг | D4: 0.1 | E4: =D4*E3 -> 110.2
A5: 1.3 | B5: Лента армирующая ( серпянка)_/150мм | C5: пог. м | D5: 1.1 | E5: =D5*E3 -> 1212.2
A6: 2 | B6: ='1.n2'!B6 -> Штукатурка стен гипсовыми смесями с предварительной огрунтовкой СКБ / толщ. от 21 до 40 мм / высотой от 4,01 до 8 метров (Штукатурка по ж/б поверхностям) | C6: м² | D6: 1 | E6: =Спец7с3э!C16+Спец6с3э!C14+Спец5с3э!C7+Спец4с3э!C16 -> 1389.7395
A7: 2.1 | B7: Грунтовка БЕТОН-КОНТАКТ | C7: кг | D7: 0.25 | E7: =$E$6*D7 -> 347.43489
A8: 2.2 | B8: Профиль маячковый_/ПМ6 | C8: пог. м | D8: 1 | E8: =$E$6*D8 -> 1389.7395
A9: 2.3 | B9: Штукатурка гипсовая | C9: кг | D9: 1 | E9: =$E$6*D9*28.57 -> 39704.859
A10: 3 | B10: ='1.n2'!B10 -> Штукатурка стен гипсовыми смесями с предварительной огрунтовкой СКБ / толщ. от 21 до 40 мм / высотой от 4,01 до 8 метров (Штукатурка по газобетонному блоку и ПГП) | C10: м² | D10: 1 | E10: =Спец7с3э!D16+Спец6с3э!D14+Спец5с3э!D7+Спец4с3э!D16 -> 2747.8019
A11: 3.1 | B11: Штукатурка гипсовая | C11: кг | D11: 1 | E11: =$E$10*D11*32.51 -> 89331.04
A12: 3.2 | B12: Грунтовка универсальный ЛАСТИМИН_ / LP-51 А | C12: кг | D12: 0.15 | E12: =$E$10*D12 -> 412.17029
A13: 3.3 | B13: Профиль маячковый_/ПМ6 | C13: пог. м | D13: 1 | E13: =$E$10*D13 -> 2747.8019
A14: 3.4 | B14: Профиль углозащитный оцинкованный 31х31 мм 0,5 мм | C14: пог. м | D14: 1 | E14: =235.75*4 -> 943
B16: Ведомость работ и используемых материалов (Шпаклевка базовая)
A17: № п.п. | B17: Наименование | C17: Ед. изм. | D17: Коэф. расхода | E17: Объем
A18: 1 | B18: ='1.n2'!B18 -> Подготовка поверхности СКБ / стен / по штукатурке / 2мм (Шпаклевка базовая) | C18: м² | D18: 1 | E18: =E10+E6 -> 4137.5415
A19: 1.1 | B19: Грунтовка универсальный ЛАСТИМИН_ / LP-51 А | C19: кг | D19: 0.15 | E19: =$E$18*D19 -> 620.63122
A20: 1.2 | B20: Шпатлевка гипсовая_ / белая | C20: кг | D20: 1.8 | E20: =$E$18*D20 -> 7447.5746
A21: 1.3 | B21: Уголок малярный | C21: пог. м | D21: 0.3 | E21: 75.13

Sheet Спец7с3э
A1: Спецификация выполненных работ (7 секция)
A2: Штукатурка стен и базовая шпаклевка
C3: по ж/б поверхностям | D3: по газобетонному блоку и ПГП | E3: Итог
A4: № п.п. | B4: Помещения: | C4: Объем, м² | D4: Объем, м²
A5: 1 | B5: 3.005 | C5: 4.4658036 | D5: 69.887667 | E5: =C5+D5 -> 74.353471
A6: 2 | B6: 3.049 | C6: 11.9 | D6: 83.583314 | E6: =C6+D6 -> 95.483314
A7: 3 | B7: 3.050 | C7: 82.408188 | D7: 126.88863 | E7: =C7+D7 -> 209.29682
A8: 4 | B8: 3.051 | C8: 66.421028 | D8: 220.5073 | E8: =C8+D8 -> 286.92833
A9: 5 | B9: 3.053 | C9: 107.20823 | D9: 120.97256 | E9: =C9+D9 -> 228.18079
A10: 6 | B10: 3.054 | C10: 58.46 | D10: 80.532919 | E10: =C10+D10 -> 138.99292
A11: 7 | B11: 3.058 | C11: 32.5728 | D11: 101.40153 | E11: =C11+D11 -> 133.97433
A12: 8 | B12: 3.059 | C12: 12.3856 | D12: 16.096 | E12: =C12+D12 -> 28.4816
A13: 9 | B13: 3.060 | C13: 66.115608 | D13: 36.970356 | E13: =C13+D13 -> 103.08596
A14: 10 | B14: 3.061 | C14: 6.8 | D14: 47.174516 | E14: =C14+D14 -> 53.974516
A15: 11 | B15: 3.062 | C15: 13.792 | D15: 36.183082 | E15: =C15+D15 -> 49.975082
B16: сумма: | C16: =SUM(C5:C15) -> 462.52926 | D16: =SUM(D5:D15) -> 940.19788 | E16: =SUM(E5:E15) -> 1402.7271

Sheet Спец6с3э
A1: Спецификация выполненных работ (6 секция)
A2: Штукатурка стен и базовая шпаклевка
C3: по ж/б поверхностям | D3: по газобетонному блоку и ПГП | E3: Итог
A4: № п.п. | B4: Помещения: | C4: Объем, м² | D4: Объем, м²
A5: 1 | B5: 3.038 | C5: 62.964 | D5: 181.70322 | E5: =C5+D5 -> 244.66722
A6: 2 | B6: 3.039 | C6: 4.330018 | D6: 67.694471 | E6: =C6+D6 -> 72.024489
A7: 3 | B7: 3.040 | C7: 64.902809 | D7: 100.62324 | E7: =C7+D7 -> 165.52605
A8: 4 | B8: 3.041 | C8: 197.50407 | D8: 149.17203 | E8: =C8+D8 -> 346.6761
A9: 5 | B9: 3.042 | C9: 16.28 | D9: 71.948571 | E9: =C9+D9 -> 88.228571
A10: 6 | B10: 3.043 | C10: 45.676007 | D10: 49.025836 | E10: =C10+D10 -> 94.701843
A11: 7 | B11: 3.044 | C11: 3.2 | D11: 29.332 | E11: =C11+D11 -> 32.532
A12: 8 | B12: 3.045 | C12: 0 | D12: 35.0376 | E12: =C12+D12 -> 35.0376
A13: 9 | B13: 3.046 | C13: 25.696 | D13: 18.7582 | E13: =C13+D13 -> 44.4542
B14: сумма: | C14: =SUM(C5:C13) -> 420.5529 | D14: =SUM(D5:D13) -> 703.29517 | E14: =SUM(E5:E13) -> 1123.8481

Sheet Спец5с3э
A1: Спецификация выполненных работ (5 секция)
A2: Штукатурка стен и базовая шпаклевка
C3: по ж/б поверхностям | D3: по газобетонному блоку и ПГП | E3: Итог
A4: № п.п. | B4: Помещения: | C4: Объем, м² | D4: Объем, м²
A5: 1 | B5: 3.036 | C5: 19.2 | D5: 98.868098 | E5: =C5+D5 -> 118.0681
A6: 2 | B6: 3.037 | C6: 87.732304 | D6: 161.63026 | E6: =C6+D6 -> 249.36256
B7: сумма: | C7: =SUM(C5:C6) -> 106.9323 | D7: =SUM(D5:D6) -> 260.49836 | E7: =SUM(E5:E6) -> 367.43066

Sheet Спец4с3э
A1: Спецификация выполненных работ
A2: Штукатурка стен и базовая шпаклевка (4 секция)
C3: по ж/б поверхностям | D3: по газобетонному блоку и ПГП | E3: Итог
A4: № п.п. | B4: Помещения: | C4: Объем, м² | D4: Объем, м²
A5: 1 | B5: 3.027 | C5: 31.24 | D5: 108.48 | E5: =C5+D5 -> 139.72
A6: 2 | B6: 3.028 | C6: 21.409132 | D6: 85.7892 | E6: =C6+D6 -> 107.19833
A7: 3 | B7: 3.030 | C7: 47.185616 | D7: 70.117448 | E7: =C7+D7 -> 117.30306
A8: 4 | B8: 3.066 | C8: 66.7 | D8: 262.95395 | E8: =C8+D8 -> 329.65395
A9: 5 | B9: 3.031 | C9: 74.4 | D9: 36.715818 | E9: =C9+D9 -> 111.11582
A10: 6 | B10: 3.057 | C10: 7.82 | D10: 31.3776 | E10: =C10+D10 -> 39.1976
A11: 7 | B11: 3.055 | C11: 1.2003268 | D11: 60.3122 | E11: =C11+D11 -> 61.512527
A12: 8 | B12: 3.064 | C12: 0 | D12: 63.1621 | E12: =C12+D12 -> 63.1621
A13: 9 | B13: 3.033 | C13: 25.72 | D13: 17.78 | E13: =C13+D13 -> 43.5
A14: 10 | B14: 3.035 | C14: 48.6 | D14: 67.626361 | E14: =C14+D14 -> 116.22636
A15: 11 | B15: 3.032 | C15: 75.45 | D15: 39.495818 | E15: =C15+D15 -> 114.94582
B16: сумма: | C16: =SUM(C5:C15) -> 399.72507 | D16: =SUM(D5:D15) -> 843.8105 | E16: =SUM(E5:E15) -> 1243.5356

Sheet Лист2
A1: 2001 | B1: 72.7 | C1: 52.5
A2: 2002 | B2: 53.1 | C2: 62.4
A3: 2003 | B3: 144.8 | C3: 171.6
A4: 2004 | B4: 44.3 | C4: 70.9
A5: 2005 | B5: 23.9 | C5: 40.5
A6: 2006 | B6: 20.4 | C6: 45.8
A7: 2007 | B7: 27.9 | C7: 137
A8: 2008 | B8: 101.7 | C8: 0
A9: 2009 | B9: 35.9 | C9: 13.1
A10: 2010 | B10: 10.8 | C10: 80
A11: 2011 | B11: 0 | C11: 33
A12: 2012 | B12: 25.9 | C12: 90.2
... A71: 2071 | B71: 57.7 | C71: 189.7

Sheet 6.n3э
B1: Ведомость работ и используемых материалов (Штукатурка)
A2: № п.п. | B2: Наименование | C2: Ед. изм. | D2: Коэф. расхода | E2: Объем
A3: 1 | B3: Оклейка швов сопряжения бетонных и других поверхностей стен, перегородок (газобетон, ПГП, панели АКОТЕК и др.) стеклохолстом | C3: пог. м | D3: 1 | E3: =(E6+E10+E15+E20)*0.45 -> 852.66
A4: 1.2 | B4: Штукатурка гипсовая | C4: кг | D4: 0.1 | E4: =D4*E3 -> 85.266
A5: 1.3 | B5: Лента армирующая ( серпянка)_/150мм | C5: пог. м | D5: 1.1 | E5: =D5*E3 -> 937.926
A6: 2 | B6: ='1.n2'!B6 -> Штукатурка стен гипсовыми смесями с предварительной огрунтовкой СКБ / толщ. от 21 до 40 мм / высотой от 4,01 до 8 метров (Штукатурка по ж/б поверхностям) | C6: м² | D6: 1 | E6: ='6n;п.'!C16 -> 719.9
A7: 2.1 | B7: Грунтовка БЕТОН-КОНТАКТ | C7: кг | D7: 0.25 | E7: =$E$6*D7 -> 179.975
A8: 2.2 | B8: Профиль маячковый_/ПМ6 | C8: пог. м | D8: 1 | E8: =$E$6*D8 -> 719.9
A9: 2.3 | B9: Штукатурка гипсовая | C9: кг | D9: 1 | E9: =$E$6*D9*28.57 -> 20567.543
A10: 3 | B10: ='1.n2'!B10 -> Штукатурка стен гипсовыми смесями с предварительной огрунтовкой СКБ / толщ. от 21 до 40 мм / высотой от 4,01 до 8 метров (Штукатурка по газобетонному блоку и ПГП) | C10: м² | D10: 1 | E10: ='6n;п.'!D16 -> 918.5
A11: 3.1 | B11: Штукатурка гипсовая | C11: кг | D11: 1 | E11: =$E$10*D11*32.51 -> 29860.435
A12: 3.2 | B12: Грунтовка универсальный ЛАСТИМИН_ / LP-51 А | C12: кг | D12: 0.15 | E12: =$E$10*D12 -> 137.775
A13: 3.3 | B13: Профиль маячковый_/ПМ6 | C13: пог. м | D13: 1 | E13: =$E$10*D13 -> 918.5
A14: 3.4 | B14: Профиль углозащитный оцинкованный 31х31 мм 0,5 мм | C14: пог. м | D14: 1 | E14: =35.75*4 -> 143
A15: 4 | B15: Штукатурка стен цементным, цементно-песчаным раствором с предварительной огрунтовкой / толщ. от 21 до 40 мм / высотой до 4 метров (Штукатурка по ж/б поверхностям) | C15: м2 | D15: 1 | E15: ='6n;п.'!C27 -> 62.5
A16: 4.1 | B16: Грунтовка БЕТОН-КОНТАКТ_/ | C16: кг | D16: 0.25 | E16: =D16*$E$15 -> 15.625
A17: 4.2 | B17: Профиль маячковый_/ПМ6 | C17: пог. м | D17: 1 | E17: =D17*$E$15 -> 62.5
A18: 4.3 | B18: Сетка штукатурная_/пластиковая/5*5 | C18: м2 | D18: 1.1 | E18: =D18*$E$15 -> 68.75
A19: 4.4 | B19: Штукатурка цементная | C19: кг | D19: 1.3 | E19: =D19*$E$15*40 -> 3250
A20: 5 | B20: Штукатурка стен цементным, цементно-песчаным раствором с предварительной огрунтовкой / толщ. от 21 до 40 мм / высотой до 4 метров (Штукатурка по газобетонному блоку и ПГП) | C20: м2 | D20: 1 | E20: ='6n;п.'!D27 -> 193.9
A21: 5.1 | B21: Грунтовка универсальный ЛАСТИМИН_ / LP-51 А | C21: кг | D21: 0.15 | E21: =$E$20*D21 -> 29.085
A22: 5.2 | B22: Профиль маячковый_/ПМ6 | C22: пог. м | D22: 1 | E22: =$E$20*D22 -> 193.9
A23: 5.3 | B23: Сетка штукатурная_/пластиковая/5*5 | C23: м2 | D23: 1.1 | E23: =$E$20*D23 -> 213.29
A24: 5.4 | B24: Штукатурка цементная | C24: кг | D24: 1.3 | E24: =$E$20*D24*40 -> 10082.8
B26: Ведомость работ и используемых материалов (Шпаклевка базовая)
A27: № п.п. | B27: Наименование | C27: Ед. изм. | D27: Коэф. расхода | E27: Объем
A28: 1 | B28: ='1.n2'!B18 -> Подготовка поверхности СКБ / стен / по штукатурке / 2мм (Шпаклевка базовая) | C28: м² | D28: 1 | E28: ='6n;п.'!E16 -> 1638.4
A29: 1.1 | B29: Грунтовка универсальный ЛАСТИМИН_ / LP-51 А | C29: кг | D29: 0.15 | E29: =D29*E28 -> 245.76
A30: 1.2 | B30: Шпатлевка гипсовая_ / белая | C30: кг | D30: 1.8 | E30: =D30*E29 -> 442.368
A31: 1.3 | B31: Уголок малярный | C31: пог. м | D31: 0.3 | E31: =D31*E30 -> 132.7104

Sheet 6n;п.
A1: Спецификация выполненных работ
A2: Штукатурка стен и базовая шпаклевка
C3: по ж/б поверхностям | D3: по газобетонному блоку и ПГП | E3: Итог
A4: № п.п. | B4: Помещения: | C4: Объем, м² | D4: Объем, м²
A5: 1 | B5: 3.001 | C5: 67.6 | D5: 55.5 | E5: 123.1
A6: 2 | B6: 3.002 | C6: 50.1 | D6: 58.2 | E6: 108.3
A7: 3 | B7: 3.003 | C7: 62.4 | D7: 71.9 | E7: 134.3
A8: 4 | B8: 3.004 | C8: 185.1 | D8: 162.9 | E8: 348
A9: 5 | B9: 3.007 | C9: 20.8 | D9: 11.3 | E9: 32.1
A10: 6 | B10: 3.01 | C10: 38.9 | D10: 115.1 | E10: 154
A11: 7 | B11: 3.011 | C11: 37.7 | D11: 97.6 | E11: 135.3
A12: 8 | B12: 3.012 | C12: 149.8 | D12: 189.5 | E12: 339.3
A13: 9 | B13: 3.013 | C13: 30.5 | D13: 79.3 | E13: 109.8
A14: 10 | B14: 3.014 | C14: 50 | D14: 57.7 | E14: 107.7
A15: 11 | B15: 3.067 | C15: 27 | D15: 19.5 | E15: 46.5
B16: Сумма | C16: =SUM(C5:C15) -> 719.9 | D16: =SUM(D5:D15) -> 918.5 | E16: =SUM(E5:E15) -> 1638.4
A18: Спецификация выполненных работ
A19: Штукатурка стен (штук. цементная)
C20: по ж/б поверхностям | D20: по газобетонному блоку и ПГП | E20: Итог
A21: № п.п. | B21: Помещения: | C21: Объем, м² | D21: Объем, м²
A22: 2 | B22: 3.009 | C22: 10.1 | D22: 77 | E22: 87.1
A23: 3 | B23: 3.015 | C23: 21.3 | D23: 48.3 | E23: 69.6
A24: 4 | B24: 3.017 | C24: 18.1 | D24: 24.7 | E24: 42.8
A25: 5 | B25: 3.018 | C25: 7.1 | D25: 22.4 | E25: 29.5
A26: 6 | B26: 3.029 | C26: 5.9 | D26: 21.5 | E26: 27.4
B27: Сумма | C27: =SUM(C21:C26) -> 62.5 | D27: =SUM(D21:D26) -> 193.9 | E27: =SUM(E21:E26) -> 256.4

Sheet 7.n2
B1: Ведомость работ и используемых материалов (Штукатурка)
A2: № п.п. | B2: Наименование | C2: Ед. изм. | D2: Коэф. расхода | E2: Объем
A3: 1 | B3: Оклейка швов сопряжения бетонных и других поверхностей стен, перегородок (газобетон, ПГП, панели АКОТЕК и др.) стеклохолстом | C3: пог. м | D3: 1 | E3: =(E6+E10+E15+E20)*0.45 -> 969.075
A4: 1.2 | B4: Штукатурка гипсовая | C4: кг | D4: 0.1 | E4: =D4*E3 -> 96.9075
A5: 1.3 | B5: Лента армирующая ( серпянка)_/150мм | C5: пог. м | D5: 1.1 | E5: =D5*E3 -> 1065.9825
A6: 2 | B6: ='1.n2'!B6 -> Штукатурка стен гипсовыми смесями с предварительной огрунтовкой СКБ / толщ. от 21 до 40 мм / высотой от 4,01 до 8 метров (Штукатурка по ж/б поверхностям) | C6: м² | D6: 1 | E6: ='7n;п.'!C20 -> 724.4
A7: 2.1 | B7: Грунтовка БЕТОН-КОНТАКТ | C7: кг | D7: 0.25 | E7: =$E$6*D7 -> 181.1
A8: 2.2 | B8: Профиль маячковый_/ПМ6 | C8: пог. м | D8: 1 | E8: =$E$6*D8 -> 724.4
A9: 2.3 | B9: Штукатурка гипсовая | C9: кг | D9: 1 | E9: =$E$6*D9*28.57 -> 20696.108
A10: 3 | B10: ='1.n2'!B10 -> Штукатурка стен гипсовыми смесями с предварительной огрунтовкой СКБ / толщ. от 21 до 40 мм / высотой от 4,01 до 8 метров (Штукатурка по газобетонному блоку и ПГП) | C10: м² | D10: 1 | E10: ='7n;п.'!D20 -> 1148.5
A11: 3.1 | B11: Штукатурка гипсовая | C11: кг | D11: 1 | E11: =$E$10*D11*32.51 -> 37337.735
A12: 3.2 | B12: Грунтовка универсальный ЛАСТИМИН_ / LP-51 А | C12: кг | D12: 0.15 | E12: =$E$10*D12 -> 172.275
A13: 3.3 | B13: Профиль маячковый_/ПМ6 | C13: пог. м | D13: 1 | E13: =$E$10*D13 -> 1148.5
A14: 3.4 | B14: Профиль углозащитный оцинкованный 31х31 мм 0,5 мм | C14: пог. м | D14: 1 | E14: =75.75*4 -> 303
A15: 4 | B15: Штукатурка стен цементным, цементно-песчаным раствором с предварительной огрунтовкой / толщ. от 21 до 40 мм / высотой до 4 метров (Штукатурка по ж/б поверхностям) | C15: м2 | D15: 1 | E15: ='7n;п.'!C32 -> 59
A16: 4.1 | B16: Грунтовка БЕТОН-КОНТАКТ_/ | C16: кг | D16: 0.25 | E16: =D16*$E$15 -> 14.75
A17: 4.2 | B17: Профиль маячковый_/ПМ6 | C17: пог. м | D17: 1 | E17: =D17*$E$15 -> 59
A18: 4.3 | B18: Сетка штукатурная_/пластиковая/5*5 | C18: м2 | D18: 1.1 | E18: =D18*$E$15 -> 64.9
A19: 4.4 | B19: Штукатурка цементная | C19: кг | D19: 1.3 | E19: =D19*$E$15*40 -> 3068
A20: 5 | B20: Штукатурка стен цементным, цементно-песчаным раствором с предварительной огрунтовкой / толщ. от 21 до 40 мм / высотой до 4 метров (Штукатурка по газобетонному блоку и ПГП) | C20: м2 | D20: 1 | E20: ='7n;п.'!D32 -> 221.6
A21: 5.1 | B21: Грунтовка универсальный ЛАСТИМИН_ / LP-51 А | C21: кг | D21: 0.15 | E21: =$E$20*D21 -> 33.24
A22: 5.2 | B22: Профиль маячковый_/ПМ6 | C22: пог. м | D22: 1 | E22: =$E$20*D22 -> 221.6
A23: 5.3 | B23: Сетка штукатурная_/пластиковая/5*5 | C23: м2 | D23: 1.1 | E23: =$E$20*D23 -> 243.76
A24: 5.4 | B24: Штукатурка цементная | C24: кг | D24: 1.3 | E24: =$E$20*D24*40 -> 11523.2
B26: Ведомость работ и используемых материалов (Шпаклевка базовая)
A27: № п.п. | B27: Наименование | C27: Ед. изм. | D27: Коэф. расхода | E27: Объем
A28: 1 | B28: ='1.n2'!B18 -> Подготовка поверхности СКБ / стен / по штукатурке / 2мм (Шпаклевка базовая) | C28: м² | D28: 1 | E28: ='7n;п.'!E20 -> 1872.9
A29: 1.1 | B29: Грунтовка универсальный ЛАСТИМИН_ / LP-51 А | C29: кг | D29: 0.15 | E29: =D29*E28 -> 280.935
A30: 1.2 | B30: Шпатлевка гипсовая_ / белая | C30: кг | D30: 1.8 | E30: =D30*E29 -> 505.683
A31: 1.3 | B31: Уголок малярный | C31: пог. м | D31: 0.3 | E31: =D31*E30 -> 151.7049

Sheet 7n;п.
A1: Спецификация выполненных работ
A2: Штукатурка стен и базовая шпаклевка
C3: по ж/б поверхностям | D3: по газобетонному блоку и ПГП | E3: Итог
A4: № п.п. | B4: Помещения: | C4: Объем, м² | D4: Объем, м²
A5: 1 | B5: 2.001 | C5: 67.9 | D5: 48.5 | E5: =C5+D5 -> 116.4
A6: 2 | B6: 2.002 | C6: 47.5 | D6: 60.4 | E6: =C6+D6 -> 107.9
A7: 3 | B7: 2.003 | C7: 140.3 | D7: 170.6 | E7: =C7+D7 -> 310.9
A8: 4 | B8: 2.004 | C8: 38.6 | D8: 64.9 | E8: =C8+D8 -> 103.5
A9: 5 | B9: 2.005 | C9: 19.5 | D9: 35.5 | E9: =C9+D9 -> 55
A10: 6 | B10: 2.007 | C10: 22.3 | D10: 134 | E10: =C10+D10 -> 156.3
A11: 7 | B11: 2.009 | C11: 30 | D11: 10.1 | E11: =C11+D11 -> 40.1
A12: 8 | B12: 2.011 | C12: 0 | D12: 28 | E12: =C12+D12 -> 28
A13: 9 | B13: 2.012 | C13: 21.3 | D13: 84.2 | E13: =C13+D13 -> 105.5
A14: 10 | B14: 2.013 | C14: 22.8 | D14: 85.8 | E14: =C14+D14 -> 108.6
A15: 11 | B15: 2.014 | C15: 35.7 | D15: 75.5 | E15: =C15+D15 -> 111.2
A16: 12 | B16: 2.015 | C16: 30.7 | D16: 83.9 | E16: =C16+D16 -> 114.6
... A19: 15 | B19: 2.07 | C19: 29.3 | D19: 19.4 | E19: =C19+D19 -> 48.7
B20: Сумма | C20: =SUM(C5:C19) -> 724.4 | D20: =SUM(D5:D19) -> 1148.5 | E20: =SUM(E5:E19) -> 1872.9
A22: Спецификация выполненных работ
A23: Штукатурка стен (штук. цементная)
C24: по ж/б поверхностям | D24: по газобетонному блоку и ПГП | E24: Итог
A25: № п.п. | B25: Помещения: | C25: Объем, м² | D25: Объем, м²
A26: 1 | B26: 2.01 | C26: 10.2 | D26: 79.5 | E26: =C26+D26 -> 89.7
A27: 2 | B27: 2.011 | C27: 0 | D27: 32.4 | E27: =C27+D27 -> 32.4
A28: 3 | B28: 2.018 | C28: 25.8 | D28: 51.9 | E28: =C28+D28 -> 77.7
A29: 4 | B29: 2.02 | C29: 16.1 | D29: 32.4 | E29: =C29+D29 -> 48.5
A30: 5 | B30: 2.021 | C30: 6.9 | D30: 25.4 | E30: =C30+D30 -> 32.3
A31: 6 | B31: 2.059 | C31: 7.9 | D31: 23.1 | E31: =C31+D31 -> 31
B32: Сумма | C32: =SUM(C25:C30) -> 59 | D32: =SUM(D25:D30) -> 221.6 | E32: =SUM(E25:E30) -> 280.6

Sheet 2расчет
K14: швы | L14: ='7.n2'!E3+'6.n3э'!E3 -> 1821.735
K15: штук жб | L15: ='7.n2'!E6+'6.n3э'!E6 -> 1444.3
L16: ='7.n2'!E10+'6.n3э'!E10 -> 2067

Sheet 8.n2
B1: Ведомость работ и используемых материалов (Штукатурка)
A2: № п.п. | B2: Наименование | C2: Ед. изм. | D2: Коэф. расхода | E2: Объем
A3: 1 | B3: Оклейка швов сопряжения бетонных и других поверхностей стен, перегородок (газобетон, ПГП, панели АКОТЕК и др.) стеклохолстом | C3: пог. м | D3: 1 | E3: =(E6+E10)*0.45 -> 239.76
A4: 1.2 | B4: Штукатурка гипсовая | C4: кг | D4: 0.1 | E4: =D4*E3 -> 23.976
A5: 1.3 | B5: Лента армирующая ( серпянка)_/150мм | C5: пог. м | D5: 1.1 | E5: =D5*E3 -> 263.736
A6: 2 | B6: ='1.n2'!B6 -> Штукатурка стен гипсовыми смесями с предварительной огрунтовкой СКБ / толщ. от 21 до 40 мм / высотой от 4,01 до 8 метров (Штукатурка по ж/б поверхностям) | C6: м² | D6: 1 | E6: =301.6-9.4 -> 292.2
A7: 2.1 | B7: Грунтовка БЕТОН-КОНТАКТ | C7: кг | D7: 0.25 | E7: =$E$6*D7 -> 73.05
A8: 2.2 | B8: Профиль маячковый_/ПМ6 | C8: пог. м | D8: 1 | E8: =$E$6*D8 -> 292.2
A9: 2.3 | B9: Штукатурка гипсовая | C9: кг | D9: 1 | E9: =$E$6*D9*28.57 -> 8348.154
A10: 3 | B10: ='1.n2'!B10 -> Штукатурка стен гипсовыми смесями с предварительной огрунтовкой СКБ / толщ. от 21 до 40 мм / высотой от 4,01 до 8 метров (Штукатурка по газобетонному блоку и ПГП) | C10: м² | D10: 1 | E10: =252.9-12.3 -> 240.6
A11: 3.1 | B11: Штукатурка гипсовая | C11: кг | D11: 1 | E11: =$E$10*D11*32.51 -> 7821.906
A12: 3.2 | B12: Грунтовка универсальный ЛАСТИМИН_ / LP-51 А | C12: кг | D12: 0.15 | E12: =$E$10*D12 -> 36.09
A13: 3.3 | B13: Профиль маячковый_/ПМ6 | C13: пог. м | D13: 1 | E13: =$E$10*D13 -> 240.6
A14: 3.4 | B14: Профиль углозащитный оцинкованный 31х31 мм 0,5 мм | C14: пог. м | D14: 1 | E14: =32*8.25 -> 264
B16: Ведомость работ и используемых материалов (Шпаклевка базовая)
A17: № п.п. | B17: Наименование | C17: Ед. изм. | D17: Коэф. расхода | E17: Объем
A18: 1 | B18: ='1.n2'!B18 -> Подготовка поверхности СКБ / стен / по штукатурке / 2мм (Шпаклевка базовая) | C18: м² | D18: 1 | E18: =E10+E6 -> 532.8
A19: 1.1 | B19: Грунтовка универсальный ЛАСТИМИН_ / LP-51 А | C19: кг | D19: 0.15 | E19: =D19*E18 -> 79.92
A20: 1.2 | B20: Шпатлевка гипсовая_ / белая | C20: кг | D20: 1.8 | E20: =D20*E19 -> 143.856
A21: 1.3 | B21: Уголок малярный | C21: пог. м | D21: 0.3 | E21: =D21*E20 -> 43.1568
B29: 2

Sheet 9.n2
B1: Ведомость работ и используемых материалов (Штукатурка)
A2: № п.п. | B2: Наименование | C2: Ед. изм. | D2: Коэф. расхода | E2: Объем
A3: 1 | B3: Оклейка швов сопряжения бетонных и других поверхностей стен, перегородок (газобетон, ПГП, панели АКОТЕК и др.) стеклохолстом | C3: пог. м | D3: 1 | E3: =(170.6) -> 170.6
A4: 1.2 | B4: Штукатурка гипсовая | C4: кг | D4: 0.1 | E4: =D4*E3 -> 17.06
A5: 1.3 | B5: Лента армирующая ( серпянка)_/150мм | C5: пог. м | D5: 1.1 | E5: =D5*E3 -> 187.66
A6: 2 | B6: ='1.n2'!B6 -> Штукатурка стен гипсовыми смесями с предварительной огрунтовкой СКБ / толщ. от 21 до 40 мм / высотой от 4,01 до 8 метров (Штукатурка по ж/б поверхностям) | C6: м² | D6: 1 | E6: ='9.n;п.'!C14 -> 342.4
A7: 2.1 | B7: Грунтовка БЕТОН-КОНТАКТ | C7: кг | D7: 0.25 | E7: =$E$6*D7 -> 85.6
A8: 2.2 | B8: Профиль маячковый_/ПМ6 | C8: пог. м | D8: 1 | E8: =$E$6*D8 -> 342.4
A9: 2.3 | B9: Штукатурка гипсовая | C9: кг | D9: 1 | E9: =$E$6*D9*28.57 -> 9782.368
A10: 3 | B10: ='1.n2'!B10 -> Штукатурка стен гипсовыми смесями с предварительной огрунтовкой СКБ / толщ. от 21 до 40 мм / высотой от 4,01 до 8 метров (Штукатурка по газобетонному блоку и ПГП) | C10: м² | D10: 1 | E10: ='9.n;п.'!D14 -> 804.7
A11: 3.1 | B11: Штукатурка гипсовая | C11: кг | D11: 1 | E11: =$E$10*D11*32.51 -> 26160.797
A12: 3.2 | B12: Грунтовка универсальный ЛАСТИМИН_ / LP-51 А | C12: кг | D12: 0.15 | E12: =$E$10*D12 -> 120.705
A13: 3.3 | B13: Профиль маячковый_/ПМ6 | C13: пог. м | D13: 1 | E13: =$E$10*D13 -> 804.7
A14: 3.4 | B14: Профиль углозащитный оцинкованный 31х31 мм 0,5 мм | C14: пог. м | D14: 1 | E14: =75.75*4 -> 303
A15: 4 | B15: Штукатурка стен цементным, цементно-песчаным раствором с предварительной огрунтовкой / толщ. от 21 до 40 мм / высотой до 4 метров (Штукатурка по ж/б поверхностям) | C15: м2 | D15: 1 | E15: ='9.n;п.'!C25 -> 28
A16: 4.1 | B16: Грунтовка БЕТОН-КОНТАКТ_/ | C16: кг | D16: 0.25 | E16: =D16*$E$15 -> 7
A17: 4.2 | B17: Профиль маячковый_/ПМ6 | C17: пог. м | D17: 1 | E17: =D17*$E$15 -> 28
A18: 4.3 | B18: Сетка штукатурная_/пластиковая/5*5 | C18: м2 | D18: 1.1 | E18: =D18*$E$15 -> 30.8
A19: 4.4 | B19: Штукатурка цементная | C19: кг | D19: 1.3 | E19: =D19*$E$15*40 -> 1456
A20: 5 | B20: Штукатурка стен цементным, цементно-песчаным раствором с предварительной огрунтовкой / толщ. от 21 до 40 мм / высотой до 4 метров (Штукатурка по газобетонному блоку и ПГП) | C20: м2 | D20: 1 | E20: ='9.n;п.'!D25 -> 272.4
A21: 5.1 | B21: Грунтовка универсальный ЛАСТИМИН_ / LP-51 А | C21: кг | D21: 0.15 | E21: =$E$20*D21 -> 40.86
A22: 5.2 | B22: Профиль маячковый_/ПМ6 | C22: пог. м | D22: 1 | E22: =$E$20*D22 -> 272.4
A23: 5.3 | B23: Сетка штукатурная_/пластиковая/5*5 | C23: м2 | D23: 1.1 | E23: =$E$20*D23 -> 299.64
A24: 5.4 | B24: Штукатурка цементная | C24: кг | D24: 1.3 | E24: =$E$20*D24*40 -> 14164.8
B26: Ведомость работ и используемых материалов (Шпаклевка базовая)
A27: № п.п. | B27: Наименование | C27: Ед. изм. | D27: Коэф. расхода | E27: Объем
A28: 1 | B28: ='1.n2'!B18 -> Подготовка поверхности СКБ / стен / по штукатурке / 2мм (Шпаклевка базовая) | C28: м² | D28: 1 | E28: ='9.n;п.'!E14 -> 1147.1
A29: 1.1 | B29: Грунтовка универсальный ЛАСТИМИН_ / LP-51 А | C29: кг | D29: 0.15 | E29: =D29*E28 -> 172.065
A30: 1.2 | B30: Шпатлевка гипсовая_ / белая | C30: кг | D30: 1.8 | E30: =D30*E29 -> 309.717
A31: 1.3 | B31: Уголок малярный | C31: пог. м | D31: 0.3 | E31: =D31*E30 -> 92.9151

Sheet 9.n;п.
A1: Спецификация выполненных работ
A2: Штукатурка стен и базовая шпаклевка
C3: по ж/б поверхностям | D3: по газобетонному блоку и ПГП | E3: Итог
A4: № п.п. | B4: Помещения: | C4: Объем, м² | D4: Объем, м² | E4: Объем, м²
A5: 1 | B5: 2022 | C5: 192.3 | D5: 324.2 | E5: =SUM(C5:D5) -> 516.5
A6: 2 | B6: 2025 | C6: 33.1 | D6: 49.3 | E6: =SUM(C6:D6) -> 82.4
A7: 3 | B7: 2030 | C7: 11.6 | D7: 68.4 | E7: =SUM(C7:D7) -> 80
A8: 4 | B8: 2032 | C8: 5.1 | D8: 65.7 | E8: =SUM(C8:D8) -> 70.8
A9: 5 | B9: 2034 | C9: 0 | D9: 41.7 | E9: =SUM(C9:D9) -> 41.7
A10: 6 | B10: 2035 | C10: 3.1 | D10: 34.8 | E10: =SUM(C10:D10) -> 37.9
A11: 7 | B11: 2065 | C11: 1.6 | D11: 26.4 | E11: =SUM(C11:D11) -> 28
A12: 8 | B12: 2067 | C12: 56.5 | D12: 176.9 | E12: =SUM(C12:D12) -> 233.4
A13: 9 | B13: 2068 | C13: 39.1 | D13: 17.3 | E13: =SUM(C13:D13) -> 56.4
B14: Сумма | C14: =SUM(C5:C13) -> 342.4 | D14: =SUM(D5:D13) -> 804.7 | E14: =SUM(E5:E13) -> 1147.1
A16: Спецификация выполненных работ
A17: Штукатурка стен (штук. цементная)
C18: по ж/б поверхностям | D18: по газобетонному блоку и ПГП | E18: Итог
A19: № п.п. | B19: Помещения: | C19: Объем, м² | D19: Объем, м² | E19: Объем, м²
A20: 1 | B20: 2026 | C20: 3.6 | D20: 55.2 | E20: =SUM(C20:D20) -> 58.8
A21: 2 | B21: 2027 | C21: 9.5 | D21: 36.3 | E21: =SUM(C21:D21) -> 45.8
A22: 3 | B22: 2028 | C22: 5.3 | D22: 75.7 | E22: =SUM(C22:D22) -> 81
A23: 4 | B23: 2029 | C23: 3.4 | D23: 38.3 | E23: =SUM(C23:D23) -> 41.7
A24: 5 | B24: 2031 | C24: 6.2 | D24: 66.9 | E24: =SUM(C24:D24) -> 73.1
B25: Сумма | C25: =SUM(C19:C24) -> 28 | D25: =SUM(D19:D24) -> 272.4 | E25: =SUM(E19:E24) -> 300.4

Sheet 10.n3
B1: Ведомость работ и используемых материалов (Штукатурка)
A2: № п.п. | B2: Наименование | C2: Ед. изм. | D2: Коэф. расхода | E2: Объем
A3: 1 | B3: Оклейка швов сопряжения бетонных и других поверхностей стен, перегородок (газобетон, ПГП, панели АКОТЕК и др.) стеклохолстом | C3: пог. м | D3: 1 | E3: =194.7 -> 194.7
A4: 1.2 | B4: Штукатурка гипсовая | C4: кг | D4: 0.1 | E4: =D4*E3 -> 19.47
A5: 1.3 | B5: Лента армирующая ( серпянка)_/150мм | C5: пог. м | D5: 1.1 | E5: =D5*E3 -> 214.17
A6: 2 | B6: ='1.n2'!B6 -> Штукатурка стен гипсовыми смесями с предварительной огрунтовкой СКБ / толщ. от 21 до 40 мм / высотой от 4,01 до 8 метров (Штукатурка по ж/б поверхностям) | C6: м² | D6: 1 | E6: ='10.n;п.'!C12 -> 273.8
A7: 2.1 | B7: Грунтовка БЕТОН-КОНТАКТ | C7: кг | D7: 0.25 | E7: =$E$6*D7 -> 68.45
A8: 2.2 | B8: Профиль маячковый_/ПМ6 | C8: пог. м | D8: 1 | E8: =$E$6*D8 -> 273.8
A9: 2.3 | B9: Штукатурка гипсовая | C9: кг | D9: 1 | E9: =$E$6*D9*28.57 -> 7822.466
A10: 3 | B10: ='1.n2'!B10 -> Штукатурка стен гипсовыми смесями с предварительной огрунтовкой СКБ / толщ. от 21 до 40 мм / высотой от 4,01 до 8 метров (Штукатурка по газобетонному блоку и ПГП) | C10: м² | D10: 1 | E10: ='10.n;п.'!D12 -> 954.3
A11: 3.1 | B11: Штукатурка гипсовая | C11: кг | D11: 1 | E11: =$E$10*D11*32.51 -> 31024.293
A12: 3.2 | B12: Грунтовка универсальный ЛАСТИМИН_ / LP-51 А | C12: кг | D12: 0.15 | E12: =$E$10*D12 -> 143.145
A13: 3.3 | B13: Профиль маячковый_/ПМ6 | C13: пог. м | D13: 1 | E13: =$E$10*D13 -> 954.3
A14: 3.4 | B14: Профиль углозащитный оцинкованный 31х31 мм 0,5 мм | C14: пог. м | D14: 1 | E14: =75.75*4 -> 303
A15: 4 | B15: Штукатурка стен цементным, цементно-песчаным раствором с предварительной огрунтовкой / толщ. от 21 до 40 мм / высотой до 4 метров (Штукатурка по ж/б поверхностям) | C15: м2 | D15: 1 | E15: ='10.n;п.'!C19 -> 2.9
A16: 4.1 | B16: Грунтовка БЕТОН-КОНТАКТ_/ | C16: кг | D16: 0.25 | E16: =D16*$E$15 -> 0.725
A17: 4.2 | B17: Профиль маячковый_/ПМ6 | C17: пог. м | D17: 1 | E17: =D17*$E$15 -> 2.9
A18: 4.3 | B18: Сетка штукатурная_/пластиковая/5*5 | C18: м2 | D18: 1.1 | E18: =D18*$E$15 -> 3.19
A19: 4.4 | B19: Штукатурка цементная | C19: кг | D19: 1.3 | E19: =D19*$E$15*40 -> 150.8
A20: 5 | B20: Штукатурка стен цементным, цементно-песчаным раствором с предварительной огрунтовкой / толщ. от 21 до 40 мм / высотой до 4 метров (Штукатурка по газобетонному блоку и ПГП) | C20: м2 | D20: 1 | E20: ='10.n;п.'!D19 -> 37.4
A21: 5.1 | B21: Грунтовка универсальный ЛАСТИМИН_ / LP-51 А | C21: кг | D21: 0.15 | E21: =$E$20*D21 -> 5.61
A22: 5.2 | B22: Профиль маячковый_/ПМ6 | C22: пог. м | D22: 1 | E22: =$E$20*D22 -> 37.4
A23: 5.3 | B23: Сетка штукатурная_/пластиковая/5*5 | C23: м2 | D23: 1.1 | E23: =$E$20*D23 -> 41.14
A24: 5.4 | B24: Штукатурка цементная | C24: кг | D24: 1.3 | E24: =$E$20*D24*40 -> 1944.8
B26: Ведомость работ и используемых материалов (Шпаклевка базовая)
A27: № п.п. | B27: Наименование | C27: Ед. изм. | D27: Коэф. расхода | E27: Объем
A28: 1 | B28: ='1.n2'!B18 -> Подготовка поверхности СКБ / стен / по штукатурке / 2мм (Шпаклевка базовая) | C28: м² | D28: 1 | E28: ='10.n;п.'!E12 -> 1228.1
A29: 1.1 | B29: Грунтовка универсальный ЛАСТИМИН_ / LP-51 А | C29: кг | D29: 0.15 | E29: =D29*E28 -> 184.215
A30: 1.2 | B30: Шпатлевка гипсовая_ / белая | C30: кг | D30: 1.8 | E30: =D30*E29 -> 331.587
A31: 1.3 | B31: Уголок малярный | C31: пог. м | D31: 0.3 | E31: =D31*E30 -> 99.4761

Sheet 10.n;п.
A1: Спецификация выполненных работ
A2: Штукатурка стен и базовая шпаклевка
C3: по ж/б поверхностям | D3: по газобетонному блоку и ПГП | E3: Итог
A4: № п.п. | B4: Помещения: | C4: Объем, м² | D4: Объем, м² | E4: Объем, м²
A5: 1 | B5: 3019 | C5: 38.1 | D5: 255.3 | E5: =SUM(C5:D5) -> 293.4
A6: 2 | B6: 3021 | C6: 15.7 | D6: 61.7 | E6: =SUM(C6:D6) -> 77.4
A7: 3 | B7: 3022 | C7: 52.8 | D7: 78.4 | E7: =SUM(C7:D7) -> 131.2
A8: 4 | B8: 3023 | C8: 79.7 | D8: 267.3 | E8: =SUM(C8:D8) -> 347
A9: 5 | B9: 3025 | C9: 0 | D9: 42.2 | E9: =SUM(C9:D9) -> 42.2
A10: 6 | B10: 3048 | C10: 36.2 | D10: 131.5 | E10: =SUM(C10:D10) -> 167.7
A11: 7 | B11: 3063 | C11: 51.3 | D11: 117.9 | E11: =SUM(C11:D11) -> 169.2
B12: Сумма | C12: =SUM(C5:C11) -> 273.8 | D12: =SUM(D5:D11) -> 954.3 | E12: =SUM(E5:E11) -> 1228.1
A14: Спецификация выполненных работ
A15: Штукатурка стен (штук. цементная)
C16: по ж/б поверхностям | D16: по газобетонному блоку и ПГП | E16: Итог
A17: № п.п. | B17: Помещения: | C17: Объем, м² | D17: Объем, м² | E17: Объем, м²
A18: 1 | B18: 3026 | C18: 2.9 | D18: 37.4 | E18: =SUM(C18:D18) -> 40.3
B19: Сумма | C19: =SUM(C17:C18) -> 2.9 | D19: =SUM(D17:D18) -> 37.4 | E19: =SUM(E17:E18) -> 40.3

Sheet Лист1
A1: Номер п/п | B1: Код узла ИСР | C1: Наименование затрат | D1: Комментарий по ИСР | E1: Комментарий подрядчика | F1: Ед. изм. | G1: Коэф.расхода | H1: Общее кол-во | I1: Осталось закрыть | J1: Сумма | K1: 1.n | L1: 2.n | M1: 3.n | N1: 4.n | O1: 5.n | P1: 6.n | Q1: 7.n | R1: 8.n | S1: 9.n | T1: 10.n | U1: 11.n | V1: 12.n | Y1: 7 | Z1: 6 | AA1: 5 | AB1: 4 | AC1: 3 | AD1: 2 | AE1: 1
A2: 1.1.1.1.1.2 | B2: 6.3.1.5.2 | C2: Стены | J2: =SUM(Таблица2[[#This Row],[1.n]:[12.n]]) -> 0 | K2: ='1.n2'!E1 -> 0 | L2: ='2.n2'!E1 -> 0 | M2: ='3.n2'!E1 -> 0 | N2: ='4.n2'!E1 -> 0 | O2: ='5.n3'!E1 -> 0 | P2: ='6.n3э'!E1 -> 0 | Q2: ='7.n2'!E1 -> 0 | R2: ='8.n2'!E1 -> 0 | S2: ='9.n2'!E1 -> 0 | T2: ='10.n3'!E1 -> 0
A3: 1.1.1.1.1.2.1 | B3: 6.3.1.5.2.1 | C3: Черновые работы по поверхности стен | J3: =SUM(Таблица2[[#This Row],[1.n]:[12.n]]) -> 0 | K3: ='1.n2'!E2 -> Объем | L3: ='2.n2'!E2 -> Объем | M3: ='3.n2'!E2 -> Объем | N3: ='4.n2'!E2 -> Объем | O3: ='5.n3'!E2 -> Объем | P3: ='6.n3э'!E2 -> Объем | Q3: ='7.n2'!E2 -> Объем | R3: ='8.n2'!E2 -> Объем | S3: ='9.n2'!E2 -> Объем | T3: ='10.n3'!E2 -> Объем
A4: 1.1.1.1.1.2.1.1 | B4: 6.3.1.5.2.1.1.1 | C4: Оклейка швов сопряжения бетонных и других поверхностей стен, перегородок (газобетон, ПГП, панели АКОТЕК и др.) стеклохолстом | E4: 2эт - 1826,61м.п., 3эт. - 2045,25м.п. | F4: пог. м | G4: 1 | H4: 3479 | I4: =Таблица2[[#This Row],[Общее кол-во]]-SUM(Таблица2[[#This Row],[1.n]:[12.n]]) -> -1270.135 | J4: =SUM(Таблица2[[#This Row],[1.n]:[12.n]]) -> 4749.135 | K4: ='1.n2'!E3 -> 267.16 | L4: ='2.n2'!E3 -> 233 | M4: ='3.n2'!E3 -> 323.32 | N4: ='4.n2'!E3 -> 396.86 | O4: ='5.n3'!E3 -> 1102 | P4: ='6.n3э'!E3 -> 852.66 | Q4: ='7.n2'!E3 -> 969.075 | R4: ='8.n2'!E3 -> 239.76 | S4: ='9.n2'!E3 -> 170.6 | T4: ='10.n3'!E3 -> 194.7
A5: 1.1.1.1.1.2.1.1.1 | C5: Шпатлевка гипсовая_ / белая / Унифицированная по ПИК-СТАНДАРТ, 30кг | F5: кг | G5: 0.3 | H5: 1043.7 | I5: =Таблица2[[#This Row],[Общее кол-во]]-SUM(Таблица2[[#This Row],[1.n]:[11.n]]) -> 568.7865 | J5: =SUM(Таблица2[[#This Row],[1.n]:[12.n]]) -> 474.9135 | K5: ='1.n2'!E4 -> 26.716 | L5: ='2.n2'!E4 -> 23.3 | M5: ='3.n2'!E4 -> 32.332 | N5: ='4.n2'!E4 -> 39.686 | O5: ='5.n3'!E4 -> 110.2 | P5: ='6.n3э'!E4 -> 85.266 | Q5: ='7.n2'!E4 -> 96.9075 | R5: ='8.n2'!E4 -> 23.976 | S5: ='9.n2'!E4 -> 17.06 | T5: ='10.n3'!E4 -> 19.47
A6: 1.1.1.1.1.2.1.1.2 | C6: Лента армирующая ( серпянка)_/150мм | F6: пог. м | G6: 1.1 | H6: 3826.9 | I6: =Таблица2[[#This Row],[Общее кол-во]]-SUM(Таблица2[[#This Row],[1.n]:[11.n]]) -> -1397.1485 | J6: =SUM(Таблица2[[#This Row],[1.n]:[12.n]]) -> 5224.0485 | K6: ='1.n2'!E5 -> 293.876 | L6: ='2.n2'!E5 -> 256.3 | M6: ='3.n2'!E5 -> 355.652 | N6: ='4.n2'!E5 -> 436.546 | O6: ='5.n3'!E5 -> 1212.2 | P6: ='6.n3э'!E5 -> 937.926 | Q6: ='7.n2'!E5 -> 1065.9825 | R6: ='8.n2'!E5 -> 263.736 | S6: ='9.n2'!E5 -> 187.66 | T6: ='10.n3'!E5 -> 214.17
A7: 1.1.1.1.1.2.1.2 | B7: 6.3.1.5.2.1.2.3 | C7: Штукатурка стен сухими смесями с установкой маяков с предварительной огрунтовкой / толщ. от 16,5 мм до 21 мм | E7: 2 этаж | F7: м2 | G7: 1 | H7: 0 | I7: =Таблица2[[#This Row],[Общее кол-во]]-SUM(Таблица2[[#This Row],[1.n]:[11.n]]) -> -5009.368 | J7: =SUM(Таблица2[[#This Row],[1.n]:[12.n]]) -> 5009.368 | K7: ='1.n2'!E6 -> 410.02 | L7: ='2.n2'!E6 -> 333.82 | M7: ='3.n2'!E6 -> 161.17 | N7: ='4.n2'!E6 -> 361.91848 | O7: ='5.n3'!E6 -> 1389.7395 | P7: ='6.n3э'!E6 -> 719.9 | Q7: ='7.n2'!E6 -> 724.4 | R7: ='8.n2'!E6 -> 292.2 | S7: ='9.n2'!E6 -> 342.4 | T7: ='10.n3'!E6 -> 273.8
A8: 1.1.1.1.1.2.1.2.1 | C8: Штукатурка гипсовая_ / Унифицированная по ПИК-СТАНДАРТ, 30кг | E8: Штукатурка гипсовая Старатели Старт 30 кг | F8: кг | G8: 1 | H8: 0 | I8: =Таблица2[[#This Row],[Общее кол-во]]-SUM(Таблица2[[#This Row],[1.n]:[11.n]]) -> -1252.342 | J8: =SUM(Таблица2[[#This Row],[1.n]:[12.n]]) -> 1252.342 | K8: ='1.n2'!E7 -> 102.505 | L8: ='2.n2'!E7 -> 83.455 | M8: ='3.n2'!E7 -> 40.2925 | N8: ='4.n2'!E7 -> 90.479619 | O8: ='5.n3'!E7 -> 347.43489 | P8: ='6.n3э'!E7 -> 179.975 | Q8: ='7.n2'!E7 -> 181.1 | R8: ='8.n2'!E7 -> 73.05 | S8: ='9.n2'!E7 -> 85.6 | T8: ='10.n3'!E7 -> 68.45
A9: 1.1.1.1.1.2.1.2.2 | C9: Грунтовка БЕТОН-КОНТАКТ_/ | F9: кг | G9: 0.25 | H9: 0 | I9: =Таблица2[[#This Row],[Общее кол-во]]-SUM(Таблица2[[#This Row],[1.n]:[11.n]]) -> -5009.368 | J9: =SUM(Таблица2[[#This Row],[1.n]:[12.n]]) -> 5009.368 | K9: ='1.n2'!E8 -> 410.02 | L9: ='2.n2'!E8 -> 333.82 | M9: ='3.n2'!E8 -> 161.17 | N9: ='4.n2'!E8 -> 361.91848 | O9: ='5.n3'!E8 -> 1389.7395 | P9: ='6.n3э'!E8 -> 719.9 | Q9: ='7.n2'!E8 -> 724.4 | R9: ='8.n2'!E8 -> 292.2 | S9: ='9.n2'!E8 -> 342.4 | T9: ='10.n3'!E8 -> 273.8
A10: 1.1.1.1.1.2.1.2.3 | C10: Профиль маячковый_/ПМ6 | F10: пог. м | G10: 1.05 | H10: 0 | I10: =Таблица2[[#This Row],[Общее кол-во]]-SUM(Таблица2[[#This Row],[1.n]:[11.n]]) -> -131813.39 | J10: =SUM(Таблица2[[#This Row],[1.n]:[12.n]]) -> 131813.39 | K10: ='1.n2'!E9 -> 410.02 | L10: ='2.n2'!E9 -> 9537.2374 | M10: ='3.n2'!E9 -> 4604.6269 | N10: ='4.n2'!E9 -> 10340.011 | O10: ='5.n3'!E9 -> 39704.859 | P10: ='6.n3э'!E9 -> 20567.543 | Q10: ='7.n2'!E9 -> 20696.108 | R10: ='8.n2'!E9 -> 8348.154 | S10: ='9.n2'!E9 -> 9782.368 | T10: ='10.n3'!E9 -> 7822.466
A11: 1.1.1.1.1.2.1.3 | B11: 6.3.1.5.2.1.4.2 | C11: Выравнивание стен с предварительной огрунтовкой / по оштукатуренной поверхности / толщ. 2 мм | E11: 2 этаж. Шпатлёвка базовая | F11: м2 | G11: 1 | H11: 0 | I11: =Таблица2[[#This Row],[Общее кол-во]]-SUM(Таблица2[[#This Row],[1.n]:[11.n]]) -> -8959.4017 | J11: =SUM(Таблица2[[#This Row],[1.n]:[12.n]]) -> 8959.4017 | K11: ='1.n2'!E10 -> 603.16 | L11: ='2.n2'!E10 -> 502.91 | M11: ='3.n2'!E10 -> 341.47 | N11: ='4.n2'!E10 -> 697.45979 | O11: ='5.n3'!E10 -> 2747.8019 | P11: ='6.n3э'!E10 -> 918.5 | Q11: ='7.n2'!E10 -> 1148.5 | R11: ='8.n2'!E10 -> 240.6 | S11: ='9.n2'!E10 -> 804.7 | T11: ='10.n3'!E10 -> 954.3
A12: 1.1.1.1.1.2.1.3.1 | C12: Шпатлевка гипсовая_ / белая / Унифицированная по ПИК-СТАНДАРТ, 30кг | E12: Шпаклевка гипсовая Старатели базовая белая 20 кг | F12: кг | G12: 1.8 | H12: 0 | I12: =Таблица2[[#This Row],[Общее кол-во]]-SUM(Таблица2[[#This Row],[1.n]:[11.n]]) -> -272264.58 | J12: =SUM(Таблица2[[#This Row],[1.n]:[12.n]]) -> 272264.58 | K12: ='1.n2'!E11 -> 603.16 | L12: ='2.n2'!E11 -> 16349.604 | M12: ='3.n2'!E11 -> 11101.19 | N12: ='4.n2'!E11 -> 22674.418 | O12: ='5.n3'!E11 -> 89331.04 | P12: ='6.n3э'!E11 -> 29860.435 | Q12: ='7.n2'!E11 -> 37337.735 | R12: ='8.n2'!E11 -> 7821.906 | S12: ='9.n2'!E11 -> 26160.797 | T12: ='10.n3'!E11 -> 31024.293
A13: 1.1.1.1.1.2.1.3.2 | C13: Уголок малярный_ / L=3м /25х25 мм | F13: шт | G13: 0.3 | H13: 0 | I13: =Таблица2[[#This Row],[Общее кол-во]]-SUM(Таблица2[[#This Row],[1.n]:[11.n]]) -> -1343.9103 | J13: =SUM(Таблица2[[#This Row],[1.n]:[12.n]]) -> 1343.9103 | K13: ='1.n2'!E12 -> 90.474 | L13: ='2.n2'!E12 -> 75.4365 | M13: ='3.n2'!E12 -> 51.2205 | N13: ='4.n2'!E12 -> 104.61897 | O13: ='5.n3'!E12 -> 412.17029 | P13: ='6.n3э'!E12 -> 137.775 | Q13: ='7.n2'!E12 -> 172.275 | R13: ='8.n2'!E12 -> 36.09 | S13: ='9.n2'!E12 -> 120.705 | T13: ='10.n3'!E12 -> 143.145
A14: 1.1.1.1.1.2.1.3.3 | C14: Лента армированная Серпянка 150мм | F14: пог. м | G14: 1 | H14: 0 | I14: =Таблица2[[#This Row],[Общее кол-во]]-SUM(Таблица2[[#This Row],[1.n]:[11.n]]) -> -8959.4017 | J14: =SUM(Таблица2[[#This Row],[1.n]:[12.n]]) -> 8959.4017 | K14: ='1.n2'!E13 -> 603.16 | L14: ='2.n2'!E13 -> 502.91 | M14: ='3.n2'!E13 -> 341.47 | N14: ='4.n2'!E13 -> 697.45979 | O14: ='5.n3'!E13 -> 2747.8019 | P14: ='6.n3э'!E13 -> 918.5 | Q14: ='7.n2'!E13 -> 1148.5 | R14: ='8.n2'!E13 -> 240.6 | S14: ='9.n2'!E13 -> 804.7 | T14: ='10.n3'!E13 -> 954.3
A15: 1.1.1.1.1.2.1.3.4 | C15: Грунтовка универсальный ЛАСТИМИН_ / LP-51 А | F15: кг | G15: 0.15 | H15: 0 | I15: =Таблица2[[#This Row],[Общее кол-во]]-SUM(Таблица2[[#This Row],[1.n]:[11.n]]) -> -2809.55 | J15: =SUM(Таблица2[[#This Row],[1.n]:[12.n]]) -> 2809.55 | K15: ='1.n2'!E14 -> 295.41 | L15: ='2.n2'!E14 -> 97.47 | M15: ='3.n2'!E14 -> 97.97 | N15: ='4.n2'!E14 -> 59.7 | O15: ='5.n3'!E14 -> 943 | P15: ='6.n3э'!E14 -> 143 | Q15: ='7.n2'!E14 -> 303 | R15: ='8.n2'!E14 -> 264 | S15: ='9.n2'!E14 -> 303 | T15: ='10.n3'!E14 -> 303
A16: 1.1.1.1.1.2.1.4 | B16: 6.3.1.5.2.1.4.2 | C16: Выравнивание стен с предварительной огрунтовкой / по оштукатуренной поверхности / толщ. 2 мм | E16: 2 этаж. Шпатлёвка финишная | F16: м2 | G16: 1 | H16: 0 | I16: =Таблица2[[#This Row],[Общее кол-во]]-SUM(Таблица2[[#This Row],[1.n]:[11.n]]) -> -152.4 | J16: =SUM(Таблица2[[#This Row],[1.n]:[12.n]]) -> 152.4 | K16: ='1.n2'!E15 -> 0 | L16: ='2.n2'!E15 -> 0 | M16: ='3.n2'!E15 -> 0 | N16: ='4.n2'!E15 -> 0 | O16: ='5.n3'!E15 -> 0 | P16: ='6.n3э'!E15 -> 62.5 | Q16: ='7.n2'!E15 -> 59 | R16: ='8.n2'!E15 -> 0 | S16: ='9.n2'!E15 -> 28 | T16: ='10.n3'!E15 -> 2.9
A17: 1.1.1.1.1.2.1.4.1 | C17: Грунтовка универсальный ЛАСТИМИН_ / LP-51 А | F17: кг | G17: 0.15 | H17: 0 | I17: =Таблица2[[#This Row],[Общее кол-во]]-SUM(Таблица2[[#This Row],[1.n]:[11.n]]) -> -38.1 | J17: =SUM(Таблица2[[#This Row],[1.n]:[12.n]]) -> 38.1 | K17: ='1.n2'!E16 -> 0 | L17: ='2.n2'!E16 -> 0 | M17: ='3.n2'!E16 -> 0 | N17: ='4.n2'!E16 -> 0 | O17: ='5.n3'!E16 -> 0 | P17: ='6.n3э'!E16 -> 15.625 | Q17: ='7.n2'!E16 -> 14.75 | R17: ='8.n2'!E16 -> 0 | S17: ='9.n2'!E16 -> 7 | T17: ='10.n3'!E16 -> 0.725
A18: 1.1.1.1.1.2.1.4.2 | C18: Шпатлевка гипсовая_ / белая / Унифицированная по ПИК-СТАНДАРТ, 30кг | E18: Шпаклевка гипсовая Старатели финишная 20 кг | F18: кг | G18: 1.8 | H18: 0 | I18: =Таблица2[[#This Row],[Общее кол-во]]-SUM(Таблица2[[#This Row],[1.n]:[11.n]]) -> -152.4 | J18: =SUM(Таблица2[[#This Row],[1.n]:[12.n]]) -> 152.4 | K18: ='1.n2'!E17 -> Объем | L18: ='2.n2'!E17 -> Объем | M18: ='3.n2'!E17 -> Объем | N18: ='4.n2'!E17 -> Объем | O18: ='5.n3'!E17 -> Объем | P18: ='6.n3э'!E17 -> 62.5 | Q18: ='7.n2'!E17 -> 59 | R18: ='8.n2'!E17 -> Объем | S18: ='9.n2'!E17 -> 28 | T18: ='10.n3'!E17 -> 2.9
A19: 1.1.1.1.1.2.1.5 | B19: 6.3.1.5.2.1.8.5 | C19: Подготовка поверхности СКБ / стен / по штукатурке / 2мм | E19: 2 этаж. Шпаклевка финишная для высококачественной отделки. | F19: м2 | G19: 1 | H19: 8128.4 | I19: =Таблица2[[#This Row],[Общее кол-во]]-SUM(Таблица2[[#This Row],[1.n]:[12.n]]) -> 8128.4 | J19: =SUM(Таблица2[[#This Row],[1.n]:[12.n]]) -> 0 | Y19: =(Y36+Y41+Y56+Y60)*0.19 -> 244.15 | Z19: =(Z36+Z41+Z56+Z60)*0.19 -> 188.689 | AA19: =(AA36+AA41+AA56+AA60)*0.19 -> 139.536 | AB19: =(AB36+AB41+AB56+AB60)*0.19 -> 328.225 | AC19: =(AC36+AC41+AC56+AC60)*0.19 -> 336.775 | AD19: =(AD36+AD41+AD56+AD60)*0.19 -> 183.027 | AE19: =(AE36+AE41+AE56+AE60)*0.19 -> 283.689 | AF19: швы 2эт
A20: 1.1.1.1.1.2.1.5.1 | C20: Шпатлевка финишная TERRACO HANDYCOAT ALL PURPOSE | F20: кг | G20: 1 | H20: 8128.4 | I20: =Таблица2[[#This Row],[Общее кол-во]]-SUM(Таблица2[[#This Row],[1.n]:[11.n]]) -> -1008.7405 | J20: =SUM(Таблица2[[#This Row],[1.n]:[12.n]]) -> 9137.1405 | K20: ='1.n2'!E19 -> 151.977 | L20: ='2.n2'!E19 -> 125.5095 | M20: ='3.n2'!E19 -> 75.396 | N20: ='4.n2'!E19 -> 158.90674 | O20: ='5.n3'!E19 -> 620.63122 | P20: ='6.n3э'!E19 -> 3250 | Q20: ='7.n2'!E19 -> 3068 | R20: ='8.n2'!E19 -> 79.92 | S20: ='9.n2'!E19 -> 1456 | T20: ='10.n3'!E19 -> 150.8 | Y20: =(Y37+Y42+Y57+Y61)*0.2037 -> 0 | Z20: =(Z37+Z42+Z57+Z61)*0.2037 -> 0 | AA20: =(AA37+AA42+AA57+AA61)*0.2037 -> 0 | AB20: =(AB37+AB42+AB57+AB61)*0.2037 -> 0 | AC20: =(AC37+AC42+AC57+AC61)*0.2037 -> 0 | AD20: =(AD37+AD42+AD57+AD61)*0.2037 -> 0 | AE20: =(AE37+AE42+AE57+AE61)*0.2037 -> 0
A21: 1.1.1.1.1.2.1.5.2 | C21: Грунтовка универсальный ЛАСТИМИН_ / LP-51 А | F21: кг | G21: 0.15 | H21: 1219.26 | I21: =Таблица2[[#This Row],[Общее кол-во]]-SUM(Таблица2[[#This Row],[1.n]:[11.n]]) -> -13238.942 | J21: =SUM(Таблица2[[#This Row],[1.n]:[12.n]]) -> 14458.202 | K21: ='1.n2'!E20 -> 1823.724 | L21: ='2.n2'!E20 -> 1506.114 | M21: ='3.n2'!E20 -> 904.752 | N21: ='4.n2'!E20 -> 1906.8809 | O21: ='5.n3'!E20 -> 7447.5746 | P21: ='6.n3э'!E20 -> 193.9 | Q21: ='7.n2'!E20 -> 221.6 | R21: ='8.n2'!E20 -> 143.856 | S21: ='9.n2'!E20 -> 272.4 | T21: ='10.n3'!E20 -> 37.4 | Y21: =(Y38+Y43+Y58+Y62)*0.2037 -> 0 | Z21: =(Z38+Z43+Z58+Z62)*0.2037 -> 0 | AA21: =(AA38+AA43+AA58+AA62)*0.2037 -> 0 | AB21: =(AB38+AB43+AB58+AB62)*0.2037 -> 0 | AC21: =(AC38+AC43+AC58+AC62)*0.2037 -> 0 | AD21: =(AD38+AD43+AD58+AD62)*0.2037 -> 0 | AE21: =(AE38+AE43+AE58+AE62)*0.2037 -> 0
A22: 1.1.1.1.1.2.1.6 | B22: 6.3.1.5.2.1.8.5 | C22: Подготовка поверхности СКБ / стен / по штукатурке / 2мм | E22: 3 этаж. Шпаклевка финишная для высококачественной отделки. | F22: м2 | G22: 1 | H22: 7374 | I22: =Таблица2[[#This Row],[Общее кол-во]]-SUM(Таблица2[[#This Row],[1.n]:[12.n]]) -> 7374 | J22: =SUM(Таблица2[[#This Row],[1.n]:[12.n]]) -> 0 | Y22: =(Y46+Y51+Y64+Y68)*0.24 -> 364.032 | Z22: =(Z46+Z51+Z64+Z68)*0.24 -> 301.392 | AA22: =(AA46+AA51+AA64+AA68)*0.24 -> 86.904 | AB22: =(AB46+AB51+AB64+AB68)*0.24 -> 347.472 | AC22: =(AC46+AC51+AC64+AC68)*0.24 -> 287.52 | AD22: =(AD46+AD51+AD64+AD68)*0.24 -> 229.968 | AE22: =(AE46+AE51+AE64+AE68)*0.24 -> 308.64 | AF22: швы 3эт
A23: 1.1.1.1.1.2.1.6.1 | C23: Грунтовка универсальный ЛАСТИМИН_ / LP-51 А | F23: кг | G23: 0.15 | H23: 1106.1 | I23: =Таблица2[[#This Row],[Общее кол-во]]-SUM(Таблица2[[#This Row],[1.n]:[11.n]]) -> 380.8 | J23: =SUM(Таблица2[[#This Row],[1.n]:[12.n]]) -> 725.3 | K23: ='1.n2'!E22 -> 0 | L23: ='2.n2'!E22 -> 0 | M23: ='3.n2'!E22 -> 0 | N23: ='4.n2'!E22 -> 0 | O23: ='5.n3'!E22 -> 0 | P23: ='6.n3э'!E22 -> 193.9 | Q23: ='7.n2'!E22 -> 221.6 | R23: ='8.n2'!E22 -> 0 | S23: ='9.n2'!E22 -> 272.4 | T23: ='10.n3'!E22 -> 37.4
A24: 1.1.1.1.1.2.1.6.2 | C24: Шпатлевка финишная TERRACO HANDYCOAT ALL PURPOSE | F24: кг | G24: 1 | H24: 7374 | I24: =Таблица2[[#This Row],[Общее кол-во]]-SUM(Таблица2[[#This Row],[1.n]:[11.n]]) -> 6576.17 | J24: =SUM(Таблица2[[#This Row],[1.n]:[12.n]]) -> 797.83 | K24: ='1.n2'!E23 -> 0 | L24: ='2.n2'!E23 -> 0 | M24: ='3.n2'!E23 -> 0 | N24: ='4.n2'!E23 -> 0 | O24: ='5.n3'!E23 -> 0 | P24: ='6.n3э'!E23 -> 213.29 | Q24: ='7.n2'!E23 -> 243.76 | R24: ='8.n2'!E23 -> 0 | S24: ='9.n2'!E23 -> 299.64 | T24: ='10.n3'!E23 -> 41.14
A25: 1.1.1.1.1.2.1.7 | B25: 6.3.1.5.2.1.8.5 | C25: Подготовка поверхности СКБ / стен / по штукатурке / 2мм | E25: 2 этаж. Шпаклевка базовая. | F25: м2 | G25: 1 | H25: 8128.4 | I25: =Таблица2[[#This Row],[Общее кол-во]]-SUM(Таблица2[[#This Row],[1.n]:[12.n]]) -> 1163.6717 | J25: =SUM(Таблица2[[#This Row],[1.n]:[12.n]]) -> 6964.7283 | K25: ='1.n2'!E18 -> 1013.18 | L25: ='2.n2'!E18 -> 836.73 | M25: ='3.n2'!E18 -> 502.64 | N25: ='4.n2'!E18 -> 1059.3783 | Q25: ='7.n2'!E28 -> 1872.9 | R25: ='8.n2'!E18 -> 532.8 | S25: ='9.n2'!E28 -> 1147.1 | U25: 0 | Y25: =SUM(Y56:Y60) -> 1285 | Z25: =SUM(Z56:Z60) -> 747.3 | AA25: =SUM(AA56:AA60) -> 734.4 | AB25: 1883.2 | AC25: =SUM(AC56:AC60) -> 1319 | AD25: =SUM(AD56:AD60) -> 770.6 | AE25: =SUM(AE56:AE60) -> 1402.3 | AF25: =SUM(Y25:AE25)-Таблица2[[#This Row],[Общее кол-во]] -> 13.4
A26: 1.1.1.1.1.2.1.7.1 | C26: Шпатлевка гипсовая_ / белая / Унифицированная по ПИК-СТАНДАРТ, 30кг | F26: кг | G26: 1.8 | H26: 14631.12 | I26: =Таблица2[[#This Row],[Общее кол-во]]-SUM(Таблица2[[#This Row],[1.n]:[11.n]]) -> 14631.12 | J26: =SUM(Таблица2[[#This Row],[1.n]:[12.n]]) -> 0 | K26: ='1.n2'!E25 -> 0 | L26: ='2.n2'!E25 -> 0 | M26: ='3.n2'!E25 -> 0 | N26: ='4.n2'!E25 -> 0 | O26: ='5.n3'!E25 -> 0 | P26: ='6.n3э'!E25 -> 0 | Q26: ='7.n2'!E25 -> 0 | R26: ='8.n2'!E25 -> 0 | S26: ='9.n2'!E25 -> 0 | T26: ='10.n3'!E25 -> 0 | AF26: =SUM(Y26:AE26)-Таблица2[[#This Row],[Общее кол-во]] -> -14631.12
A27: 1.1.1.1.1.2.1.7.2 | C27: Грунтовка универсальный ЛАСТИМИН_ / LP-51 А | F27: кг | G27: 0.15 | H27: 1219.26 | I27: =Таблица2[[#This Row],[Общее кол-во]]-SUM(Таблица2[[#This Row],[1.n]:[11.n]]) -> 1219.26 | J27: =SUM(Таблица2[[#This Row],[1.n]:[12.n]]) -> 0 | K27: ='1.n2'!E26 -> 0 | L27: ='2.n2'!E26 -> 0 | M27: ='3.n2'!E26 -> 0 | N27: ='4.n2'!E26 -> 0 | O27: ='5.n3'!E26 -> 0 | P27: ='6.n3э'!E26 -> 0 | Q27: ='7.n2'!E26 -> 0 | R27: ='8.n2'!E26 -> 0 | S27: ='9.n2'!E26 -> 0 | T27: ='10.n3'!E26 -> 0 | AF27: =SUM(Y27:AE27)-Таблица2[[#This Row],[Общее кол-во]] -> -1219.26
A28: 1.1.1.1.1.2.1.8 | B28: 6.3.1.5.2.1.8.5 | C28: Подготовка поверхности СКБ / стен / по штукатурке / 2мм | E28: 3 этаж. Шпаклевка базовая. | F28: м2 | G28: 1 | H28: 7374 | I28: =Таблица2[[#This Row],[Общее кол-во]]-SUM(Таблица2[[#This Row],[1.n]:[12.n]]) -> 369.95854 | J28: =SUM(Таблица2[[#This Row],[1.n]:[12.n]]) -> 7004.0415 | O28: ='5.n3'!E18 -> 4137.5415 | P28: ='6.n3э'!E28 -> 1638.4 | T28: ='10.n3'!E28 -> 1228.1 | V28: 0 | Y28: =SUM(Y64:Y68) -> 1516.8 | Z28: =SUM(Z64:Z68) -> 1010 | AA28: =SUM(AA64:AA68) -> 362.1 | AB28: =SUM(AB64:AB68) -> 1293.1 | AC28: =SUM(AC64:AC68) -> 1155.9 | AD28: =SUM(AD64:AD68) -> 765 | AE28: =SUM(AE64:AE68) -> 1195.2 | AF28: =SUM(Y28:AE28)-Таблица2[[#This Row],[Общее кол-во]] -> -75.9 | AK28: 47.176551 | AL28: 52.823449 | AM28: 3479
A29: 1.1.1.1.1.2.1.8.1 | C29: Грунтовка универсальный ЛАСТИМИН_ / LP-51 А | F29: кг | G29: 0.15 | H29: 1106.1 | I29: =Таблица2[[#This Row],[Общее кол-во]]-SUM(Таблица2[[#This Row],[1.n]:[11.n]]) -> -4780.4 | J29: =SUM(Таблица2[[#This Row],[1.n]:[12.n]]) -> 5886.5 | K29: ='1.n2'!E28 -> 0 | L29: ='2.n2'!E28 -> 0 | M29: ='3.n2'!E28 -> 0 | N29: ='4.n2'!E28 -> 0 | O29: ='5.n3'!E28 -> 0 | P29: ='6.n3э'!E28 -> 1638.4 | Q29: ='7.n2'!E28 -> 1872.9 | R29: ='8.n2'!E28 -> 0 | S29: ='9.n2'!E28 -> 1147.1 | T29: ='10.n3'!E28 -> 1228.1 | AF29: =SUM(Y29:AE29)-Таблица2[[#This Row],[Общее кол-во]] -> -1106.1
